Workbook

Sheet Lundi 
B2: VILLE | AP2: =20/5 -> 4
C3: 10 | D3: 3 | E3: 2 | F3: 2 | G3: 3 | H3: 3 | I3: 1 | J3: 1 | K3: 1 | L3: 1 | M3: =+H3 -> 3 | N3: 1 | O3: =+H3 -> 3 | R3: =+(2*M3)/12 -> 0.5 | S3: =+(1*I3)/6 -> 0.16666667 | T3: =+(2*I3)/20 -> 0.1 | U3: =+(2*H3)/10 -> 0.6 | V3: =+(3*I3)/20 -> 0.15 | AR3: =80/5 -> 16 | AU3: =24/2 -> 12
C5: OBJECTIFS JOURNALIERS | W5: REALISATIONS | BD5: Commentaires | BE5: Impressions des PDV et des clients
A6: N° | B6: Agent promoteur | C6: Nombre de visite / Type de PDV | H6: Nombre de référencement / Type de PDV | M6: Pose de matériel de visibilité | R6: Vente en cartons | W6: Nombre de visite / Type de PDV | AB6: Présence produits antérieure | AG6: Nombre de référencement / Type de PDV | AL6: Nouveau Référencement par SKU | AQ6: Vente en cartons | AV6: Pose de matériel de visibilité | BA6: Gratuits offerts en sachet
C7: Boutique | D7: Superette | E7: Kiosque | F7: Tablier | G7: Pushcart | H7: Boutique | I7: Superette | J7: Kiosque | K7: Tablier | L7: Pushcart | M7: Affiche Biblos Lait Prémium 16g & 360g | N7: Affiche Biblos Lait Excellence | O7: Affiche Biblos Flocons d' Avoine | P7: Hanger | Q7: Wobbler | R7: Biblos Lait Premium 16g | S7: Biblos Lait Premium 360g | T7: Biblos Lait Excellence 900g | U7: Biblos Flocon d'avoine 50g | V7: Biblos Flocon d'avoine 400g | W7: Boutique | X7: Superette | Y7: Kiosque | Z7: Tablier | AA7: Pushcart | AB7: Biblos Lait Premium 16g | AC7: Biblos Lait Premium 360g | AD7: Biblos Lait Excellence 900g | AE7: Biblos Flocon d'avoine 50g | AF7: Biblos Flocon d'avoine 400g | AG7: Boutique | AH7: Superette | AI7: Kiosque | AJ7: Tablier | AK7: Pushcart | AL7: Biblos Lait Premium 16g | AM7: Biblos Lait Premium 360g | AN7: Biblos Lait Excellence 900g | AO7: Biblos Flocon d'avoine 50g | AP7: Biblos Flocon d'avoine 400g | AQ7: Biblos Lait Premium 16g | AR7: Biblos Lait Premium 360g | AS7: Biblos Lait Excellence 900g | AT7: Biblos Flocon d'avoine 50g | AU7: Biblos Flocon d'avoine 400g | AV7: Affiche Biblos Lait Prémium 16g & 360g | AW7: Affiche Biblos Lait Excellence | AX7: Affiche Biblos Flocons d' Avoine | AY7: Hanger | AZ7: Wobbler | BA7: Biblos Lait Premium 16g | BB7: Biblos Lait Excellence 900g | BC7: Biblos Flocon d'avoine 50g
A8: 1 | B8: DIBI SIMEON | C8: =+C$3 -> 10 | D8: =+D$3 -> 3 | E8: =+E$3 -> 2 | F8: =+F$3 -> 2 | G8: =+G$3 -> 3 | H8: =+H$3 -> 3 | I8: =+I$3 -> 1 | J8: =+J$3 -> 1 | ... V8: =+V$3 -> 0.15 | W8: =15+20 -> 35 | AE8: 1 | AG8: =3+1+4+5 -> 13 | AL8: 3 | AN8: 1 | AO8: 5 | AP8: 5 | AQ8: 1 | AS8: =6/20 -> 0.3 | AT8: 1 | AU8: 2 | AV8: 3 | AX8: 2 | BA8: =10+10 -> 20 | BC8: =10+20 -> 30
A9: 2 | B9: DAGO BRICE | C9: =+C$3 -> 10 | D9: =+D$3 -> 3 | E9: =+E$3 -> 2 | F9: =+F$3 -> 2 | G9: =+G$3 -> 3 | H9: =+H$3 -> 3 | I9: =+I$3 -> 1 | J9: =+J$3 -> 1 | ... V9: =+V$3 -> 0.15 | W9: =20+20 -> 40 | AB9: 1 | AG9: =1+1+2+10 -> 14 | AL9: 2 | AN9: 1 | AO9: 2 | AP9: 10 | AQ9: =4/12 -> 0.33333333 | AS9: =3/20 -> 0.15 | AT9: 0.5 | AU9: 4.5 | AV9: 3 | AX9: 2 | BA9: =4+5 -> 9 | BC9: =5+40+4 -> 49
A10: 3 | B10: KRA EVAVARISTE | C10: =+C$3 -> 10 | D10: =+D$3 -> 3 | E10: =+E$3 -> 2 | F10: =+F$3 -> 2 | G10: =+G$3 -> 3 | H10: =+H$3 -> 3 | I10: =+I$3 -> 1 | J10: =+J$3 -> 1 | ... V10: =+V$3 -> 0.15 | W10: =26+21 -> 47 | AD10: 1 | AG10: =4+1+1+5 -> 11 | AL10: 4 | AN10: 2 | AO10: 1 | AP10: 5 | AQ10: 1.5 | AS10: =3/20 -> 0.15 | AT10: 0.4 | AU10: 2 | AV10: 3 | AX10: 2 | BA10: =16+5 -> 21 | BC10: =4+20 -> 24
A11: 4 | B11: DIOMANDE ESTHER | C11: =+C$3 -> 10 | D11: =+D$3 -> 3 | E11: =+E$3 -> 2 | F11: =+F$3 -> 2 | G11: =+G$3 -> 3 | H11: =+H$3 -> 3 | I11: =+I$3 -> 1 | J11: =+J$3 -> 1 | ... V11: =+V$3 -> 0.15 | W11: =28+25 -> 53 | AF11: 1 | AG11: =4+1+1+7 -> 13 | AL11: 4 | AN11: 1 | AO11: 1 | AP11: 7 | AQ11: 2 | AS11: =3/20 -> 0.15 | AT11: 0.5 | AU11: 2.5 | AV11: 3 | AX11: 2 | BA11: =20+5 -> 25 | BC11: =5+20+4 -> 29
A12: 5 | B12: BADA LANDRY | C12: =+C$3 -> 10 | D12: =+D$3 -> 3 | E12: =+E$3 -> 2 | F12: =+F$3 -> 2 | G12: =+G$3 -> 3 | H12: =+H$3 -> 3 | I12: =+I$3 -> 1 | J12: =+J$3 -> 1 | ... V12: =+V$3 -> 0.15 | W12: =28+25 -> 53 | AB12: 1 | AD12: 1 | AG12: =1+1+4+10 -> 16 | AL12: 2 | AN12: 2 | AO12: 4 | AP12: 10 | AQ12: =5/12 -> 0.41666667 | AS12: =9/20 -> 0.45 | AT12: 1 | AU12: 3 | AV12: 3 | AX12: 2 | BA12: =5+15 -> 20 | BC12: =10+30 -> 40
A13: 6 | B13: KOUAME JOSE | C13: =+C$3 -> 10 | D13: =+D$3 -> 3 | E13: =+E$3 -> 2 | F13: =+F$3 -> 2 | G13: =+G$3 -> 3 | H13: =+H$3 -> 3 | I13: =+I$3 -> 1 | J13: =+J$3 -> 1 | ... V13: =+V$3 -> 0.15 | W13: =18+23 -> 41 | AB13: 1 | AE13: 1 | AG13: =1+2+8 -> 11 | AL13: 2 | AO13: 3 | AP13: 8 | AQ13: =0.5 -> 0.5 | AT13: 1 | AU13: 2.5 | AV13: 3 | AX13: 2 | BA13: 6 | BC13: =10+20+4 -> 34
A14: 7 | B14: FANY BARAKISSA | C14: =+C$3 -> 10 | D14: =+D$3 -> 3 | E14: =+E$3 -> 2 | F14: =+F$3 -> 2 | G14: =+G$3 -> 3 | H14: =+H$3 -> 3 | I14: =+I$3 -> 1 | J14: =+J$3 -> 1 | ... V14: =+V$3 -> 0.15 | W14: =25+25 -> 50 | AG14: =1+1+1+6 -> 9 | AL14: 1 | AN14: 1 | AO14: 1 | AP14: 6 | AQ14: =4/12 -> 0.33333333 | AS14: =3/20 -> 0.15 | AT14: 0.6 | AU14: 1.5 | AV14: 3 | AX14: 2 | BA14: =4+5 -> 9 | BC14: =6+10+4 -> 20
A15: 8 | B15: KONAN IVETTE | C15: =+C$3 -> 10 | D15: =+D$3 -> 3 | E15: =+E$3 -> 2 | F15: =+F$3 -> 2 | G15: =+G$3 -> 3 | H15: =+H$3 -> 3 | I15: =+I$3 -> 1 | J15: =+J$3 -> 1 | ... V15: =+V$3 -> 0.15 | W15: =25+22 -> 47 | AF15: 1 | AG15: =1+1+2+7 -> 11 | AL15: 1 | AN15: 1 | AO15: 2 | AP15: 8 | AQ15: =6/12 -> 0.5 | AS15: =3/20 -> 0.15 | AT15: 0.5 | AU15: 2 | AV15: 3 | AX15: 2 | BA15: =6+5 -> 11 | BC15: =5+20 -> 25
A16: 9 | B16: KRA PACOME | C16: =+C$3 -> 10 | D16: =+D$3 -> 3 | E16: =+E$3 -> 2 | F16: =+F$3 -> 2 | G16: =+G$3 -> 3 | H16: =+H$3 -> 3 | I16: =+I$3 -> 1 | J16: =+J$3 -> 1 | ... V16: =+V$3 -> 0.15 | W16: =24+25 -> 49 | AD16: 1 | AG16: =1+1+1+9 -> 12 | AL16: 1 | AN16: 2 | AO16: 1 | AP16: 9 | AQ16: =2/12 -> 0.16666667 | AS16: =6/20 -> 0.3 | AT16: 0.6 | AU16: 3 | AV16: 3 | AX16: 2 | BA16: =2+10 -> 12 | BC16: =6+30 -> 36
A17: 10 | B17: OULAY EMMENUELLA | C17: =+C$3 -> 10 | D17: =+D$3 -> 3 | E17: =+E$3 -> 2 | F17: =+F$3 -> 2 | G17: =+G$3 -> 3 | H17: =+H$3 -> 3 | I17: =+I$3 -> 1 | J17: =+J$3 -> 1 | ... V17: =+V$3 -> 0.15 | W17: =15+27 -> 42 | AG17: =1+1+3+4 -> 9 | AL17: 1 | AN17: 1 | AO17: 3 | AP17: 4 | AQ17: =2/12 -> 0.16666667 | AS17: =3/20 -> 0.15 | AT17: 1 | AU17: 1 | AV17: 3 | AX17: 2 | BA17: =2+5 -> 7 | BC17: =10+10 -> 20
A18: 11 | B18: KONATE MARIAM | C18: =+C$3 -> 10 | D18: =+D$3 -> 3 | E18: =+E$3 -> 2 | F18: =+F$3 -> 2 | G18: =+G$3 -> 3 | H18: =+H$3 -> 3 | I18: =+I$3 -> 1 | J18: =+J$3 -> 1 | ... V18: =+V$3 -> 0.15 | W18: =24+24 -> 48 | AG18: =1+1+1+15 -> 18 | AL18: 1 | AN18: 1 | AO18: 1 | AP18: 15 | AQ18: =8/12 -> 0.66666667 | AS18: =3/20 -> 0.15 | AT18: 0.5 | AU18: 5 | AV18: 3 | AX18: 2 | BA18: =8+5 -> 13 | BC18: =5+50 -> 55
A19: 12 | B19: KOUAME JORES | C19: =+C$3 -> 10 | D19: =+D$3 -> 3 | E19: =+E$3 -> 2 | F19: =+F$3 -> 2 | G19: =+G$3 -> 3 | H19: =+H$3 -> 3 | I19: =+I$3 -> 1 | J19: =+J$3 -> 1 | ... V19: =+V$3 -> 0.15 | W19: =27+23 -> 50 | AG19: =6+4+1 -> 11 | AL19: 6 | AO19: 4 | AP19: 1 | AQ19: 2 | AT19: 1 | AU19: =5/20 -> 0.25 | AV19: 3 | AX19: 2 | BA19: 20 | BC19: =10+2 -> 12
A20: 13 | B20: KOUAKOU ADJOUA ROSE | C20: =+C$3 -> 10 | D20: =+D$3 -> 3 | E20: =+E$3 -> 2 | F20: =+F$3 -> 2 | G20: =+G$3 -> 3 | H20: =+H$3 -> 3 | I20: =+I$3 -> 1 | J20: =+J$3 -> 1 | ... V20: =+V$3 -> 0.15 | W20: =20+24 -> 44 | AB20: 1 | AE20: 1 | AF20: 1 | AG20: =4+1+4+1 -> 10 | AL20: 4 | AN20: 1 | AO20: 5 | AP20: 2 | AQ20: 1.5 | AS20: =3/20 -> 0.15 | AT20: 1 | AU20: =5/20 -> 0.25 | AV20: 3 | AX20: 2 | BA20: =16+5 -> 21 | BC20: =10+2 -> 12
A21: 14 | B21: OULAY WILFRIED | C21: =+C$3 -> 10 | D21: =+D$3 -> 3 | E21: =+E$3 -> 2 | F21: =+F$3 -> 2 | G21: =+G$3 -> 3 | H21: =+H$3 -> 3 | I21: =+I$3 -> 1 | J21: =+J$3 -> 1 | ... V21: =+V$3 -> 0.15 | W21: =25+23 -> 48 | AD21: 1 | AG21: =1+1+1+7 -> 10 | AL21: 1 | AN21: 1 | AO21: 1 | AP21: 7 | AQ21: 0.5 | AS21: =1/20 -> 0.05 | AT21: 0.4 | AU21: 2 | AV21: 3 | AX21: 2 | BA21: 6 | BC21: =4+20 -> 24
A22: 15 | B22: KONATE MOUSSA | C22: =+C$3 -> 10 | D22: =+D$3 -> 3 | E22: =+E$3 -> 2 | F22: =+F$3 -> 2 | G22: =+G$3 -> 3 | H22: =+H$3 -> 3 | I22: =+I$3 -> 1 | J22: =+J$3 -> 1 | ... V22: =+V$3 -> 0.15 | W22: =29+26 -> 55 | AE22: 1 | AG22: =1+1+2+6 -> 10 | AL22: 1 | AN22: 1 | AO22: 3 | AP22: 6 | AQ22: =3/12 -> 0.25 | AS22: =3/20 -> 0.15 | AT22: 0.5 | AU22: 2 | AV22: 3 | AX22: 2 | BA22: =3+5 -> 8 | BC22: =5+20 -> 25
A23: 16 | B23: NGORAN AXCEL | C23: =+C$3 -> 10 | D23: =+D$3 -> 3 | E23: =+E$3 -> 2 | F23: =+F$3 -> 2 | G23: =+G$3 -> 3 | H23: =+H$3 -> 3 | I23: =+I$3 -> 1 | J23: =+J$3 -> 1 | ... V23: =+V$3 -> 0.15 | W23: =30+30 -> 60 | AB23: 1 | AD23: 1 | AG23: =1+1+3+8 -> 13 | AL23: 1 | AN23: 2 | AO23: 3 | AP23: 8 | AQ23: =2/12 -> 0.16666667 | AS23: =3/20 -> 0.15 | AT23: 1 | AU23: 2.5 | AV23: 3 | AX23: 2 | BA23: =2+5 -> 7 | BC23: =10+20+4 -> 34
A24: 17 | B24: TRAORE ARSENE | C24: =+C$3 -> 10 | D24: =+D$3 -> 3 | E24: =+E$3 -> 2 | F24: =+F$3 -> 2 | G24: =+G$3 -> 3 | H24: =+H$3 -> 3 | I24: =+I$3 -> 1 | J24: =+J$3 -> 1 | ... V24: =+V$3 -> 0.15 | W24: =30+24 -> 54 | AG24: =5+1+4+18 -> 28 | AL24: 5 | AN24: 1 | AO24: 4 | AP24: 18 | AQ24: 2 | AS24: =3/20 -> 0.15 | AT24: 1 | AU24: 6 | AV24: 3 | AX24: 2 | BA24: =20+5 -> 25 | BC24: =10+60 -> 70
A25: 18 | B25: NGUESSAN INNOCENT | C25: =+C$3 -> 10 | D25: =+D$3 -> 3 | E25: =+E$3 -> 2 | F25: =+F$3 -> 2 | G25: =+G$3 -> 3 | H25: =+H$3 -> 3 | I25: =+I$3 -> 1 | J25: =+J$3 -> 1 | ... V25: =+V$3 -> 0.15 | W25: =26+24 -> 50 | AE25: 1 | AG25: =1+1+2+10 -> 14 | AL25: 1 | AN25: 1 | AO25: 3 | AP25: 10 | AQ25: 0.5 | AS25: =3/20 -> 0.15 | AT25: 0.5 | AU25: 3 | AV25: 3 | AX25: 2 | BA25: =6+5 -> 11 | BC25: =5+30 -> 35
A26: 19 | B26: KOUAME ARISTIDE | C26: =+C$3 -> 10 | D26: =+D$3 -> 3 | E26: =+E$3 -> 2 | F26: =+F$3 -> 2 | G26: =+G$3 -> 3 | H26: =+H$3 -> 3 | I26: =+I$3 -> 1 | J26: =+J$3 -> 1 | ... V26: =+V$3 -> 0.15 | W26: =29+26 -> 55 | AB26: 1 | AG26: =1+1+7+11 -> 20 | AL26: 2 | AN26: 1 | AO26: 7 | AP26: 11 | AQ26: =6/12 -> 0.5 | AS26: =3/20 -> 0.15 | AT26: 2 | AU26: 3 | AV26: 3 | AX26: 2 | BA26: =6+5 -> 11 | BC26: =20+30 -> 50
A27: 20 | B27: BERTRAND | C27: =+C$3 -> 10 | D27: =+D$3 -> 3 | E27: =+E$3 -> 2 | F27: =+F$3 -> 2 | G27: =+G$3 -> 3 | H27: =+H$3 -> 3 | I27: =+I$3 -> 1 | J27: =+J$3 -> 1 | ... V27: =+V$3 -> 0.15 | W27: =31+22 -> 53 | AB27: 1 | AG27: =5+1+3+13 -> 22 | AL27: 5 | AN27: 1 | AO27: 3 | AP27: 13 | AQ27: 1 | AS27: =6/20 -> 0.3 | AT27: 1 | AU27: 4 | AV27: 3 | AX27: 2 | BA27: =10+10 -> 20 | BC27: =10+40 -> 50
B28: TOTAL | C28: =SUM(C8:C27) -> 200 | D28: =SUM(D8:D27) -> 60 | E28: =SUM(E8:E27) -> 40 | F28: =SUM(F8:F27) -> 40 | G28: =SUM(G8:G27) -> 60 | H28: =SUM(H8:H27) -> 60 | I28: =SUM(I8:I27) -> 20 | J28: =SUM(J8:J27) -> 20 | ... BE28: =SUM(BE8:BE27) -> 0
AQ33: 9 | AS33: 1.35 | AT33: 8 | AU33: 34 | AV33: j sup
AQ34: =SUM(AQ32:AQ33) -> 9 | AS34: =SUM(AS32:AS33) -> 1.35 | AT34: =SUM(AT32:AT33) -> 8 | AU34: =SUM(AU32:AU33) -> 34
AR36: =0.035*20 -> 0.7
AS38: =AS34*20 -> 27

Sheet Mardi
B2: VILLE
C3: 10 | D3: 3 | E3: 2 | F3: 2 | G3: 3 | H3: 3 | I3: 1 | J3: 1 | K3: 1 | L3: 1 | M3: =+H3 -> 3 | N3: 1 | O3: =+H3 -> 3 | R3: =+(2*M3)/12 -> 0.5 | S3: =+(1*I3)/6 -> 0.16666667 | T3: =+(2*I3)/20 -> 0.1 | U3: =+(2*H3)/10 -> 0.6 | V3: =+(3*I3)/20 -> 0.15 | AW3: =18/20 -> 0.9
C5: OBJECTIFS JOURNALIERS | W5: REALISATIONS | BD5: Commentaires | BE5: Impressions des PDV et des clients
A6: N° | B6: Agent promoteur | C6: Nombre de visite / Type de PDV | H6: Nombre de référencement / Type de PDV | M6: Pose de matériel de visibilité | R6: Vente en cartons | W6: Nombre de visite / Type de PDV | AB6: Présence produits antérieure | AG6: Nombre de référencement / Type de PDV | AL6: Nouveau Référencement par SKU | AQ6: Vente en cartons | AV6: Pose de matériel de visibilité | BA6: Gratuits offerts en sachet
C7: Boutique | D7: Superette | E7: Kiosque | F7: Tablier | G7: Pushcart | H7: Boutique | I7: Superette | J7: Kiosque | K7: Tablier | L7: Pushcart | M7: Affiche Biblos Lait Prémium 16g & 360g | N7: Affiche Biblos Lait Excellence | O7: Affiche Biblos Flocons d' Avoine | P7: Hanger | Q7: Wobbler | R7: Biblos Lait Premium 16g | S7: Biblos Lait Premium 360g | T7: Biblos Lait Excellence 900g | U7: Biblos Flocon d'avoine 50g | V7: Biblos Flocon d'avoine 400g | W7: Boutique | X7: Superette | Y7: Kiosque | Z7: Tablier | AA7: Pushcart | AB7: Biblos Lait Premium 16g | AC7: Biblos Lait Premium 360g | AD7: Biblos Lait Excellence 900g | AE7: Biblos Flocon d'avoine 50g | AF7: Biblos Flocon d'avoine 400g | AG7: Boutique | AH7: Superette | AI7: Kiosque | AJ7: Tablier | AK7: Pushcart | AL7: Biblos Lait Premium 16g | AM7: Biblos Lait Premium 360g | AN7: Biblos Lait Excellence 900g | AO7: Biblos Flocon d'avoine 50g | AP7: Biblos Flocon d'avoine 400g | AQ7: Biblos Lait Premium 16g | AR7: Biblos Lait Premium 360g | AS7: Biblos Lait Excellence 900g | AT7: Biblos Flocon d'avoine 50g | AU7: Biblos Flocon d'avoine 400g | AV7: Affiche Biblos Lait Prémium 16g & 360g | AW7: Affiche Biblos Lait Excellence | AX7: Affiche Biblos Flocons d' Avoine | AY7: Hanger | AZ7: Wobbler | BA7: Biblos Lait Premium 16g | BB7: Biblos Lait Excellence 900g | BC7: Biblos Flocon d'avoine 50g
A8: 1 | B8: DIBI SIMEON | C8: =+C$3 -> 10 | D8: =+D$3 -> 3 | E8: =+E$3 -> 2 | F8: =+F$3 -> 2 | G8: =+G$3 -> 3 | H8: =+H$3 -> 3 | I8: =+I$3 -> 1 | J8: =+J$3 -> 1 | ... V8: =+V$3 -> 0.15 | W8: 28 | AE8: 2 | AG8: =1+1+1+4 -> 7 | AL8: 1 | AN8: 1 | AO8: 3 | AP8: 4 | AQ8: =50/120 -> 0.41666667 | AS8: =3/20 -> 0.15 | AT8: 0.6 | AU8: 1.5 | AV8: 3 | AX8: 2 | BA8: =5+5 -> 10 | BC8: =6+10+4 -> 20
A9: 2 | B9: DAGO BRICE | C9: =+C$3 -> 10 | D9: =+D$3 -> 3 | E9: =+E$3 -> 2 | F9: =+F$3 -> 2 | G9: =+G$3 -> 3 | H9: =+H$3 -> 3 | I9: =+I$3 -> 1 | J9: =+J$3 -> 1 | ... V9: =+V$3 -> 0.15 | W9: 20 | AB9: 1 | AG9: =1+1+6 -> 8 | AL9: 1 | AN9: 1 | AP9: 6 | AQ9: =40/120 -> 0.33333333 | AS9: =1/20 -> 0.05 | AU9: 1.5 | AV9: 3 | AX9: 2 | BA9: =4 -> 4 | BC9: =10+4 -> 14
A10: 3 | B10: KRA EVAVARISTE | C10: =+C$3 -> 10 | D10: =+D$3 -> 3 | E10: =+E$3 -> 2 | F10: =+F$3 -> 2 | G10: =+G$3 -> 3 | H10: =+H$3 -> 3 | I10: =+I$3 -> 1 | J10: =+J$3 -> 1 | ... V10: =+V$3 -> 0.15 | W10: 24 | AG10: =5+1+4+2 -> 12 | AL10: 5 | AN10: 1 | AO10: 4 | AP10: 2 | AQ10: 1.5 | AS10: =6/20 -> 0.3 | AT10: 1 | AU10: 1 | AV10: 3 | AX10: 2 | BA10: =10+6+10 -> 26 | BC10: =10+10 -> 20
A11: 4 | B11: DIOMANDE ESTHER | C11: =+C$3 -> 10 | D11: =+D$3 -> 3 | E11: =+E$3 -> 2 | F11: =+F$3 -> 2 | G11: =+G$3 -> 3 | H11: =+H$3 -> 3 | I11: =+I$3 -> 1 | J11: =+J$3 -> 1 | ... V11: =+V$3 -> 0.15 | W11: 27 | AB11: 1 | AD11: 1 | AG11: =1+1+1+7 -> 10 | AL11: 2 | AN11: 2 | AO11: 1 | AP11: 7 | AQ11: =50/120 -> 0.41666667 | AS11: =3/20 -> 0.15 | AT11: 0.4 | AU11: 2 | AV11: 3 | AX11: 2 | BA11: =5+5 -> 10 | BC11: =4+20 -> 24
A12: 5 | B12: BADA LANDRY | C12: =+C$3 -> 10 | D12: =+D$3 -> 3 | E12: =+E$3 -> 2 | F12: =+F$3 -> 2 | G12: =+G$3 -> 3 | H12: =+H$3 -> 3 | I12: =+I$3 -> 1 | J12: =+J$3 -> 1 | ... V12: =+V$3 -> 0.15 | W12: 28 | AB12: 1 | AF12: 1 | AG12: =3+1+8 -> 12 | AL12: 4 | AO12: 1 | AP12: 9 | AQ12: 1 | AT12: 0.4 | AU12: 2 | AV12: 3 | AX12: 2 | BA12: 10 | BC12: =4+20 -> 24
A13: 6 | B13: KOUAME JOSE | C13: =+C$3 -> 10 | D13: =+D$3 -> 3 | E13: =+E$3 -> 2 | F13: =+F$3 -> 2 | G13: =+G$3 -> 3 | H13: =+H$3 -> 3 | I13: =+I$3 -> 1 | J13: =+J$3 -> 1 | ... V13: =+V$3 -> 0.15 | W13: 25 | AG13: =1+2+2 -> 5 | AL13: 1 | AO13: 2 | AP13: 2 | AQ13: =40/120 -> 0.33333333 | AT13: 0.5 | AU13: 0.5 | AV13: 3 | AX13: 2 | BA13: 4 | BC13: =5+4 -> 9
A14: 7 | B14: FANY BARAKISSA | C14: =+C$3 -> 10 | D14: =+D$3 -> 3 | E14: =+E$3 -> 2 | F14: =+F$3 -> 2 | G14: =+G$3 -> 3 | H14: =+H$3 -> 3 | I14: =+I$3 -> 1 | J14: =+J$3 -> 1 | ... V14: =+V$3 -> 0.15 | W14: 25 | AD14: 1 | AF14: 1 | AG14: =1+1 -> 2 | AL14: 1 | AN14: 1 | AO14: 1 | AP14: 1 | AQ14: =60/120 -> 0.5 | AT14: 0.4 | AV14: 3 | AX14: 2 | BA14: 6 | BC14: 4
A15: 8 | B15: KONAN IVETTE | C15: =+C$3 -> 10 | D15: =+D$3 -> 3 | E15: =+E$3 -> 2 | F15: =+F$3 -> 2 | G15: =+G$3 -> 3 | H15: =+H$3 -> 3 | I15: =+I$3 -> 1 | J15: =+J$3 -> 1 | ... V15: =+V$3 -> 0.15 | W15: 28 | AE15: 1 | AG15: =1+1+1+3 -> 6 | AL15: 1 | AN15: 1 | AO15: 2 | AP15: 3 | AQ15: =20/120 -> 0.16666667 | AS15: =3/20 -> 0.15 | AT15: 0.5 | AU15: 1 | AV15: 3 | AX15: 2 | BA15: =2+5 -> 7 | BC15: =5+10 -> 15
A16: 9 | B16: KRA PACOME | C16: =+C$3 -> 10 | D16: =+D$3 -> 3 | E16: =+E$3 -> 2 | F16: =+F$3 -> 2 | G16: =+G$3 -> 3 | H16: =+H$3 -> 3 | I16: =+I$3 -> 1 | J16: =+J$3 -> 1 | ... V16: =+V$3 -> 0.15 | W16: 30 | AB16: 1 | AG16: =3+1+1 -> 5 | AL16: 4 | AN16: 1 | AP16: 1 | AQ16: 1 | AS16: =3/20 -> 0.15 | AU16: 0.5 | AV16: 3 | AX16: 2 | BA16: =10+5 -> 15 | BC16: 4
A17: 10 | B17: OULAY EMMENUELLA | C17: =+C$3 -> 10 | D17: =+D$3 -> 3 | E17: =+E$3 -> 2 | F17: =+F$3 -> 2 | G17: =+G$3 -> 3 | H17: =+H$3 -> 3 | I17: =+I$3 -> 1 | J17: =+J$3 -> 1 | ... V17: =+V$3 -> 0.15 | W17: 27 | AB17: 1 | AD17: 1 | AF17: 2 | AG17: =1+1+1 -> 3 | AL17: 2 | AN17: 1 | AO17: 1 | AP17: 3 | AQ17: =80/120 -> 0.66666667 | AT17: 0.6 | AU17: 0.5 | AV17: 3 | AX17: 2 | BA17: 8 | BC17: =6+4 -> 10
A18: 11 | B18: KONATE MARIAM | C18: =+C$3 -> 10 | D18: =+D$3 -> 3 | E18: =+E$3 -> 2 | F18: =+F$3 -> 2 | G18: =+G$3 -> 3 | H18: =+H$3 -> 3 | I18: =+I$3 -> 1 | J18: =+J$3 -> 1 | ... V18: =+V$3 -> 0.15 | W18: 30 | AG18: =1+1+2+3 -> 7 | AL18: 1 | AN18: 1 | AO18: 2 | AP18: 3 | AQ18: =40/120 -> 0.33333333 | AS18: =3/20 -> 0.15 | AT18: 0.8 | AU18: =19/20 -> 0.95 | AV18: 3 | AX18: 2 | BA18: =4+5 -> 9 | BC18: =8+6 -> 14
A19: 12 | B19: KOUAME JORES | C19: =+C$3 -> 10 | D19: =+D$3 -> 3 | E19: =+E$3 -> 2 | F19: =+F$3 -> 2 | G19: =+G$3 -> 3 | H19: =+H$3 -> 3 | I19: =+I$3 -> 1 | J19: =+J$3 -> 1 | ... V19: =+V$3 -> 0.15 | W19: 26 | AG19: =1+1+2+6 -> 10 | AL19: 1 | AN19: 1 | AO19: 2 | AP19: 6 | AQ19: 0.5 | AS19: =3/20 -> 0.15 | AT19: 1 | AU19: 2.5 | AV19: 3 | AX19: 2 | BA19: =6+5 -> 11 | BC19: =10+20+4 -> 34
A20: 13 | B20: KOUAKOU ADJOUA ROSE | C20: =+C$3 -> 10 | D20: =+D$3 -> 3 | E20: =+E$3 -> 2 | F20: =+F$3 -> 2 | G20: =+G$3 -> 3 | H20: =+H$3 -> 3 | I20: =+I$3 -> 1 | J20: =+J$3 -> 1 | ... V20: =+V$3 -> 0.15 | W20: 30 | AC20: 1 | AE20: 1 | AG20: =1+1+2+3 -> 7 | AL20: 1 | AM20: 1 | AN20: 1 | AO20: 3 | AP20: 3 | AQ20: =40/120 -> 0.33333333 | AS20: =6/20 -> 0.3 | AT20: 0.6 | AU20: =15/20 -> 0.75 | AV20: 3 | AX20: 2 | BA20: =4+10 -> 14 | BC20: =6+6 -> 12
A21: 14 | B21: OULAY WILFRIED | C21: =+C$3 -> 10 | D21: =+D$3 -> 3 | E21: =+E$3 -> 2 | F21: =+F$3 -> 2 | G21: =+G$3 -> 3 | H21: =+H$3 -> 3 | I21: =+I$3 -> 1 | J21: =+J$3 -> 1 | ... V21: =+V$3 -> 0.15 | W21: 25 | AF21: 2 | AG21: =1+2+1 -> 4 | AL21: 1 | AO21: 2 | AP21: 3 | AQ21: =30/120 -> 0.25 | AT21: 0.8 | AU21: =5/20 -> 0.25 | AV21: 3 | AX21: 2 | BA21: 3 | BC21: =8+2 -> 10
A22: 15 | B22: KONATE MOUSSA | C22: =+C$3 -> 10 | D22: =+D$3 -> 3 | E22: =+E$3 -> 2 | F22: =+F$3 -> 2 | G22: =+G$3 -> 3 | H22: =+H$3 -> 3 | I22: =+I$3 -> 1 | J22: =+J$3 -> 1 | ... V22: =+V$3 -> 0.15 | W22: 30 | AE22: 2 | AG22: =1+1+1+5 -> 8 | AL22: 1 | AN22: 1 | AO22: 3 | AP22: 5 | AQ22: =50/120 -> 0.41666667 | AS22: =3/20 -> 0.15 | AT22: 0.5 | AU22: 2 | AV22: 3 | AX22: 2 | BA22: =5+5 -> 10 | BC22: =5+20 -> 25
A23: 16 | B23: NGORAN AXCEL | C23: =+C$3 -> 10 | D23: =+D$3 -> 3 | E23: =+E$3 -> 2 | F23: =+F$3 -> 2 | G23: =+G$3 -> 3 | H23: =+H$3 -> 3 | I23: =+I$3 -> 1 | J23: =+J$3 -> 1 | ... V23: =+V$3 -> 0.15 | W23: 26 | AE23: 1 | AF23: 1 | AG23: =1+1+2 -> 4 | AL23: 1 | AO23: 2 | AP23: 3 | AQ23: =60/120 -> 0.5 | AT23: 0.4 | AU23: 1 | AV23: 3 | AX23: 2 | BA23: 6 | BC23: =4+10 -> 14
A24: 17 | B24: TRAORE ARSENE | C24: =+C$3 -> 10 | D24: =+D$3 -> 3 | E24: =+E$3 -> 2 | F24: =+F$3 -> 2 | G24: =+G$3 -> 3 | H24: =+H$3 -> 3 | I24: =+I$3 -> 1 | J24: =+J$3 -> 1 | ... V24: =+V$3 -> 0.15 | W24: 30 | AG24: =1+1+2+4 -> 8 | AL24: 1 | AN24: 1 | AO24: 2 | AP24: 4 | AQ24: =40/120 -> 0.33333333 | AS24: =3/20 -> 0.15 | AT24: 0.8 | AU24: 1 | AV24: 3 | AX24: 2 | BA24: =4+5 -> 9 | BC24: =8+10 -> 18
A25: 18 | B25: NGUESSAN INNOCENT | C25: =+C$3 -> 10 | D25: =+D$3 -> 3 | E25: =+E$3 -> 2 | F25: =+F$3 -> 2 | G25: =+G$3 -> 3 | H25: =+H$3 -> 3 | I25: =+I$3 -> 1 | J25: =+J$3 -> 1 | ... V25: =+V$3 -> 0.15 | W25: 25 | AE25: 1 | AF25: 1 | AG25: =1+2+7 -> 10 | AL25: 1 | AO25: 3 | AP25: 8 | AQ25: =40/120 -> 0.33333333 | AT25: 0.7 | AU25: 2 | AV25: 3 | AX25: 2 | BA25: 4 | BC25: =7+20 -> 27
A26: 19 | B26: KOUAME ARISTIDE | C26: =+C$3 -> 10 | D26: =+D$3 -> 3 | E26: =+E$3 -> 2 | F26: =+F$3 -> 2 | G26: =+G$3 -> 3 | H26: =+H$3 -> 3 | I26: =+I$3 -> 1 | J26: =+J$3 -> 1 | ... V26: =+V$3 -> 0.15 | W26: 27 | AB26: 2 | AG26: =1+1+1+4 -> 7 | AL26: 2 | AN26: 1 | AO26: 1 | AP26: 4 | AQ26: =20/120 -> 0.16666667 | AS26: =3/20 -> 0.15 | AT26: 0.4 | AU26: 1 | AV26: 3 | AX26: 2 | BA26: =2+5 -> 7 | BC26: =4+10 -> 14
A27: 20 | B27: BERTRAND | C27: =+C$3 -> 10 | D27: =+D$3 -> 3 | E27: =+E$3 -> 2 | F27: =+F$3 -> 2 | G27: =+G$3 -> 3 | H27: =+H$3 -> 3 | I27: =+I$3 -> 1 | J27: =+J$3 -> 1 | ... V27: =+V$3 -> 0.15 | W27: 26 | AB27: 1 | AF27: 1 | AG27: =3+3+6 -> 12 | AL27: 3 | AO27: 3 | AP27: 7 | AQ27: 0.5 | AT27: 0.6 | AU27: 2 | AV27: 3 | AX27: 2 | BA27: 10 | BC27: =10+20 -> 30
B28: TOTAL | C28: =SUM(C8:C27) -> 200 | D28: =SUM(D8:D27) -> 60 | E28: =SUM(E8:E27) -> 40 | F28: =SUM(F8:F27) -> 40 | G28: =SUM(G8:G27) -> 60 | H28: =SUM(H8:H27) -> 60 | I28: =SUM(I8:I27) -> 20 | J28: =SUM(J8:J27) -> 20 | ... BE28: =SUM(BE8:BE27) -> 0
AV32: =0.3 -> 0.3 | AW32: =0.2*20 -> 4 | AX32: =AV32*20 -> 6

Sheet Mercredi
B2: VILLE
C3: 10 | D3: 3 | E3: 2 | F3: 2 | G3: 3 | H3: 3 | I3: 1 | J3: 1 | K3: 1 | L3: 1 | M3: =+H3 -> 3 | N3: 1 | O3: =+H3 -> 3 | R3: =+(2*M3)/12 -> 0.5 | S3: =+(1*I3)/6 -> 0.16666667 | T3: =+(2*I3)/20 -> 0.1 | U3: =+(2*H3)/10 -> 0.6 | V3: =+(3*I3)/20 -> 0.15
C5: OBJECTIFS JOURNALIERS | W5: REALISATIONS | BD5: Commentaires | BE5: Impressions des PDV et des clients
A6: N° | B6: Agent promoteur | C6: Nombre de visite / Type de PDV | H6: Nombre de référencement / Type de PDV | M6: Pose de matériel de visibilité | R6: Vente en cartons | W6: Nombre de visite / Type de PDV | AB6: Présence produits antérieure | AG6: Nombre de référencement / Type de PDV | AL6: Nouveau Référencement par SKU | AQ6: Vente en cartons | AV6: Pose de matériel de visibilité | BA6: Gratuits offerts en sachet
C7: Boutique | D7: Superette | E7: Kiosque | F7: Tablier | G7: Pushcart | H7: Boutique | I7: Superette | J7: Kiosque | K7: Tablier | L7: Pushcart | M7: Affiche Biblos Lait Prémium 16g & 360g | N7: Affiche Biblos Lait Excellence | O7: Affiche Biblos Flocons d' Avoine | P7: Hanger | Q7: Wobbler | R7: Biblos Lait Premium 16g | S7: Biblos Lait Premium 360g | T7: Biblos Lait Excellence 900g | U7: Biblos Flocon d'avoine 50g | V7: Biblos Flocon d'avoine 400g | W7: Boutique | X7: Superette | Y7: Kiosque | Z7: Tablier | AA7: Pushcart | AB7: Biblos Lait Premium 16g | AC7: Biblos Lait Premium 360g | AD7: Biblos Lait Excellence 900g | AE7: Biblos Flocon d'avoine 50g | AF7: Biblos Flocon d'avoine 400g | AG7: Boutique | AH7: Superette | AI7: Kiosque | AJ7: Tablier | AK7: Pushcart | AL7: Biblos Lait Premium 16g | AM7: Biblos Lait Premium 360g | AN7: Biblos Lait Excellence 900g | AO7: Biblos Flocon d'avoine 50g | AP7: Biblos Flocon d'avoine 400g | AQ7: Biblos Lait Premium 16g | AR7: Biblos Lait Premium 360g | AS7: Biblos Lait Excellence 900g | AT7: Biblos Flocon d'avoine 50g | AU7: Biblos Flocon d'avoine 400g | AV7: Affiche Biblos Lait Prémium 16g & 360g | AW7: Affiche Biblos Lait Excellence | AX7: Affiche Biblos Flocons d' Avoine | AY7: Hanger | AZ7: Wobbler | BA7: Biblos Lait Premium 16g | BB7: Biblos Lait Excellence 900g | BC7: Biblos Flocon d'avoine 50g
A8: 1 | B8: DIBI SIMEON | C8: =+C$3 -> 10 | D8: =+D$3 -> 3 | E8: =+E$3 -> 2 | F8: =+F$3 -> 2 | G8: =+G$3 -> 3 | H8: =+H$3 -> 3 | I8: =+I$3 -> 1 | J8: =+J$3 -> 1 | ... V8: =+V$3 -> 0.15 | W8: 25 | AF8: 1 | AG8: =1+4+6 -> 11 | AN8: 1 | AO8: 4 | AP8: 7 | AS8: =3/20 -> 0.15 | AT8: 1 | AU8: 2 | AV8: 5 | AW8: 5 | AX8: 5 | BA8: 5 | BC8: =10+20 -> 30
A9: 2 | B9: DAGO BRICE | C9: =+C$3 -> 10 | D9: =+D$3 -> 3 | E9: =+E$3 -> 2 | F9: =+F$3 -> 2 | G9: =+G$3 -> 3 | H9: =+H$3 -> 3 | I9: =+I$3 -> 1 | J9: =+J$3 -> 1 | ... V9: =+V$3 -> 0.15 | W9: 28 | AG9: =1+1+5 -> 7 | AL9: 1 | AN9: 1 | AP9: 5 | AQ9: =2/12 -> 0.16666667 | AS9: =4/20 -> 0.2 | AU9: 1.5 | AV9: 5 | AW9: 5 | AX9: 5 | BA9: =2+5 -> 7 | BC9: =10+4 -> 14
A10: 3 | B10: KRA EVAVARISTE | C10: =+C$3 -> 10 | D10: =+D$3 -> 3 | E10: =+E$3 -> 2 | F10: =+F$3 -> 2 | G10: =+G$3 -> 3 | H10: =+H$3 -> 3 | I10: =+I$3 -> 1 | J10: =+J$3 -> 1 | ... V10: =+V$3 -> 0.15 | W10: 25 | AB10: 1 | AG10: =1+1+2+1 -> 5 | AL10: 1 | AN10: 1 | AO10: 2 | AP10: 2 | AQ10: =3/12 -> 0.25 | AS10: =3/20 -> 0.15 | AT10: 0.7 | AU10: 0.5 | AV10: 5 | AW10: 5 | AX10: 5 | BA10: =3+5 -> 8 | BC10: =7+4 -> 11
A11: 4 | B11: DIOMANDE ESTHER | C11: =+C$3 -> 10 | D11: =+D$3 -> 3 | E11: =+E$3 -> 2 | F11: =+F$3 -> 2 | G11: =+G$3 -> 3 | H11: =+H$3 -> 3 | I11: =+I$3 -> 1 | J11: =+J$3 -> 1 | ... V11: =+V$3 -> 0.15 | W11: 25 | AE11: 1 | AG11: =1+1+1+5 -> 8 | AL11: 1 | AN11: 1 | AO11: 2 | AP11: 5 | AQ11: =4/12 -> 0.33333333 | AS11: =3/20 -> 0.15 | AT11: 0.5 | AU11: 1 | AV11: 5 | AW11: 5 | AX11: 5 | BA11: =4+5 -> 9 | BC11: =5+10 -> 15
A12: 5 | B12: BADA LANDRY | C12: =+C$3 -> 10 | D12: =+D$3 -> 3 | E12: =+E$3 -> 2 | F12: =+F$3 -> 2 | G12: =+G$3 -> 3 | H12: =+H$3 -> 3 | I12: =+I$3 -> 1 | J12: =+J$3 -> 1 | ... V12: =+V$3 -> 0.15 | W12: 30 | AD12: 1 | AE12: 1 | AG12: =1+1+6 -> 8 | AL12: 1 | AN12: 2 | AP12: 7 | AQ12: =5/12 -> 0.41666667 | AS12: =3/20 -> 0.15 | AU12: 2 | AV12: 5 | AW12: 5 | AX12: 5 | BA12: =5+5 -> 10 | BC12: =20 -> 20
A13: 6 | B13: KOUAME JOSE | C13: =+C$3 -> 10 | D13: =+D$3 -> 3 | E13: =+E$3 -> 2 | F13: =+F$3 -> 2 | G13: =+G$3 -> 3 | H13: =+H$3 -> 3 | I13: =+I$3 -> 1 | J13: =+J$3 -> 1 | ... V13: =+V$3 -> 0.15 | W13: 25 | AB13: 1 | AE13: 1 | AG13: =1+1+2 -> 4 | AL13: 1 | AN13: 1 | AO13: 2 | AP13: 2 | AS13: =3/20 -> 0.15 | AT13: 0.4 | AU13: 0.5 | AV13: 5 | AW13: 5 | AX13: 5 | BA13: 5 | BC13: =4+4 -> 8
A14: 7 | B14: FANY BARAKISSA | C14: =+C$3 -> 10 | D14: =+D$3 -> 3 | E14: =+E$3 -> 2 | F14: =+F$3 -> 2 | G14: =+G$3 -> 3 | H14: =+H$3 -> 3 | I14: =+I$3 -> 1 | J14: =+J$3 -> 1 | ... V14: =+V$3 -> 0.15 | W14: 23 | AG14: =1+2 -> 3 | AL14: 1 | AP14: 2 | AQ14: =5/12 -> 0.41666667 | AU14: 0.5 | AV14: 5 | AW14: 5 | AX14: 5 | BA14: 5 | BC14: 4
A15: 8 | B15: KONAN IVETTE | C15: =+C$3 -> 10 | D15: =+D$3 -> 3 | E15: =+E$3 -> 2 | F15: =+F$3 -> 2 | G15: =+G$3 -> 3 | H15: =+H$3 -> 3 | I15: =+I$3 -> 1 | J15: =+J$3 -> 1 | ... V15: =+V$3 -> 0.15 | W15: 25 | AB15: 1 | AG15: =1+1+2+4 -> 8 | AL15: 1 | AN15: 1 | AO15: 2 | AP15: 4 | AQ15: =4/12 -> 0.33333333 | AS15: =3/20 -> 0.15 | AT15: 0.6 | AU15: 1 | AV15: 5 | AW15: 5 | AX15: 5 | BA15: =4+5 -> 9 | BC15: =6+10 -> 16
A16: 9 | B16: KRA PACOME | C16: =+C$3 -> 10 | D16: =+D$3 -> 3 | E16: =+E$3 -> 2 | F16: =+F$3 -> 2 | G16: =+G$3 -> 3 | H16: =+H$3 -> 3 | I16: =+I$3 -> 1 | J16: =+J$3 -> 1 | ... V16: =+V$3 -> 0.15 | W16: 28 | AF16: 1 | AG16: =1+1+3 -> 5 | AL16: 1 | AO16: 1 | AP16: 4 | AQ16: =3/12 -> 0.25 | AT16: 0.2 | AU16: 1 | AV16: 5 | AW16: 5 | AX16: 5 | BA16: 3 | BC16: =2+10 -> 12
A17: 10 | B17: OULAY EMMENUELLA | C17: =+C$3 -> 10 | D17: =+D$3 -> 3 | E17: =+E$3 -> 2 | F17: =+F$3 -> 2 | G17: =+G$3 -> 3 | H17: =+H$3 -> 3 | I17: =+I$3 -> 1 | J17: =+J$3 -> 1 | ... V17: =+V$3 -> 0.15 | W17: 27 | AF17: 1 | AG17: =1+1+1+3 -> 6 | AL17: 1 | AN17: 1 | AO17: 1 | AP17: 4 | AQ17: =2/12 -> 0.16666667 | AS17: =3/20 -> 0.15 | AT17: 0.2 | AU17: 1 | AV17: 5 | AW17: 5 | AX17: 5 | BA17: =2+5 -> 7 | BC17: =2+10 -> 12
A18: 11 | B18: KONATE MARIAM | C18: =+C$3 -> 10 | D18: =+D$3 -> 3 | E18: =+E$3 -> 2 | F18: =+F$3 -> 2 | G18: =+G$3 -> 3 | H18: =+H$3 -> 3 | I18: =+I$3 -> 1 | J18: =+J$3 -> 1 | ... V18: =+V$3 -> 0.15 | W18: 23 | AD18: 1 | AG18: =1+4 -> 5 | AL18: 1 | AN18: 1 | AP18: 4 | AQ18: =3/12 -> 0.25 | AU18: 1 | AV18: 5 | AW18: 5 | AX18: 5 | BA18: 3 | BC18: 10
A19: 12 | B19: KOUAME JORES | C19: =+C$3 -> 10 | D19: =+D$3 -> 3 | E19: =+E$3 -> 2 | F19: =+F$3 -> 2 | G19: =+G$3 -> 3 | H19: =+H$3 -> 3 | I19: =+I$3 -> 1 | J19: =+J$3 -> 1 | ... V19: =+V$3 -> 0.15 | W19: 25 | AG19: =1+4 -> 5 | AO19: 1 | AP19: 4 | AT19: 0.4 | AU19: 1 | AV19: 5 | AW19: 5 | AX19: 5 | BC19: =4+10 -> 14
A20: 13 | B20: KOUAKOU ADJOUA ROSE | C20: =+C$3 -> 10 | D20: =+D$3 -> 3 | E20: =+E$3 -> 2 | F20: =+F$3 -> 2 | G20: =+G$3 -> 3 | H20: =+H$3 -> 3 | I20: =+I$3 -> 1 | J20: =+J$3 -> 1 | ... V20: =+V$3 -> 0.15 | W20: 27 | AE20: 2 | AG20: =1+1+4 -> 6 | AL20: 1 | AN20: 1 | AO20: 2 | AP20: 4 | AQ20: =6/12 -> 0.5 | AS20: =3/20 -> 0.15 | AU20: 1 | AV20: 5 | AW20: 5 | AX20: 5 | BA20: =6+5 -> 11 | BC20: 10
A21: 14 | B21: OULAY WILFRIED | C21: =+C$3 -> 10 | D21: =+D$3 -> 3 | E21: =+E$3 -> 2 | F21: =+F$3 -> 2 | G21: =+G$3 -> 3 | H21: =+H$3 -> 3 | I21: =+I$3 -> 1 | J21: =+J$3 -> 1 | ... V21: =+V$3 -> 0.15 | W21: 28 | AG21: =1+1+4 -> 6 | AL21: 1 | AN21: 1 | AP21: 4 | AQ21: =4/12 -> 0.33333333 | AS21: =3/20 -> 0.15 | AU21: 1.5 | AV21: 5 | AW21: 5 | AX21: 5 | BA21: =4+5 -> 9 | BC21: =10+4 -> 14
A22: 15 | B22: KONATE MOUSSA | C22: =+C$3 -> 10 | D22: =+D$3 -> 3 | E22: =+E$3 -> 2 | F22: =+F$3 -> 2 | G22: =+G$3 -> 3 | H22: =+H$3 -> 3 | I22: =+I$3 -> 1 | J22: =+J$3 -> 1 | ... V22: =+V$3 -> 0.15 | W22: 11 | AE22: 1 | AG22: =1+4 -> 5 | AL22: 1 | AO22: 1 | AP22: 4 | AQ22: =5/12 -> 0.41666667 | AU22: 1 | AV22: 5 | AW22: 5 | AX22: 5 | BA22: 5 | BC22: 10
A23: 16 | B23: NGORAN AXCEL | C23: =+C$3 -> 10 | D23: =+D$3 -> 3 | E23: =+E$3 -> 2 | F23: =+F$3 -> 2 | G23: =+G$3 -> 3 | H23: =+H$3 -> 3 | I23: =+I$3 -> 1 | J23: =+J$3 -> 1 | ... V23: =+V$3 -> 0.15 | W23: 20 | AG23: =1+4 -> 5 | AN23: 1 | AP23: 4 | AS23: =3/20 -> 0.15 | AU23: 1 | AV23: 5 | AW23: 5 | AX23: 5 | BA23: 5 | BC23: 10
A24: 17 | B24: TRAORE ARSENE | C24: =+C$3 -> 10 | D24: =+D$3 -> 3 | E24: =+E$3 -> 2 | F24: =+F$3 -> 2 | G24: =+G$3 -> 3 | H24: =+H$3 -> 3 | I24: =+I$3 -> 1 | J24: =+J$3 -> 1 | ... V24: =+V$3 -> 0.15 | W24: 22 | AD24: 1 | AF24: 1 | AG24: =1+2+8 -> 11 | AL24: 1 | AN24: 1 | AO24: 2 | AP24: 9 | AQ24: =5/12 -> 0.41666667 | AT24: 0.5 | AU24: 3 | AV24: 5 | AW24: 5 | AX24: 5 | BA24: 5 | BC24: =5+30 -> 35
A25: 18 | B25: NGUESSAN INNOCENT | C25: =+C$3 -> 10 | D25: =+D$3 -> 3 | E25: =+E$3 -> 2 | F25: =+F$3 -> 2 | G25: =+G$3 -> 3 | H25: =+H$3 -> 3 | I25: =+I$3 -> 1 | J25: =+J$3 -> 1 | ... V25: =+V$3 -> 0.15 | W25: 25 | AG25: =1+3 -> 4 | AL25: 1 | AP25: 3 | AQ25: =4/12 -> 0.33333333 | AU25: 1 | AV25: 5 | AW25: 5 | AX25: 5 | BA25: 4 | BC25: 10
A26: 19 | B26: KOUAME ARISTIDE | C26: =+C$3 -> 10 | D26: =+D$3 -> 3 | E26: =+E$3 -> 2 | F26: =+F$3 -> 2 | G26: =+G$3 -> 3 | H26: =+H$3 -> 3 | I26: =+I$3 -> 1 | J26: =+J$3 -> 1 | ... V26: =+V$3 -> 0.15 | W26: 24 | AE26: 1 | AG26: =1+1+3 -> 5 | AN26: 1 | AO26: 2 | AP26: 3 | AS26: =3/20 -> 0.15 | AT26: 0.5 | AU26: 1.5 | AV26: 5 | AW26: 5 | AX26: 5 | BA26: 5 | BC26: =5+10+4 -> 19
A27: 20 | B27: BERTRAND | C27: =+C$3 -> 10 | D27: =+D$3 -> 3 | E27: =+E$3 -> 2 | F27: =+F$3 -> 2 | G27: =+G$3 -> 3 | H27: =+H$3 -> 3 | I27: =+I$3 -> 1 | J27: =+J$3 -> 1 | ... V27: =+V$3 -> 0.15 | W27: 20 | AB27: 1 | AD27: 1 | AG27: =2+1+3+6 -> 12 | AL27: 3 | AN27: 1 | AO27: 3 | AP27: 6 | AQ27: =5/12 -> 0.41666667 | AS27: =3/20 -> 0.15 | AT27: 1 | AU27: 2 | AV27: 5 | AW27: 5 | AX27: 5 | BA27: =5+5 -> 10 | BC27: =10+20 -> 30
B28: TOTAL | C28: =SUM(C8:C27) -> 200 | D28: =SUM(D8:D27) -> 60 | E28: =SUM(E8:E27) -> 40 | F28: =SUM(F8:F27) -> 40 | G28: =SUM(G8:G27) -> 60 | H28: =SUM(H8:H27) -> 60 | I28: =SUM(I8:I27) -> 20 | J28: =SUM(J8:J27) -> 20 | ... BE28: =SUM(BE8:BE27) -> 0

Sheet Jeudi
B2: VILLE
C3: 10 | D3: 3 | E3: 2 | F3: 2 | G3: 3 | H3: 3 | I3: 1 | J3: 1 | K3: 1 | L3: 1 | M3: =+H3 -> 3 | N3: 1 | O3: =+H3 -> 3 | R3: =+(2*M3)/12 -> 0.5 | S3: =+(1*I3)/6 -> 0.16666667 | T3: =+(2*I3)/20 -> 0.1 | U3: =+(2*H3)/10 -> 0.6 | V3: =+(3*I3)/20 -> 0.15
C5: OBJECTIFS JOURNALIERS | W5: REALISATIONS | BD5: Commentaires | BE5: Impressions des PDV et des clients
A6: N° | B6: Agent promoteur | C6: Nombre de visite / Type de PDV | H6: Nombre de référencement / Type de PDV | M6: Pose de matériel de visibilité | R6: Vente en cartons | W6: Nombre de visite / Type de PDV | AB6: Présence produits antérieure | AG6: Nombre de référencement / Type de PDV | AL6: Nouveau Référencement par SKU | AQ6: Vente en cartons | AV6: Pose de matériel de visibilité | BA6: Gratuits offerts en sachet
C7: Boutique | D7: Superette | E7: Kiosque | F7: Tablier | G7: Pushcart | H7: Boutique | I7: Superette | J7: Kiosque | K7: Tablier | L7: Pushcart | M7: Affiche Biblos Lait Prémium 16g & 360g | N7: Affiche Biblos Lait Excellence | O7: Affiche Biblos Flocons d' Avoine | P7: Hanger | Q7: Wobbler | R7: Biblos Lait Premium 16g | S7: Biblos Lait Premium 360g | T7: Biblos Lait Excellence 900g | U7: Biblos Flocon d'avoine 50g | V7: Biblos Flocon d'avoine 400g | W7: Boutique | X7: Superette | Y7: Kiosque | Z7: Tablier | AA7: Pushcart | AB7: Biblos Lait Premium 16g | AC7: Biblos Lait Premium 360g | AD7: Biblos Lait Excellence 900g | AE7: Biblos Flocon d'avoine 50g | AF7: Biblos Flocon d'avoine 400g | AG7: Boutique | AH7: Superette | AI7: Kiosque | AJ7: Tablier | AK7: Pushcart | AL7: Biblos Lait Premium 16g | AM7: Biblos Lait Premium 360g | AN7: Biblos Lait Excellence 900g | AO7: Biblos Flocon d'avoine 50g | AP7: Biblos Flocon d'avoine 400g | AQ7: Biblos Lait Premium 16g | AR7: Biblos Lait Premium 360g | AS7: Biblos Lait Excellence 900g | AT7: Biblos Flocon d'avoine 50g | AU7: Biblos Flocon d'avoine 400g | AV7: Affiche Biblos Lait Prémium 16g & 360g | AW7: Affiche Biblos Lait Excellence | AX7: Affiche Biblos Flocons d' Avoine | AY7: Hanger | AZ7: Wobbler | BA7: Biblos Lait Premium 16g | BB7: Biblos Lait Excellence 900g | BC7: Biblos Flocon d'avoine 50g
A8: 1 | B8: DIBI SIMEON | C8: =+C$3 -> 10 | D8: =+D$3 -> 3 | E8: =+E$3 -> 2 | F8: =+F$3 -> 2 | G8: =+G$3 -> 3 | H8: =+H$3 -> 3 | I8: =+I$3 -> 1 | J8: =+J$3 -> 1 | ... V8: =+V$3 -> 0.15 | W8: 25 | AB8: 1 | AF8: 1 | AG8: =1+1+2+4 -> 8 | AL8: 2 | AN8: 1 | AO8: 2 | AP8: 5 | AQ8: =4/12 -> 0.33333333 | AS8: =3/20 -> 0.15 | AT8: 0.5 | AU8: 1 | AV8: 5 | AW8: 5 | AX8: 5 | BA8: =4+5 -> 9 | BC8: =5+10 -> 15
A9: 2 | B9: DAGO BRICE | C9: =+C$3 -> 10 | D9: =+D$3 -> 3 | E9: =+E$3 -> 2 | F9: =+F$3 -> 2 | G9: =+G$3 -> 3 | H9: =+H$3 -> 3 | I9: =+I$3 -> 1 | J9: =+J$3 -> 1 | ... V9: =+V$3 -> 0.15 | W9: 23 | AF9: 1 | AG9: =1+3+6 -> 10 | AL9: 1 | AO9: 3 | AP9: 6 | AQ9: =5/12 -> 0.41666667 | AT9: 0.5 | AU9: 2 | AV9: 5 | AW9: 5 | AX9: 5 | BA9: 5 | BC9: =5+20 -> 25
A10: 3 | B10: KRA EVAVARISTE | C10: =+C$3 -> 10 | D10: =+D$3 -> 3 | E10: =+E$3 -> 2 | F10: =+F$3 -> 2 | G10: =+G$3 -> 3 | H10: =+H$3 -> 3 | I10: =+I$3 -> 1 | J10: =+J$3 -> 1 | ... V10: =+V$3 -> 0.15 | W10: 28 | AG10: =1+1+5 -> 7 | AL10: 1 | AO10: 1 | AP10: 5 | AQ10: =4/12 -> 0.33333333 | AT10: 0.6 | AU10: 1.5 | AV10: 5 | AW10: 5 | AX10: 5 | BA10: 4 | BC10: =6+14 -> 20
A11: 4 | B11: DIOMANDE ESTHER | C11: =+C$3 -> 10 | D11: =+D$3 -> 3 | E11: =+E$3 -> 2 | F11: =+F$3 -> 2 | G11: =+G$3 -> 3 | H11: =+H$3 -> 3 | I11: =+I$3 -> 1 | J11: =+J$3 -> 1 | ... V11: =+V$3 -> 0.15 | W11: 26 | AB11: 1 | AG11: =2+1+6 -> 9 | AL11: 3 | AN11: 1 | AP11: 6 | AQ11: =8/12 -> 0.66666667 | AS11: =3/20 -> 0.15 | AU11: 2 | AV11: 5 | AW11: 5 | AX11: 5 | BA11: =8+5 -> 13 | BC11: 20
A12: 5 | B12: BADA LANDRY | C12: =+C$3 -> 10 | D12: =+D$3 -> 3 | E12: =+E$3 -> 2 | F12: =+F$3 -> 2 | G12: =+G$3 -> 3 | H12: =+H$3 -> 3 | I12: =+I$3 -> 1 | J12: =+J$3 -> 1 | ... V12: =+V$3 -> 0.15 | W12: 28 | AG12: =1+3+7 -> 11 | AL12: 1 | AO12: 3 | AP12: 7 | AQ12: =6/12 -> 0.5 | AT12: 1 | AU12: 2 | AV12: 5 | AW12: 5 | AX12: 5 | BA12: 6 | BC12: =10+20 -> 30
A13: 6 | B13: KOUAME JOSE | C13: =+C$3 -> 10 | D13: =+D$3 -> 3 | E13: =+E$3 -> 2 | F13: =+F$3 -> 2 | G13: =+G$3 -> 3 | H13: =+H$3 -> 3 | I13: =+I$3 -> 1 | J13: =+J$3 -> 1 | ... V13: =+V$3 -> 0.15 | W13: 27 | AD13: 1 | AG13: =3+1+1+1 -> 6 | AL13: 3 | AN13: 2 | AO13: 1 | AP13: 1 | AQ13: =12/12 -> 1 | AS13: =4/20 -> 0.2 | AT13: 0.6 | AU13: 0.5 | AV13: 5 | AW13: 5 | AX13: 5 | BA13: =10+5 -> 15 | BC13: =6+4 -> 10
A14: 7 | B14: FANY BARAKISSA | C14: =+C$3 -> 10 | D14: =+D$3 -> 3 | E14: =+E$3 -> 2 | F14: =+F$3 -> 2 | G14: =+G$3 -> 3 | H14: =+H$3 -> 3 | I14: =+I$3 -> 1 | J14: =+J$3 -> 1 | ... V14: =+V$3 -> 0.15 | W14: 23 | AG14: =1+1+7 -> 9 | AL14: 1 | AO14: 1 | AP14: 7 | AQ14: =2/12 -> 0.16666667 | AT14: 0.4 | AU14: 2 | AV14: 5 | AW14: 5 | AX14: 5 | BA14: 2 | BC14: =4+20 -> 24
A15: 8 | B15: KONAN IVETTE | C15: =+C$3 -> 10 | D15: =+D$3 -> 3 | E15: =+E$3 -> 2 | F15: =+F$3 -> 2 | G15: =+G$3 -> 3 | H15: =+H$3 -> 3 | I15: =+I$3 -> 1 | J15: =+J$3 -> 1 | ... V15: =+V$3 -> 0.15 | W15: 25 | AE15: 1 | AG15: =1+1+2+6 -> 10 | AL15: 1 | AN15: 1 | AO15: 3 | AP15: 6 | AQ15: =4/12 -> 0.33333333 | AS15: =3/20 -> 0.15 | AT15: 0.5 | AU15: 2 | AV15: 5 | AW15: 5 | AX15: 5 | BA15: =4+5 -> 9 | BC15: =5+20 -> 25
A16: 9 | B16: KRA PACOME | C16: =+C$3 -> 10 | D16: =+D$3 -> 3 | E16: =+E$3 -> 2 | F16: =+F$3 -> 2 | G16: =+G$3 -> 3 | H16: =+H$3 -> 3 | I16: =+I$3 -> 1 | J16: =+J$3 -> 1 | ... V16: =+V$3 -> 0.15 | W16: 31 | AG16: =1+1+9 -> 11 | AL16: 1 | AO16: 1 | AP16: 9 | AQ16: =5/12 -> 0.41666667 | AT16: 0.6 | AU16: 3 | AV16: 5 | AW16: 5 | AX16: 5 | BA16: 5 | BC16: =6+30 -> 36
A17: 10 | B17: OULAY EMMENUELLA | C17: =+C$3 -> 10 | D17: =+D$3 -> 3 | E17: =+E$3 -> 2 | F17: =+F$3 -> 2 | G17: =+G$3 -> 3 | H17: =+H$3 -> 3 | I17: =+I$3 -> 1 | J17: =+J$3 -> 1 | ... V17: =+V$3 -> 0.15 | W17: 26 | AF17: 1 | AG17: =1+1+2+10 -> 14 | AL17: 1 | AN17: 1 | AO17: 2 | AP17: 11 | AQ17: =5/12 -> 0.41666667 | AS17: =3/20 -> 0.15 | AT17: 0.4 | AU17: 4 | AV17: 5 | AW17: 5 | AX17: 5 | BA17: =5+5 -> 10 | BC17: =4+40 -> 44
A18: 11 | B18: KONATE MARIAM | C18: =+C$3 -> 10 | D18: =+D$3 -> 3 | E18: =+E$3 -> 2 | F18: =+F$3 -> 2 | G18: =+G$3 -> 3 | H18: =+H$3 -> 3 | I18: =+I$3 -> 1 | J18: =+J$3 -> 1 | ... V18: =+V$3 -> 0.15 | W18: 26 | AG18: =4+1+2+4 -> 11 | AL18: 4 | AN18: 1 | AO18: 2 | AP18: 4 | AQ18: =12/12 -> 1 | AS18: =3/20 -> 0.15 | AT18: 0.5 | AU18: 2 | AV18: 5 | AW18: 5 | AX18: 5 | BA18: =10+5 -> 15 | BC18: =5+20 -> 25
A19: 12 | B19: KOUAME JORES | C19: =+C$3 -> 10 | D19: =+D$3 -> 3 | E19: =+E$3 -> 2 | F19: =+F$3 -> 2 | G19: =+G$3 -> 3 | H19: =+H$3 -> 3 | I19: =+I$3 -> 1 | J19: =+J$3 -> 1 | ... V19: =+V$3 -> 0.15 | W19: 27 | AG19: =1+3 -> 4 | AL19: 1 | AP19: 3 | AQ19: =5/12 -> 0.41666667 | AU19: 1 | AV19: 5 | AW19: 5 | AX19: 5 | BA19: 5 | BC19: 20
A20: 13 | B20: KOUAKOU ADJOUA ROSE | C20: =+C$3 -> 10 | D20: =+D$3 -> 3 | E20: =+E$3 -> 2 | F20: =+F$3 -> 2 | G20: =+G$3 -> 3 | H20: =+H$3 -> 3 | I20: =+I$3 -> 1 | J20: =+J$3 -> 1 | ... V20: =+V$3 -> 0.15 | W20: 25 | AE20: 2 | AG20: =2+1+1+6 -> 10 | AL20: 2 | AN20: 1 | AO20: 3 | AP20: 6 | AQ20: =8/12 -> 0.66666667 | AS20: =6/20 -> 0.3 | AT20: 0.4 | AU20: 2 | AV20: 5 | AW20: 5 | AX20: 5 | BA20: =8+10 -> 18 | BC20: =4+20 -> 24
A21: 14 | B21: OULAY WILFRIED | C21: =+C$3 -> 10 | D21: =+D$3 -> 3 | E21: =+E$3 -> 2 | F21: =+F$3 -> 2 | G21: =+G$3 -> 3 | H21: =+H$3 -> 3 | I21: =+I$3 -> 1 | J21: =+J$3 -> 1 | ... V21: =+V$3 -> 0.15 | W21: 28 | AB21: 1 | AG21: =1+1+1+5 -> 8 | AL21: 2 | AN21: 1 | AO21: 1 | AP21: 5 | AQ21: =12/12 -> 1 | AS21: =3/20 -> 0.15 | AT21: 0.5 | AU21: 1.5 | AV21: 5 | AW21: 5 | AX21: 5 | BA21: =10+5 -> 15 | BC21: =5+14 -> 19
A22: 15 | B22: KONATE MOUSSA | C22: =+C$3 -> 10 | D22: =+D$3 -> 3 | E22: =+E$3 -> 2 | F22: =+F$3 -> 2 | G22: =+G$3 -> 3 | H22: =+H$3 -> 3 | I22: =+I$3 -> 1 | J22: =+J$3 -> 1 | ... V22: =+V$3 -> 0.15 | W22: 30 | AF22: 1 | AG22: =1+1+1+1 -> 4 | AL22: 1 | AN22: 1 | AO22: 1 | AP22: 2 | AQ22: =6/12 -> 0.5 | AS22: =3/20 -> 0.15 | AT22: 0.5 | AU22: 0.5 | AV22: 5 | AW22: 5 | AX22: 5 | BA22: =6+5 -> 11 | BC22: =5+4 -> 9
A23: 16 | B23: NGORAN AXCEL | C23: =+C$3 -> 10 | D23: =+D$3 -> 3 | E23: =+E$3 -> 2 | F23: =+F$3 -> 2 | G23: =+G$3 -> 3 | H23: =+H$3 -> 3 | I23: =+I$3 -> 1 | J23: =+J$3 -> 1 | ... V23: =+V$3 -> 0.15 | W23: 25 | AB23: 1 | AG23: =1+1+4 -> 6 | AL23: 2 | AO23: 1 | AP23: 4 | AQ23: =6/12 -> 0.5 | AT23: 0.2 | AU23: 1 | AV23: 5 | AW23: 5 | AX23: 5 | BA23: 6 | BC23: =2+10 -> 12
A24: 17 | B24: TRAORE ARSENE | C24: =+C$3 -> 10 | D24: =+D$3 -> 3 | E24: =+E$3 -> 2 | F24: =+F$3 -> 2 | G24: =+G$3 -> 3 | H24: =+H$3 -> 3 | I24: =+I$3 -> 1 | J24: =+J$3 -> 1 | ... V24: =+V$3 -> 0.15 | W24: 28 | AG24: =1+1+1+3 -> 6 | AL24: 1 | AN24: 1 | AO24: 1 | AP24: 3 | AQ24: =6/12 -> 0.5 | AS24: =3/20 -> 0.15 | AT24: 0.3 | AU24: 1 | AV24: 5 | AW24: 5 | AX24: 5 | BA24: =6+5 -> 11 | BC24: =3+10 -> 13
A25: 18 | B25: NGUESSAN INNOCENT | C25: =+C$3 -> 10 | D25: =+D$3 -> 3 | E25: =+E$3 -> 2 | F25: =+F$3 -> 2 | G25: =+G$3 -> 3 | H25: =+H$3 -> 3 | I25: =+I$3 -> 1 | J25: =+J$3 -> 1 | ... V25: =+V$3 -> 0.15 | W25: 26 | AE25: 1 | AG25: =1+7 -> 8 | AL25: 1 | AO25: 1 | AP25: 7 | AQ25: =12/12 -> 1 | AU25: 2 | AV25: 5 | AW25: 5 | AX25: 5 | BA25: 10 | BC25: 20
A26: 19 | B26: KOUAME ARISTIDE | C26: =+C$3 -> 10 | D26: =+D$3 -> 3 | E26: =+E$3 -> 2 | F26: =+F$3 -> 2 | G26: =+G$3 -> 3 | H26: =+H$3 -> 3 | I26: =+I$3 -> 1 | J26: =+J$3 -> 1 | ... V26: =+V$3 -> 0.15 | W26: 20 | AC26: 1 | AG26: =1+1+3 -> 5 | AL26: 1 | AM26: 1 | AN26: 1 | AP26: 3 | AQ26: =3/12 -> 0.25 | AS26: =3/20 -> 0.15 | AU26: 1 | AV26: 5 | AW26: 5 | AX26: 5 | BA26: =3+5 -> 8 | BC26: 10
A27: 20 | B27: BERTRAND | C27: =+C$3 -> 10 | D27: =+D$3 -> 3 | E27: =+E$3 -> 2 | F27: =+F$3 -> 2 | G27: =+G$3 -> 3 | H27: =+H$3 -> 3 | I27: =+I$3 -> 1 | J27: =+J$3 -> 1 | ... V27: =+V$3 -> 0.15 | W27: 28 | AB27: 1 | AD27: 1 | AG27: =1+1+1+10 -> 13 | AL27: 2 | AN27: 1 | AO27: 1 | AP27: 10 | AQ27: =7/12 -> 0.58333333 | AS27: =3/20 -> 0.15 | AT27: 0.5 | AU27: 4 | AV27: 5 | AW27: 5 | AX27: 5 | BA27: =7+5 -> 12 | BC27: =5+40 -> 45
B28: TOTAL | C28: =SUM(C8:C27) -> 200 | D28: =SUM(D8:D27) -> 60 | E28: =SUM(E8:E27) -> 40 | F28: =SUM(F8:F27) -> 40 | G28: =SUM(G8:G27) -> 60 | H28: =SUM(H8:H27) -> 60 | I28: =SUM(I8:I27) -> 20 | J28: =SUM(J8:J27) -> 20 | ... BE28: =SUM(BE8:BE27) -> 0

Sheet Vendredi
B2: VILLE
C3: 10 | D3: 3 | E3: 2 | F3: 2 | G3: 3 | H3: 3 | I3: 1 | J3: 1 | K3: 1 | L3: 1 | M3: =+H3 -> 3 | N3: 1 | O3: =+H3 -> 3 | R3: =+(2*M3)/12 -> 0.5 | S3: =+(1*I3)/6 -> 0.16666667 | T3: =+(2*I3)/20 -> 0.1 | U3: =+(2*H3)/10 -> 0.6 | V3: =+(3*I3)/20 -> 0.15
C5: OBJECTIFS JOURNALIERS | W5: REALISATIONS | BD5: Commentaires | BE5: Impressions des PDV et des clients
A6: N° | B6: Agent promoteur | C6: Nombre de visite / Type de PDV | H6: Nombre de référencement / Type de PDV | M6: Pose de matériel de visibilité | R6: Vente en cartons | W6: Nombre de visite / Type de PDV | AB6: Présence produits antérieure | AG6: Nombre de référencement / Type de PDV | AL6: Nouveau Référencement par SKU | AQ6: Vente en cartons | AV6: Pose de matériel de visibilité | BA6: Gratuits offerts en sachet
C7: Boutique | D7: Superette | E7: Kiosque | F7: Tablier | G7: Pushcart | H7: Boutique | I7: Superette | J7: Kiosque | K7: Tablier | L7: Pushcart | M7: Affiche Biblos Lait Prémium 16g & 360g | N7: Affiche Biblos Lait Excellence | O7: Affiche Biblos Flocons d' Avoine | P7: Hanger | Q7: Wobbler | R7: Biblos Lait Premium 16g | S7: Biblos Lait Premium 360g | T7: Biblos Lait Excellence 900g | U7: Biblos Flocon d'avoine 50g | V7: Biblos Flocon d'avoine 400g | W7: Boutique | X7: Superette | Y7: Kiosque | Z7: Tablier | AA7: Pushcart | AB7: Biblos Lait Premium 16g | AC7: Biblos Lait Premium 360g | AD7: Biblos Lait Excellence 900g | AE7: Biblos Flocon d'avoine 50g | AF7: Biblos Flocon d'avoine 400g | AG7: Boutique | AH7: Superette | AI7: Kiosque | AJ7: Tablier | AK7: Pushcart | AL7: Biblos Lait Premium 16g | AM7: Biblos Lait Premium 360g | AN7: Biblos Lait Excellence 900g | AO7: Biblos Flocon d'avoine 50g | AP7: Biblos Flocon d'avoine 400g | AQ7: Biblos Lait Premium 16g | AR7: Biblos Lait Premium 360g | AS7: Biblos Lait Excellence 900g | AT7: Biblos Flocon d'avoine 50g | AU7: Biblos Flocon d'avoine 400g | AV7: Affiche Biblos Lait Prémium 16g & 360g | AW7: Affiche Biblos Lait Excellence | AX7: Affiche Biblos Flocons d' Avoine | AY7: Hanger | AZ7: Wobbler | BA7: Biblos Lait Premium 16g | BB7: Biblos Lait Excellence 900g | BC7: Biblos Flocon d'avoine 50g
A8: 1 | B8: DIBI SIMEON | C8: =+C$3 -> 10 | D8: =+D$3 -> 3 | E8: =+E$3 -> 2 | F8: =+F$3 -> 2 | G8: =+G$3 -> 3 | H8: =+H$3 -> 3 | I8: =+I$3 -> 1 | J8: =+J$3 -> 1 | ... V8: =+V$3 -> 0.15 | W8: 25 | AE8: 1 | AG8: =1+1+1+5 -> 8 | AL8: 1 | AN8: 1 | AO8: 2 | AP8: 5 | AQ8: =4/12 -> 0.33333333 | AS8: =3/20 -> 0.15 | AT8: 0.4 | AU8: 2 | AV8: 5 | AW8: 5 | AX8: 5 | BA8: =4+5 -> 9 | BC8: =4+20 -> 24
A9: 2 | B9: DAGO BRICE | C9: =+C$3 -> 10 | D9: =+D$3 -> 3 | E9: =+E$3 -> 2 | F9: =+F$3 -> 2 | G9: =+G$3 -> 3 | H9: =+H$3 -> 3 | I9: =+I$3 -> 1 | J9: =+J$3 -> 1 | ... V9: =+V$3 -> 0.15 | W9: 25 | AG9: =1+8 -> 9 | AL9: 1 | AP9: 8 | AQ9: =6/12 -> 0.5 | AU9: 3 | AV9: 5 | AW9: 5 | AX9: 5 | BA9: 6 | BC9: 30
A10: 3 | B10: KRA K. EVAVARISTE | C10: =+C$3 -> 10 | D10: =+D$3 -> 3 | E10: =+E$3 -> 2 | F10: =+F$3 -> 2 | G10: =+G$3 -> 3 | H10: =+H$3 -> 3 | I10: =+I$3 -> 1 | J10: =+J$3 -> 1 | ... V10: =+V$3 -> 0.15 | W10: 24 | AB10: 1 | AE10: 1 | AG10: =1+1+6 -> 8 | AL10: 2 | AO10: 1 | AP10: 6 | AQ10: =3/12 -> 0.25 | AT10: 0.4 | AU10: 2 | AV10: 5 | AW10: 5 | AX10: 5 | BA10: 3 | BC10: =4+20 -> 24
A11: 4 | B11: DIOMANDE ESTHER | C11: =+C$3 -> 10 | D11: =+D$3 -> 3 | E11: =+E$3 -> 2 | F11: =+F$3 -> 2 | G11: =+G$3 -> 3 | H11: =+H$3 -> 3 | I11: =+I$3 -> 1 | J11: =+J$3 -> 1 | ... V11: =+V$3 -> 0.15 | W11: 24 | AB11: 1 | AG11: =1+1+7 -> 9 | AL11: 1 | AN11: 1 | AP11: 7 | AQ11: =5/12 -> 0.41666667 | AS11: =3/20 -> 0.15 | AU11: 2.5 | AV11: 5 | AW11: 5 | AX11: 5 | BA11: =5+5 -> 10 | BC11: =20+4 -> 24
A12: 5 | B12: BADA LANDRY | C12: =+C$3 -> 10 | D12: =+D$3 -> 3 | E12: =+E$3 -> 2 | F12: =+F$3 -> 2 | G12: =+G$3 -> 3 | H12: =+H$3 -> 3 | I12: =+I$3 -> 1 | J12: =+J$3 -> 1 | ... V12: =+V$3 -> 0.15 | W12: 30 | AE12: 1 | AG12: =1+2 -> 3 | AO12: 1 | AP12: 2 | AT12: 0.4 | AU12: 0.5 | AV12: 5 | AW12: 5 | AX12: 5 | BC12: =4+4 -> 8
A13: 6 | B13: KOUAME JOSE | C13: =+C$3 -> 10 | D13: =+D$3 -> 3 | E13: =+E$3 -> 2 | F13: =+F$3 -> 2 | G13: =+G$3 -> 3 | H13: =+H$3 -> 3 | I13: =+I$3 -> 1 | J13: =+J$3 -> 1 | ... V13: =+V$3 -> 0.15 | W13: 25 | AG13: =1+1+1+6 -> 9 | AL13: 1 | AN13: 1 | AO13: 1 | AP13: 6 | AQ13: =2/12 -> 0.16666667 | AS13: =3/20 -> 0.15 | AT13: 0.4 | AU13: 2 | AV13: 5 | AW13: 5 | AX13: 5 | BA13: =2+5 -> 7 | BC13: =4+20 -> 24
A14: 7 | B14: FANY BARAKISSA | C14: =+C$3 -> 10 | D14: =+D$3 -> 3 | E14: =+E$3 -> 2 | F14: =+F$3 -> 2 | G14: =+G$3 -> 3 | H14: =+H$3 -> 3 | I14: =+I$3 -> 1 | J14: =+J$3 -> 1 | ... V14: =+V$3 -> 0.15 | W14: 23 | AE14: 1 | AG14: =1+1+1+10 -> 13 | AL14: 1 | AN14: 1 | AO14: 2 | AP14: 10 | AQ14: =8/12 -> 0.66666667 | AS14: =3/20 -> 0.15 | AT14: 0.2 | AU14: 3 | AV14: 5 | AW14: 5 | AX14: 5 | BA14: =8+5 -> 13 | BC14: =2+30 -> 32
A15: 8 | B15: KONAN IVETTE | C15: =+C$3 -> 10 | D15: =+D$3 -> 3 | E15: =+E$3 -> 2 | F15: =+F$3 -> 2 | G15: =+G$3 -> 3 | H15: =+H$3 -> 3 | I15: =+I$3 -> 1 | J15: =+J$3 -> 1 | ... V15: =+V$3 -> 0.15 | W15: 24 | AG15: =1+1 -> 2 | AL15: 1 | AP15: 1 | AQ15: =6/12 -> 0.5 | AU15: 0.5 | AV15: 5 | AW15: 5 | AX15: 5 | BA15: 6 | BC15: 4
A16: 9 | B16: KRA PACOME | C16: =+C$3 -> 10 | D16: =+D$3 -> 3 | E16: =+E$3 -> 2 | F16: =+F$3 -> 2 | G16: =+G$3 -> 3 | H16: =+H$3 -> 3 | I16: =+I$3 -> 1 | J16: =+J$3 -> 1 | ... V16: =+V$3 -> 0.15 | W16: 29 | AD16: 1 | AG16: =1+1+7 -> 9 | AL16: 1 | AN16: 1 | AO16: 1 | AP16: 7 | AQ16: =5/12 -> 0.41666667 | AT16: 0.4 | AU16: 1 | AV16: 5 | AW16: 5 | AX16: 5 | BA16: 5 | BC16: =4+10 -> 14
A17: 10 | B17: OULAY EMMENUELLA | C17: =+C$3 -> 10 | D17: =+D$3 -> 3 | E17: =+E$3 -> 2 | F17: =+F$3 -> 2 | G17: =+G$3 -> 3 | H17: =+H$3 -> 3 | I17: =+I$3 -> 1 | J17: =+J$3 -> 1 | ... V17: =+V$3 -> 0.15 | W17: 27 | AG17: =1+4 -> 5 | AN17: 1 | AP17: 4 | AS17: =6/20 -> 0.3 | AU17: 1 | AV17: 5 | AW17: 5 | AX17: 5 | BA17: 10 | BC17: 10
A18: 11 | B18: KONATE MARIAM | C18: =+C$3 -> 10 | D18: =+D$3 -> 3 | E18: =+E$3 -> 2 | F18: =+F$3 -> 2 | G18: =+G$3 -> 3 | H18: =+H$3 -> 3 | I18: =+I$3 -> 1 | J18: =+J$3 -> 1 | ... V18: =+V$3 -> 0.15 | W18: 25 | AG18: =1+1+1+6 -> 9 | AL18: 1 | AN18: 1 | AO18: 1 | AP18: 6 | AQ18: =5/12 -> 0.41666667 | AS18: =3/20 -> 0.15 | AT18: 0.4 | AU18: 2 | AV18: 5 | AW18: 5 | AX18: 5 | BA18: =5+5 -> 10 | BC18: =4+20 -> 24
A19: 12 | B19: KOUAME JAURES | C19: =+C$3 -> 10 | D19: =+D$3 -> 3 | E19: =+E$3 -> 2 | F19: =+F$3 -> 2 | G19: =+G$3 -> 3 | H19: =+H$3 -> 3 | I19: =+I$3 -> 1 | J19: =+J$3 -> 1 | ... V19: =+V$3 -> 0.15 | W19: 27 | AD19: 1 | AE19: 2 | AF19: 1 | AG19: =1+1+2 -> 4 | AL19: 1 | AN19: 1 | AO19: 2 | AP19: 3 | AQ19: =4/12 -> 0.33333333 | AS19: =3/20 -> 0.15 | AU19: 1 | AV19: 5 | AW19: 5 | AX19: 5 | BA19: =4+5 -> 9 | BC19: 10
A20: 13 | B20: KOUAKOU ADJOUA ROSE | C20: =+C$3 -> 10 | D20: =+D$3 -> 3 | E20: =+E$3 -> 2 | F20: =+F$3 -> 2 | G20: =+G$3 -> 3 | H20: =+H$3 -> 3 | I20: =+I$3 -> 1 | J20: =+J$3 -> 1 | ... V20: =+V$3 -> 0.15 | W20: 23 | AF20: 1 | AG20: =2+6 -> 8 | AL20: 2 | AP20: 7 | AQ20: =8/12 -> 0.66666667 | AU20: 1.5 | AV20: 5 | AW20: 5 | AX20: 5 | BA20: 8 | BC20: =10+4 -> 14
A21: 14 | B21: OULAY WILFRIED | C21: =+C$3 -> 10 | D21: =+D$3 -> 3 | E21: =+E$3 -> 2 | F21: =+F$3 -> 2 | G21: =+G$3 -> 3 | H21: =+H$3 -> 3 | I21: =+I$3 -> 1 | J21: =+J$3 -> 1 | ... V21: =+V$3 -> 0.15 | W21: 27 | AG21: =1+1+2+9 -> 13 | AL21: 1 | AN21: 1 | AO21: 2 | AP21: 9 | AQ21: =4/12 -> 0.33333333 | AS21: =4/20 -> 0.2 | AT21: 0.5 | AU21: 3 | AV21: 5 | AW21: 5 | AX21: 5 | BA21: =4+5 -> 9 | BC21: =5+30 -> 35
A22: 15 | B22: TRAORE ARSENE | C22: =+C$3 -> 10 | D22: =+D$3 -> 3 | E22: =+E$3 -> 2 | F22: =+F$3 -> 2 | G22: =+G$3 -> 3 | H22: =+H$3 -> 3 | I22: =+I$3 -> 1 | J22: =+J$3 -> 1 | ... V22: =+V$3 -> 0.15 | AE22: 1 | AG22: =1+6 -> 7 | AN22: 2 | AP22: 6 | AS22: =3/20 -> 0.15 | AU22: 2 | AV22: 5 | AW22: 5 | AX22: 5 | BA22: 5 | BC22: 20
A23: 16 | B23: NGUESSAN INNOCENT | C23: =+C$3 -> 10 | D23: =+D$3 -> 3 | E23: =+E$3 -> 2 | F23: =+F$3 -> 2 | G23: =+G$3 -> 3 | H23: =+H$3 -> 3 | I23: =+I$3 -> 1 | J23: =+J$3 -> 1 | ... V23: =+V$3 -> 0.15 | W23: 27 | AB23: 1 | AG23: =1+1+7 -> 9 | AL23: 2 | AN23: 1 | AP23: 7 | AQ23: =6/12 -> 0.5 | AS23: =3/20 -> 0.15 | AU23: 2 | AV23: 5 | AW23: 5 | AX23: 5 | BA23: =6+5 -> 11 | BC23: 20
A24: 17 | B24: KOUAME ARISTIDE | C24: =+C$3 -> 10 | D24: =+D$3 -> 3 | E24: =+E$3 -> 2 | F24: =+F$3 -> 2 | G24: =+G$3 -> 3 | H24: =+H$3 -> 3 | I24: =+I$3 -> 1 | J24: =+J$3 -> 1 | ... V24: =+V$3 -> 0.15 | W24: 28 | AG24: =1+1+11 -> 13 | AL24: 1 | AO24: 1 | AP24: 11 | AQ24: =6/12 -> 0.5 | AT24: 0.4 | AU24: 3 | AV24: 5 | AW24: 5 | AX24: 5 | BA24: 6 | BC24: =4+30 -> 34
A25: 18 | B25: GRACE | C25: =+C$3 -> 10 | D25: =+D$3 -> 3 | E25: =+E$3 -> 2 | F25: =+F$3 -> 2 | G25: =+G$3 -> 3 | H25: =+H$3 -> 3 | I25: =+I$3 -> 1 | J25: =+J$3 -> 1 | ... V25: =+V$3 -> 0.15 | W25: 23 | AB25: 1 | AG25: =1+1+4 -> 6 | AN25: 1 | AO25: 1 | AP25: 4 | AS25: =3/20 -> 0.15 | AT25: 0.5 | AU25: 2 | AV25: 5 | AW25: 5 | AX25: 5 | BA25: 5 | BC25: =5+20 -> 25
A26: 19 | B26: KOUAME STEPHANIE | C26: =+C$3 -> 10 | D26: =+D$3 -> 3 | E26: =+E$3 -> 2 | F26: =+F$3 -> 2 | G26: =+G$3 -> 3 | H26: =+H$3 -> 3 | I26: =+I$3 -> 1 | J26: =+J$3 -> 1 | ... V26: =+V$3 -> 0.15 | W26: 25 | AB26: 1 | AF26: 1 | AG26: =1+2 -> 3 | AL26: 2 | AP26: 3 | AQ26: =6/12 -> 0.5 | AU26: 1 | AV26: 5 | AW26: 5 | AX26: 5 | BA26: 6 | BC26: 10
A27: 20 | B27: BERTRAND | C27: =+C$3 -> 10 | D27: =+D$3 -> 3 | E27: =+E$3 -> 2 | F27: =+F$3 -> 2 | G27: =+G$3 -> 3 | H27: =+H$3 -> 3 | I27: =+I$3 -> 1 | J27: =+J$3 -> 1 | ... V27: =+V$3 -> 0.15 | W27: 27 | AD27: 1 | AG27: =1+1+6 -> 8 | AL27: 1 | AN27: 2 | AP27: 6 | AQ27: =6/12 -> 0.5 | AS27: =3/20 -> 0.15 | AU27: 2 | AV27: 5 | AW27: 5 | AX27: 5 | BA27: =6+5 -> 11 | BC27: 20
B28: TOTAL | C28: =SUM(C8:C27) -> 200 | D28: =SUM(D8:D27) -> 60 | E28: =SUM(E8:E27) -> 40 | F28: =SUM(F8:F27) -> 40 | G28: =SUM(G8:G27) -> 60 | H28: =SUM(H8:H27) -> 60 | I28: =SUM(I8:I27) -> 20 | J28: =SUM(J8:J27) -> 20 | ... BE28: =SUM(BE8:BE27) -> 0

Sheet Samedi
B2: VILLE
C3: 10 | D3: 3 | E3: 2 | F3: 2 | G3: 3 | H3: 3 | I3: 1 | J3: 1 | K3: 1 | L3: 1 | M3: =+H3 -> 3 | N3: 1 | O3: =+H3 -> 3 | R3: =+(2*M3)/12 -> 0.5 | S3: =+(1*I3)/6 -> 0.16666667 | T3: =+(2*I3)/20 -> 0.1 | U3: =+(2*H3)/10 -> 0.6 | V3: =+(3*I3)/20 -> 0.15
C5: OBJECTIFS JOURNALIERS | W5: REALISATIONS | BD5: Commentaires | BE5: Impressions des PDV et des clients
A6: N° | B6: Agent promoteur | C6: Nombre de visite / Type de PDV | H6: Nombre de référencement / Type de PDV | M6: Pose de matériel de visibilité | R6: Vente en cartons | W6: Nombre de visite / Type de PDV | AB6: Présence produits antérieure | AG6: Nombre de référencement / Type de PDV | AL6: Nouveau Référencement par SKU | AQ6: Vente en cartons | AV6: Pose de matériel de visibilité | BA6: Gratuits offerts en sachet
C7: Boutique | D7: Superette | E7: Kiosque | F7: Tablier | G7: Pushcart | H7: Boutique | I7: Superette | J7: Kiosque | K7: Tablier | L7: Pushcart | M7: Affiche Biblos Lait Prémium 16g & 360g | N7: Affiche Biblos Lait Excellence | O7: Affiche Biblos Flocons d' Avoine | P7: Hanger | Q7: Wobbler | R7: Biblos Lait Premium 16g | S7: Biblos Lait Premium 360g | T7: Biblos Lait Excellence 900g | U7: Biblos Flocon d'avoine 50g | V7: Biblos Flocon d'avoine 400g | W7: Boutique | X7: Superette | Y7: Kiosque | Z7: Tablier | AA7: Pushcart | AB7: Biblos Lait Premium 16g | AC7: Biblos Lait Premium 360g | AD7: Biblos Lait Excellence 900g | AE7: Biblos Flocon d'avoine 50g | AF7: Biblos Flocon d'avoine 400g | AG7: Boutique | AH7: Superette | AI7: Kiosque | AJ7: Tablier | AK7: Pushcart | AL7: Biblos Lait Premium 16g | AM7: Biblos Lait Premium 360g | AN7: Biblos Lait Excellence 900g | AO7: Biblos Flocon d'avoine 50g | AP7: Biblos Flocon d'avoine 400g | AQ7: Biblos Lait Premium 16g | AR7: Biblos Lait Premium 360g | AS7: Biblos Lait Excellence 900g | AT7: Biblos Flocon d'avoine 50g | AU7: Biblos Flocon d'avoine 400g | AV7: Affiche Biblos Lait Prémium 16g & 360g | AW7: Affiche Biblos Lait Excellence | AX7: Affiche Biblos Flocons d' Avoine | AY7: Hanger | AZ7: Wobbler | BA7: Biblos Lait Premium 16g | BB7: Biblos Lait Excellence 900g | BC7: Biblos Flocon d'avoine 50g
A8: 1 | B8: DIBI SIMEON | C8: =+C$3 -> 10 | D8: =+D$3 -> 3 | E8: =+E$3 -> 2 | F8: =+F$3 -> 2 | G8: =+G$3 -> 3 | H8: =+H$3 -> 3 | I8: =+I$3 -> 1 | J8: =+J$3 -> 1 | ... V8: =+V$3 -> 0.15 | W8: 27 | AB8: 1 | AG8: =1+1+5 -> 7 | AL8: 2 | AO8: 1 | AP8: 5 | AQ8: =5/12 -> 0.41666667 | AT8: 0.4 | AU8: 1 | AV8: 5 | AW8: 5 | AX8: 5 | BA8: 5 | BC8: =4+10 -> 14
A9: 2 | B9: DAGO BRICE | C9: =+C$3 -> 10 | D9: =+D$3 -> 3 | E9: =+E$3 -> 2 | F9: =+F$3 -> 2 | G9: =+G$3 -> 3 | H9: =+H$3 -> 3 | I9: =+I$3 -> 1 | J9: =+J$3 -> 1 | ... V9: =+V$3 -> 0.15 | W9: 28 | AE9: 1 | AG9: =1+4 -> 5 | AL9: 1 | AO9: 1 | AP9: 4 | AQ9: =5/12 -> 0.41666667 | AU9: 1 | AV9: 5 | AW9: 5 | AX9: 5 | BA9: 5 | BC9: 10
A10: 3 | B10: KRA K. EVAVARISTE | C10: =+C$3 -> 10 | D10: =+D$3 -> 3 | E10: =+E$3 -> 2 | F10: =+F$3 -> 2 | G10: =+G$3 -> 3 | H10: =+H$3 -> 3 | I10: =+I$3 -> 1 | J10: =+J$3 -> 1 | ... V10: =+V$3 -> 0.15 | W10: 29 | AG10: =1+5 -> 6 | AN10: 1 | AP10: 5 | AS10: =3/20 -> 0.15 | AU10: 1.5 | AV10: 5 | AW10: 5 | AX10: 5 | BA10: 5 | BC10: =10+4 -> 14
A11: 4 | B11: DIOMANDE ESTHER | C11: =+C$3 -> 10 | D11: =+D$3 -> 3 | E11: =+E$3 -> 2 | F11: =+F$3 -> 2 | G11: =+G$3 -> 3 | H11: =+H$3 -> 3 | I11: =+I$3 -> 1 | J11: =+J$3 -> 1 | ... V11: =+V$3 -> 0.15 | W11: 26 | AG11: =1+1+5 -> 7 | AL11: 1 | AN11: 1 | AP11: 5 | AQ11: =4/12 -> 0.33333333 | AS11: 0.15 | AU11: 2 | AV11: 5 | AW11: 5 | AX11: 5 | BA11: =4+5 -> 9 | BC11: 20
A12: 5 | B12: BADA LANDRY | C12: =+C$3 -> 10 | D12: =+D$3 -> 3 | E12: =+E$3 -> 2 | F12: =+F$3 -> 2 | G12: =+G$3 -> 3 | H12: =+H$3 -> 3 | I12: =+I$3 -> 1 | J12: =+J$3 -> 1 | ... V12: =+V$3 -> 0.15 | W12: 29 | AE12: 1 | AG12: =1+2 -> 3 | AN12: 1 | AO12: 1 | AP12: 2 | AS12: 0.15 | AU12: 1 | AV12: 5 | AW12: 5 | AX12: 5 | BA12: 5 | BC12: 10
A13: 6 | B13: KOUAME JOSE | C13: =+C$3 -> 10 | D13: =+D$3 -> 3 | E13: =+E$3 -> 2 | F13: =+F$3 -> 2 | G13: =+G$3 -> 3 | H13: =+H$3 -> 3 | I13: =+I$3 -> 1 | J13: =+J$3 -> 1 | ... V13: =+V$3 -> 0.15 | W13: 27 | AG13: =1+1+1 -> 3 | AL13: 1 | AO13: 1 | AP13: 1 | AQ13: =5/12 -> 0.41666667 | AT13: 0.6 | AU13: 0.5 | AV13: 5 | AW13: 5 | AX13: 5 | BA13: 5 | BC13: =6+4 -> 10
A14: 7 | B14: FANY BARAKISSA | C14: =+C$3 -> 10 | D14: =+D$3 -> 3 | E14: =+E$3 -> 2 | F14: =+F$3 -> 2 | G14: =+G$3 -> 3 | H14: =+H$3 -> 3 | I14: =+I$3 -> 1 | J14: =+J$3 -> 1 | ... V14: =+V$3 -> 0.15 | W14: 28 | AG14: =1+3 -> 4 | AN14: 1 | AP14: 3 | AS14: 0.15 | AU14: 0.5 | AV14: 5 | AW14: 5 | AX14: 5 | BA14: 5 | BC14: 4
A15: 8 | B15: KONAN IVETTE | C15: =+C$3 -> 10 | D15: =+D$3 -> 3 | E15: =+E$3 -> 2 | F15: =+F$3 -> 2 | G15: =+G$3 -> 3 | H15: =+H$3 -> 3 | I15: =+I$3 -> 1 | J15: =+J$3 -> 1 | ... V15: =+V$3 -> 0.15 | W15: 25 | AE15: 1 | AG15: =1+1+1+6 -> 9 | AL15: 1 | AN15: 1 | AO15: 2 | AP15: 6 | AQ15: =5/12 -> 0.41666667 | AS15: 0.15 | AT15: 0.3 | AU15: 2 | AV15: 5 | AW15: 5 | AX15: 5 | BA15: =5+5 -> 10 | BC15: =3+20 -> 23
A16: 9 | B16: KRA PACOME | C16: =+C$3 -> 10 | D16: =+D$3 -> 3 | E16: =+E$3 -> 2 | F16: =+F$3 -> 2 | G16: =+G$3 -> 3 | H16: =+H$3 -> 3 | I16: =+I$3 -> 1 | J16: =+J$3 -> 1 | ... V16: =+V$3 -> 0.15 | W16: 24 | AG16: =1+1+2+5 -> 9 | AL16: 1 | AN16: 1 | AO16: 2 | AP16: 5 | AQ16: =4/12 -> 0.33333333 | AS16: 0.15 | AT16: 0.5 | AU16: 1.5 | AV16: 5 | AW16: 5 | AX16: 5 | BA16: =4+5 -> 9 | BC16: =5+10+4 -> 19
A17: 10 | B17: OULAY EMMENUELLA | C17: =+C$3 -> 10 | D17: =+D$3 -> 3 | E17: =+E$3 -> 2 | F17: =+F$3 -> 2 | G17: =+G$3 -> 3 | H17: =+H$3 -> 3 | I17: =+I$3 -> 1 | J17: =+J$3 -> 1 | ... V17: =+V$3 -> 0.15 | W17: 27 | AF17: 1 | AG17: 1 | AL17: 1 | AP17: 1 | AQ17: =5/12 -> 0.41666667 | AV17: 5 | AW17: 5 | AX17: 5 | BA17: 5
A18: 11 | B18: KONATE MARIAM | C18: =+C$3 -> 10 | D18: =+D$3 -> 3 | E18: =+E$3 -> 2 | F18: =+F$3 -> 2 | G18: =+G$3 -> 3 | H18: =+H$3 -> 3 | I18: =+I$3 -> 1 | J18: =+J$3 -> 1 | ... V18: =+V$3 -> 0.15 | W18: 23 | AB18: 2 | AD18: 1 | AG18: =1+1+1+7 -> 10 | AL18: 3 | AN18: 2 | AO18: 1 | AP18: 7 | AQ18: =4/12 -> 0.33333333 | AS18: 0.15 | AT18: 0.4 | AU18: 2 | AV18: 5 | AW18: 5 | AX18: 5 | BA18: =4+5 -> 9 | BC18: =4+20 -> 24
A19: 12 | B19: KOUAME JAURES | C19: =+C$3 -> 10 | D19: =+D$3 -> 3 | E19: =+E$3 -> 2 | F19: =+F$3 -> 2 | G19: =+G$3 -> 3 | H19: =+H$3 -> 3 | I19: =+I$3 -> 1 | J19: =+J$3 -> 1 | ... V19: =+V$3 -> 0.15 | W19: 26 | AG19: =1+10 -> 11 | AN19: 1 | AP19: 10 | AS19: =4/20 -> 0.2 | AU19: 3 | AV19: 5 | AW19: 5 | AX19: 5 | BA19: 5 | BC19: 30
A20: 13 | B20: KOUAKOU ADJOUA ROSE | C20: =+C$3 -> 10 | D20: =+D$3 -> 3 | E20: =+E$3 -> 2 | F20: =+F$3 -> 2 | G20: =+G$3 -> 3 | H20: =+H$3 -> 3 | I20: =+I$3 -> 1 | J20: =+J$3 -> 1 | ... V20: =+V$3 -> 0.15 | W20: 24 | AE20: 2 | AG20: =1+4 -> 5 | AL20: 1 | AO20: 2 | AP20: 4 | AQ20: =5/12 -> 0.41666667 | AU20: 1.5 | AV20: 5 | AW20: 5 | AX20: 5 | BA20: 5 | BC20: 14
A21: 14 | B21: OULAY WILFRIED | C21: =+C$3 -> 10 | D21: =+D$3 -> 3 | E21: =+E$3 -> 2 | F21: =+F$3 -> 2 | G21: =+G$3 -> 3 | H21: =+H$3 -> 3 | I21: =+I$3 -> 1 | J21: =+J$3 -> 1 | ... V21: =+V$3 -> 0.15 | W21: 28 | AG21: =1+1+1+3 -> 6 | AL21: 1 | AN21: 1 | AO21: 1 | AP21: 3 | AQ21: =6/12 -> 0.5 | AS21: 0.15 | AT21: 0.5 | AU21: 1 | AV21: 5 | AW21: 5 | AX21: 5 | BA21: =6+5 -> 11 | BC21: =5+10 -> 15
A22: 15 | B22: TRAORE ARSENE | C22: =+C$3 -> 10 | D22: =+D$3 -> 3 | E22: =+E$3 -> 2 | F22: =+F$3 -> 2 | G22: =+G$3 -> 3 | H22: =+H$3 -> 3 | I22: =+I$3 -> 1 | J22: =+J$3 -> 1 | ... V22: =+V$3 -> 0.15 | W22: 27 | AG22: =1+1 -> 2 | AL22: 1 | AP22: 1 | AQ22: =5/12 -> 0.41666667 | AU22: 0.5 | AV22: 5 | AW22: 5 | AX22: 5 | BA22: 5 | BC22: 4
A23: 16 | B23: NGUESSAN INNOCENT | C23: =+C$3 -> 10 | D23: =+D$3 -> 3 | E23: =+E$3 -> 2 | F23: =+F$3 -> 2 | G23: =+G$3 -> 3 | H23: =+H$3 -> 3 | I23: =+I$3 -> 1 | J23: =+J$3 -> 1 | ... V23: =+V$3 -> 0.15 | W23: 27 | AB23: 1 | AG23: =1+3 -> 4 | AL23: 2 | AP23: 3 | AQ23: =6/12 -> 0.5 | AU23: 1 | AV23: 5 | AW23: 5 | AX23: 5 | BA23: 6 | BC23: 10
A24: 17 | B24: KOUAME ARISTIDE | C24: =+C$3 -> 10 | D24: =+D$3 -> 3 | E24: =+E$3 -> 2 | F24: =+F$3 -> 2 | G24: =+G$3 -> 3 | H24: =+H$3 -> 3 | I24: =+I$3 -> 1 | J24: =+J$3 -> 1 | ... V24: =+V$3 -> 0.15 | W24: 25 | AD24: 1 | AF24: 1 | AG24: =1+1+4 -> 6 | AN24: 2 | AO24: 1 | AP24: 5 | AS24: 0.15 | AT24: 0.5 | AU24: 1 | AV24: 5 | AW24: 5 | AX24: 5 | BA24: 5 | BC24: =5+10 -> 15
A25: 18 | B25: GRACE | C25: =+C$3 -> 10 | D25: =+D$3 -> 3 | E25: =+E$3 -> 2 | F25: =+F$3 -> 2 | G25: =+G$3 -> 3 | H25: =+H$3 -> 3 | I25: =+I$3 -> 1 | J25: =+J$3 -> 1 | ... V25: =+V$3 -> 0.15 | W25: 25 | AG25: =1+1+1+8 -> 11 | AL25: 1 | AN25: 1 | AO25: 1 | AP25: 8 | AQ25: =4/12 -> 0.33333333 | AS25: 0.15 | AT25: 0.4 | AU25: 2 | AV25: 5 | AW25: 5 | AX25: 5 | BA25: =4+5 -> 9 | BC25: =4+20 -> 24
