Workbook

Sheet Lundi S1
C3: 15 | D3: 3 | E3: 5 | F3: 2 | G3: 5 | H3: 3 | I3: 1 | J3: 1 | K3: 1 | L3: 1 | M3: =+H3 -> 3 | N3: 1 | O3: =+H3 -> 3 | R3: =+(2*M3)/12 -> 0.5 | S3: =+(1*I3)/6 -> 0.16666667 | T3: =+(2*I3)/20 -> 0.1 | U3: =+(2*H3)/10 -> 0.6 | V3: =+(3*I3)/20 -> 0.15
A4: GAGNOA JOUR 1
C5: OBJECTIFS JOURNALIERS | W5: REALISATIONS | AT5: Commentaires | AU5: Impressions des PDV et des clients
A6: N° | B6: Agent promoteur | C6: Nombre de visite / Type de PDV | H6: Nombre de référencement / Type de PDV | M6: Pose de matériel de visibilité | R6: Vente en cartons | W6: Nombre de visite / Type de PDV | AB6: Nombre de référencement / Type de PDV | AG6: Pose de matériel de visibilité | AL6: Vente en cartons | AQ6: Gratuits offerts en sachet
C7: Boutique | D7: Superette | E7: Kiosque | F7: Tablier | G7: Pushcart | H7: Boutique | I7: Superette | J7: Kiosque | K7: Tablier | L7: Pushcart | M7: Affiche Biblos Lait Prémium 16g & 360g | N7: Affiche Biblos Lait Excellence | O7: Affiche Biblos Flocons d' Avoine | P7: Hanger | Q7: Wobbler | R7: Biblos Lait Premium 16g | S7: Biblos Lait Premium 360g | T7: Biblos Lait Excellence 900g | U7: Biblos Flocon d'avoine 50g | V7: Biblos Flocon d'avoine 400g | W7: Boutique | X7: Superette | Y7: Kiosque | Z7: Tablier | AA7: Pushcart | AB7: Boutique | AC7: Superette | AD7: Kiosque | AE7: Tablier | AF7: Pushcart | AG7: Affiche Biblos Lait Prémium 16g & 360g | AH7: Affiche Biblos Lait Excellence | AI7: Affiche Biblos Flocons d' Avoine | AJ7: Hanger | AK7: Wobbler | AL7: Biblos Lait Premium 16g | AM7: Biblos Lait Premium 360g | AN7: Biblos Lait Excellence 900g | AO7: Biblos Flocon d'avoine 50g | AP7: Biblos Flocon d'avoine 400g | AQ7: Biblos Lait Premium 16g | AR7: Biblos Lait Excellence 900g | AS7: Biblos Flocon d'avoine 50g
A8: 1 | C8: =+C$3 -> 15 | D8: =+D$3 -> 3 | E8: =+E$3 -> 5 | F8: =+F$3 -> 2 | G8: =+G$3 -> 5 | H8: =+H$3 -> 3 | I8: =+I$3 -> 1 | J8: =+J$3 -> 1 | ... V8: =+V$3 -> 0.15 | W8: 21 | Z8: 1 | AA8: 1 | AB8: 11 | AG8: 5 | AI8: 5 | AL8: 0.58 | AO8: =60/100 -> 0.6 | AQ8: 7 | AS8: 6
A9: 2 | C9: =+C$3 -> 15 | D9: =+D$3 -> 3 | E9: =+E$3 -> 5 | F9: =+F$3 -> 2 | G9: =+G$3 -> 5 | H9: =+H$3 -> 3 | I9: =+I$3 -> 1 | J9: =+J$3 -> 1 | ... V9: =+V$3 -> 0.15 | W9: 19 | AB9: 9 | AG9: 5 | AI9: 5 | AL9: 0.42 | AN9: =3/20 -> 0.15 | AQ9: 5 | AT9: Le commerciale de la zone à déjà référencé certains points de détaillants
A10: 3 | C10: =+C$3 -> 15 | D10: =+D$3 -> 3 | E10: =+E$3 -> 5 | F10: =+F$3 -> 2 | G10: =+G$3 -> 5 | H10: =+H$3 -> 3 | I10: =+I$3 -> 1 | J10: =+J$3 -> 1 | ... V10: =+V$3 -> 0.15 | W10: 21 | Z10: 1 | AB10: 7 | AE10: 1 | AF10: 1 | AG10: 5 | AI10: 5 | AL10: 0.42 | AN10: =1/20 -> 0.05 | AO10: =40/100 -> 0.4 | AQ10: 5 | AS10: 4 | AT10: Certains sont sont reticents car les produits sont nouveaux et prefèrent attendre le demande des consommateurs ou une communication grand media avant de se decider
A11: 4 | C11: =+C$3 -> 15 | D11: =+D$3 -> 3 | E11: =+E$3 -> 5 | F11: =+F$3 -> 2 | G11: =+G$3 -> 5 | H11: =+H$3 -> 3 | I11: =+I$3 -> 1 | J11: =+J$3 -> 1 | ... V11: =+V$3 -> 0.15 | W11: 22 | AA11: 1 | AB11: 8 | AG11: 5 | AI11: 5 | AL11: 0.42 | AN11: =2/20 -> 0.1 | AO11: =50/100 -> 0.5 | AQ11: 5 | AS11: 5
A12: 5 | C12: =+C$3 -> 15 | D12: =+D$3 -> 3 | E12: =+E$3 -> 5 | F12: =+F$3 -> 2 | G12: =+G$3 -> 5 | H12: =+H$3 -> 3 | I12: =+I$3 -> 1 | J12: =+J$3 -> 1 | ... V12: =+V$3 -> 0.15 | W12: 28 | AB12: 10 | AG12: 5 | AI12: 5 | AL12: 0.5 | AO12: =60/100 -> 0.6 | AQ12: 6 | AS12: 6
A13: 6 | C13: =+C$3 -> 15 | D13: =+D$3 -> 3 | E13: =+E$3 -> 5 | F13: =+F$3 -> 2 | G13: =+G$3 -> 5 | H13: =+H$3 -> 3 | I13: =+I$3 -> 1 | J13: =+J$3 -> 1 | ... V13: =+V$3 -> 0.15 | W13: 26 | AB13: 11 | AG13: 5 | AI13: 5 | AL13: 0.5 | AN13: =3/20 -> 0.15 | AP13: =2/20 -> 0.1 | AQ13: 6 | AT13: La majeur partie des acheteurs ont fait des achats de détail (chapelet ou sachet)
A14: 7 | C14: =+C$3 -> 15 | D14: =+D$3 -> 3 | E14: =+E$3 -> 5 | F14: =+F$3 -> 2 | G14: =+G$3 -> 5 | H14: =+H$3 -> 3 | I14: =+I$3 -> 1 | J14: =+J$3 -> 1 | ... V14: =+V$3 -> 0.15 | W14: 23 | AB14: 12 | AG14: 5 | AI14: 5 | AL14: 1 | AO14: =70/100 -> 0.7 | AQ14: 12 | AS14: 8
A15: 8 | C15: =+C$3 -> 15 | D15: =+D$3 -> 3 | E15: =+E$3 -> 5 | F15: =+F$3 -> 2 | G15: =+G$3 -> 5 | H15: =+H$3 -> 3 | I15: =+I$3 -> 1 | J15: =+J$3 -> 1 | ... V15: =+V$3 -> 0.15 | W15: 20 | AB15: 9 | AG15: 5 | AI15: 5 | AL15: 0 | AN15: =1/20 -> 0.05 | AO15: =50/100 -> 0.5 | AP15: =1/20 -> 0.05 | AS15: 5 | AT15: Le format 360g de lait n'était pas disponible
A16: 9 | C16: =+C$3 -> 15 | D16: =+D$3 -> 3 | E16: =+E$3 -> 5 | F16: =+F$3 -> 2 | G16: =+G$3 -> 5 | H16: =+H$3 -> 3 | I16: =+I$3 -> 1 | J16: =+J$3 -> 1 | ... V16: =+V$3 -> 0.15 | W16: 31 | Z16: 2 | AA16: 1 | AB16: 12 | AF16: 1 | AG16: 5 | AI16: 5 | AL16: 0.33 | AQ16: 4
A17: 10 | C17: =+C$3 -> 15 | D17: =+D$3 -> 3 | E17: =+E$3 -> 5 | F17: =+F$3 -> 2 | G17: =+G$3 -> 5 | H17: =+H$3 -> 3 | I17: =+I$3 -> 1 | J17: =+J$3 -> 1 | ... V17: =+V$3 -> 0.15 | W17: 22 | AB17: 11 | AG17: 5 | AI17: 5 | AL17: 0.17 | AO17: =10/100 -> 0.1 | AP17: =5/20 -> 0.25 | AQ17: 2 | AS17: 3
A18: 11 | C18: =+C$3 -> 15 | D18: =+D$3 -> 3 | E18: =+E$3 -> 5 | F18: =+F$3 -> 2 | G18: =+G$3 -> 5 | H18: =+H$3 -> 3 | I18: =+I$3 -> 1 | J18: =+J$3 -> 1 | ... V18: =+V$3 -> 0.15 | W18: 19 | AB18: 10 | AG18: 5 | AI18: 5 | AL18: 0.42 | AO18: =40/100 -> 0.4 | AQ18: 5 | AS18: 4
A19: 12 | C19: =+C$3 -> 15 | D19: =+D$3 -> 3 | E19: =+E$3 -> 5 | F19: =+F$3 -> 2 | G19: =+G$3 -> 5 | H19: =+H$3 -> 3 | I19: =+I$3 -> 1 | J19: =+J$3 -> 1 | ... V19: =+V$3 -> 0.15 | W19: 21 | AB19: 7 | AG19: 5 | AI19: 5 | AL19: 0.42 | AN19: =2/20 -> 0.1 | AO19: =60/100 -> 0.6 | AQ19: 4 | AS19: 6
A20: 13 | C20: =+C$3 -> 15 | D20: =+D$3 -> 3 | E20: =+E$3 -> 5 | F20: =+F$3 -> 2 | G20: =+G$3 -> 5 | H20: =+H$3 -> 3 | I20: =+I$3 -> 1 | J20: =+J$3 -> 1 | ... V20: =+V$3 -> 0.15 | W20: 23 | AB20: 13 | AG20: 5 | AI20: 5 | AL20: 0.42 | AQ20: 5
A21: 14 | C21: =+C$3 -> 15 | D21: =+D$3 -> 3 | E21: =+E$3 -> 5 | F21: =+F$3 -> 2 | G21: =+G$3 -> 5 | H21: =+H$3 -> 3 | I21: =+I$3 -> 1 | J21: =+J$3 -> 1 | ... V21: =+V$3 -> 0.15 | W21: 27 | AB21: 10 | AG21: 5 | AI21: 5 | AL21: 0.17 | AN21: =3/20 -> 0.15 | AO21: =60/100 -> 0.6 | AQ21: 2 | AS21: 6
A22: 15 | C22: =+C$3 -> 15 | D22: =+D$3 -> 3 | E22: =+E$3 -> 5 | F22: =+F$3 -> 2 | G22: =+G$3 -> 5 | H22: =+H$3 -> 3 | I22: =+I$3 -> 1 | J22: =+J$3 -> 1 | ... V22: =+V$3 -> 0.15 | W22: 18 | X22: 1 | AB22: 10 | AG22: 5 | AI22: 5 | AL22: 0.42 | AQ22: 5
A23: 16 | C23: =+C$3 -> 15 | D23: =+D$3 -> 3 | E23: =+E$3 -> 5 | F23: =+F$3 -> 2 | G23: =+G$3 -> 5 | H23: =+H$3 -> 3 | I23: =+I$3 -> 1 | J23: =+J$3 -> 1 | ... V23: =+V$3 -> 0.15 | W23: 25 | Z23: 2 | AB23: 12 | AG23: 5 | AI23: 5 | AL23: 0.33 | AO23: =60/100 -> 0.6 | AQ23: 4 | AS23: 6
A24: 17 | C24: =+C$3 -> 15 | D24: =+D$3 -> 3 | E24: =+E$3 -> 5 | F24: =+F$3 -> 2 | G24: =+G$3 -> 5 | H24: =+H$3 -> 3 | I24: =+I$3 -> 1 | J24: =+J$3 -> 1 | ... V24: =+V$3 -> 0.15 | W24: 23 | Y24: 1 | AA24: 1 | AB24: 9 | AG24: 5 | AI24: 5 | AL24: 0.42 | AO24: =60/100 -> 0.6 | AP24: =2/20 -> 0.1 | AQ24: 5 | AS24: 7
A25: 18 | C25: =+C$3 -> 15 | D25: =+D$3 -> 3 | E25: =+E$3 -> 5 | F25: =+F$3 -> 2 | G25: =+G$3 -> 5 | H25: =+H$3 -> 3 | I25: =+I$3 -> 1 | J25: =+J$3 -> 1 | ... V25: =+V$3 -> 0.15 | W25: 20 | AB25: 12 | AG25: 5 | AI25: 5 | AL25: 0.5 | AN25: =1/20 -> 0.05 | AO25: =50/100 -> 0.5 | AQ25: 6 | AS25: 5
A26: 19 | C26: =+C$3 -> 15 | D26: =+D$3 -> 3 | E26: =+E$3 -> 5 | F26: =+F$3 -> 2 | G26: =+G$3 -> 5 | H26: =+H$3 -> 3 | I26: =+I$3 -> 1 | J26: =+J$3 -> 1 | ... V26: =+V$3 -> 0.15 | W26: 18 | X26: 1 | AB26: 8 | AF26: 1 | AG26: 5 | AI26: 5 | AL26: 0.33 | AO26: =35/100 -> 0.35 | AQ26: 4 | AS26: 6
A27: 20 | C27: =+C$3 -> 15 | D27: =+D$3 -> 3 | E27: =+E$3 -> 5 | F27: =+F$3 -> 2 | G27: =+G$3 -> 5 | H27: =+H$3 -> 3 | I27: =+I$3 -> 1 | J27: =+J$3 -> 1 | ... V27: =+V$3 -> 0.15
A28: 21 | C28: =+C$3 -> 15 | D28: =+D$3 -> 3 | E28: =+E$3 -> 5 | F28: =+F$3 -> 2 | G28: =+G$3 -> 5 | H28: =+H$3 -> 3 | I28: =+I$3 -> 1 | J28: =+J$3 -> 1 | ... V28: =+V$3 -> 0.15
A29: 22 | C29: =+C$3 -> 15 | D29: =+D$3 -> 3 | E29: =+E$3 -> 5 | F29: =+F$3 -> 2 | G29: =+G$3 -> 5 | H29: =+H$3 -> 3 | I29: =+I$3 -> 1 | J29: =+J$3 -> 1 | ... V29: =+V$3 -> 0.15
A30: 23 | C30: =+C$3 -> 15 | D30: =+D$3 -> 3 | E30: =+E$3 -> 5 | F30: =+F$3 -> 2 | G30: =+G$3 -> 5 | H30: =+H$3 -> 3 | I30: =+I$3 -> 1 | J30: =+J$3 -> 1 | ... V30: =+V$3 -> 0.15
A31: 24 | C31: =+C$3 -> 15 | D31: =+D$3 -> 3 | E31: =+E$3 -> 5 | F31: =+F$3 -> 2 | G31: =+G$3 -> 5 | H31: =+H$3 -> 3 | I31: =+I$3 -> 1 | J31: =+J$3 -> 1 | ... V31: =+V$3 -> 0.15
A32: 25 | C32: =+C$3 -> 15 | D32: =+D$3 -> 3 | E32: =+E$3 -> 5 | F32: =+F$3 -> 2 | G32: =+G$3 -> 5 | H32: =+H$3 -> 3 | I32: =+I$3 -> 1 | J32: =+J$3 -> 1 | ... V32: =+V$3 -> 0.15
A33: 26 | C33: =+C$3 -> 15 | D33: =+D$3 -> 3 | E33: =+E$3 -> 5 | F33: =+F$3 -> 2 | G33: =+G$3 -> 5 | H33: =+H$3 -> 3 | I33: =+I$3 -> 1 | J33: =+J$3 -> 1 | ... V33: =+V$3 -> 0.15
A34: 27 | C34: =+C$3 -> 15 | D34: =+D$3 -> 3 | E34: =+E$3 -> 5 | F34: =+F$3 -> 2 | G34: =+G$3 -> 5 | H34: =+H$3 -> 3 | I34: =+I$3 -> 1 | J34: =+J$3 -> 1 | ... V34: =+V$3 -> 0.15
A35: 28 | C35: =+C$3 -> 15 | D35: =+D$3 -> 3 | E35: =+E$3 -> 5 | F35: =+F$3 -> 2 | G35: =+G$3 -> 5 | H35: =+H$3 -> 3 | I35: =+I$3 -> 1 | J35: =+J$3 -> 1 | ... V35: =+V$3 -> 0.15
A36: 29 | C36: =+C$3 -> 15 | D36: =+D$3 -> 3 | E36: =+E$3 -> 5 | F36: =+F$3 -> 2 | G36: =+G$3 -> 5 | H36: =+H$3 -> 3 | I36: =+I$3 -> 1 | J36: =+J$3 -> 1 | ... V36: =+V$3 -> 0.15
A37: 30 | C37: =+C$3 -> 15 | D37: =+D$3 -> 3 | E37: =+E$3 -> 5 | F37: =+F$3 -> 2 | G37: =+G$3 -> 5 | H37: =+H$3 -> 3 | I37: =+I$3 -> 1 | J37: =+J$3 -> 1 | ... V37: =+V$3 -> 0.15
B38: TOTAL | C38: =SUM(C8:C37) -> 450 | D38: =SUM(D8:D37) -> 90 | E38: =SUM(E8:E37) -> 150 | F38: =SUM(F8:F37) -> 60 | G38: =SUM(G8:G37) -> 150 | H38: =SUM(H8:H37) -> 90 | I38: =SUM(I8:I37) -> 30 | J38: =SUM(J8:J37) -> 30 | ... AU38: =SUM(AU8:AU37) -> 0

Sheet Mardi S1
C3: =+'Lundi S1'!C3 -> 15 | D3: =+'Lundi S1'!D3 -> 3 | E3: =+'Lundi S1'!E3 -> 5 | F3: =+'Lundi S1'!F3 -> 2 | G3: =+'Lundi S1'!G3 -> 5 | H3: =+'Lundi S1'!H3 -> 3 | I3: =+'Lundi S1'!I3 -> 1 | J3: =+'Lundi S1'!J3 -> 1 | ... V3: =+'Lundi S1'!V3 -> 0.15
A4: GAGNOA JOUR 2
C5: OBJECTIFS JOURNALIERS | W5: REALISATIONS | AT5: Commentaires | AU5: Impressions des PDV et des clients
A6: N° | B6: Agent promoteur | C6: Nombre de visite / Type de PDV | H6: Nombre de référencement / Type de PDV | M6: Pose de matériel de visibilité | R6: Vente en cartons | W6: Nombre de visite / Type de PDV | AB6: Nombre de référencement / Type de PDV | AG6: Pose de matériel de visibilité | AL6: Vente en cartons | AQ6: Gratuits offerts en sachet
C7: Boutique | D7: Superette | E7: Kiosque | F7: Tablier | G7: Pushcart | H7: Boutique | I7: Superette | J7: Kiosque | K7: Tablier | L7: Pushcart | M7: Affiche Biblos Lait Prémium 16g & 360g | N7: Affiche Biblos Lait Excellence | O7: Affiche Biblos Flocons d' Avoine | P7: Hanger | Q7: Wobbler | R7: Biblos Lait Premium 16g | S7: Biblos Lait Premium 360g | T7: Biblos Lait Excellence 900g | U7: Biblos Flocon d'avoine 50g | V7: Biblos Flocon d'avoine 400g | W7: Boutique | X7: Superette | Y7: Kiosque | Z7: Tablier | AA7: Pushcart | AB7: Boutique | AC7: Superette | AD7: Kiosque | AE7: Tablier | AF7: Pushcart | AG7: Affiche Biblos Lait Prémium 16g & 360g | AH7: Affiche Biblos Lait Excellence | AI7: Affiche Biblos Flocons d' Avoine | AJ7: Hanger | AK7: Wobbler | AL7: Biblos Lait Premium 16g | AM7: Biblos Lait Premium 360g | AN7: Biblos Lait Excellence 900g | AO7: Biblos Flocon d'avoine 50g | AP7: Biblos Flocon d'avoine 400g | AQ7: Biblos Lait Premium 16g | AR7: Biblos Lait Excellence 900g | AS7: Biblos Flocon d'avoine 50g
A8: 1 | C8: =+C$3 -> 15 | D8: =+D$3 -> 3 | E8: =+E$3 -> 5 | F8: =+F$3 -> 2 | G8: =+G$3 -> 5 | H8: =+H$3 -> 3 | I8: =+I$3 -> 1 | J8: =+J$3 -> 1 | ... V8: =+V$3 -> 0.15 | W8: 26 | X8: 2 | Z8: 1 | AA8: 2 | AB8: 18 | AE8: 1 | AG8: 5 | AI8: 5 | AL8: 0.67 | AO8: 1 | AP8: =20/20 -> 1 | AQ8: 8 | AS8: 20
A9: 2 | C9: =+C$3 -> 15 | D9: =+D$3 -> 3 | E9: =+E$3 -> 5 | F9: =+F$3 -> 2 | G9: =+G$3 -> 5 | H9: =+H$3 -> 3 | I9: =+I$3 -> 1 | J9: =+J$3 -> 1 | ... V9: =+V$3 -> 0.15 | W9: 25 | Y9: 1 | Z9: 2 | AA9: 1 | AB9: 11 | AD9: 1 | AE9: 1 | AG9: 5 | AI9: 5 | AL9: 0.5 | AO9: =20/100 -> 0.2 | AP9: =4/20 -> 0.2 | AQ9: 6 | AS9: 3
A10: 3 | C10: =+C$3 -> 15 | D10: =+D$3 -> 3 | E10: =+E$3 -> 5 | F10: =+F$3 -> 2 | G10: =+G$3 -> 5 | H10: =+H$3 -> 3 | I10: =+I$3 -> 1 | J10: =+J$3 -> 1 | ... V10: =+V$3 -> 0.15 | W10: 31 | AB10: 15 | AG10: 5 | AI10: 5 | AL10: 0.58 | AN10: =2/20 -> 0.1 | AO10: =10/100 -> 0.1 | AP10: =10/20 -> 0.5 | AQ10: 7 | AS10: 5
A11: 4 | C11: =+C$3 -> 15 | D11: =+D$3 -> 3 | E11: =+E$3 -> 5 | F11: =+F$3 -> 2 | G11: =+G$3 -> 5 | H11: =+H$3 -> 3 | I11: =+I$3 -> 1 | J11: =+J$3 -> 1 | ... V11: =+V$3 -> 0.15 | W11: 30 | Z11: 2 | AB11: 14 | AE11: 1 | AG11: 5 | AI11: 5 | AL11: 1 | AN11: =3/20 -> 0.15 | AO11: =40/100 -> 0.4 | AP11: =10/20 -> 0.5 | AQ11: 12 | AS11: 8
A12: 5 | C12: =+C$3 -> 15 | D12: =+D$3 -> 3 | E12: =+E$3 -> 5 | F12: =+F$3 -> 2 | G12: =+G$3 -> 5 | H12: =+H$3 -> 3 | I12: =+I$3 -> 1 | J12: =+J$3 -> 1 | ... V12: =+V$3 -> 0.15 | W12: 27 | AB12: 13 | AG12: 5 | AI12: 5 | AL12: 0.5 | AO12: =60/100 -> 0.6 | AP12: =6/20 -> 0.3 | AQ12: 6 | AS12: 8
A13: 6 | C13: =+C$3 -> 15 | D13: =+D$3 -> 3 | E13: =+E$3 -> 5 | F13: =+F$3 -> 2 | G13: =+G$3 -> 5 | H13: =+H$3 -> 3 | I13: =+I$3 -> 1 | J13: =+J$3 -> 1 | ... V13: =+V$3 -> 0.15 | W13: 29 | AB13: 15 | AG13: 5 | AI13: 5 | AL13: 0.67 | AO13: =40/100 -> 0.4 | AP13: =10/20 -> 0.5 | AQ13: 8 | AS13: 8
A14: 7 | C14: =+C$3 -> 15 | D14: =+D$3 -> 3 | E14: =+E$3 -> 5 | F14: =+F$3 -> 2 | G14: =+G$3 -> 5 | H14: =+H$3 -> 3 | I14: =+I$3 -> 1 | J14: =+J$3 -> 1 | ... V14: =+V$3 -> 0.15 | W14: 30 | AB14: 16 | AG14: 5 | AI14: 5 | AL14: 1 | AN14: =2/20 -> 0.1 | AP14: =6/20 -> 0.3 | AQ14: 12 | AS14: 2
A15: 8 | C15: =+C$3 -> 15 | D15: =+D$3 -> 3 | E15: =+E$3 -> 5 | F15: =+F$3 -> 2 | G15: =+G$3 -> 5 | H15: =+H$3 -> 3 | I15: =+I$3 -> 1 | J15: =+J$3 -> 1 | ... V15: =+V$3 -> 0.15 | W15: 27 | Y15: 2 | Z15: 2 | AA15: 2 | AB15: 17 | AE15: 2 | AF15: 1 | AG15: 5 | AI15: 5 | AL15: 0.83 | AO15: =60/100 -> 0.6 | AP15: =20/20 -> 1 | AQ15: 10 | AS15: 16
A16: 9 | C16: =+C$3 -> 15 | D16: =+D$3 -> 3 | E16: =+E$3 -> 5 | F16: =+F$3 -> 2 | G16: =+G$3 -> 5 | H16: =+H$3 -> 3 | I16: =+I$3 -> 1 | J16: =+J$3 -> 1 | ... V16: =+V$3 -> 0.15 | W16: 23 | AA16: 1 | AB16: 16 | AG16: 5 | AI16: 5 | AL16: 0.92 | AN16: =4/20 -> 0.2 | AO16: 1 | AP16: =5/20 -> 0.25 | AQ16: 11 | AS16: 12
A17: 10 | C17: =+C$3 -> 15 | D17: =+D$3 -> 3 | E17: =+E$3 -> 5 | F17: =+F$3 -> 2 | G17: =+G$3 -> 5 | H17: =+H$3 -> 3 | I17: =+I$3 -> 1 | J17: =+J$3 -> 1 | ... V17: =+V$3 -> 0.15 | W17: 30 | Y17: 1 | AB17: 14 | AG17: 5 | AI17: 5 | AL17: 1 | AN17: =2/20 -> 0.1 | AO17: 1 | AP17: =8/20 -> 0.4 | AQ17: 12 | AS17: 13
A18: 11 | C18: =+C$3 -> 15 | D18: =+D$3 -> 3 | E18: =+E$3 -> 5 | F18: =+F$3 -> 2 | G18: =+G$3 -> 5 | H18: =+H$3 -> 3 | I18: =+I$3 -> 1 | J18: =+J$3 -> 1 | ... V18: =+V$3 -> 0.15 | W18: 27 | Z18: 1 | AB18: 13 | AE18: 1 | AG18: 5 | AI18: 5 | AL18: 0.83 | AN18: =2/20 -> 0.1 | AO18: =60/100 -> 0.6 | AP18: =20/20 -> 1 | AQ18: 10 | AS18: 16
A19: 12 | C19: =+C$3 -> 15 | D19: =+D$3 -> 3 | E19: =+E$3 -> 5 | F19: =+F$3 -> 2 | G19: =+G$3 -> 5 | H19: =+H$3 -> 3 | I19: =+I$3 -> 1 | J19: =+J$3 -> 1 | ... V19: =+V$3 -> 0.15 | W19: 25 | AB19: 12 | AG19: 4 | AI19: 5 | AL19: 0.6 | AO19: 1 | AP19: =5/20 -> 0.25 | AQ19: 8 | AS19: 12
A20: 13 | C20: =+C$3 -> 15 | D20: =+D$3 -> 3 | E20: =+E$3 -> 5 | F20: =+F$3 -> 2 | G20: =+G$3 -> 5 | H20: =+H$3 -> 3 | I20: =+I$3 -> 1 | J20: =+J$3 -> 1 | ... V20: =+V$3 -> 0.15 | W20: 29 | Z20: 3 | AB20: 10 | AE20: 2 | AG20: 5 | AI20: 5 | AL20: 1 | AN20: =2/20 -> 0.1 | AO20: 2 | AP20: =7/20 -> 0.35 | AQ20: 1 | AS20: 23
A21: 14 | C21: =+C$3 -> 15 | D21: =+D$3 -> 3 | E21: =+E$3 -> 5 | F21: =+F$3 -> 2 | G21: =+G$3 -> 5 | H21: =+H$3 -> 3 | I21: =+I$3 -> 1 | J21: =+J$3 -> 1 | ... V21: =+V$3 -> 0.15 | W21: 26 | X21: 1 | Y21: 1 | AB21: 15 | AD21: 1 | AG21: 5 | AI21: 4 | AL21: 1 | AO21: 1 | AP21: =8/20 -> 0.4 | AQ21: 12 | AS21: 13
A22: 15 | C22: =+C$3 -> 15 | D22: =+D$3 -> 3 | E22: =+E$3 -> 5 | F22: =+F$3 -> 2 | G22: =+G$3 -> 5 | H22: =+H$3 -> 3 | I22: =+I$3 -> 1 | J22: =+J$3 -> 1 | ... V22: =+V$3 -> 0.15 | W22: 30 | AB22: 15 | AG22: 5 | AI22: 5 | AL22: 0.42 | AN22: =2/20 -> 0.1 | AP22: =10/20 -> 0.5 | AQ22: 5 | AS22: 4
A23: 16 | C23: =+C$3 -> 15 | D23: =+D$3 -> 3 | E23: =+E$3 -> 5 | F23: =+F$3 -> 2 | G23: =+G$3 -> 5 | H23: =+H$3 -> 3 | I23: =+I$3 -> 1 | J23: =+J$3 -> 1 | ... V23: =+V$3 -> 0.15 | W23: 28 | Y23: 2 | AA23: 1 | AB23: 12 | AG23: 5 | AI23: 5 | AL23: 0.42 | AN23: =1/20 -> 0.05 | AO23: =80/100 -> 0.8 | AP23: =7/20 -> 0.35 | AQ23: 5 | AS23: 10
A24: 17 | C24: =+C$3 -> 15 | D24: =+D$3 -> 3 | E24: =+E$3 -> 5 | F24: =+F$3 -> 2 | G24: =+G$3 -> 5 | H24: =+H$3 -> 3 | I24: =+I$3 -> 1 | J24: =+J$3 -> 1 | ... V24: =+V$3 -> 0.15 | W24: 24 | X24: 1 | Y24: 2 | Z24: 3 | AB24: 15 | AD24: 1 | AE24: 1 | AG24: 5 | AI24: 5 | AL24: 0.58 | AN24: =1/20 -> 0.05 | AO24: =80/100 -> 0.8 | AP24: =10/20 -> 0.5 | AQ24: 7 | AS24: 12
A25: 18 | C25: =+C$3 -> 15 | D25: =+D$3 -> 3 | E25: =+E$3 -> 5 | F25: =+F$3 -> 2 | G25: =+G$3 -> 5 | H25: =+H$3 -> 3 | I25: =+I$3 -> 1 | J25: =+J$3 -> 1 | ... V25: =+V$3 -> 0.15 | W25: 20 | Z25: 5 | AA25: 1 | AB25: 10 | AE25: 3 | AG25: 5 | AI25: 5 | AL25: 0.58 | AN25: =2/20 -> 0.1 | AO25: 1 | AP25: =6/20 -> 0.3 | AQ25: 7 | AS25: 12
A26: 19 | C26: =+C$3 -> 15 | D26: =+D$3 -> 3 | E26: =+E$3 -> 5 | F26: =+F$3 -> 2 | G26: =+G$3 -> 5 | H26: =+H$3 -> 3 | I26: =+I$3 -> 1 | J26: =+J$3 -> 1 | ... V26: =+V$3 -> 0.15 | W26: 25 | AA26: 1 | AB26: 10 | AG26: 5 | AI26: 5 | AL26: 0.42 | AO26: =50/100 -> 0.5 | AP26: =10/20 -> 0.5 | AQ26: 5 | AS26: 10
A27: 20 | C27: =+C$3 -> 15 | D27: =+D$3 -> 3 | E27: =+E$3 -> 5 | F27: =+F$3 -> 2 | G27: =+G$3 -> 5 | H27: =+H$3 -> 3 | I27: =+I$3 -> 1 | J27: =+J$3 -> 1 | ... V27: =+V$3 -> 0.15 | W27: 30 | Z27: 3 | AB27: 14 | AE27: 1 | AG27: 3 | AI27: 5 | AL27: 0.5 | AN27: =3/20 -> 0.15 | AO27: 1 | AP27: =8/20 -> 0.4 | AQ27: 6 | AS27: 12
A28: 21 | C28: =+C$3 -> 15 | D28: =+D$3 -> 3 | E28: =+E$3 -> 5 | F28: =+F$3 -> 2 | G28: =+G$3 -> 5 | H28: =+H$3 -> 3 | I28: =+I$3 -> 1 | J28: =+J$3 -> 1 | ... V28: =+V$3 -> 0.15
A29: 22 | C29: =+C$3 -> 15 | D29: =+D$3 -> 3 | E29: =+E$3 -> 5 | F29: =+F$3 -> 2 | G29: =+G$3 -> 5 | H29: =+H$3 -> 3 | I29: =+I$3 -> 1 | J29: =+J$3 -> 1 | ... V29: =+V$3 -> 0.15
A30: 23 | C30: =+C$3 -> 15 | D30: =+D$3 -> 3 | E30: =+E$3 -> 5 | F30: =+F$3 -> 2 | G30: =+G$3 -> 5 | H30: =+H$3 -> 3 | I30: =+I$3 -> 1 | J30: =+J$3 -> 1 | ... V30: =+V$3 -> 0.15
A31: 24 | C31: =+C$3 -> 15 | D31: =+D$3 -> 3 | E31: =+E$3 -> 5 | F31: =+F$3 -> 2 | G31: =+G$3 -> 5 | H31: =+H$3 -> 3 | I31: =+I$3 -> 1 | J31: =+J$3 -> 1 | ... V31: =+V$3 -> 0.15
A32: 25 | C32: =+C$3 -> 15 | D32: =+D$3 -> 3 | E32: =+E$3 -> 5 | F32: =+F$3 -> 2 | G32: =+G$3 -> 5 | H32: =+H$3 -> 3 | I32: =+I$3 -> 1 | J32: =+J$3 -> 1 | ... V32: =+V$3 -> 0.15
A33: 26 | C33: =+C$3 -> 15 | D33: =+D$3 -> 3 | E33: =+E$3 -> 5 | F33: =+F$3 -> 2 | G33: =+G$3 -> 5 | H33: =+H$3 -> 3 | I33: =+I$3 -> 1 | J33: =+J$3 -> 1 | ... V33: =+V$3 -> 0.15
A34: 27 | C34: =+C$3 -> 15 | D34: =+D$3 -> 3 | E34: =+E$3 -> 5 | F34: =+F$3 -> 2 | G34: =+G$3 -> 5 | H34: =+H$3 -> 3 | I34: =+I$3 -> 1 | J34: =+J$3 -> 1 | ... V34: =+V$3 -> 0.15
A35: 28 | C35: =+C$3 -> 15 | D35: =+D$3 -> 3 | E35: =+E$3 -> 5 | F35: =+F$3 -> 2 | G35: =+G$3 -> 5 | H35: =+H$3 -> 3 | I35: =+I$3 -> 1 | J35: =+J$3 -> 1 | ... V35: =+V$3 -> 0.15
A36: 29 | C36: =+C$3 -> 15 | D36: =+D$3 -> 3 | E36: =+E$3 -> 5 | F36: =+F$3 -> 2 | G36: =+G$3 -> 5 | H36: =+H$3 -> 3 | I36: =+I$3 -> 1 | J36: =+J$3 -> 1 | ... V36: =+V$3 -> 0.15
A37: 30 | C37: =+C$3 -> 15 | D37: =+D$3 -> 3 | E37: =+E$3 -> 5 | F37: =+F$3 -> 2 | G37: =+G$3 -> 5 | H37: =+H$3 -> 3 | I37: =+I$3 -> 1 | J37: =+J$3 -> 1 | ... V37: =+V$3 -> 0.15
B38: TOTAL | C38: =SUM(C8:C37) -> 450 | D38: =SUM(D8:D37) -> 90 | E38: =SUM(E8:E37) -> 150 | F38: =SUM(F8:F37) -> 60 | G38: =SUM(G8:G37) -> 150 | H38: =SUM(H8:H37) -> 90 | I38: =SUM(I8:I37) -> 30 | J38: =SUM(J8:J37) -> 30 | ... AU38: =SUM(AU8:AU37) -> 0
AS41: =AS38+'Lundi S1'!AS38 -> 296
AS42: =AS41/100 -> 2.96

Sheet Mercredi S1
C2: =+'Lundi S1'!C3 -> 15 | D2: =+'Lundi S1'!D3 -> 3 | E2: =+'Lundi S1'!E3 -> 5 | F2: =+'Lundi S1'!F3 -> 2 | G2: =+'Lundi S1'!G3 -> 5 | H2: =+'Lundi S1'!H3 -> 3 | I2: =+'Lundi S1'!I3 -> 1 | J2: =+'Lundi S1'!J3 -> 1 | ... V2: =+'Lundi S1'!V3 -> 0.15
A3: DALOA JOUR 1
C4: OBJECTIFS JOURNALIERS | W4: REALISATIONS | AT4: Commentaires | AU4: Impressions des PDV et des clients
A5: N° | B5: Agent promoteur | C5: Nombre de visite / Type de PDV | H5: Nombre de référencement / Type de PDV | M5: Pose de matériel de visibilité | R5: Vente en cartons | W5: Nombre de visite / Type de PDV | AB5: Nombre de référencement / Type de PDV | AG5: Pose de matériel de visibilité | AL5: Vente en cartons | AQ5: Gratuits offerts en sachet
C6: Boutique | D6: Superette | E6: Kiosque | F6: Tablier | G6: Pushcart | H6: Boutique | I6: Superette | J6: Kiosque | K6: Tablier | L6: Pushcart | M6: Affiche Biblos Lait Prémium 16g & 360g | N6: Affiche Biblos Lait Excellence | O6: Affiche Biblos Flocons d' Avoine | P6: Hanger | Q6: Wobbler | R6: Biblos Lait Premium 16g | S6: Biblos Lait Premium 360g | T6: Biblos Lait Excellence 900g | U6: Biblos Flocon d'avoine 50g | V6: Biblos Flocon d'avoine 400g | W6: Boutique | X6: Superette | Y6: Kiosque | Z6: Tablier | AA6: Pushcart | AB6: Boutique | AC6: Superette | AD6: Kiosque | AE6: Tablier | AF6: Pushcart | AG6: Affiche Biblos Lait Prémium 16g & 360g | AH6: Affiche Biblos Lait Excellence | AI6: Affiche Biblos Flocons d' Avoine | AJ6: Hanger | AK6: Wobbler | AL6: Biblos Lait Premium 16g | AM6: Biblos Lait Premium 360g | AN6: Biblos Lait Excellence 900g | AO6: Biblos Flocon d'avoine 50g | AP6: Biblos Flocon d'avoine 400g | AQ6: Biblos Lait Premium 16g | AR6: Biblos Lait Excellence 900g | AS6: Biblos Flocon d'avoine 50g
A7: 1 | C7: =+C$2 -> 15 | D7: =+D$2 -> 3 | E7: =+E$2 -> 5 | F7: =+F$2 -> 2 | G7: =+G$2 -> 5 | H7: =+H$2 -> 3 | I7: =+I$2 -> 1 | J7: =+J$2 -> 1 | ... V7: =+V$2 -> 0.15 | W7: 28 | Y7: 2 | Z7: 4 | AA7: 3 | AB7: 12 | AD7: 1 | AE7: 1 | AF7: 1 | AG7: 5 | AI7: 5 | AL7: 0.42 | AN7: =2/20 -> 0.1 | AO7: =60/100 -> 0.6 | AP7: =20/20 -> 1 | AQ7: 5 | AS7: =6+10 -> 16
A8: 2 | C8: =+C$2 -> 15 | D8: =+D$2 -> 3 | E8: =+E$2 -> 5 | F8: =+F$2 -> 2 | G8: =+G$2 -> 5 | H8: =+H$2 -> 3 | I8: =+I$2 -> 1 | J8: =+J$2 -> 1 | ... V8: =+V$2 -> 0.15 | W8: 33 | Z8: 5 | AB8: 15 | AG8: 5 | AI8: 5 | AL8: 0.17 | AN8: =3/20 -> 0.15 | AO8: =40/100 -> 0.4 | AP8: =10/20 -> 0.5 | AQ8: =2+5 -> 7 | AS8: =4+4 -> 8 | AT8: Idem
A9: 3 | C9: =+C$2 -> 15 | D9: =+D$2 -> 3 | E9: =+E$2 -> 5 | F9: =+F$2 -> 2 | G9: =+G$2 -> 5 | H9: =+H$2 -> 3 | I9: =+I$2 -> 1 | J9: =+J$2 -> 1 | ... V9: =+V$2 -> 0.15 | W9: 24 | X9: 1 | Y9: 3 | Z9: 2 | AA9: 2 | AB9: 11 | AG9: 5 | AI9: 5 | AL9: 0.42 | AN9: =2/20 -> 0.1 | AO9: =60/100 -> 0.6 | AP9: =40/20 -> 2 | AQ9: 5 | AS9: =6+20 -> 26
A10: 4 | C10: =+C$2 -> 15 | D10: =+D$2 -> 3 | E10: =+E$2 -> 5 | F10: =+F$2 -> 2 | G10: =+G$2 -> 5 | H10: =+H$2 -> 3 | I10: =+I$2 -> 1 | J10: =+J$2 -> 1 | ... V10: =+V$2 -> 0.15 | W10: 30 | Y10: 1 | Z10: 1 | AB10: 14 | AE10: 1 | AG10: 5 | AI10: 5 | AL10: 0.5 | AN10: =3/20 -> 0.15 | AO10: =40/100 -> 0.4 | AP10: =20/20 -> 1 | AQ10: =6+5 -> 11 | AS10: =4+10 -> 14
A11: 5 | C11: =+C$2 -> 15 | D11: =+D$2 -> 3 | E11: =+E$2 -> 5 | F11: =+F$2 -> 2 | G11: =+G$2 -> 5 | H11: =+H$2 -> 3 | I11: =+I$2 -> 1 | J11: =+J$2 -> 1 | ... V11: =+V$2 -> 0.15 | W11: 27 | Y11: 2 | AB11: 16 | AD11: 1 | AG11: 5 | AI11: 5 | AL11: 0.25 | AN11: =2/20 -> 0.1 | AO11: =100/100 -> 1 | AP11: =20/20 -> 1 | AQ11: 3 | AS11: =10+10 -> 20
A12: 6 | C12: =+C$2 -> 15 | D12: =+D$2 -> 3 | E12: =+E$2 -> 5 | F12: =+F$2 -> 2 | G12: =+G$2 -> 5 | H12: =+H$2 -> 3 | I12: =+I$2 -> 1 | J12: =+J$2 -> 1 | ... V12: =+V$2 -> 0.15 | W12: 31 | AB12: 13 | AD12: 1 | AG12: 5 | AI12: 5 | AL12: 0.33 | AN12: =3/20 -> 0.15 | AO12: =60/100 -> 0.6 | AP12: =10/20 -> 0.5 | AQ12: =4+5 -> 9 | AS12: =6+4 -> 10
A13: 7 | C13: =+C$2 -> 15 | D13: =+D$2 -> 3 | E13: =+E$2 -> 5 | F13: =+F$2 -> 2 | G13: =+G$2 -> 5 | H13: =+H$2 -> 3 | I13: =+I$2 -> 1 | J13: =+J$2 -> 1 | ... V13: =+V$2 -> 0.15 | W13: 32 | X13: 2 | Y13: 1 | AB13: 16 | AG13: 5 | AI13: 5 | AL13: 0.33 | AN13: =2/20 -> 0.1 | AO13: =80/100 -> 0.8 | AP13: =10/20 -> 0.5 | AQ13: 4 | AS13: =8+4 -> 12
A14: 8 | C14: =+C$2 -> 15 | D14: =+D$2 -> 3 | E14: =+E$2 -> 5 | F14: =+F$2 -> 2 | G14: =+G$2 -> 5 | H14: =+H$2 -> 3 | I14: =+I$2 -> 1 | J14: =+J$2 -> 1 | ... V14: =+V$2 -> 0.15 | W14: 30 | X14: 1 | AB14: 13 | AG14: 5 | AI14: 5 | AL14: 0.67 | AN14: =3/20 -> 0.15 | AO14: =100/100 -> 1 | AP14: =20/20 -> 1 | AQ14: =8+5 -> 13 | AS14: =10+10 -> 20
A15: 9 | C15: =+C$2 -> 15 | D15: =+D$2 -> 3 | E15: =+E$2 -> 5 | F15: =+F$2 -> 2 | G15: =+G$2 -> 5 | H15: =+H$2 -> 3 | I15: =+I$2 -> 1 | J15: =+J$2 -> 1 | ... V15: =+V$2 -> 0.15 | W15: 25 | Y15: 3 | AB15: 14 | AD15: 2 | AG15: 5 | AI15: 5 | AL15: 0.25 | AN15: =3/20 -> 0.15 | AO15: =40/100 -> 0.4 | AP15: =10/20 -> 0.5 | AQ15: =2+5 -> 7 | AS15: =4+4 -> 8
A16: 10 | C16: =+C$2 -> 15 | D16: =+D$2 -> 3 | E16: =+E$2 -> 5 | F16: =+F$2 -> 2 | G16: =+G$2 -> 5 | H16: =+H$2 -> 3 | I16: =+I$2 -> 1 | J16: =+J$2 -> 1 | ... V16: =+V$2 -> 0.15 | W16: 31 | Y16: 3 | AB16: 15 | AG16: 5 | AI16: 5 | AL16: 0.5 | AN16: =6/20 -> 0.3 | AO16: =40/100 -> 0.4 | AP16: =10/20 -> 0.5 | AQ16: =6+10 -> 16 | AS16: =4+4 -> 8
A17: 11 | C17: =+C$2 -> 15 | D17: =+D$2 -> 3 | E17: =+E$2 -> 5 | F17: =+F$2 -> 2 | G17: =+G$2 -> 5 | H17: =+H$2 -> 3 | I17: =+I$2 -> 1 | J17: =+J$2 -> 1 | ... V17: =+V$2 -> 0.15 | W17: 25 | Z17: 5 | AB17: 12 | AE17: 3 | AG17: 5 | AI17: 5 | AL17: 0.25 | AN17: =2/20 -> 0.1 | AO17: =100/100 -> 1 | AP17: =15/20 -> 0.75 | AQ17: 3 | AS17: =10+6 -> 16
A18: 12 | C18: =+C$2 -> 15 | D18: =+D$2 -> 3 | E18: =+E$2 -> 5 | F18: =+F$2 -> 2 | G18: =+G$2 -> 5 | H18: =+H$2 -> 3 | I18: =+I$2 -> 1 | J18: =+J$2 -> 1 | ... V18: =+V$2 -> 0.15 | W18: 32 | X18: 1 | AB18: 16 | AC18: 1 | AG18: 5 | AI18: 5 | AL18: 0.25 | AN18: =3/20 -> 0.15 | AO18: =80/100 -> 0.8 | AP18: =40/20 -> 2 | AQ18: =3+5 -> 8 | AS18: =8+20 -> 28
A19: 13 | C19: =+C$2 -> 15 | D19: =+D$2 -> 3 | E19: =+E$2 -> 5 | F19: =+F$2 -> 2 | G19: =+G$2 -> 5 | H19: =+H$2 -> 3 | I19: =+I$2 -> 1 | J19: =+J$2 -> 1 | ... V19: =+V$2 -> 0.15 | W19: 33 | X19: 1 | Z19: 1 | AA19: 3 | AB19: 13 | AG19: 5 | AI19: 5 | AN19: =3/20 -> 0.15 | AO19: =60/100 -> 0.6 | AP19: =20/20 -> 1 | AQ19: =0+5 -> 5 | AS19: =6+10 -> 16
A20: 14 | C20: =+C$2 -> 15 | D20: =+D$2 -> 3 | E20: =+E$2 -> 5 | F20: =+F$2 -> 2 | G20: =+G$2 -> 5 | H20: =+H$2 -> 3 | I20: =+I$2 -> 1 | J20: =+J$2 -> 1 | ... V20: =+V$2 -> 0.15 | W20: 29 | Y20: 4 | Z20: 3 | AB20: 14 | AD20: 2 | AE20: 1 | AG20: 5 | AI20: 5 | AL20: 0.33 | AN20: =3/20 -> 0.15 | AO20: =60/100 -> 0.6 | AP20: =20/20 -> 1 | AQ20: =4+5 -> 9 | AS20: =6+10 -> 16
A21: 15 | C21: =+C$2 -> 15 | D21: =+D$2 -> 3 | E21: =+E$2 -> 5 | F21: =+F$2 -> 2 | G21: =+G$2 -> 5 | H21: =+H$2 -> 3 | I21: =+I$2 -> 1 | J21: =+J$2 -> 1 | ... V21: =+V$2 -> 0.15 | W21: 30 | AB21: 15 | AG21: 5 | AI21: 5 | AL21: 0.42 | AN21: =3/20 -> 0.15 | AO21: =50/100 -> 0.5 | AP21: =12/20 -> 0.6 | AQ21: =5+5 -> 10 | AS21: =5+4 -> 9
A22: 16 | C22: =+C$2 -> 15 | D22: =+D$2 -> 3 | E22: =+E$2 -> 5 | F22: =+F$2 -> 2 | G22: =+G$2 -> 5 | H22: =+H$2 -> 3 | I22: =+I$2 -> 1 | J22: =+J$2 -> 1 | ... V22: =+V$2 -> 0.15 | W22: 31 | AA22: 1 | AB22: 13 | AG22: 5 | AI22: 5 | AL22: 0.67 | AN22: =3/20 -> 0.15 | AO22: =100/100 -> 1 | AP22: =15/20 -> 0.75 | AQ22: =8+5 -> 13 | AS22: =10+6 -> 16
A23: 17 | C23: =+C$2 -> 15 | D23: =+D$2 -> 3 | E23: =+E$2 -> 5 | F23: =+F$2 -> 2 | G23: =+G$2 -> 5 | H23: =+H$2 -> 3 | I23: =+I$2 -> 1 | J23: =+J$2 -> 1 | ... V23: =+V$2 -> 0.15 | W23: 25 | Z23: 3 | AB23: 10 | AE23: 1 | AG23: 5 | AI23: 5 | AL23: 0.42 | AN23: =2/20 -> 0.1 | AO23: =80/100 -> 0.8 | AP23: =20/20 -> 1 | AQ23: 5 | AS23: =8+10 -> 18
A24: 18 | C24: =+C$2 -> 15 | D24: =+D$2 -> 3 | E24: =+E$2 -> 5 | F24: =+F$2 -> 2 | G24: =+G$2 -> 5 | H24: =+H$2 -> 3 | I24: =+I$2 -> 1 | J24: =+J$2 -> 1 | ... V24: =+V$2 -> 0.15 | W24: 30 | X24: 1 | AB24: 17 | AC24: 1 | AG24: 5 | AI24: 5 | AL24: 0.33 | AN24: =3/20 -> 0.15 | AO24: =100/100 -> 1 | AP24: =20/20 -> 1 | AQ24: =4+5 -> 9 | AS24: =10+10 -> 20
A25: 19 | C25: =+C$2 -> 15 | D25: =+D$2 -> 3 | E25: =+E$2 -> 5 | F25: =+F$2 -> 2 | G25: =+G$2 -> 5 | H25: =+H$2 -> 3 | I25: =+I$2 -> 1 | J25: =+J$2 -> 1 | ... V25: =+V$2 -> 0.15 | W25: 28 | AB25: 14 | AG25: 5 | AI25: 5 | AL25: 0.5 | AN25: =3/20 -> 0.15 | AO25: =50/100 -> 0.5 | AP25: =10/20 -> 0.5 | AQ25: =6+5 -> 11 | AS25: =5+4 -> 9
A26: 20 | C26: =+C$2 -> 15 | D26: =+D$2 -> 3 | E26: =+E$2 -> 5 | F26: =+F$2 -> 2 | G26: =+G$2 -> 5 | H26: =+H$2 -> 3 | I26: =+I$2 -> 1 | J26: =+J$2 -> 1 | ... V26: =+V$2 -> 0.15 | W26: 23 | X26: 2 | Y26: 1 | Z26: 1 | AA26: 3 | AB26: 11 | AC26: 1 | AE26: 1 | AF26: 2 | AG26: 5 | AI26: 5 | AN26: =4/20 -> 0.2 | AO26: =100/100 -> 1 | AP26: =20/20 -> 1 | AQ26: =0+5 -> 5 | AS26: =10+10 -> 20
A27: 21 | C27: =+C$2 -> 15 | D27: =+D$2 -> 3 | E27: =+E$2 -> 5 | F27: =+F$2 -> 2 | G27: =+G$2 -> 5 | H27: =+H$2 -> 3 | I27: =+I$2 -> 1 | J27: =+J$2 -> 1 | ... V27: =+V$2 -> 0.15 | W27: =SUM(W7:W26) -> 577 | X27: =SUM(X7:X26) -> 9 | Y27: =SUM(Y7:Y26) -> 20 | Z27: =SUM(Z7:Z26) -> 25 | AA27: =SUM(AA7:AA26) -> 12
A28: 22 | C28: =+C$2 -> 15 | D28: =+D$2 -> 3 | E28: =+E$2 -> 5 | F28: =+F$2 -> 2 | G28: =+G$2 -> 5 | H28: =+H$2 -> 3 | I28: =+I$2 -> 1 | J28: =+J$2 -> 1 | ... V28: =+V$2 -> 0.15
A29: 23 | C29: =+C$2 -> 15 | D29: =+D$2 -> 3 | E29: =+E$2 -> 5 | F29: =+F$2 -> 2 | G29: =+G$2 -> 5 | H29: =+H$2 -> 3 | I29: =+I$2 -> 1 | J29: =+J$2 -> 1 | ... V29: =+V$2 -> 0.15
A30: 24 | C30: =+C$2 -> 15 | D30: =+D$2 -> 3 | E30: =+E$2 -> 5 | F30: =+F$2 -> 2 | G30: =+G$2 -> 5 | H30: =+H$2 -> 3 | I30: =+I$2 -> 1 | J30: =+J$2 -> 1 | ... V30: =+V$2 -> 0.15
A31: 25 | C31: =+C$2 -> 15 | D31: =+D$2 -> 3 | E31: =+E$2 -> 5 | F31: =+F$2 -> 2 | G31: =+G$2 -> 5 | H31: =+H$2 -> 3 | I31: =+I$2 -> 1 | J31: =+J$2 -> 1 | ... V31: =+V$2 -> 0.15
A32: 26 | C32: =+C$2 -> 15 | D32: =+D$2 -> 3 | E32: =+E$2 -> 5 | F32: =+F$2 -> 2 | G32: =+G$2 -> 5 | H32: =+H$2 -> 3 | I32: =+I$2 -> 1 | J32: =+J$2 -> 1 | ... V32: =+V$2 -> 0.15
A33: 27 | C33: =+C$2 -> 15 | D33: =+D$2 -> 3 | E33: =+E$2 -> 5 | F33: =+F$2 -> 2 | G33: =+G$2 -> 5 | H33: =+H$2 -> 3 | I33: =+I$2 -> 1 | J33: =+J$2 -> 1 | ... V33: =+V$2 -> 0.15
A34: 28 | C34: =+C$2 -> 15 | D34: =+D$2 -> 3 | E34: =+E$2 -> 5 | F34: =+F$2 -> 2 | G34: =+G$2 -> 5 | H34: =+H$2 -> 3 | I34: =+I$2 -> 1 | J34: =+J$2 -> 1 | ... V34: =+V$2 -> 0.15
A35: 29 | C35: =+C$2 -> 15 | D35: =+D$2 -> 3 | E35: =+E$2 -> 5 | F35: =+F$2 -> 2 | G35: =+G$2 -> 5 | H35: =+H$2 -> 3 | I35: =+I$2 -> 1 | J35: =+J$2 -> 1 | ... V35: =+V$2 -> 0.15
A36: 30 | C36: =+C$2 -> 15 | D36: =+D$2 -> 3 | E36: =+E$2 -> 5 | F36: =+F$2 -> 2 | G36: =+G$2 -> 5 | H36: =+H$2 -> 3 | I36: =+I$2 -> 1 | J36: =+J$2 -> 1 | ... V36: =+V$2 -> 0.15
B37: TOTAL | C37: =SUM(C7:C36) -> 450 | D37: =SUM(D7:D36) -> 90 | E37: =SUM(E7:E36) -> 150 | F37: =SUM(F7:F36) -> 60 | G37: =SUM(G7:G36) -> 150 | H37: =SUM(H7:H36) -> 90 | I37: =SUM(I7:I36) -> 30 | J37: =SUM(J7:J36) -> 30 | ... AU37: =SUM(AU7:AU36) -> 0

Sheet Jeudi S1
C2: =+'Lundi S1'!C3 -> 15 | D2: =+'Lundi S1'!D3 -> 3 | E2: =+'Lundi S1'!E3 -> 5 | F2: =+'Lundi S1'!F3 -> 2 | G2: =+'Lundi S1'!G3 -> 5 | H2: =+'Lundi S1'!H3 -> 3 | I2: =+'Lundi S1'!I3 -> 1 | J2: =+'Lundi S1'!J3 -> 1 | ... V2: =+'Lundi S1'!V3 -> 0.15
A3: DALOA JOUR 2
C4: OBJECTIFS JOURNALIERS | W4: REALISATIONS | AT4: Commentaires | AU4: Impressions des PDV et des clients
A5: N° | B5: Agent promoteur | C5: Nombre de visite / Type de PDV | H5: Nombre de référencement / Type de PDV | M5: Pose de matériel de visibilité | R5: Vente en cartons | W5: Nombre de visite / Type de PDV | AB5: Nombre de référencement / Type de PDV | AG5: Pose de matériel de visibilité | AL5: Vente en cartons | AQ5: Gratuits offerts
C6: Boutique | D6: Superette | E6: Kiosque | F6: Tablier | G6: Pushcart | H6: Boutique | I6: Superette | J6: Kiosque | K6: Tablier | L6: Pushcart | M6: Affiche Biblos Lait Prémium 16g & 360g | N6: Affiche Biblos Lait Excellence | O6: Affiche Biblos Flocons d' Avoine | P6: Hanger | Q6: Wobbler | R6: Biblos Lait Premium 16g | S6: Biblos Lait Premium 360g | T6: Biblos Lait Excellence 900g | U6: Biblos Flocon d'avoine 50g | V6: Biblos Flocon d'avoine 400g | W6: Boutique | X6: Superette | Y6: Kiosque | Z6: Tablier | AA6: Pushcart | AB6: Boutique | AC6: Superette | AD6: Kiosque | AE6: Tablier | AF6: Pushcart | AG6: Affiche Biblos Lait Prémium 16g & 360g | AH6: Affiche Biblos Lait Excellence | AI6: Affiche Biblos Flocons d' Avoine | AJ6: Hanger | AK6: Wobbler | AL6: Biblos Lait Premium 16g | AM6: Biblos Lait Premium 360g | AN6: Biblos Lait Excellence 900g | AO6: Biblos Flocon d'avoine 50g | AP6: Biblos Flocon d'avoine 400g | AQ6: Biblos Lait Premium 16g | AR6: Biblos Lait Excellence 900g | AS6: Biblos Flocon d'avoine 50g
A7: 1 | C7: =+C$2 -> 15 | D7: =+D$2 -> 3 | E7: =+E$2 -> 5 | F7: =+F$2 -> 2 | G7: =+G$2 -> 5 | H7: =+H$2 -> 3 | I7: =+I$2 -> 1 | J7: =+J$2 -> 1 | ... V7: =+V$2 -> 0.15 | W7: 29 | X7: 1 | Z7: 5 | AA7: 1 | AB7: 15 | AE7: 2 | AF7: 1 | AG7: 5 | AI7: 5 | AL7: 0.25 | AO7: =20/100 -> 0.2 | AP7: =20/20 -> 1 | AQ7: 3 | AS7: =2+10 -> 12
A8: 2 | C8: =+C$2 -> 15 | D8: =+D$2 -> 3 | E8: =+E$2 -> 5 | F8: =+F$2 -> 2 | G8: =+G$2 -> 5 | H8: =+H$2 -> 3 | I8: =+I$2 -> 1 | J8: =+J$2 -> 1 | ... V8: =+V$2 -> 0.15 | W8: 25 | Y8: 1 | Z8: 3 | AB8: 11 | AD8: 1 | AE8: 2 | AG8: 5 | AI8: 5 | AL8: 0.83 | AN8: =3/20 -> 0.15 | AO8: =40/100 -> 0.4 | AP8: =10/20 -> 0.5 | AQ8: =10+5 -> 15 | AS8: =4+4 -> 8
A9: 3 | C9: =+C$2 -> 15 | D9: =+D$2 -> 3 | E9: =+E$2 -> 5 | F9: =+F$2 -> 2 | G9: =+G$2 -> 5 | H9: =+H$2 -> 3 | I9: =+I$2 -> 1 | J9: =+J$2 -> 1 | ... V9: =+V$2 -> 0.15 | W9: 28 | AB9: 15 | AG9: 5 | AI9: 5 | AL9: 0.5 | AO9: =60/100 -> 0.6 | AP9: =10/20 -> 0.5 | AQ9: 6 | AS9: =6+4 -> 10 | AT9: Le 360G était indisponible
A10: 4 | C10: =+C$2 -> 15 | D10: =+D$2 -> 3 | E10: =+E$2 -> 5 | F10: =+F$2 -> 2 | G10: =+G$2 -> 5 | H10: =+H$2 -> 3 | I10: =+I$2 -> 1 | J10: =+J$2 -> 1 | ... V10: =+V$2 -> 0.15 | W10: 31 | X10: 1 | Z10: 4 | AB10: 15 | AF10: 4 | AG10: 5 | AI10: 5 | AL10: 0.33 | AN10: =3/20 -> 0.15 | AO10: =50/100 -> 0.5 | AP10: =20/20 -> 1 | AQ10: =4+5 -> 9 | AS10: =5+10 -> 15
A11: 5 | C11: =+C$2 -> 15 | D11: =+D$2 -> 3 | E11: =+E$2 -> 5 | F11: =+F$2 -> 2 | G11: =+G$2 -> 5 | H11: =+H$2 -> 3 | I11: =+I$2 -> 1 | J11: =+J$2 -> 1 | ... V11: =+V$2 -> 0.15 | W11: 28 | Z11: 1 | AA11: 3 | AB11: 13 | AG11: 5 | AI11: 5 | AL11: 0.25 | AN11: =3/20 -> 0.15 | AO11: =40/100 -> 0.4 | AP11: =20/20 -> 1 | AQ11: =3+5 -> 8 | AS11: =4+10 -> 14
A12: 6 | C12: =+C$2 -> 15 | D12: =+D$2 -> 3 | E12: =+E$2 -> 5 | F12: =+F$2 -> 2 | G12: =+G$2 -> 5 | H12: =+H$2 -> 3 | I12: =+I$2 -> 1 | J12: =+J$2 -> 1 | ... V12: =+V$2 -> 0.15 | W12: 23 | X12: 1 | Z12: 6 | AB12: 11 | AE12: 3 | AG12: 5 | AI12: 5 | AL12: 0.25 | AN12: =3/20 -> 0.15 | AO12: =20/100 -> 0.2 | AP12: =15/20 -> 0.75 | AQ12: =3+5 -> 8 | AS12: =2+6 -> 8
A13: 7 | C13: =+C$2 -> 15 | D13: =+D$2 -> 3 | E13: =+E$2 -> 5 | F13: =+F$2 -> 2 | G13: =+G$2 -> 5 | H13: =+H$2 -> 3 | I13: =+I$2 -> 1 | J13: =+J$2 -> 1 | ... V13: =+V$2 -> 0.15 | W13: 26 | Y13: 2 | AA13: 2 | AB13: 16 | AD13: 1 | AF13: 1 | AG13: 5 | AI13: 5 | AL13: 0.67 | AN13: =3/20 -> 0.15 | AO13: =20/100 -> 0.2 | AP13: =20/20 -> 1 | AQ13: =8+5 -> 13 | AS13: =2+10 -> 12
A14: 8 | C14: =+C$2 -> 15 | D14: =+D$2 -> 3 | E14: =+E$2 -> 5 | F14: =+F$2 -> 2 | G14: =+G$2 -> 5 | H14: =+H$2 -> 3 | I14: =+I$2 -> 1 | J14: =+J$2 -> 1 | ... V14: =+V$2 -> 0.15 | W14: 30 | AB14: 20 | AG14: 5 | AI14: 5 | AL14: 0.33 | AO14: =30/100 -> 0.3 | AP14: =40/20 -> 2 | AQ14: 4 | AS14: =3+20 -> 23
A15: 9 | C15: =+C$2 -> 15 | D15: =+D$2 -> 3 | E15: =+E$2 -> 5 | F15: =+F$2 -> 2 | G15: =+G$2 -> 5 | H15: =+H$2 -> 3 | I15: =+I$2 -> 1 | J15: =+J$2 -> 1 | ... V15: =+V$2 -> 0.15 | W15: 34 | X15: 1 | AA15: 2 | AB15: 16 | AG15: 5 | AI15: 5 | AL15: 0.17 | AO15: =40/100 -> 0.4 | AP15: =20/20 -> 1 | AQ15: 2 | AS15: =4+10 -> 14
A16: 10 | C16: =+C$2 -> 15 | D16: =+D$2 -> 3 | E16: =+E$2 -> 5 | F16: =+F$2 -> 2 | G16: =+G$2 -> 5 | H16: =+H$2 -> 3 | I16: =+I$2 -> 1 | J16: =+J$2 -> 1 | ... V16: =+V$2 -> 0.15 | W16: 28 | Z16: 1 | AB16: 14 | AG16: 5 | AI16: 5 | AL16: 0.5 | AN16: =3/20 -> 0.15 | AO16: =60/100 -> 0.6 | AP16: =10/20 -> 0.5 | AQ16: =6+5 -> 11 | AS16: =6+4 -> 10
A17: 11 | C17: =+C$2 -> 15 | D17: =+D$2 -> 3 | E17: =+E$2 -> 5 | F17: =+F$2 -> 2 | G17: =+G$2 -> 5 | H17: =+H$2 -> 3 | I17: =+I$2 -> 1 | J17: =+J$2 -> 1 | ... V17: =+V$2 -> 0.15 | W17: 26 | Y17: 2 | Z17: 1 | AB17: 15 | AD17: 1 | AG17: 5 | AI17: 5 | AL17: 0.33 | AO17: =40/100 -> 0.4 | AP17: =5/20 -> 0.25 | AQ17: 4 | AS17: =4+2 -> 6
A18: 12 | C18: =+C$2 -> 15 | D18: =+D$2 -> 3 | E18: =+E$2 -> 5 | F18: =+F$2 -> 2 | G18: =+G$2 -> 5 | H18: =+H$2 -> 3 | I18: =+I$2 -> 1 | J18: =+J$2 -> 1 | ... V18: =+V$2 -> 0.15 | W18: 33 | X18: 1 | AB18: 16 | AG18: 5 | AI18: 5 | AL18: 0.33 | AO18: =20/100 -> 0.2 | AP18: =10/20 -> 0.5 | AQ18: 4 | AS18: =2+4 -> 6
A19: 13 | C19: =+C$2 -> 15 | D19: =+D$2 -> 3 | E19: =+E$2 -> 5 | F19: =+F$2 -> 2 | G19: =+G$2 -> 5 | H19: =+H$2 -> 3 | I19: =+I$2 -> 1 | J19: =+J$2 -> 1 | ... V19: =+V$2 -> 0.15 | W19: 28 | Y19: 3 | Z19: 1 | AB19: 12 | AD19: 1 | AE19: 1 | AG19: 5 | AI19: 5 | AL19: 0.42 | AO19: =50/100 -> 0.5 | AP19: =13/20 -> 0.65 | AQ19: 5 | AS19: =5+4 -> 9
A20: 14 | C20: =+C$2 -> 15 | D20: =+D$2 -> 3 | E20: =+E$2 -> 5 | F20: =+F$2 -> 2 | G20: =+G$2 -> 5 | H20: =+H$2 -> 3 | I20: =+I$2 -> 1 | J20: =+J$2 -> 1 | ... V20: =+V$2 -> 0.15 | W20: 25 | Z20: 2 | AB20: 16 | AG20: 5 | AI20: 5 | AL20: 0.33 | AN20: =2/20 -> 0.1 | AO20: =60/100 -> 0.6 | AP20: =15/20 -> 0.75 | AQ20: 4 | AS20: =6+6 -> 12
A21: 15 | C21: =+C$2 -> 15 | D21: =+D$2 -> 3 | E21: =+E$2 -> 5 | F21: =+F$2 -> 2 | G21: =+G$2 -> 5 | H21: =+H$2 -> 3 | I21: =+I$2 -> 1 | J21: =+J$2 -> 1 | ... V21: =+V$2 -> 0.15 | W21: 20 | X21: 1 | Z21: 1 | AA21: 1 | AB21: 13 | AG21: 5 | AI21: 5 | AL21: 0.17 | AO21: =40/100 -> 0.4 | AP21: =40/20 -> 2 | AQ21: 2 | AS21: =4+20 -> 24
A22: 16 | C22: =+C$2 -> 15 | D22: =+D$2 -> 3 | E22: =+E$2 -> 5 | F22: =+F$2 -> 2 | G22: =+G$2 -> 5 | H22: =+H$2 -> 3 | I22: =+I$2 -> 1 | J22: =+J$2 -> 1 | ... V22: =+V$2 -> 0.15 | W22: 26 | Y22: 2 | AB22: 15 | AD22: 2 | AG22: 5 | AI22: 5 | AL22: 0.33 | AN22: =3/20 -> 0.15 | AO22: =50/100 -> 0.5 | AP22: =20/20 -> 1 | AQ22: =4+5 -> 9 | AS22: =5+10 -> 15
A23: 17 | C23: =+C$2 -> 15 | D23: =+D$2 -> 3 | E23: =+E$2 -> 5 | F23: =+F$2 -> 2 | G23: =+G$2 -> 5 | H23: =+H$2 -> 3 | I23: =+I$2 -> 1 | J23: =+J$2 -> 1 | ... V23: =+V$2 -> 0.15 | W23: 30 | AA23: 1 | AB23: 15 | AG23: 5 | AI23: 5 | AL23: 0.25 | AO23: =40/100 -> 0.4 | AP23: =20/20 -> 1 | AQ23: 2 | AS23: =4+10 -> 14
A24: 18 | C24: =+C$2 -> 15 | D24: =+D$2 -> 3 | E24: =+E$2 -> 5 | F24: =+F$2 -> 2 | G24: =+G$2 -> 5 | H24: =+H$2 -> 3 | I24: =+I$2 -> 1 | J24: =+J$2 -> 1 | ... V24: =+V$2 -> 0.15 | W24: 29 | Y24: 1 | AB24: 10 | AG24: 5 | AI24: 5 | AL24: 0.08 | AN24: =2/20 -> 0.1 | AO24: =30/100 -> 0.3 | AP24: =30/20 -> 1.5 | AQ24: 1 | AS24: =3+14 -> 17
A25: 19 | C25: =+C$2 -> 15 | D25: =+D$2 -> 3 | E25: =+E$2 -> 5 | F25: =+F$2 -> 2 | G25: =+G$2 -> 5 | H25: =+H$2 -> 3 | I25: =+I$2 -> 1 | J25: =+J$2 -> 1 | ... V25: =+V$2 -> 0.15 | W25: 32 | Z25: 3 | AB25: 13 | AE25: 2 | AG25: 5 | AI25: 5 | AL25: 0.33 | AN25: =1/20 -> 0.05 | AO25: =60/100 -> 0.6 | AP25: =20/20 -> 1 | AQ25: 4 | AS25: =6+10 -> 16
A26: 20 | C26: =+C$2 -> 15 | D26: =+D$2 -> 3 | E26: =+E$2 -> 5 | F26: =+F$2 -> 2 | G26: =+G$2 -> 5 | H26: =+H$2 -> 3 | I26: =+I$2 -> 1 | J26: =+J$2 -> 1 | ... V26: =+V$2 -> 0.15 | W26: 27 | Z26: 3 | AB26: 15 | AE26: 1 | AG26: 5 | AI26: 5 | AL26: 0.42 | AN26: =3/20 -> 0.15 | AO26: =30/100 -> 0.3 | AP26: =20/20 -> 1 | AQ26: =5+5 -> 10 | AS26: =3+10 -> 13
A27: 21 | C27: =+C$2 -> 15 | D27: =+D$2 -> 3 | E27: =+E$2 -> 5 | F27: =+F$2 -> 2 | G27: =+G$2 -> 5 | H27: =+H$2 -> 3 | I27: =+I$2 -> 1 | J27: =+J$2 -> 1 | ... V27: =+V$2 -> 0.15 | W27: =SUM(W7:W26) -> 558 | X27: =SUM(X7:X26) -> 6 | Y27: =SUM(Y7:Y26) -> 11 | Z27: =SUM(Z7:Z26) -> 31 | AA27: =SUM(AA7:AA26) -> 10
A28: 22 | C28: =+C$2 -> 15 | D28: =+D$2 -> 3 | E28: =+E$2 -> 5 | F28: =+F$2 -> 2 | G28: =+G$2 -> 5 | H28: =+H$2 -> 3 | I28: =+I$2 -> 1 | J28: =+J$2 -> 1 | ... V28: =+V$2 -> 0.15
A29: 23 | C29: =+C$2 -> 15 | D29: =+D$2 -> 3 | E29: =+E$2 -> 5 | F29: =+F$2 -> 2 | G29: =+G$2 -> 5 | H29: =+H$2 -> 3 | I29: =+I$2 -> 1 | J29: =+J$2 -> 1 | ... V29: =+V$2 -> 0.15
A30: 24 | C30: =+C$2 -> 15 | D30: =+D$2 -> 3 | E30: =+E$2 -> 5 | F30: =+F$2 -> 2 | G30: =+G$2 -> 5 | H30: =+H$2 -> 3 | I30: =+I$2 -> 1 | J30: =+J$2 -> 1 | ... V30: =+V$2 -> 0.15
A31: 25 | C31: =+C$2 -> 15 | D31: =+D$2 -> 3 | E31: =+E$2 -> 5 | F31: =+F$2 -> 2 | G31: =+G$2 -> 5 | H31: =+H$2 -> 3 | I31: =+I$2 -> 1 | J31: =+J$2 -> 1 | ... V31: =+V$2 -> 0.15
A32: 26 | C32: =+C$2 -> 15 | D32: =+D$2 -> 3 | E32: =+E$2 -> 5 | F32: =+F$2 -> 2 | G32: =+G$2 -> 5 | H32: =+H$2 -> 3 | I32: =+I$2 -> 1 | J32: =+J$2 -> 1 | ... V32: =+V$2 -> 0.15
A33: 27 | C33: =+C$2 -> 15 | D33: =+D$2 -> 3 | E33: =+E$2 -> 5 | F33: =+F$2 -> 2 | G33: =+G$2 -> 5 | H33: =+H$2 -> 3 | I33: =+I$2 -> 1 | J33: =+J$2 -> 1 | ... V33: =+V$2 -> 0.15
A34: 28 | C34: =+C$2 -> 15 | D34: =+D$2 -> 3 | E34: =+E$2 -> 5 | F34: =+F$2 -> 2 | G34: =+G$2 -> 5 | H34: =+H$2 -> 3 | I34: =+I$2 -> 1 | J34: =+J$2 -> 1 | ... V34: =+V$2 -> 0.15
A35: 29 | C35: =+C$2 -> 15 | D35: =+D$2 -> 3 | E35: =+E$2 -> 5 | F35: =+F$2 -> 2 | G35: =+G$2 -> 5 | H35: =+H$2 -> 3 | I35: =+I$2 -> 1 | J35: =+J$2 -> 1 | ... V35: =+V$2 -> 0.15
A36: 30 | C36: =+C$2 -> 15 | D36: =+D$2 -> 3 | E36: =+E$2 -> 5 | F36: =+F$2 -> 2 | G36: =+G$2 -> 5 | H36: =+H$2 -> 3 | I36: =+I$2 -> 1 | J36: =+J$2 -> 1 | ... V36: =+V$2 -> 0.15
B37: TOTAL | C37: =SUM(C7:C36) -> 450 | D37: =SUM(D7:D36) -> 90 | E37: =SUM(E7:E36) -> 150 | F37: =SUM(F7:F36) -> 60 | G37: =SUM(G7:G36) -> 150 | H37: =SUM(H7:H36) -> 90 | I37: =SUM(I7:I36) -> 30 | J37: =SUM(J7:J36) -> 30 | ... AU37: =SUM(AU7:AU36) -> 0

Sheet Vendredi S1
C2: =+'Lundi S1'!C3 -> 15 | D2: =+'Lundi S1'!D3 -> 3 | E2: =+'Lundi S1'!E3 -> 5 | F2: =+'Lundi S1'!F3 -> 2 | G2: =+'Lundi S1'!G3 -> 5 | H2: =+'Lundi S1'!H3 -> 3 | I2: =+'Lundi S1'!I3 -> 1 | J2: =+'Lundi S1'!J3 -> 1 | ... V2: =+'Lundi S1'!V3 -> 0.15
A3: YAMOUSSOUKRO JOUR 1
C4: OBJECTIFS JOURNALIERS | W4: REALISATIONS | AT4: Commentaires | AU4: Impressions des PDV et des clients
A5: N° | B5: Agent promoteur | C5: Nombre de visite / Type de PDV | H5: Nombre de référencement / Type de PDV | M5: Pose de matériel de visibilité | R5: Vente en cartons | W5: Nombre de visite / Type de PDV | AB5: Nombre de référencement / Type de PDV | AG5: Pose de matériel de visibilité | AL5: Vente en cartons | AQ5: Gratuits offerts
C6: Boutique | D6: Superette | E6: Kiosque | F6: Tablier | G6: Pushcart | H6: Boutique | I6: Superette | J6: Kiosque | K6: Tablier | L6: Pushcart | M6: Affiche Biblos Lait Prémium 16g & 360g | N6: Affiche Biblos Lait Excellence | O6: Affiche Biblos Flocons d' Avoine | P6: Hanger | Q6: Wobbler | R6: Biblos Lait Premium 16g | S6: Biblos Lait Premium 360g | T6: Biblos Lait Excellence 900g | U6: Biblos Flocon d'avoine 50g | V6: Biblos Flocon d'avoine 400g | W6: Boutique | X6: Superette | Y6: Kiosque | Z6: Tablier | AA6: Pushcart | AB6: Boutique | AC6: Superette | AD6: Kiosque | AE6: Tablier | AF6: Pushcart | AG6: Affiche Biblos Lait Prémium 16g & 360g | AH6: Affiche Biblos Lait Excellence | AI6: Affiche Biblos Flocons d' Avoine | AJ6: Hanger | AK6: Wobbler | AL6: Biblos Lait Premium 16g | AM6: Biblos Lait Premium 360g | AN6: Biblos Lait Excellence 900g | AO6: Biblos Flocon d'avoine 50g | AP6: Biblos Flocon d'avoine 400g | AQ6: Biblos Lait Premium 16g | AR6: Biblos Lait Excellence 900g | AS6: Biblos Flocon d'avoine 50g
A7: 1 | C7: =+C$2 -> 15 | D7: =+D$2 -> 3 | E7: =+E$2 -> 5 | F7: =+F$2 -> 2 | G7: =+G$2 -> 5 | H7: =+H$2 -> 3 | I7: =+I$2 -> 1 | J7: =+J$2 -> 1 | ... V7: =+V$2 -> 0.15 | W7: 21 | X7: 1 | Z7: 4 | AA7: 2 | AB7: 11 | AE7: 2 | AG7: 5 | AI7: 5 | AL7: 0.67 | AN7: =3/20 -> 0.15 | AO7: =30/100 -> 0.3 | AP7: 1 | AQ7: =8+5 -> 13 | AS7: =3+10 -> 13
A8: 2 | C8: =+C$2 -> 15 | D8: =+D$2 -> 3 | E8: =+E$2 -> 5 | F8: =+F$2 -> 2 | G8: =+G$2 -> 5 | H8: =+H$2 -> 3 | I8: =+I$2 -> 1 | J8: =+J$2 -> 1 | ... V8: =+V$2 -> 0.15 | W8: 27 | Z8: 5 | AB8: 9 | AE8: 1 | AG8: 5 | AI8: 5 | AL8: 0.5 | AN8: =6/20 -> 0.3 | AO8: 0.5 | AP8: 0.5 | AQ8: =6+10 -> 16 | AS8: =5+4 -> 9
A9: 3 | C9: =+C$2 -> 15 | D9: =+D$2 -> 3 | E9: =+E$2 -> 5 | F9: =+F$2 -> 2 | G9: =+G$2 -> 5 | H9: =+H$2 -> 3 | I9: =+I$2 -> 1 | J9: =+J$2 -> 1 | ... V9: =+V$2 -> 0.15 | W9: 30 | Y9: 2 | Z9: 5 | AA9: 1 | AB9: 14 | AE9: 2 | AG9: 5 | AI9: 5 | AL9: 0.5 | AN9: =3/20 -> 0.15 | AO9: 0.6 | AP9: 1 | AQ9: =6+5 -> 11 | AS9: =6+10 -> 16
A10: 4 | C10: =+C$2 -> 15 | D10: =+D$2 -> 3 | E10: =+E$2 -> 5 | F10: =+F$2 -> 2 | G10: =+G$2 -> 5 | H10: =+H$2 -> 3 | I10: =+I$2 -> 1 | J10: =+J$2 -> 1 | ... V10: =+V$2 -> 0.15 | W10: 29 | Y10: 2 | AB10: 7 | AD10: 1 | AG10: 5 | AI10: 5 | AL10: 0.33 | AN10: =3/20 -> 0.15 | AO10: 0.4 | AP10: 1 | AQ10: =4+5 -> 9 | AS10: =4+10 -> 14
A11: 5 | C11: =+C$2 -> 15 | D11: =+D$2 -> 3 | E11: =+E$2 -> 5 | F11: =+F$2 -> 2 | G11: =+G$2 -> 5 | H11: =+H$2 -> 3 | I11: =+I$2 -> 1 | J11: =+J$2 -> 1 | ... V11: =+V$2 -> 0.15 | W11: 30 | AB11: 8 | AG11: 5 | AI11: 5 | AL11: 0.42 | AO11: 0.5 | AP11: 3 | AQ11: 5 | AS11: =5+30 -> 35
A12: 6 | C12: =+C$2 -> 15 | D12: =+D$2 -> 3 | E12: =+E$2 -> 5 | F12: =+F$2 -> 2 | G12: =+G$2 -> 5 | H12: =+H$2 -> 3 | I12: =+I$2 -> 1 | J12: =+J$2 -> 1 | ... V12: =+V$2 -> 0.15 | W12: 30 | Y12: 2 | Z12: 1 | AB12: 10 | AD12: 2 | AG12: 5 | AI12: 5 | AL12: 0.25 | AN12: =6/20 -> 0.3 | AO12: 0.4 | AP12: 0.5 | AQ12: =3+10 -> 13 | AS12: =4+4 -> 8
A13: 7 | C13: =+C$2 -> 15 | D13: =+D$2 -> 3 | E13: =+E$2 -> 5 | F13: =+F$2 -> 2 | G13: =+G$2 -> 5 | H13: =+H$2 -> 3 | I13: =+I$2 -> 1 | J13: =+J$2 -> 1 | ... V13: =+V$2 -> 0.15 | W13: 35 | X13: 1 | AB13: 9 | AD13: 1 | AG13: 5 | AI13: 5 | AL13: 0.08 | AO13: 0.5 | AP13: 2 | AQ13: 1 | AS13: =5+20 -> 25
A14: 8 | C14: =+C$2 -> 15 | D14: =+D$2 -> 3 | E14: =+E$2 -> 5 | F14: =+F$2 -> 2 | G14: =+G$2 -> 5 | H14: =+H$2 -> 3 | I14: =+I$2 -> 1 | J14: =+J$2 -> 1 | ... V14: =+V$2 -> 0.15 | W14: 31 | AA14: 3 | AB14: 13 | AF14: 1 | AG14: 5 | AI14: 5 | AL14: 0.33 | AN14: =3/20 -> 0.15 | AO14: 0.5 | AP14: 1 | AQ14: =4+5 -> 9 | AS14: =5+10 -> 15
A15: 9 | C15: =+C$2 -> 15 | D15: =+D$2 -> 3 | E15: =+E$2 -> 5 | F15: =+F$2 -> 2 | G15: =+G$2 -> 5 | H15: =+H$2 -> 3 | I15: =+I$2 -> 1 | J15: =+J$2 -> 1 | ... V15: =+V$2 -> 0.15 | W15: 30 | AB15: 12 | AG15: 5 | AI15: 5 | AL15: 0.42 | AO15: 0.4 | AP15: 1.5 | AQ15: 5 | AS15: =4+14 -> 18 | AT15: Idem
A16: 10 | C16: =+C$2 -> 15 | D16: =+D$2 -> 3 | E16: =+E$2 -> 5 | F16: =+F$2 -> 2 | G16: =+G$2 -> 5 | H16: =+H$2 -> 3 | I16: =+I$2 -> 1 | J16: =+J$2 -> 1 | ... V16: =+V$2 -> 0.15 | W16: 22 | Y16: 1 | Z16: 3 | AB16: 7 | AD16: 1 | AE16: 1 | AG16: 5 | AI16: 5 | AL16: 0.33 | AO16: 0.8 | AP16: 1 | AQ16: 4 | AS16: =8+10 -> 18
A17: 11 | C17: =+C$2 -> 15 | D17: =+D$2 -> 3 | E17: =+E$2 -> 5 | F17: =+F$2 -> 2 | G17: =+G$2 -> 5 | H17: =+H$2 -> 3 | I17: =+I$2 -> 1 | J17: =+J$2 -> 1 | ... V17: =+V$2 -> 0.15 | W17: 30 | AB17: 10 | AG17: 5 | AI17: 5 | AL17: 0.5 | AN17: =6/20 -> 0.3 | AO17: 1 | AP17: 1.5 | AQ17: =6+10 -> 16 | AS17: =10+14 -> 24
A18: 12 | C18: =+C$2 -> 15 | D18: =+D$2 -> 3 | E18: =+E$2 -> 5 | F18: =+F$2 -> 2 | G18: =+G$2 -> 5 | H18: =+H$2 -> 3 | I18: =+I$2 -> 1 | J18: =+J$2 -> 1 | ... V18: =+V$2 -> 0.15 | W18: 27 | X18: 1 | Y18: 1 | AB18: 13 | AD18: 1 | AG18: 5 | AI18: 5 | AL18: 0.5 | AN18: =3/20 -> 0.15 | AO18: 0.6 | AP18: 1 | AQ18: =6+5 -> 11 | AS18: =6+10 -> 16
A19: 13 | C19: =+C$2 -> 15 | D19: =+D$2 -> 3 | E19: =+E$2 -> 5 | F19: =+F$2 -> 2 | G19: =+G$2 -> 5 | H19: =+H$2 -> 3 | I19: =+I$2 -> 1 | J19: =+J$2 -> 1 | ... V19: =+V$2 -> 0.15 | W19: 33 | AB19: 8 | AG19: 5 | AI19: 5 | AL19: 0.42 | AN19: =3/20 -> 0.15 | AO19: 0.5 | AP19: 1 | AQ19: =5+5 -> 10 | AS19: =5+10 -> 15
A20: 14 | C20: =+C$2 -> 15 | D20: =+D$2 -> 3 | E20: =+E$2 -> 5 | F20: =+F$2 -> 2 | G20: =+G$2 -> 5 | H20: =+H$2 -> 3 | I20: =+I$2 -> 1 | J20: =+J$2 -> 1 | ... V20: =+V$2 -> 0.15 | W20: 28 | X20: 1 | Z20: 3 | AA20: 1 | AB20: 10 | AC20: 1 | AE20: 2 | AF20: 1 | AG20: 5 | AI20: 5 | AL20: 0.42 | AN20: =3/20 -> 0.15 | AO20: 0.5 | AP20: 1 | AQ20: =5+5 -> 10 | AS20: =5+10 -> 15 | AT20: C'est après le 1er jour de vente que le grossiste nous a signifiés que le 360G est disponible. Nous en avons vendu le 2ème jour hier.
A21: 15 | C21: =+C$2 -> 15 | D21: =+D$2 -> 3 | E21: =+E$2 -> 5 | F21: =+F$2 -> 2 | G21: =+G$2 -> 5 | H21: =+H$2 -> 3 | I21: =+I$2 -> 1 | J21: =+J$2 -> 1 | ... V21: =+V$2 -> 0.15 | W21: 30 | Y21: 2 | AB21: 13 | AD21: 2 | AG21: 5 | AI21: 5 | AL21: 0.33 | AN21: =6/20 -> 0.3 | AO21: 1 | AP21: 1 | AQ21: =4+10 -> 14 | AS21: =10+10 -> 20
A22: 16 | C22: =+C$2 -> 15 | D22: =+D$2 -> 3 | E22: =+E$2 -> 5 | F22: =+F$2 -> 2 | G22: =+G$2 -> 5 | H22: =+H$2 -> 3 | I22: =+I$2 -> 1 | J22: =+J$2 -> 1 | ... V22: =+V$2 -> 0.15 | W22: 31 | X22: 1 | Z22: 2 | AB22: 9 | AE22: 1 | AG22: 5 | AI22: 5 | AL22: 0.5 | AN22: =3/20 -> 0.15 | AO22: 0.7 | AP22: 1 | AQ22: =6+5 -> 11 | AS22: =7+10 -> 17
A23: 17 | C23: =+C$2 -> 15 | D23: =+D$2 -> 3 | E23: =+E$2 -> 5 | F23: =+F$2 -> 2 | G23: =+G$2 -> 5 | H23: =+H$2 -> 3 | I23: =+I$2 -> 1 | J23: =+J$2 -> 1 | ... V23: =+V$2 -> 0.15 | W23: 32 | Z23: 1 | AA23: 1 | AB23: 13 | AG23: 5 | AI23: 5 | AL23: 0.5 | AN23: =3/20 -> 0.15 | AO23: 1 | AP23: 0.5 | AQ23: =6+5 -> 11 | AS23: =10+4 -> 14
A24: 18 | C24: =+C$2 -> 15 | D24: =+D$2 -> 3 | E24: =+E$2 -> 5 | F24: =+F$2 -> 2 | G24: =+G$2 -> 5 | H24: =+H$2 -> 3 | I24: =+I$2 -> 1 | J24: =+J$2 -> 1 | ... V24: =+V$2 -> 0.15 | W24: 26 | Z24: 4 | AB24: 11 | AE24: 1 | AG24: 5 | AI24: 5 | AL24: 0.42 | AN24: =3/20 -> 0.15 | AO24: 0.4 | AP24: 0.5 | AQ24: =5+5 -> 10 | AS24: =4+4 -> 8
A25: 19 | C25: =+C$2 -> 15 | D25: =+D$2 -> 3 | E25: =+E$2 -> 5 | F25: =+F$2 -> 2 | G25: =+G$2 -> 5 | H25: =+H$2 -> 3 | I25: =+I$2 -> 1 | J25: =+J$2 -> 1 | ... V25: =+V$2 -> 0.15 | W25: 28 | Y25: 1 | Z25: 1 | AA25: 1 | AB25: 8 | AD25: 1 | AE25: 1 | AG25: 5 | AI25: 5 | AL25: 0.17 | AN25: =3/20 -> 0.15 | AO25: 0.2 | AP25: 1 | AQ25: =2+5 -> 7 | AS25: =2+10 -> 12
A26: 20 | C26: =+C$2 -> 15 | D26: =+D$2 -> 3 | E26: =+E$2 -> 5 | F26: =+F$2 -> 2 | G26: =+G$2 -> 5 | H26: =+H$2 -> 3 | I26: =+I$2 -> 1 | J26: =+J$2 -> 1 | ... V26: =+V$2 -> 0.15 | W26: 30 | AA26: 2 | AB26: 12 | AF26: 1 | AG26: 5 | AI26: 5 | AL26: 0.42 | AN26: =3/20 -> 0.15 | AO26: 1.2 | AP26: 1 | AQ26: =5+5 -> 10 | AS26: =12+10 -> 22
A27: 21 | C27: =+C$2 -> 15 | D27: =+D$2 -> 3 | E27: =+E$2 -> 5 | F27: =+F$2 -> 2 | G27: =+G$2 -> 5 | H27: =+H$2 -> 3 | I27: =+I$2 -> 1 | J27: =+J$2 -> 1 | ... V27: =+V$2 -> 0.15 | W27: =SUM(W7:W26) -> 580 | X27: =SUM(X7:X26) -> 5 | Y27: =SUM(Y7:Y26) -> 11 | Z27: =SUM(Z7:Z26) -> 29 | AA27: =SUM(AA7:AA26) -> 11
A28: 22 | C28: =+C$2 -> 15 | D28: =+D$2 -> 3 | E28: =+E$2 -> 5 | F28: =+F$2 -> 2 | G28: =+G$2 -> 5 | H28: =+H$2 -> 3 | I28: =+I$2 -> 1 | J28: =+J$2 -> 1 | ... V28: =+V$2 -> 0.15
A29: 23 | C29: =+C$2 -> 15 | D29: =+D$2 -> 3 | E29: =+E$2 -> 5 | F29: =+F$2 -> 2 | G29: =+G$2 -> 5 | H29: =+H$2 -> 3 | I29: =+I$2 -> 1 | J29: =+J$2 -> 1 | ... V29: =+V$2 -> 0.15
A30: 24 | C30: =+C$2 -> 15 | D30: =+D$2 -> 3 | E30: =+E$2 -> 5 | F30: =+F$2 -> 2 | G30: =+G$2 -> 5 | H30: =+H$2 -> 3 | I30: =+I$2 -> 1 | J30: =+J$2 -> 1 | ... V30: =+V$2 -> 0.15
A31: 25 | C31: =+C$2 -> 15 | D31: =+D$2 -> 3 | E31: =+E$2 -> 5 | F31: =+F$2 -> 2 | G31: =+G$2 -> 5 | H31: =+H$2 -> 3 | I31: =+I$2 -> 1 | J31: =+J$2 -> 1 | ... V31: =+V$2 -> 0.15
A32: 26 | C32: =+C$2 -> 15 | D32: =+D$2 -> 3 | E32: =+E$2 -> 5 | F32: =+F$2 -> 2 | G32: =+G$2 -> 5 | H32: =+H$2 -> 3 | I32: =+I$2 -> 1 | J32: =+J$2 -> 1 | ... V32: =+V$2 -> 0.15
A33: 27 | C33: =+C$2 -> 15 | D33: =+D$2 -> 3 | E33: =+E$2 -> 5 | F33: =+F$2 -> 2 | G33: =+G$2 -> 5 | H33: =+H$2 -> 3 | I33: =+I$2 -> 1 | J33: =+J$2 -> 1 | ... V33: =+V$2 -> 0.15
A34: 28 | C34: =+C$2 -> 15 | D34: =+D$2 -> 3 | E34: =+E$2 -> 5 | F34: =+F$2 -> 2 | G34: =+G$2 -> 5 | H34: =+H$2 -> 3 | I34: =+I$2 -> 1 | J34: =+J$2 -> 1 | ... V34: =+V$2 -> 0.15
A35: 29 | C35: =+C$2 -> 15 | D35: =+D$2 -> 3 | E35: =+E$2 -> 5 | F35: =+F$2 -> 2 | G35: =+G$2 -> 5 | H35: =+H$2 -> 3 | I35: =+I$2 -> 1 | J35: =+J$2 -> 1 | ... V35: =+V$2 -> 0.15
A36: 30 | C36: =+C$2 -> 15 | D36: =+D$2 -> 3 | E36: =+E$2 -> 5 | F36: =+F$2 -> 2 | G36: =+G$2 -> 5 | H36: =+H$2 -> 3 | I36: =+I$2 -> 1 | J36: =+J$2 -> 1 | ... V36: =+V$2 -> 0.15
B37: TOTAL | C37: =SUM(C7:C36) -> 450 | D37: =SUM(D7:D36) -> 90 | E37: =SUM(E7:E36) -> 150 | F37: =SUM(F7:F36) -> 60 | G37: =SUM(G7:G36) -> 150 | H37: =SUM(H7:H36) -> 90 | I37: =SUM(I7:I36) -> 30 | J37: =SUM(J7:J36) -> 30 | ... AU37: =SUM(AU7:AU36) -> 0

Sheet Samedi S1
C2: =+'Lundi S1'!C3 -> 15 | D2: =+'Lundi S1'!D3 -> 3 | E2: =+'Lundi S1'!E3 -> 5 | F2: =+'Lundi S1'!F3 -> 2 | G2: =+'Lundi S1'!G3 -> 5 | H2: =+'Lundi S1'!H3 -> 3 | I2: =+'Lundi S1'!I3 -> 1 | J2: =+'Lundi S1'!J3 -> 1 | ... V2: =+'Lundi S1'!V3 -> 0.15
C4: OBJECTIFS JOURNALIERS | W4: REALISATIONS | AT4: Commentaires | AU4: Impressions des PDV et des clients
A5: N° | B5: Agent promoteur | C5: Nombre de visite / Type de PDV | H5: Nombre de référencement / Type de PDV | M5: Pose de matériel de visibilité | R5: Vente en cartons | W5: Nombre de visite / Type de PDV | AB5: Nombre de référencement / Type de PDV | AG5: Pose de matériel de visibilité | AL5: Vente en cartons | AQ5: Gratuits offerts
C6: Boutique | D6: Superette | E6: Kiosque | F6: Tablier | G6: Pushcart | H6: Boutique | I6: Superette | J6: Kiosque | K6: Tablier | L6: Pushcart | M6: Affiche Biblos Lait Prémium 16g & 360g | N6: Affiche Biblos Lait Excellence | O6: Affiche Biblos Flocons d' Avoine | P6: Hanger | Q6: Wobbler | R6: Biblos Lait Premium 16g | S6: Biblos Lait Premium 360g | T6: Biblos Lait Excellence 900g | U6: Biblos Flocon d'avoine 50g | V6: Biblos Flocon d'avoine 400g | W6: Boutique | X6: Superette | Y6: Kiosque | Z6: Tablier | AA6: Pushcart | AB6: Boutique | AC6: Superette | AD6: Kiosque | AE6: Tablier | AF6: Pushcart | AG6: Affiche Biblos Lait Prémium 16g & 360g | AH6: Affiche Biblos Lait Excellence | AI6: Affiche Biblos Flocons d' Avoine | AJ6: Hanger | AK6: Wobbler | AL6: Biblos Lait Premium 16g | AM6: Biblos Lait Premium 360g | AN6: Biblos Lait Excellence 900g | AO6: Biblos Flocon d'avoine 50g | AP6: Biblos Flocon d'avoine 400g | AQ6: Biblos Lait Premium 16g | AR6: Biblos Lait Excellence 900g | AS6: Biblos Flocon d'avoine 50g
A7: 1 | C7: =+C$2 -> 15 | D7: =+D$2 -> 3 | E7: =+E$2 -> 5 | F7: =+F$2 -> 2 | G7: =+G$2 -> 5 | H7: =+H$2 -> 3 | I7: =+I$2 -> 1 | J7: =+J$2 -> 1 | ... V7: =+V$2 -> 0.15 | W7: 1 | X7: 1 | Y7: 1 | Z7: 1 | AA7: 1 | AB7: 1 | AC7: 1 | AD7: 1 | AE7: 1 | AF7: 1 | AG7: 1 | AH7: 1 | AI7: 1 | AJ7: 1 | AK7: 1 | AL7: 1 | AM7: 1 | AN7: 1 | AO7: 1 | AP7: 1 | AQ7: 1 | AR7: 1 | AS7: 1
A8: 2 | C8: =+C$2 -> 15 | D8: =+D$2 -> 3 | E8: =+E$2 -> 5 | F8: =+F$2 -> 2 | G8: =+G$2 -> 5 | H8: =+H$2 -> 3 | I8: =+I$2 -> 1 | J8: =+J$2 -> 1 | ... V8: =+V$2 -> 0.15
A9: 3 | C9: =+C$2 -> 15 | D9: =+D$2 -> 3 | E9: =+E$2 -> 5 | F9: =+F$2 -> 2 | G9: =+G$2 -> 5 | H9: =+H$2 -> 3 | I9: =+I$2 -> 1 | J9: =+J$2 -> 1 | ... V9: =+V$2 -> 0.15
A10: 4 | C10: =+C$2 -> 15 | D10: =+D$2 -> 3 | E10: =+E$2 -> 5 | F10: =+F$2 -> 2 | G10: =+G$2 -> 5 | H10: =+H$2 -> 3 | I10: =+I$2 -> 1 | J10: =+J$2 -> 1 | ... V10: =+V$2 -> 0.15
A11: 5 | C11: =+C$2 -> 15 | D11: =+D$2 -> 3 | E11: =+E$2 -> 5 | F11: =+F$2 -> 2 | G11: =+G$2 -> 5 | H11: =+H$2 -> 3 | I11: =+I$2 -> 1 | J11: =+J$2 -> 1 | ... V11: =+V$2 -> 0.15
A12: 6 | C12: =+C$2 -> 15 | D12: =+D$2 -> 3 | E12: =+E$2 -> 5 | F12: =+F$2 -> 2 | G12: =+G$2 -> 5 | H12: =+H$2 -> 3 | I12: =+I$2 -> 1 | J12: =+J$2 -> 1 | ... V12: =+V$2 -> 0.15
A13: 7 | C13: =+C$2 -> 15 | D13: =+D$2 -> 3 | E13: =+E$2 -> 5 | F13: =+F$2 -> 2 | G13: =+G$2 -> 5 | H13: =+H$2 -> 3 | I13: =+I$2 -> 1 | J13: =+J$2 -> 1 | ... V13: =+V$2 -> 0.15
A14: 8 | C14: =+C$2 -> 15 | D14: =+D$2 -> 3 | E14: =+E$2 -> 5 | F14: =+F$2 -> 2 | G14: =+G$2 -> 5 | H14: =+H$2 -> 3 | I14: =+I$2 -> 1 | J14: =+J$2 -> 1 | ... V14: =+V$2 -> 0.15
A15: 9 | C15: =+C$2 -> 15 | D15: =+D$2 -> 3 | E15: =+E$2 -> 5 | F15: =+F$2 -> 2 | G15: =+G$2 -> 5 | H15: =+H$2 -> 3 | I15: =+I$2 -> 1 | J15: =+J$2 -> 1 | ... V15: =+V$2 -> 0.15
A16: 10 | C16: =+C$2 -> 15 | D16: =+D$2 -> 3 | E16: =+E$2 -> 5 | F16: =+F$2 -> 2 | G16: =+G$2 -> 5 | H16: =+H$2 -> 3 | I16: =+I$2 -> 1 | J16: =+J$2 -> 1 | ... V16: =+V$2 -> 0.15
A17: 11 | C17: =+C$2 -> 15 | D17: =+D$2 -> 3 | E17: =+E$2 -> 5 | F17: =+F$2 -> 2 | G17: =+G$2 -> 5 | H17: =+H$2 -> 3 | I17: =+I$2 -> 1 | J17: =+J$2 -> 1 | ... V17: =+V$2 -> 0.15
A18: 12 | C18: =+C$2 -> 15 | D18: =+D$2 -> 3 | E18: =+E$2 -> 5 | F18: =+F$2 -> 2 | G18: =+G$2 -> 5 | H18: =+H$2 -> 3 | I18: =+I$2 -> 1 | J18: =+J$2 -> 1 | ... V18: =+V$2 -> 0.15
A19: 13 | C19: =+C$2 -> 15 | D19: =+D$2 -> 3 | E19: =+E$2 -> 5 | F19: =+F$2 -> 2 | G19: =+G$2 -> 5 | H19: =+H$2 -> 3 | I19: =+I$2 -> 1 | J19: =+J$2 -> 1 | ... V19: =+V$2 -> 0.15
... A36: 30 | C36: =+C$2 -> 15 | D36: =+D$2 -> 3 | E36: =+E$2 -> 5 | F36: =+F$2 -> 2 | G36: =+G$2 -> 5 | H36: =+H$2 -> 3 | I36: =+I$2 -> 1 | J36: =+J$2 -> 1 | ... V36: =+V$2 -> 0.15
B37: TOTAL | C37: =SUM(C7:C36) -> 450 | D37: =SUM(D7:D36) -> 90 | E37: =SUM(E7:E36) -> 150 | F37: =SUM(F7:F36) -> 60 | G37: =SUM(G7:G36) -> 150 | H37: =SUM(H7:H36) -> 90 | I37: =SUM(I7:I36) -> 30 | J37: =SUM(J7:J36) -> 30 | ... AU37: =SUM(AU7:AU36) -> 0

Sheet Synthèse S1
C2: 15 | D2: 3 | E2: 5 | F2: 2 | G2: 5 | H2: 5 | I2: 1 | J2: 1 | K2: 1 | L2: 2 | M2: =+H2 -> 5 | N2: 1 | O2: =+H2 -> 5 | R2: =+(2*M2)/12 -> 0.83333333 | S2: =+(1*I2)/6 -> 0.16666667 | T2: =+(2*I2)/20 -> 0.1 | U2: =+(2*H2)/10 -> 1 | V2: =+(3*I2)/20 -> 0.15
C4: OBJECTIFS JOURNALIERS | W4: REALISATIONS | AT4: Commentaires | AU4: Impressions des PDV et des clients
A5: N° | B5: Agent promoteur | C5: Nombre de visite / Type de PDV | H5: Nombre de référencement / Type de PDV | M5: Pose de matériel de visibilité | R5: Vente en cartons | W5: Nombre de visite / Type de PDV | AB5: Nombre de référencement / Type de PDV | AG5: Pose de matériel de visibilité | AL5: Vente en cartons | AQ5: Gratuits offerts
C6: Boutique | D6: Superette | E6: Kiosque | F6: Tablier | G6: Pushcart | H6: Boutique | I6: Superette | J6: Kiosque | K6: Tablier | L6: Pushcart | M6: Affiche Biblos Lait Prémium 16g & 360g | N6: Affiche Biblos Lait Excellence | O6: Affiche Biblos Flocons d' Avoine | P6: Hanger | Q6: Wobbler | R6: Biblos Lait Premium 16g | S6: Biblos Lait Premium 360g | T6: Biblos Lait Excellence 900g | U6: Biblos Flocon d'avoine 50g | V6: Biblos Flocon d'avoine 400g | W6: Boutique | X6: Superette | Y6: Kiosque | Z6: Tablier | AA6: Pushcart | AB6: Boutique | AC6: Superette | AD6: Kiosque | AE6: Tablier | AF6: Pushcart | AG6: Affiche Biblos Lait Prémium 16g & 360g | AH6: Affiche Biblos Lait Excellence | AI6: Affiche Biblos Flocons d' Avoine | AJ6: Hanger | AK6: Wobbler | AL6: Biblos Lait Premium 16g | AM6: Biblos Lait Premium 360g | AN6: Biblos Lait Excellence 900g | AO6: Biblos Flocon d'avoine 50g | AP6: Biblos Flocon d'avoine 400g | AQ6: Biblos Lait Premium 16g | AR6: Biblos Lait Excellence 900g | AS6: Biblos Flocon d'avoine 50g
A7: 1 | C7: =+'Lundi S1'!C8+'Mardi S1'!C8+'Mercredi S1'!C7+'Jeudi S1'!C7+'Vendredi S1'!C7+'Samedi S1'!C7 -> 90 | D7: =+'Lundi S1'!D8+'Mardi S1'!D8+'Mercredi S1'!D7+'Jeudi S1'!D7+'Vendredi S1'!D7+'Samedi S1'!D7 -> 18 | E7: =+'Lundi S1'!E8+'Mardi S1'!E8+'Mercredi S1'!E7+'Jeudi S1'!E7+'Vendredi S1'!E7+'Samedi S1'!E7 -> 30 | F7: =+'Lundi S1'!F8+'Mardi S1'!F8+'Mercredi S1'!F7+'Jeudi S1'!F7+'Vendredi S1'!F7+'Samedi S1'!F7 -> 12 | G7: =+'Lundi S1'!G8+'Mardi S1'!G8+'Mercredi S1'!G7+'Jeudi S1'!G7+'Vendredi S1'!G7+'Samedi S1'!G7 -> 30 | H7: =+'Lundi S1'!H8+'Mardi S1'!H8+'Mercredi S1'!H7+'Jeudi S1'!H7+'Vendredi S1'!H7+'Samedi S1'!H7 -> 18 | I7: =+'Lundi S1'!I8+'Mardi S1'!I8+'Mercredi S1'!I7+'Jeudi S1'!I7+'Vendredi S1'!I7+'Samedi S1'!I7 -> 6 | J7: =+'Lundi S1'!J8+'Mardi S1'!J8+'Mercredi S1'!J7+'Jeudi S1'!J7+'Vendredi S1'!J7+'Samedi S1'!J7 -> 6 | ... AS7: =+'Lundi S1'!AS8+'Mardi S1'!AS8+'Mercredi S1'!AS7+'Jeudi S1'!AS7+'Vendredi S1'!AS7+'Samedi S1'!AS7 -> 68
