Workbook

Sheet JEUDI 22 JANV
B2: SAN PEDRO/ 22/01/2026 | AQ2: 2 | AR2: 3 | AS2: 4 | AT2: 5 | AU2: 6 | AV2: 7 | AW2: 8 | AX2: 9 | AY2: 10 | AZ2: 11
C3: 10 | D3: 3 | E3: 2 | F3: 2 | G3: 3 | H3: 3 | I3: 1 | J3: 1 | K3: 1 | L3: 1 | M3: =+H3 -> 3 | N3: 1 | O3: =+H3 -> 3 | R3: =+(2*M3)/12 -> 0.5 | S3: =+(1*I3)/6 -> 0.16666667 | T3: =+(2*I3)/20 -> 0.1 | U3: =+(2*H3)/10 -> 0.6 | V3: =+(3*I3)/20 -> 0.15 | AQ3: =2/12 -> 0.16666667 | AR3: =3/12 -> 0.25 | AS3: =4/12 -> 0.33333333 | AT3: =5/12 -> 0.41666667 | AU3: =6/12 -> 0.5 | AV3: =7/12 -> 0.58333333 | AW3: =8/12 -> 0.66666667 | AX3: =9/12 -> 0.75 | AY3: =10/12 -> 0.83333333 | AZ3: =11/12 -> 0.91666667
C5: OBJECTIFS JOURNALIERS | W5: REALISATIONS | BD5: Commentaires | BE5: Impressions des PDV et des clients
A6: N° | B6: Agent promoteur | C6: Nombre de visite / Type de PDV | H6: Nombre de référencement / Type de PDV | M6: Pose de matériel de visibilité | R6: Vente en cartons | W6: Nombre de visite / Type de PDV | AB6: Présence produits antérieure | AG6: Nombre de référencement / Type de PDV | AL6: Nouveau Référencement par SKU | AQ6: Vente en cartons | AV6: Pose de matériel de visibilité | BA6: Gratuits offerts en sachet
C7: Boutique | D7: Superette | E7: Kiosque | F7: Tablier | G7: Pushcart | H7: Boutique | I7: Superette | J7: Kiosque | K7: Tablier | L7: Pushcart | M7: Affiche Biblos Lait Prémium 16g & 360g | N7: Affiche Biblos Lait Excellence | O7: Affiche Biblos Flocons d' Avoine | P7: Hanger | Q7: Wobbler | R7: Biblos Lait Premium 16g | S7: Biblos Lait Premium 360g | T7: Biblos Lait Excellence 900g | U7: Biblos Flocon d'avoine 50g | V7: Biblos Flocon d'avoine 400g | W7: Boutique | X7: Superette | Y7: Kiosque | Z7: Tablier | AA7: Pushcart | AB7: Biblos Lait Premium 16g | AC7: Biblos Lait Premium 360g | AD7: Biblos Lait Excellence 900g | AE7: Biblos Flocon d'avoine 50g | AF7: Biblos Flocon d'avoine 400g | AG7: Boutique | AH7: Superette | AI7: Kiosque | AJ7: Tablier | AK7: Pushcart | AL7: Biblos Lait Premium 16g | AM7: Biblos Lait Premium 360g | AN7: Biblos Lait Excellence 900g | AO7: Biblos Flocon d'avoine 50g | AP7: Biblos Flocon d'avoine 400g | AQ7: Biblos Lait Premium 16g | AR7: Biblos Lait Premium 360g | AS7: Biblos Lait Excellence 900g | AT7: Biblos Flocon d'avoine 50g | AU7: Biblos Flocon d'avoine 400g | AV7: Affiche Biblos Lait Prémium 16g & 360g | AW7: Affiche Biblos Lait Excellence | AX7: Affiche Biblos Flocons d' Avoine | AY7: Hanger | AZ7: Wobbler | BA7: Biblos Lait Premium 16g | BB7: Biblos Lait Excellence 900g | BC7: Biblos Flocon d'avoine 50g
A8: 1 | B8: DIBI SIMEON | C8: =+C$3 -> 10 | D8: =+D$3 -> 3 | E8: =+E$3 -> 2 | F8: =+F$3 -> 2 | G8: =+G$3 -> 3 | H8: =+H$3 -> 3 | I8: =+I$3 -> 1 | J8: =+J$3 -> 1 | ... V8: =+V$3 -> 0.15 | W8: 28 | AG8: 6 | AL8: 2 | AN8: 1 | AP8: 3 | AQ8: 1 | AS8: 0.15 | AU8: 2 | AV8: 3 | AW8: 3 | AX8: 3 | BA8: 18 | BC8: 20
A9: 2 | B9: KRA EVAVARISTE | C9: =+C$3 -> 10 | D9: =+D$3 -> 3 | E9: =+E$3 -> 2 | F9: =+F$3 -> 2 | G9: =+G$3 -> 3 | H9: =+H$3 -> 3 | I9: =+I$3 -> 1 | J9: =+J$3 -> 1 | ... V9: =+V$3 -> 0.15 | W9: 27 | AB9: 1 | AF9: 1 | AG9: 7 | AL9: 2 | AN9: 1 | AP9: 2 | AQ9: 1 | AS9: 0.05 | AU9: 1 | AV9: 3 | AW9: 3 | AX9: 3 | BA9: 12 | BC9: 10
A10: 3 | B10: DIOMANDE ESTHER | C10: =+C$3 -> 10 | D10: =+D$3 -> 3 | E10: =+E$3 -> 2 | F10: =+F$3 -> 2 | G10: =+G$3 -> 3 | H10: =+H$3 -> 3 | I10: =+I$3 -> 1 | J10: =+J$3 -> 1 | ... V10: =+V$3 -> 0.15 | W10: 28 | AG10: 4 | AL10: 1 | AN10: 1 | AO10: 1 | AP10: 1 | AQ10: 0.5 | AS10: 0.15 | AT10: 0.5 | AU10: 1 | AV10: 3 | AW10: 3 | AX10: 3 | BA10: 12 | BC10: 15
A11: 4 | B11: BADA LANDRY | C11: =+C$3 -> 10 | D11: =+D$3 -> 3 | E11: =+E$3 -> 2 | F11: =+F$3 -> 2 | G11: =+G$3 -> 3 | H11: =+H$3 -> 3 | I11: =+I$3 -> 1 | J11: =+J$3 -> 1 | ... V11: =+V$3 -> 0.15 | W11: 27 | AD11: 1 | AF11: 1 | AG11: 7 | AL11: 1 | AN11: 1 | AO11: 1 | AP11: 2 | AQ11: 0.42 | AS11: 0.15 | AT11: 0.5 | AU11: 1.5 | AV11: 3 | AW11: 3 | AX11: 3 | BA11: 11 | BC11: 20
A12: 5 | B12: KOUAME JOSE | C12: =+C$3 -> 10 | D12: =+D$3 -> 3 | E12: =+E$3 -> 2 | F12: =+F$3 -> 2 | G12: =+G$3 -> 3 | H12: =+H$3 -> 3 | I12: =+I$3 -> 1 | J12: =+J$3 -> 1 | ... V12: =+V$3 -> 0.15 | W12: 30 | AG12: 3 | AL12: 1 | AO12: 1 | AP12: 1 | AQ12: 0.5 | AT12: 0.5 | AU12: 1 | AV12: 3 | AW12: 3 | AX12: 3 | BA12: 6 | BC12: 15
A13: 6 | B13: FANY BARAKISSA | C13: =+C$3 -> 10 | D13: =+D$3 -> 3 | E13: =+E$3 -> 2 | F13: =+F$3 -> 2 | G13: =+G$3 -> 3 | H13: =+H$3 -> 3 | I13: =+I$3 -> 1 | J13: =+J$3 -> 1 | ... V13: =+V$3 -> 0.15 | W13: 27 | AB13: 1 | AF13: 1 | AG13: 6 | AL13: 1 | AO13: 1 | AP13: 2 | AQ13: 0.33 | AT13: 0.5 | AU13: 1 | AV13: 3 | AW13: 3 | AX13: 3 | BA13: 4 | BC13: 15
A14: 7 | B14: KONAN IVETTE | C14: =+C$3 -> 10 | D14: =+D$3 -> 3 | E14: =+E$3 -> 2 | F14: =+F$3 -> 2 | G14: =+G$3 -> 3 | H14: =+H$3 -> 3 | I14: =+I$3 -> 1 | J14: =+J$3 -> 1 | ... V14: =+V$3 -> 0.15 | W14: 25 | AG14: 5 | AL14: 1 | AN14: 1 | AO14: 1 | AP14: 2 | AQ14: 0.5 | AS14: 0.15 | AT14: 1 | AU14: 1 | AV14: 3 | AW14: 3 | AX14: 3 | BA14: 12 | BC14: 20
A15: 8 | B15: KRA PACOME | C15: =+C$3 -> 10 | D15: =+D$3 -> 3 | E15: =+E$3 -> 2 | F15: =+F$3 -> 2 | G15: =+G$3 -> 3 | H15: =+H$3 -> 3 | I15: =+I$3 -> 1 | J15: =+J$3 -> 1 | ... V15: =+V$3 -> 0.15 | W15: 26 | AF15: 1 | AG15: 7 | AL15: 1 | AO15: 2 | AP15: 3 | AQ15: 0.5 | AT15: 1 | AU15: 2 | AV15: 3 | AW15: 3 | AX15: 3 | BA15: 6 | BC15: 30
A16: 9 | B16: KONATE MARIAM | C16: =+C$3 -> 10 | D16: =+D$3 -> 3 | E16: =+E$3 -> 2 | F16: =+F$3 -> 2 | G16: =+G$3 -> 3 | H16: =+H$3 -> 3 | I16: =+I$3 -> 1 | J16: =+J$3 -> 1 | ... V16: =+V$3 -> 0.15 | W16: 29 | AG16: 5 | AL16: 1 | AN16: 1 | AO16: 1 | AP16: 2 | AQ16: 1 | AS16: 0.3 | AT16: 0.5 | AU16: 1 | AV16: 3 | AW16: 3 | AX16: 3 | BA16: 24 | BC16: 15
A17: 10 | B17: KOUAKOU ROSE | C17: =+C$3 -> 10 | D17: =+D$3 -> 3 | E17: =+E$3 -> 2 | F17: =+F$3 -> 2 | G17: =+G$3 -> 3 | H17: =+H$3 -> 3 | I17: =+I$3 -> 1 | J17: =+J$3 -> 1 | ... V17: =+V$3 -> 0.15 | W17: 26 | AG17: 5 | AL17: 1 | AN17: 1 | AO17: 1 | AP17: 2 | AQ17: 0.5 | AS17: 0.15 | AT17: 0.5 | AU17: 1 | AV17: 3 | AW17: 3 | AX17: 3 | BA17: 12 | BC17: 15
A18: 11 | B18: OULAY WILFRIED | C18: =+C$3 -> 10 | D18: =+D$3 -> 3 | E18: =+E$3 -> 2 | F18: =+F$3 -> 2 | G18: =+G$3 -> 3 | H18: =+H$3 -> 3 | I18: =+I$3 -> 1 | J18: =+J$3 -> 1 | ... V18: =+V$3 -> 0.15 | W18: 29 | AB18: 1 | AF18: 1 | AG18: 4 | AL18: 1 | AP18: 1 | AQ18: 0.67 | AU18: 1 | AV18: 3 | AW18: 3 | AX18: 3 | BA18: 8 | BC18: 10
A19: 12 | B19: NGUESSAN INNOCENT | C19: =+C$3 -> 10 | D19: =+D$3 -> 3 | E19: =+E$3 -> 2 | F19: =+F$3 -> 2 | G19: =+G$3 -> 3 | H19: =+H$3 -> 3 | I19: =+I$3 -> 1 | J19: =+J$3 -> 1 | ... V19: =+V$3 -> 0.15 | W19: 28 | AF19: 2 | AG19: 8 | AL19: 1 | AO19: 2 | AP19: 3 | AQ19: 0.5 | AT19: 1 | AU19: 1.5 | AV19: 3 | AW19: 3 | AX19: 3 | BA19: 6 | BC19: 25
A20: 13 | B20: ARISTIDE KOUAME | C20: =+C$3 -> 10 | D20: =+D$3 -> 3 | E20: =+E$3 -> 2 | F20: =+F$3 -> 2 | G20: =+G$3 -> 3 | H20: =+H$3 -> 3 | I20: =+I$3 -> 1 | J20: =+J$3 -> 1 | ... V20: =+V$3 -> 0.15 | W20: 27 | AB20: 1 | AG20: 6 | AL20: 1 | AN20: 1 | AO20: 1 | AP20: 2 | AQ20: 0.5 | AS20: 0.15 | AT20: 1 | AU20: 1 | AV20: 3 | AW20: 3 | AX20: 3 | BA20: 12 | BC20: 20
A21: 14 | B21: ANGE STEPHANIE | C21: =+C$3 -> 10 | D21: =+D$3 -> 3 | E21: =+E$3 -> 2 | F21: =+F$3 -> 2 | G21: =+G$3 -> 3 | H21: =+H$3 -> 3 | I21: =+I$3 -> 1 | J21: =+J$3 -> 1 | ... V21: =+V$3 -> 0.15 | W21: 30 | AG21: 4 | AL21: 1 | AN21: 1 | AO21: 1 | AP21: 1 | AQ21: 0.5 | AS21: 0.15 | AT21: 1 | AU21: 1 | AV21: 3 | AW21: 3 | AX21: 3 | BA21: 12 | BC21: 20
A22: 15 | B22: KOUADIO FLORENT | C22: =+C$3 -> 10 | D22: =+D$3 -> 3 | E22: =+E$3 -> 2 | F22: =+F$3 -> 2 | G22: =+G$3 -> 3 | H22: =+H$3 -> 3 | I22: =+I$3 -> 1 | J22: =+J$3 -> 1 | ... V22: =+V$3 -> 0.15 | W22: 30 | AC22: 1 | AG22: 6 | AL22: 1 | AN22: 1 | AO22: 1 | AP22: 2 | AQ22: 0.5 | AS22: 0.15 | AT22: 0.5 | AU22: 1 | AV22: 3 | AW22: 3 | AX22: 3 | BA22: 12 | BC22: 15
A23: 16 | B23: SERIE ULRICHE | C23: =+C$3 -> 10 | D23: =+D$3 -> 3 | E23: =+E$3 -> 2 | F23: =+F$3 -> 2 | G23: =+G$3 -> 3 | H23: =+H$3 -> 3 | I23: =+I$3 -> 1 | J23: =+J$3 -> 1 | ... V23: =+V$3 -> 0.15 | W23: 25 | AG23: 4 | AL23: 2 | AP23: 2 | AQ23: 1 | AU23: 1 | AV23: 3 | AW23: 3 | AX23: 3 | BA23: 12 | BC23: 10
A24: 17 | B24: KOADIO SARAH | C24: =+C$3 -> 10 | D24: =+D$3 -> 3 | E24: =+E$3 -> 2 | F24: =+F$3 -> 2 | G24: =+G$3 -> 3 | H24: =+H$3 -> 3 | I24: =+I$3 -> 1 | J24: =+J$3 -> 1 | ... V24: =+V$3 -> 0.15 | W24: 25 | AD24: 1 | AE24: 1 | AG24: 9 | AL24: 1 | AN24: 1 | AO24: 1 | AP24: 4 | AQ24: 0.58 | AS24: 0.15 | AT24: 0.5 | AU24: 2 | AV24: 3 | AW24: 3 | AX24: 3 | BA24: 13 | BC24: 25
A25: 18 | B25: MLEHI ANGE | C25: =+C$3 -> 10 | D25: =+D$3 -> 3 | E25: =+E$3 -> 2 | F25: =+F$3 -> 2 | G25: =+G$3 -> 3 | H25: =+H$3 -> 3 | I25: =+I$3 -> 1 | J25: =+J$3 -> 1 | ... V25: =+V$3 -> 0.15 | W25: 25 | AF25: 2 | AG25: 7 | AL25: 1 | AM25: 2 | AN25: 1 | AP25: 1 | AQ25: 0.67 | AR25: 0.83 | AS25: 0.15 | AU25: 1 | AV25: 3 | AW25: 3 | AX25: 3 | BA25: 24 | BC25: 10
A26: 19 | C26: =+C$3 -> 10 | D26: =+D$3 -> 3 | E26: =+E$3 -> 2 | F26: =+F$3 -> 2 | G26: =+G$3 -> 3 | H26: =+H$3 -> 3 | I26: =+I$3 -> 1 | J26: =+J$3 -> 1 | ... V26: =+V$3 -> 0.15 | AB26: 1
A27: 20 | C27: =+C$3 -> 10 | D27: =+D$3 -> 3 | E27: =+E$3 -> 2 | F27: =+F$3 -> 2 | G27: =+G$3 -> 3 | H27: =+H$3 -> 3 | I27: =+I$3 -> 1 | J27: =+J$3 -> 1 | ... V27: =+V$3 -> 0.15
B28: TOTAL | C28: =SUM(C8:C27) -> 200 | D28: =SUM(D8:D27) -> 60 | E28: =SUM(E8:E27) -> 40 | F28: =SUM(F8:F27) -> 40 | G28: =SUM(G8:G27) -> 60 | H28: =SUM(H8:H27) -> 60 | I28: =SUM(I8:I27) -> 20 | J28: =SUM(J8:J27) -> 20 | ... BE28: =SUM(BE8:BE27) -> 0
AQ30: 11C 2CH | AR30: 5SACH | AS30: 1C 17SACH | AT30: 9C 1CHA | AU30: 22C
AR32: =5/6 -> 0.83333333
AS33: =37/20 -> 1.85

Sheet VEND 23 JANV
A2: SAN PEDRO/ 23/01/2026 | AQ2: 2 | AR2: 3 | AS2: 4 | AT2: 5 | AU2: 6 | AV2: 7 | AW2: 8 | AX2: 9 | AY2: 10 | AZ2: 11
C3: 10 | D3: 3 | E3: 2 | F3: 2 | G3: 3 | H3: 3 | I3: 1 | J3: 1 | K3: 1 | L3: 1 | M3: =+H3 -> 3 | N3: 1 | O3: =+H3 -> 3 | R3: =+(2*M3)/12 -> 0.5 | S3: =+(1*I3)/6 -> 0.16666667 | T3: =+(2*I3)/20 -> 0.1 | U3: =+(2*H3)/10 -> 0.6 | V3: =+(3*I3)/20 -> 0.15 | AQ3: =2/12 -> 0.16666667 | AR3: =3/12 -> 0.25 | AS3: =4/12 -> 0.33333333 | AT3: =5/12 -> 0.41666667 | AU3: =6/12 -> 0.5 | AV3: =7/12 -> 0.58333333 | AW3: =8/12 -> 0.66666667 | AX3: =9/12 -> 0.75 | AY3: =10/12 -> 0.83333333 | AZ3: =11/12 -> 0.91666667
C5: OBJECTIFS JOURNALIERS | W5: REALISATIONS | BD5: Commentaires | BE5: Impressions des PDV et des clients
A6: N° | B6: Agent promoteur | C6: Nombre de visite / Type de PDV | H6: Nombre de référencement / Type de PDV | M6: Pose de matériel de visibilité | R6: Vente en cartons | W6: Nombre de visite / Type de PDV | AB6: Présence produits antérieure | AG6: Nombre de référencement / Type de PDV | AL6: Nouveau Référencement par SKU | AQ6: Vente en cartons | AV6: Pose de matériel de visibilité | BA6: Gratuits offerts en sachet
C7: Boutique | D7: Superette | E7: Kiosque | F7: Tablier | G7: Pushcart | H7: Boutique | I7: Superette | J7: Kiosque | K7: Tablier | L7: Pushcart | M7: Affiche Biblos Lait Prémium 16g & 360g | N7: Affiche Biblos Lait Excellence | O7: Affiche Biblos Flocons d' Avoine | P7: Hanger | Q7: Wobbler | R7: Biblos Lait Premium 16g | S7: Biblos Lait Premium 360g | T7: Biblos Lait Excellence 900g | U7: Biblos Flocon d'avoine 50g | V7: Biblos Flocon d'avoine 400g | W7: Boutique | X7: Superette | Y7: Kiosque | Z7: Tablier | AA7: Pushcart | AB7: Biblos Lait Premium 16g | AC7: Biblos Lait Premium 360g | AD7: Biblos Lait Excellence 900g | AE7: Biblos Flocon d'avoine 50g | AF7: Biblos Flocon d'avoine 400g | AG7: Boutique | AH7: Superette | AI7: Kiosque | AJ7: Tablier | AK7: Pushcart | AL7: Biblos Lait Premium 16g | AM7: Biblos Lait Premium 360g | AN7: Biblos Lait Excellence 900g | AO7: Biblos Flocon d'avoine 50g | AP7: Biblos Flocon d'avoine 400g | AQ7: Biblos Lait Premium 16g | AR7: Biblos Lait Premium 360g | AS7: Biblos Lait Excellence 900g | AT7: Biblos Flocon d'avoine 50g | AU7: Biblos Flocon d'avoine 400g | AV7: Affiche Biblos Lait Prémium 16g & 360g | AW7: Affiche Biblos Lait Excellence | AX7: Affiche Biblos Flocons d' Avoine | AY7: Hanger | AZ7: Wobbler | BA7: Biblos Lait Premium 16g | BB7: Biblos Lait Excellence 900g | BC7: Biblos Flocon d'avoine 50g
A8: 1 | B8: DIBI SIMEON | C8: =+C$3 -> 10 | D8: =+D$3 -> 3 | E8: =+E$3 -> 2 | F8: =+F$3 -> 2 | G8: =+G$3 -> 3 | H8: =+H$3 -> 3 | I8: =+I$3 -> 1 | J8: =+J$3 -> 1 | ... V8: =+V$3 -> 0.15 | W8: 27 | AB8: 1 | AE8: 2 | AG8: 6 | AL8: 2 | AN8: 1 | AO8: 3 | AP8: 3 | AQ8: 0.5 | AS8: 0.3 | AT8: 0.3 | AU8: 3 | AV8: 3 | AW8: 3 | AX8: 3 | BA8: 18 | BC8: 33
A9: 2 | B9: KRA EVAVARISTE | C9: =+C$3 -> 10 | D9: =+D$3 -> 3 | E9: =+E$3 -> 2 | F9: =+F$3 -> 2 | G9: =+G$3 -> 3 | H9: =+H$3 -> 3 | I9: =+I$3 -> 1 | J9: =+J$3 -> 1 | ... V9: =+V$3 -> 0.15 | W9: 27 | AB9: 2 | AD9: 1 | AF9: 1 | AG9: 7 | AL9: 2 | AM9: 1 | AN9: 2 | AO9: 1 | AP9: 4 | AQ9: 0.5 | AR9: 0.5 | AS9: 0.15 | AT9: 1 | AU9: 3 | AV9: 3 | AW9: 3 | AX9: 3 | BA9: 18 | BC9: 40
A10: 3 | B10: DIOMANDE ESTHER | C10: =+C$3 -> 10 | D10: =+D$3 -> 3 | E10: =+E$3 -> 2 | F10: =+F$3 -> 2 | G10: =+G$3 -> 3 | H10: =+H$3 -> 3 | I10: =+I$3 -> 1 | J10: =+J$3 -> 1 | ... V10: =+V$3 -> 0.15 | W10: 24 | AE10: 1 | AF10: 1 | AG10: 5 | AL10: 2 | AN10: 2 | AO10: 1 | AP10: 2 | AQ10: 1 | AS10: 0.3 | AU10: 1 | AV10: 3 | AW10: 3 | AX10: 3 | BA10: 24 | BC10: 10
A11: 4 | B11: BADA LANDRY | C11: =+C$3 -> 10 | D11: =+D$3 -> 3 | E11: =+E$3 -> 2 | F11: =+F$3 -> 2 | G11: =+G$3 -> 3 | H11: =+H$3 -> 3 | I11: =+I$3 -> 1 | J11: =+J$3 -> 1 | ... V11: =+V$3 -> 0.15 | W11: 28 | AB11: 1 | AE11: 1 | AG11: 5 | AL11: 2 | AN11: 1 | AO11: 2 | AP11: 2 | AQ11: 0.5 | AS11: 0.15 | AT11: 0.5 | AU11: 1.5 | AV11: 3 | AW11: 3 | AX11: 3 | BA11: 12 | BC11: 20
A12: 5 | B12: KOUAME JOSE | C12: =+C$3 -> 10 | D12: =+D$3 -> 3 | E12: =+E$3 -> 2 | F12: =+F$3 -> 2 | G12: =+G$3 -> 3 | H12: =+H$3 -> 3 | I12: =+I$3 -> 1 | J12: =+J$3 -> 1 | ... V12: =+V$3 -> 0.15 | W12: 26 | AB12: 2 | AG12: 4 | AL12: 3 | AM12: 1 | AN12: 1 | AP12: 1 | AQ12: 0.33 | AR12: 0.5 | AS12: 0.15 | AU12: 1 | AV12: 3 | AW12: 3 | AX12: 3 | BA12: 16 | BC12: 10
A13: 6 | B13: FANY BARAKISSA | C13: =+C$3 -> 10 | D13: =+D$3 -> 3 | E13: =+E$3 -> 2 | F13: =+F$3 -> 2 | G13: =+G$3 -> 3 | H13: =+H$3 -> 3 | I13: =+I$3 -> 1 | J13: =+J$3 -> 1 | ... V13: =+V$3 -> 0.15 | W13: 25 | AB13: 2 | AE13: 1 | AG13: 4 | AL13: 2 | AN13: 1 | AO13: 2 | AP13: 2 | AS13: 0.15 | AT13: 1 | AU13: 2 | AV13: 3 | AW13: 3 | AX13: 3 | BA13: 6 | BC13: 30
A14: 7 | B14: KONAN IVETTE | C14: =+C$3 -> 10 | D14: =+D$3 -> 3 | E14: =+E$3 -> 2 | F14: =+F$3 -> 2 | G14: =+G$3 -> 3 | H14: =+H$3 -> 3 | I14: =+I$3 -> 1 | J14: =+J$3 -> 1 | ... V14: =+V$3 -> 0.15 | W14: 20 | AC14: 1 | AE14: 1 | AG14: 5 | AL14: 2 | AM14: 1 | AN14: 1 | AO14: 1 | AP14: 2 | AQ14: 1 | AS14: 0.15 | AU14: 2 | AV14: 3 | AW14: 3 | AX14: 3 | BA14: 18 | BC14: 20
A15: 8 | B15: KRA PACOME | C15: =+C$3 -> 10 | D15: =+D$3 -> 3 | E15: =+E$3 -> 2 | F15: =+F$3 -> 2 | G15: =+G$3 -> 3 | H15: =+H$3 -> 3 | I15: =+I$3 -> 1 | J15: =+J$3 -> 1 | ... V15: =+V$3 -> 0.15 | W15: 25 | AD15: 1 | AF15: 1 | AG15: 4 | AL15: 1 | AN15: 2 | AP15: 3 | AQ15: 0.25 | AS15: 0.15 | AU15: 2 | AV15: 3 | AW15: 3 | AX15: 3 | BA15: 9 | BC15: 20
A16: 9 | B16: KONATE MARIAM | C16: =+C$3 -> 10 | D16: =+D$3 -> 3 | E16: =+E$3 -> 2 | F16: =+F$3 -> 2 | G16: =+G$3 -> 3 | H16: =+H$3 -> 3 | I16: =+I$3 -> 1 | J16: =+J$3 -> 1 | ... V16: =+V$3 -> 0.15 | W16: 23 | AB16: 3 | AE16: 2 | AF16: 1 | AG16: 6 | AL16: 2 | AN16: 1 | AO16: 3 | AP16: 4 | AQ16: 1 | AS16: 0.15 | AT16: 0.5 | AU16: 2.5 | AV16: 3 | AW16: 3 | AX16: 3 | BA16: 18 | BC16: 30
A17: 10 | B17: KOUAKOU ROSE | C17: =+C$3 -> 10 | D17: =+D$3 -> 3 | E17: =+E$3 -> 2 | F17: =+F$3 -> 2 | G17: =+G$3 -> 3 | H17: =+H$3 -> 3 | I17: =+I$3 -> 1 | J17: =+J$3 -> 1 | ... V17: =+V$3 -> 0.15 | W17: 20 | AD17: 1 | AG17: 4 | AL17: 1 | AN17: 1 | AO17: 1 | AP17: 2 | AQ17: 0.5 | AS17: 0.15 | AU17: 2 | AV17: 3 | AW17: 3 | AX17: 3 | BA17: 12 | BC17: 20
A18: 11 | B18: OULAY WILFRIED | C18: =+C$3 -> 10 | D18: =+D$3 -> 3 | E18: =+E$3 -> 2 | F18: =+F$3 -> 2 | G18: =+G$3 -> 3 | H18: =+H$3 -> 3 | I18: =+I$3 -> 1 | J18: =+J$3 -> 1 | ... V18: =+V$3 -> 0.15 | W18: 27 | AB18: 1 | AE18: 1 | AG18: 5 | AL18: 2 | AN18: 1 | AO18: 2 | AP18: 2 | AQ18: 0.5 | AS18: 0.15 | AT18: 1 | AU18: 2 | AV18: 3 | AW18: 3 | AX18: 3 | BA18: 12 | BC18: 30
A19: 12 | B19: NGUESSAN INNOCENT | C19: =+C$3 -> 10 | D19: =+D$3 -> 3 | E19: =+E$3 -> 2 | F19: =+F$3 -> 2 | G19: =+G$3 -> 3 | H19: =+H$3 -> 3 | I19: =+I$3 -> 1 | J19: =+J$3 -> 1 | ... V19: =+V$3 -> 0.15 | W19: 25 | AE19: 1 | AG19: 4 | AL19: 1 | AN19: 1 | AO19: 1 | AP19: 2 | AQ19: 0.5 | AS19: =4/20 -> 0.2 | AU19: 1.5 | AV19: 3 | AW19: 3 | AX19: 3 | BA19: 12 | BC19: 15
A20: 13 | B20: ARISTIDE KOUAME | C20: =+C$3 -> 10 | D20: =+D$3 -> 3 | E20: =+E$3 -> 2 | F20: =+F$3 -> 2 | G20: =+G$3 -> 3 | H20: =+H$3 -> 3 | I20: =+I$3 -> 1 | J20: =+J$3 -> 1 | ... V20: =+V$3 -> 0.15 | W20: 23 | AB20: 1 | AD20: 1 | AE20: 2 | AF20: 1 | AG20: 4 | AL20: 2 | AN20: 1 | AO20: 2 | AP20: 3 | AQ20: 0.33 | AS20: 0.15 | AT20: 0.6 | AU20: 2 | AV20: 3 | AW20: 3 | AX20: 3 | BA20: 10 | BC20: 26
A21: 14 | B21: ANGE STEPHANIE | C21: =+C$3 -> 10 | D21: =+D$3 -> 3 | E21: =+E$3 -> 2 | F21: =+F$3 -> 2 | G21: =+G$3 -> 3 | H21: =+H$3 -> 3 | I21: =+I$3 -> 1 | J21: =+J$3 -> 1 | ... V21: =+V$3 -> 0.15 | W21: 26 | AB21: 2 | AG21: 5 | AL21: 2 | AM21: 1 | AN21: 2 | AP21: 2 | AR21: 0.5 | AS21: 0.3 | AU21: 1.5 | AV21: 3 | AW21: 3 | AX21: 3 | BA21: 18 | BC21: 15
A22: 15 | B22: KOUADIO FLORENT | C22: =+C$3 -> 10 | D22: =+D$3 -> 3 | E22: =+E$3 -> 2 | F22: =+F$3 -> 2 | G22: =+G$3 -> 3 | H22: =+H$3 -> 3 | I22: =+I$3 -> 1 | J22: =+J$3 -> 1 | ... V22: =+V$3 -> 0.15 | W22: 24 | AE22: 1 | AF22: 1 | AG22: 5 | AL22: 1 | AN22: 1 | AO22: 2 | AP22: 3 | AQ22: 0.5 | AS22: 0.15 | AT22: 0.5 | AU22: 2 | AV22: 3 | AW22: 3 | AX22: 3 | BA22: 12 | BC22: 25
A23: 16 | B23: SERIE ULRICHE | C23: =+C$3 -> 10 | D23: =+D$3 -> 3 | E23: =+E$3 -> 2 | F23: =+F$3 -> 2 | G23: =+G$3 -> 3 | H23: =+H$3 -> 3 | I23: =+I$3 -> 1 | J23: =+J$3 -> 1 | ... V23: =+V$3 -> 0.15 | W23: 27 | AE23: 1 | AG23: 5 | AL23: 1 | AM23: 1 | AN23: 1 | AO23: 1 | AP23: 2 | AQ23: 0.33 | AR23: =3/6 -> 0.5 | AS23: 0.3 | AU23: 1 | AV23: 3 | AW23: 3 | AX23: 3 | BA23: 22 | BC23: 10
A24: 17 | B24: KOADIO SARAH | C24: =+C$3 -> 10 | D24: =+D$3 -> 3 | E24: =+E$3 -> 2 | F24: =+F$3 -> 2 | G24: =+G$3 -> 3 | H24: =+H$3 -> 3 | I24: =+I$3 -> 1 | J24: =+J$3 -> 1 | ... V24: =+V$3 -> 0.15 | W24: 26 | AB24: 1 | AC24: 1 | AE24: 2 | AF24: 2 | AG24: 5 | AL24: 2 | AM24: 1 | AN24: 1 | AO24: 1 | AP24: 2 | AQ24: 0.42 | AS24: 0.15 | AT24: 0.5 | AU24: 2 | AV24: 3 | AW24: 3 | AX24: 3 | BA24: 11 | BC24: 25
A25: 18 | B25: MLEHI ANGE | C25: =+C$3 -> 10 | D25: =+D$3 -> 3 | E25: =+E$3 -> 2 | F25: =+F$3 -> 2 | G25: =+G$3 -> 3 | H25: =+H$3 -> 3 | I25: =+I$3 -> 1 | J25: =+J$3 -> 1 | ... V25: =+V$3 -> 0.15 | W25: 26 | AB25: 2 | AD25: 1 | AE25: 1 | AF25: 1 | AG25: 4 | AL25: 1 | AN25: 1 | AO25: 1 | AP25: 3 | AQ25: 0.33 | AS25: 0.3 | AU25: 1.5 | AV25: 3 | AW25: 3 | AX25: 3 | BA25: 16 | BC25: 15
A26: 19 | C26: =+C$3 -> 10 | D26: =+D$3 -> 3 | E26: =+E$3 -> 2 | F26: =+F$3 -> 2 | G26: =+G$3 -> 3 | H26: =+H$3 -> 3 | I26: =+I$3 -> 1 | J26: =+J$3 -> 1 | ... V26: =+V$3 -> 0.15
A27: 20 | C27: =+C$3 -> 10 | D27: =+D$3 -> 3 | E27: =+E$3 -> 2 | F27: =+F$3 -> 2 | G27: =+G$3 -> 3 | H27: =+H$3 -> 3 | I27: =+I$3 -> 1 | J27: =+J$3 -> 1 | ... V27: =+V$3 -> 0.15
C28: =SUM(C8:C27) -> 200 | D28: =SUM(D8:D27) -> 60 | E28: =SUM(E8:E27) -> 40 | F28: =SUM(F8:F27) -> 40 | G28: =SUM(G8:G27) -> 60 | H28: =SUM(H8:H27) -> 60 | I28: =SUM(I8:I27) -> 20 | J28: =SUM(J8:J27) -> 20 | ... BE28: =SUM(BE8:BE27) -> 0
AQ30: 8-6ch | AR30: 1c*6 | AS30: 3c-6 | AT30: 5-9ch | AU30: 33,5c
AX34: =12/3 -> 4

Sheet SAM 24 JANV
B2: SAN PEDRO | AO2: 2 | AP2: 3 | AQ2: 4 | AR2: 5 | AS2: 6 | AT2: 7 | AU2: 8 | AV2: 9 | AW2: 10 | AX2: 11
C3: 10 | D3: 3 | E3: 2 | F3: 2 | G3: 3 | H3: 3 | I3: 1 | J3: 1 | K3: 1 | L3: 1 | M3: =+H3 -> 3 | N3: 1 | O3: =+H3 -> 3 | R3: =+(2*M3)/12 -> 0.5 | S3: =+(1*I3)/6 -> 0.16666667 | T3: =+(2*I3)/20 -> 0.1 | U3: =+(2*H3)/10 -> 0.6 | V3: =+(3*I3)/20 -> 0.15 | AO3: =2/12 -> 0.16666667 | AP3: =3/12 -> 0.25 | AQ3: =4/12 -> 0.33333333 | AR3: =5/12 -> 0.41666667 | AS3: =6/12 -> 0.5 | AT3: =7/12 -> 0.58333333 | AU3: =8/12 -> 0.66666667 | AV3: =9/12 -> 0.75 | AW3: =10/12 -> 0.83333333 | AX3: =11/12 -> 0.91666667
C5: OBJECTIFS JOURNALIERS | W5: REALISATIONS | BD5: Commentaires | BE5: Impressions des PDV et des clients
A6: N° | B6: Agent promoteur | C6: Nombre de visite / Type de PDV | H6: Nombre de référencement / Type de PDV | M6: Pose de matériel de visibilité | R6: Vente en cartons | W6: Nombre de visite / Type de PDV | AB6: Présence produits antérieure | AG6: Nombre de référencement / Type de PDV | AL6: Nouveau Référencement par SKU | AQ6: Vente en cartons | AV6: Pose de matériel de visibilité | BA6: Gratuits offerts en sachet
C7: Boutique | D7: Superette | E7: Kiosque | F7: Tablier | G7: Pushcart | H7: Boutique | I7: Superette | J7: Kiosque | K7: Tablier | L7: Pushcart | M7: Affiche Biblos Lait Prémium 16g & 360g | N7: Affiche Biblos Lait Excellence | O7: Affiche Biblos Flocons d' Avoine | P7: Hanger | Q7: Wobbler | R7: Biblos Lait Premium 16g | S7: Biblos Lait Premium 360g | T7: Biblos Lait Excellence 900g | U7: Biblos Flocon d'avoine 50g | V7: Biblos Flocon d'avoine 400g | W7: Boutique | X7: Superette | Y7: Kiosque | Z7: Tablier | AA7: Pushcart | AB7: Biblos Lait Premium 16g | AC7: Biblos Lait Premium 360g | AD7: Biblos Lait Excellence 900g | AE7: Biblos Flocon d'avoine 50g | AF7: Biblos Flocon d'avoine 400g | AG7: Boutique | AH7: Superette | AI7: Kiosque | AJ7: Tablier | AK7: Pushcart | AL7: Biblos Lait Premium 16g | AM7: Biblos Lait Premium 360g | AN7: Biblos Lait Excellence 900g | AO7: Biblos Flocon d'avoine 50g | AP7: Biblos Flocon d'avoine 400g | AQ7: Biblos Lait Premium 16g | AR7: Biblos Lait Premium 360g | AS7: Biblos Lait Excellence 900g | AT7: Biblos Flocon d'avoine 50g | AU7: Biblos Flocon d'avoine 400g | AV7: Affiche Biblos Lait Prémium 16g & 360g | AW7: Affiche Biblos Lait Excellence | AX7: Affiche Biblos Flocons d' Avoine | AY7: Hanger | AZ7: Wobbler | BA7: Biblos Lait Premium 16g | BB7: Biblos Lait Excellence 900g | BC7: Biblos Flocon d'avoine 50g
A8: 1 | B8: DIBI SIMEON | C8: =+C$3 -> 10 | D8: =+D$3 -> 3 | E8: =+E$3 -> 2 | F8: =+F$3 -> 2 | G8: =+G$3 -> 3 | H8: =+H$3 -> 3 | I8: =+I$3 -> 1 | J8: =+J$3 -> 1 | ... V8: =+V$3 -> 0.15 | W8: 24 | AD8: 1 | AF8: 1 | AG8: 4 | AL8: 1 | AM8: 1 | AN8: 2 | AP8: 2 | AQ8: 1 | AR8: 0.33 | AS8: 0.15 | AU8: 1 | AV8: 3 | AW8: 3 | AX8: 3 | BA8: 22 | BC8: 10
A9: 2 | B9: KRA EVAVARISTE | C9: =+C$3 -> 10 | D9: =+D$3 -> 3 | E9: =+E$3 -> 2 | F9: =+F$3 -> 2 | G9: =+G$3 -> 3 | H9: =+H$3 -> 3 | I9: =+I$3 -> 1 | J9: =+J$3 -> 1 | ... V9: =+V$3 -> 0.15 | W9: 29 | AB9: 1 | AE9: 1 | AG9: 6 | AL9: 1 | AN9: 1 | AO9: 1 | AP9: 4 | AS9: 0.3 | AT9: 1 | AU9: 3 | AV9: 3 | AW9: 3 | AX9: 3 | BA9: 12 | BC9: 40
A10: 3 | B10: DIOMANDE ESTHER | C10: =+C$3 -> 10 | D10: =+D$3 -> 3 | E10: =+E$3 -> 2 | F10: =+F$3 -> 2 | G10: =+G$3 -> 3 | H10: =+H$3 -> 3 | I10: =+I$3 -> 1 | J10: =+J$3 -> 1 | ... V10: =+V$3 -> 0.15 | W10: 25 | AD10: 1 | AE10: 1 | AG10: 4 | AL10: 2 | AN10: 2 | AO10: 1 | AP10: 1 | AQ10: 1.5 | AS10: 0.3 | AU10: 1 | AV10: 3 | AW10: 3 | AX10: 3 | BA10: 30 | BC10: 10
A11: 4 | B11: BADA LANDRY | C11: =+C$3 -> 10 | D11: =+D$3 -> 3 | E11: =+E$3 -> 2 | F11: =+F$3 -> 2 | G11: =+G$3 -> 3 | H11: =+H$3 -> 3 | I11: =+I$3 -> 1 | J11: =+J$3 -> 1 | ... V11: =+V$3 -> 0.15 | W11: 27 | AB11: 2 | AF11: 1 | AG11: 5 | AL11: 3 | AN11: 1 | AO11: 1 | AP11: 3 | AQ11: 0.5 | AS11: 0.15 | AT11: 0.5 | AU11: 2 | AV11: 3 | AW11: 3 | AX11: 3 | BA11: 12 | BC11: 25
A12: 5 | B12: KOUAME JOSE | C12: =+C$3 -> 10 | D12: =+D$3 -> 3 | E12: =+E$3 -> 2 | F12: =+F$3 -> 2 | G12: =+G$3 -> 3 | H12: =+H$3 -> 3 | I12: =+I$3 -> 1 | J12: =+J$3 -> 1 | ... V12: =+V$3 -> 0.15 | W12: 26 | AC12: 1 | AE12: 1 | AG12: 2 | AM12: 1 | AN12: 1 | AO12: 1 | AP12: 1 | AS12: 0.3 | AU12: 1 | AV12: 3 | AW12: 3 | AX12: 3 | BA12: 12 | BC12: 10
A13: 6 | B13: FANY BARAKISSA | C13: =+C$3 -> 10 | D13: =+D$3 -> 3 | E13: =+E$3 -> 2 | F13: =+F$3 -> 2 | G13: =+G$3 -> 3 | H13: =+H$3 -> 3 | I13: =+I$3 -> 1 | J13: =+J$3 -> 1 | ... V13: =+V$3 -> 0.15 | W13: 23 | AB13: 1 | AF13: 1 | AG13: 4 | AL13: 2 | AN13: 1 | AP13: 3 | AQ13: 1 | AS13: 0.15 | AU13: 1 | AV13: 3 | AW13: 3 | AX13: 3 | BA13: 18 | BC13: 10
A14: 7 | B14: KONAN IVETTE | C14: =+C$3 -> 10 | D14: =+D$3 -> 3 | E14: =+E$3 -> 2 | F14: =+F$3 -> 2 | G14: =+G$3 -> 3 | H14: =+H$3 -> 3 | I14: =+I$3 -> 1 | J14: =+J$3 -> 1 | ... V14: =+V$3 -> 0.15 | W14: 21 | AG14: 2 | AN14: 1 | AP14: 1 | AS14: 0.15 | AU14: 1 | AV14: 3 | AW14: 3 | AX14: 3 | BA14: 6 | BC14: 10
A15: 8 | B15: KRA PACOME | C15: =+C$3 -> 10 | D15: =+D$3 -> 3 | E15: =+E$3 -> 2 | F15: =+F$3 -> 2 | G15: =+G$3 -> 3 | H15: =+H$3 -> 3 | I15: =+I$3 -> 1 | J15: =+J$3 -> 1 | ... V15: =+V$3 -> 0.15 | W15: 28 | AB15: 1 | AD15: 1 | AE15: 1 | AG15: 5 | AL15: 1 | AN15: 2 | AO15: 2 | AP15: 2 | AQ15: 0.5 | AS15: 0.3 | AT15: 0.5 | AU15: 2 | AV15: 3 | AW15: 3 | AX15: 3 | BA15: 18 | BC15: 25
A16: 9 | B16: KONATE MARIAM | C16: =+C$3 -> 10 | D16: =+D$3 -> 3 | E16: =+E$3 -> 2 | F16: =+F$3 -> 2 | G16: =+G$3 -> 3 | H16: =+H$3 -> 3 | I16: =+I$3 -> 1 | J16: =+J$3 -> 1 | ... V16: =+V$3 -> 0.15 | W16: 24 | AF16: 1 | AG16: 4 | AL16: 1 | AN16: 1 | AP16: 3 | AQ16: 0.5 | AS16: 0.15 | AU16: 1.5 | AV16: 3 | AW16: 3 | AX16: 3 | BA16: 12 | BC16: 15
A17: 10 | B17: KOUAKOU ROSE | C17: =+C$3 -> 10 | D17: =+D$3 -> 3 | E17: =+E$3 -> 2 | F17: =+F$3 -> 2 | G17: =+G$3 -> 3 | H17: =+H$3 -> 3 | I17: =+I$3 -> 1 | J17: =+J$3 -> 1 | ... V17: =+V$3 -> 0.15 | W17: 25 | AB17: 2 | AE17: 1 | AG17: 3 | AL17: 2 | AN17: 1 | AO17: 1 | AP17: 1 | AS17: 0.3 | AT17: 0.5 | AU17: 1 | AV17: 3 | AW17: 3 | AX17: 3 | BA17: 12 | BC17: 15
A18: 11 | B18: OULAY WILFRIED | C18: =+C$3 -> 10 | D18: =+D$3 -> 3 | E18: =+E$3 -> 2 | F18: =+F$3 -> 2 | G18: =+G$3 -> 3 | H18: =+H$3 -> 3 | I18: =+I$3 -> 1 | J18: =+J$3 -> 1 | ... V18: =+V$3 -> 0.15 | W18: 27 | AD18: 1 | AG18: 4 | AL18: 1 | AN18: 2 | AP18: 2 | AQ18: 0.5 | AS18: 0.15 | AU18: 1.5 | AV18: 3 | AW18: 3 | AX18: 3 | BA18: 12 | BC18: 15
A19: 12 | B19: NGUESSAN INNOCENT | C19: =+C$3 -> 10 | D19: =+D$3 -> 3 | E19: =+E$3 -> 2 | F19: =+F$3 -> 2 | G19: =+G$3 -> 3 | H19: =+H$3 -> 3 | I19: =+I$3 -> 1 | J19: =+J$3 -> 1 | ... V19: =+V$3 -> 0.15 | W19: 26 | AE19: 2 | AF19: 1 | AG19: 4 | AL19: 1 | AN19: 1 | AO19: 2 | AP19: 3 | AQ19: 1 | AS19: 0.15 | AU19: 2 | AV19: 3 | AW19: 3 | AX19: 3 | BA19: 18 | BC19: 20
A20: 13 | B20: ARISTIDE KOUAME | C20: =+C$3 -> 10 | D20: =+D$3 -> 3 | E20: =+E$3 -> 2 | F20: =+F$3 -> 2 | G20: =+G$3 -> 3 | H20: =+H$3 -> 3 | I20: =+I$3 -> 1 | J20: =+J$3 -> 1 | ... V20: =+V$3 -> 0.15 | W20: 26 | AB20: 1 | AG20: 4 | AL20: 1 | AN20: 1 | AP20: 2 | AQ20: 0.5 | AS20: 0.15 | AU20: 1.5 | AV20: 3 | AW20: 3 | AX20: 3 | BA20: 12 | BC20: 15
A21: 14 | B21: ANGE STEPHANIE | C21: =+C$3 -> 10 | D21: =+D$3 -> 3 | E21: =+E$3 -> 2 | F21: =+F$3 -> 2 | G21: =+G$3 -> 3 | H21: =+H$3 -> 3 | I21: =+I$3 -> 1 | J21: =+J$3 -> 1 | ... V21: =+V$3 -> 0.15 | W21: 27 | AE21: 2 | AF21: 1 | AG21: 6 | AL21: 1 | AN21: 1 | AO21: 1 | AP21: 5 | AQ21: 0.5 | AS21: 0.15 | AU21: 3 | AV21: 3 | AW21: 3 | AX21: 3 | BA21: 12 | BC21: 30
A22: 15 | B22: KOUADIO FLORENT | C22: =+C$3 -> 10 | D22: =+D$3 -> 3 | E22: =+E$3 -> 2 | F22: =+F$3 -> 2 | G22: =+G$3 -> 3 | H22: =+H$3 -> 3 | I22: =+I$3 -> 1 | J22: =+J$3 -> 1 | ... V22: =+V$3 -> 0.15 | W22: 27 | AB22: 1 | AC22: 1 | AF22: 1 | AG22: 3 | AL22: 2 | AM22: 1 | AN22: 1 | AP22: 1 | AQ22: 1 | AS22: 0.15 | AU22: 1 | AV22: 3 | AW22: 3 | AX22: 3 | BA22: 18 | BC22: 10
A23: 16 | B23: SERIE ULRICHE | C23: =+C$3 -> 10 | D23: =+D$3 -> 3 | E23: =+E$3 -> 2 | F23: =+F$3 -> 2 | G23: =+G$3 -> 3 | H23: =+H$3 -> 3 | I23: =+I$3 -> 1 | J23: =+J$3 -> 1 | ... V23: =+V$3 -> 0.15 | W23: 24 | AB23: 1 | AD23: 1 | AE23: 1 | AF23: 1 | AG23: 5 | AL23: 2 | AN23: 1 | AO23: 2 | AP23: 2 | AQ23: 0.5 | AS23: 0.3 | AT23: 0.5 | AU23: 2 | AV23: 3 | AW23: 3 | AX23: 3 | BA23: 18 | BC23: 25
A24: 17 | B24: KOADIO SARAH | C24: =+C$3 -> 10 | D24: =+D$3 -> 3 | E24: =+E$3 -> 2 | F24: =+F$3 -> 2 | G24: =+G$3 -> 3 | H24: =+H$3 -> 3 | I24: =+I$3 -> 1 | J24: =+J$3 -> 1 | ... V24: =+V$3 -> 0.15 | W24: 26 | AE24: 2 | AG24: 3 | AM24: 1 | AN24: 1 | AO24: 2 | AP24: 1 | AR24: 0.5 | AS24: 0.15 | AU24: 1 | AV24: 3 | AW24: 3 | AX24: 3 | BA24: 12 | BC24: 10
A25: 18 | B25: MLEHI ANGE | C25: =+C$3 -> 10 | D25: =+D$3 -> 3 | E25: =+E$3 -> 2 | F25: =+F$3 -> 2 | G25: =+G$3 -> 3 | H25: =+H$3 -> 3 | I25: =+I$3 -> 1 | J25: =+J$3 -> 1 | ... V25: =+V$3 -> 0.15 | W25: 27 | AB25: 1 | AE25: 1 | AG25: 4 | AL25: 2 | AN25: 1 | AO25: 1 | AP25: 2 | AQ25: 0.5 | AS25: 0.15 | AU25: 1.5 | AV25: 3 | AW25: 3 | AX25: 3 | BA25: 12 | BC25: 15
A26: 19 | C26: =+C$3 -> 10 | D26: =+D$3 -> 3 | E26: =+E$3 -> 2 | F26: =+F$3 -> 2 | G26: =+G$3 -> 3 | H26: =+H$3 -> 3 | I26: =+I$3 -> 1 | J26: =+J$3 -> 1 | ... V26: =+V$3 -> 0.15
A27: 20 | C27: =+C$3 -> 10 | D27: =+D$3 -> 3 | E27: =+E$3 -> 2 | F27: =+F$3 -> 2 | G27: =+G$3 -> 3 | H27: =+H$3 -> 3 | I27: =+I$3 -> 1 | J27: =+J$3 -> 1 | ... V27: =+V$3 -> 0.15
B28: TOTAL | C28: =SUM(C8:C27) -> 200 | D28: =SUM(D8:D27) -> 60 | E28: =SUM(E8:E27) -> 40 | F28: =SUM(F8:F27) -> 40 | G28: =SUM(G8:G27) -> 60 | H28: =SUM(H8:H27) -> 60 | I28: =SUM(I8:I27) -> 20 | J28: =SUM(J8:J27) -> 20 | ... BE28: =SUM(BE8:BE27) -> 0
AQ30: 9c* 6ch | AR30: 5sach | AS30: 3c*12 sa | AT30: 3ct | AU30: 28ct

Sheet LUND 26 JANV
B2: SAN PEDRO | AP2: 2 | AQ2: 3 | AR2: 4 | AS2: 5 | AT2: 6 | AU2: 7 | AV2: 8 | AW2: 9 | AX2: 10 | AY2: 11
C3: 10 | D3: 3 | E3: 2 | F3: 2 | G3: 3 | H3: 3 | I3: 1 | J3: 1 | K3: 1 | L3: 1 | M3: =+H3 -> 3 | N3: 1 | O3: =+H3 -> 3 | R3: =+(2*M3)/12 -> 0.5 | S3: =+(1*I3)/6 -> 0.16666667 | T3: =+(2*I3)/20 -> 0.1 | U3: =+(2*H3)/10 -> 0.6 | V3: =+(3*I3)/20 -> 0.15 | AP3: =2/12 -> 0.16666667 | AQ3: =3/12 -> 0.25 | AR3: =4/12 -> 0.33333333 | AS3: =5/12 -> 0.41666667 | AT3: =6/12 -> 0.5 | AU3: =7/12 -> 0.58333333 | AV3: =8/12 -> 0.66666667 | AW3: =9/12 -> 0.75 | AX3: =10/12 -> 0.83333333 | AY3: =11/12 -> 0.91666667
C5: OBJECTIFS JOURNALIERS | W5: REALISATIONS | BD5: Commentaires | BE5: Impressions des PDV et des clients
A6: N° | B6: Agent promoteur | C6: Nombre de visite / Type de PDV | H6: Nombre de référencement / Type de PDV | M6: Pose de matériel de visibilité | R6: Vente en cartons | W6: Nombre de visite / Type de PDV | AB6: Présence produits antérieure | AG6: Nombre de référencement / Type de PDV | AL6: Nouveau Référencement par SKU | AQ6: Vente en cartons | AV6: Pose de matériel de visibilité | BA6: Gratuits offerts en sachet
C7: Boutique | D7: Superette | E7: Kiosque | F7: Tablier | G7: Pushcart | H7: Boutique | I7: Superette | J7: Kiosque | K7: Tablier | L7: Pushcart | M7: Affiche Biblos Lait Prémium 16g & 360g | N7: Affiche Biblos Lait Excellence | O7: Affiche Biblos Flocons d' Avoine | P7: Hanger | Q7: Wobbler | R7: Biblos Lait Premium 16g | S7: Biblos Lait Premium 360g | T7: Biblos Lait Excellence 900g | U7: Biblos Flocon d'avoine 50g | V7: Biblos Flocon d'avoine 400g | W7: Boutique | X7: Superette | Y7: Kiosque | Z7: Tablier | AA7: Pushcart | AB7: Biblos Lait Premium 16g | AC7: Biblos Lait Premium 360g | AD7: Biblos Lait Excellence 900g | AE7: Biblos Flocon d'avoine 50g | AF7: Biblos Flocon d'avoine 400g | AG7: Boutique | AH7: Superette | AI7: Kiosque | AJ7: Tablier | AK7: Pushcart | AL7: Biblos Lait Premium 16g | AM7: Biblos Lait Premium 360g | AN7: Biblos Lait Excellence 900g | AO7: Biblos Flocon d'avoine 50g | AP7: Biblos Flocon d'avoine 400g | AQ7: Biblos Lait Premium 16g | AR7: Biblos Lait Premium 360g | AS7: Biblos Lait Excellence 900g | AT7: Biblos Flocon d'avoine 50g | AU7: Biblos Flocon d'avoine 400g | AV7: Affiche Biblos Lait Prémium 16g & 360g | AW7: Affiche Biblos Lait Excellence | AX7: Affiche Biblos Flocons d' Avoine | AY7: Hanger | AZ7: Wobbler | BA7: Biblos Lait Premium 16g | BB7: Biblos Lait Excellence 900g | BC7: Biblos Flocon d'avoine 50g
A8: 1 | B8: DIBI SIMEON | C8: =+C$3 -> 10 | D8: =+D$3 -> 3 | E8: =+E$3 -> 2 | F8: =+F$3 -> 2 | G8: =+G$3 -> 3 | H8: =+H$3 -> 3 | I8: =+I$3 -> 1 | J8: =+J$3 -> 1 | ... V8: =+V$3 -> 0.15 | W8: 25 | AE8: 1 | AF8: 1 | AG8: 3 | AL8: 1 | AN8: 1 | AO8: 1 | AP8: 2 | AQ8: 0.5 | AS8: 0.15 | AU8: 1 | AV8: 3 | AW8: 3 | AX8: 3 | BA8: 12 | BC8: 10
A9: 2 | B9: KRA EVAVARISTE | C9: =+C$3 -> 10 | D9: =+D$3 -> 3 | E9: =+E$3 -> 2 | F9: =+F$3 -> 2 | G9: =+G$3 -> 3 | H9: =+H$3 -> 3 | I9: =+I$3 -> 1 | J9: =+J$3 -> 1 | ... V9: =+V$3 -> 0.15 | W9: 20 | AB9: 1 | AE9: 1 | AG9: 5 | AL9: 1 | AO9: 2 | AP9: 2 | AQ9: 0.5 | AT9: 0.5 | AU9: 2 | AV9: 3 | AW9: 3 | AX9: 3 | BA9: 6 | BC9: 25
A10: 3 | B10: DIOMANDE ESTHER | C10: =+C$3 -> 10 | D10: =+D$3 -> 3 | E10: =+E$3 -> 2 | F10: =+F$3 -> 2 | G10: =+G$3 -> 3 | H10: =+H$3 -> 3 | I10: =+I$3 -> 1 | J10: =+J$3 -> 1 | ... V10: =+V$3 -> 0.15 | W10: 22 | AB10: 1 | AG10: 4 | AL10: 1 | AN10: 1 | AP10: 2 | AQ10: 0.5 | AS10: 0.15 | AU10: 1 | AV10: 3 | AW10: 3 | AX10: 3 | BA10: 12 | BC10: 10
A11: 4 | B11: BADA LANDRY | C11: =+C$3 -> 10 | D11: =+D$3 -> 3 | E11: =+E$3 -> 2 | F11: =+F$3 -> 2 | G11: =+G$3 -> 3 | H11: =+H$3 -> 3 | I11: =+I$3 -> 1 | J11: =+J$3 -> 1 | ... V11: =+V$3 -> 0.15 | W11: 24 | AE11: 1 | AF11: 1 | AG11: 4 | AL11: 1 | AO11: 2 | AP11: 3 | AQ11: 0.5 | AT11: 0.5 | AU11: 2 | AV11: 3 | AW11: 3 | AX11: 3 | BA11: 6 | BC11: 25
A12: 5 | B12: KOUAME JOSE | C12: =+C$3 -> 10 | D12: =+D$3 -> 3 | E12: =+E$3 -> 2 | F12: =+F$3 -> 2 | G12: =+G$3 -> 3 | H12: =+H$3 -> 3 | I12: =+I$3 -> 1 | J12: =+J$3 -> 1 | ... V12: =+V$3 -> 0.15 | W12: 20 | AG12: 4 | AL12: 1 | AO12: 1 | AP12: 2 | AQ12: 0.5 | AT12: 0.5 | AU12: 2 | AV12: 3 | AW12: 3 | AX12: 3 | BA12: 6 | BC12: 25
A13: 6 | B13: FANY BARAKISSA | C13: =+C$3 -> 10 | D13: =+D$3 -> 3 | E13: =+E$3 -> 2 | F13: =+F$3 -> 2 | G13: =+G$3 -> 3 | H13: =+H$3 -> 3 | I13: =+I$3 -> 1 | J13: =+J$3 -> 1 | ... V13: =+V$3 -> 0.15 | W13: 20 | AB13: 1 | AC13: 1 | AE13: 1 | AF13: 1 | AG13: 3 | AL13: 1 | AN13: 1 | AO13: 1 | AP13: 2 | AQ13: 0.5 | AS13: 0.15 | AU13: 1 | AV13: 3 | AW13: 3 | AX13: 3 | BA13: 12 | BC13: 10
A14: 7 | B14: KONAN IVETTE | C14: =+C$3 -> 10 | D14: =+D$3 -> 3 | E14: =+E$3 -> 2 | F14: =+F$3 -> 2 | G14: =+G$3 -> 3 | H14: =+H$3 -> 3 | I14: =+I$3 -> 1 | J14: =+J$3 -> 1 | ... V14: =+V$3 -> 0.15 | W14: 20 | AB14: 1 | AE14: 2 | AG14: 4 | AL14: 1 | AO14: 3 | AP14: 2 | AQ14: 0.5 | AT14: 0.5 | AU14: 2 | AV14: 3 | AW14: 3 | AX14: 3 | BA14: 6 | BC14: 25
A15: 8 | B15: KRA PACOME | C15: =+C$3 -> 10 | D15: =+D$3 -> 3 | E15: =+E$3 -> 2 | F15: =+F$3 -> 2 | G15: =+G$3 -> 3 | H15: =+H$3 -> 3 | I15: =+I$3 -> 1 | J15: =+J$3 -> 1 | ... V15: =+V$3 -> 0.15 | W15: 23 | AD15: 1 | AF15: 1 | AG15: 4 | AL15: 1 | AM15: 1 | AO15: 1 | AP15: 3 | AQ15: 0.5 | AT15: 0.5 | AU15: 2 | AV15: 3 | AW15: 3 | AX15: 3 | BA15: 6 | BC15: 25
A16: 9 | B16: KONATE MARIAM | C16: =+C$3 -> 10 | D16: =+D$3 -> 3 | E16: =+E$3 -> 2 | F16: =+F$3 -> 2 | G16: =+G$3 -> 3 | H16: =+H$3 -> 3 | I16: =+I$3 -> 1 | J16: =+J$3 -> 1 | ... V16: =+V$3 -> 0.15 | W16: 20 | AB16: 2 | AE16: 1 | AG16: 4 | AL16: 1 | AO16: 2 | AP16: 2 | AQ16: 0.5 | AT16: 0.5 | AU16: 2 | AV16: 3 | AW16: 3 | AX16: 3 | BA16: 6 | BC16: 25
A17: 10 | B17: KOUAKOU ROSE | C17: =+C$3 -> 10 | D17: =+D$3 -> 3 | E17: =+E$3 -> 2 | F17: =+F$3 -> 2 | G17: =+G$3 -> 3 | H17: =+H$3 -> 3 | I17: =+I$3 -> 1 | J17: =+J$3 -> 1 | ... V17: =+V$3 -> 0.15 | W17: 24 | AE17: 1 | AG17: 5 | AL17: 1 | AO17: 2 | AP17: 3 | AQ17: 0.5 | AT17: 1 | AU17: 2 | AV17: 3 | AW17: 3 | AX17: 3 | BA17: 6 | BC17: 30
A18: 11 | B18: OULAY WILFRIED | C18: =+C$3 -> 10 | D18: =+D$3 -> 3 | E18: =+E$3 -> 2 | F18: =+F$3 -> 2 | G18: =+G$3 -> 3 | H18: =+H$3 -> 3 | I18: =+I$3 -> 1 | J18: =+J$3 -> 1 | ... V18: =+V$3 -> 0.15 | W18: 20 | AB18: 1 | AG18: 5 | AL18: 1 | AM18: 1 | AO18: 1 | AP18: 2 | AQ18: 0.5 | AR18: 0.5 | AT18: 0.5 | AU18: 2 | AV18: 3 | AW18: 3 | AX18: 3 | BA18: 12 | BC18: 25
A19: 12 | B19: NGUESSAN INNOCENT | C19: =+C$3 -> 10 | D19: =+D$3 -> 3 | E19: =+E$3 -> 2 | F19: =+F$3 -> 2 | G19: =+G$3 -> 3 | H19: =+H$3 -> 3 | I19: =+I$3 -> 1 | J19: =+J$3 -> 1 | ... V19: =+V$3 -> 0.15 | W19: 21 | AE19: 1 | AF19: 1 | AG19: 4 | AL19: 1 | AN19: 1 | AO19: 1 | AP19: 2 | AQ19: 0.5 | AS19: =4/20 -> 0.2 | AU19: 1.5 | AV19: 3 | AW19: 3 | AX19: 3 | BA19: 12 | BC19: 15
A20: 13 | B20: ARISTIDE KOUAME | C20: =+C$3 -> 10 | D20: =+D$3 -> 3 | E20: =+E$3 -> 2 | F20: =+F$3 -> 2 | G20: =+G$3 -> 3 | H20: =+H$3 -> 3 | I20: =+I$3 -> 1 | J20: =+J$3 -> 1 | ... V20: =+V$3 -> 0.15 | W20: 23 | AB20: 1 | AD20: 1 | AE20: 1 | AG20: 4 | AL20: 1 | AN20: 1 | AO20: 2 | AP20: 2 | AQ20: 0.5 | AT20: 0.5 | AU20: 1.5 | AV20: 3 | AW20: 3 | AX20: 3 | BA20: 6 | BC20: 20
A21: 14 | B21: ANGE STEPHANIE | C21: =+C$3 -> 10 | D21: =+D$3 -> 3 | E21: =+E$3 -> 2 | F21: =+F$3 -> 2 | G21: =+G$3 -> 3 | H21: =+H$3 -> 3 | I21: =+I$3 -> 1 | J21: =+J$3 -> 1 | ... V21: =+V$3 -> 0.15 | W21: 22 | AC21: 1 | AF21: 1 | AG21: 3 | AL21: 2 | AP21: 2 | AQ21: 0.5 | AU21: 2 | AV21: 3 | AW21: 3 | AX21: 3 | BA21: 6 | BC21: 20
A22: 15 | B22: KOUADIO FLORENT | C22: =+C$3 -> 10 | D22: =+D$3 -> 3 | E22: =+E$3 -> 2 | F22: =+F$3 -> 2 | G22: =+G$3 -> 3 | H22: =+H$3 -> 3 | I22: =+I$3 -> 1 | J22: =+J$3 -> 1 | ... V22: =+V$3 -> 0.15 | W22: 22 | AG22: 4 | AL22: 1 | AO22: 1 | AP22: 2 | AQ22: 0.5 | AT22: 1 | AU22: 2 | AV22: 3 | AW22: 3 | AX22: 3 | BA22: 6 | BC22: 30
A23: 16 | B23: SERIE ULRICHE | C23: =+C$3 -> 10 | D23: =+D$3 -> 3 | E23: =+E$3 -> 2 | F23: =+F$3 -> 2 | G23: =+G$3 -> 3 | H23: =+H$3 -> 3 | I23: =+I$3 -> 1 | J23: =+J$3 -> 1 | ... V23: =+V$3 -> 0.15 | W23: 21 | AB23: 1 | AE23: 1 | AG23: 4 | AL23: 1 | AM23: 1 | AO23: 2 | AP23: 1 | AQ23: 1 | AR23: 0.5 | AT23: 0.5 | AU23: 0.5 | AV23: 3 | AW23: 3 | AX23: 3 | BA23: 18 | BC23: 10
A24: 17 | B24: KOADIO SARAH | C24: =+C$3 -> 10 | D24: =+D$3 -> 3 | E24: =+E$3 -> 2 | F24: =+F$3 -> 2 | G24: =+G$3 -> 3 | H24: =+H$3 -> 3 | I24: =+I$3 -> 1 | J24: =+J$3 -> 1 | ... V24: =+V$3 -> 0.15 | W24: 22 | AE24: 2 | AG24: 2 | AN24: 1 | AO24: 2 | AP24: 1 | AS24: 0.5 | AU24: 1 | AV24: 3 | AW24: 3 | AX24: 3 | BA24: 6 | BC24: 10
A25: 18 | B25: MLEHI ANGE | C25: =+C$3 -> 10 | D25: =+D$3 -> 3 | E25: =+E$3 -> 2 | F25: =+F$3 -> 2 | G25: =+G$3 -> 3 | H25: =+H$3 -> 3 | I25: =+I$3 -> 1 | J25: =+J$3 -> 1 | ... V25: =+V$3 -> 0.15 | W25: 24 | AB25: 1 | AC25: 1 | AE25: 1 | AF25: 1 | AG25: 4 | AL25: 2 | AO25: 2 | AP25: 3 | AQ25: 0.5 | AT25: 0.5 | AU25: 1.5 | AV25: 3 | AW25: 3 | AX25: 3 | BA25: 6 | BC25: 20
A26: 19 | C26: =+C$3 -> 10 | D26: =+D$3 -> 3 | E26: =+E$3 -> 2 | F26: =+F$3 -> 2 | G26: =+G$3 -> 3 | H26: =+H$3 -> 3 | I26: =+I$3 -> 1 | J26: =+J$3 -> 1 | ... V26: =+V$3 -> 0.15
A27: 20 | C27: =+C$3 -> 10 | D27: =+D$3 -> 3 | E27: =+E$3 -> 2 | F27: =+F$3 -> 2 | G27: =+G$3 -> 3 | H27: =+H$3 -> 3 | I27: =+I$3 -> 1 | J27: =+J$3 -> 1 | ... V27: =+V$3 -> 0.15
B28: TOTAL | C28: =SUM(C8:C27) -> 200 | D28: =SUM(D8:D27) -> 60 | E28: =SUM(E8:E27) -> 40 | F28: =SUM(F8:F27) -> 40 | G28: =SUM(G8:G27) -> 60 | H28: =SUM(H8:H27) -> 60 | I28: =SUM(I8:I27) -> 20 | J28: =SUM(J8:J27) -> 20 | ... BE28: =SUM(BE8:BE27) -> 0
AQ30: 9 | AR30: 1 | AS30: 1*3sa | AT30: 7 | AU30: 29
AS33: =23/20 -> 1.15

Sheet MAR 27 JANV
AP1: 2 | AQ1: 3 | AR1: 4 | AS1: 5 | AT1: 6 | AU1: 7 | AV1: 8 | AW1: 9 | AX1: 10 | AY1: 11
B2: SAN PEDRO | AP2: =2/12 -> 0.16666667 | AQ2: =3/12 -> 0.25 | AR2: =4/12 -> 0.33333333 | AS2: =5/12 -> 0.41666667 | AT2: =6/12 -> 0.5 | AU2: =7/12 -> 0.58333333 | AV2: =8/12 -> 0.66666667 | AW2: =9/12 -> 0.75 | AX2: =10/12 -> 0.83333333 | AY2: =11/12 -> 0.91666667
C3: 10 | D3: 3 | E3: 2 | F3: 2 | G3: 3 | H3: 3 | I3: 1 | J3: 1 | K3: 1 | L3: 1 | M3: =+H3 -> 3 | N3: 1 | O3: =+H3 -> 3 | R3: =+(2*M3)/12 -> 0.5 | S3: =+(1*I3)/6 -> 0.16666667 | T3: =+(2*I3)/20 -> 0.1 | U3: =+(2*H3)/10 -> 0.6 | V3: =+(3*I3)/20 -> 0.15
C5: OBJECTIFS JOURNALIERS | W5: REALISATIONS | BD5: Commentaires | BE5: Impressions des PDV et des clients
A6: N° | B6: Agent promoteur | C6: Nombre de visite / Type de PDV | H6: Nombre de référencement / Type de PDV | M6: Pose de matériel de visibilité | R6: Vente en cartons | W6: Nombre de visite / Type de PDV | AB6: Présence produits antérieure | AG6: Nombre de référencement / Type de PDV | AL6: Nouveau Référencement par SKU | AQ6: Vente en cartons | AV6: Pose de matériel de visibilité | BA6: Gratuits offerts en sachet
C7: Boutique | D7: Superette | E7: Kiosque | F7: Tablier | G7: Pushcart | H7: Boutique | I7: Superette | J7: Kiosque | K7: Tablier | L7: Pushcart | M7: Affiche Biblos Lait Prémium 16g & 360g | N7: Affiche Biblos Lait Excellence | O7: Affiche Biblos Flocons d' Avoine | P7: Hanger | Q7: Wobbler | R7: Biblos Lait Premium 16g | S7: Biblos Lait Premium 360g | T7: Biblos Lait Excellence 900g | U7: Biblos Flocon d'avoine 50g | V7: Biblos Flocon d'avoine 400g | W7: Boutique | X7: Superette | Y7: Kiosque | Z7: Tablier | AA7: Pushcart | AB7: Biblos Lait Premium 16g | AC7: Biblos Lait Premium 360g | AD7: Biblos Lait Excellence 900g | AE7: Biblos Flocon d'avoine 50g | AF7: Biblos Flocon d'avoine 400g | AG7: Boutique | AH7: Superette | AI7: Kiosque | AJ7: Tablier | AK7: Pushcart | AL7: Biblos Lait Premium 16g | AM7: Biblos Lait Premium 360g | AN7: Biblos Lait Excellence 900g | AO7: Biblos Flocon d'avoine 50g | AP7: Biblos Flocon d'avoine 400g | AQ7: Biblos Lait Premium 16g | AR7: Biblos Lait Premium 360g | AS7: Biblos Lait Excellence 900g | AT7: Biblos Flocon d'avoine 50g | AU7: Biblos Flocon d'avoine 400g | AV7: Affiche Biblos Lait Prémium 16g & 360g | AW7: Affiche Biblos Lait Excellence | AX7: Affiche Biblos Flocons d' Avoine | AY7: Hanger | AZ7: Wobbler | BA7: Biblos Lait Premium 16g | BB7: Biblos Lait Excellence 900g | BC7: Biblos Flocon d'avoine 50g
A8: 1 | B8: DIBI SIMEON | C8: =+C$3 -> 10 | D8: =+D$3 -> 3 | E8: =+E$3 -> 2 | F8: =+F$3 -> 2 | G8: =+G$3 -> 3 | H8: =+H$3 -> 3 | I8: =+I$3 -> 1 | J8: =+J$3 -> 1 | ... V8: =+V$3 -> 0.15 | W8: 20 | AB8: 1 | AE8: 1 | AF8: 1 | AG8: 4 | AL8: 1 | AM8: 1 | AN8: 1 | AO8: 1 | AP8: 2 | AQ8: 1 | AR8: 0.5 | AS8: 0.3 | AU8: 0.5 | AV8: 3 | AW8: 3 | AX8: 3 | BA8: 30 | BC8: 5
A9: 2 | B9: KRA EVAVARISTE | C9: =+C$3 -> 10 | D9: =+D$3 -> 3 | E9: =+E$3 -> 2 | F9: =+F$3 -> 2 | G9: =+G$3 -> 3 | H9: =+H$3 -> 3 | I9: =+I$3 -> 1 | J9: =+J$3 -> 1 | ... V9: =+V$3 -> 0.15 | W9: 15 | AB9: 1 | AF9: 1 | AG9: 5 | AL9: 2 | AN9: 1 | AO9: 1 | AP9: 3 | AQ9: 0.5 | AS9: 0.15 | AT9: 1 | AU9: 1.5 | AV9: 3 | AW9: 3 | AX9: 3 | BA9: 12 | BC9: 25
A10: 3 | B10: DIOMANDE ESTHER | C10: =+C$3 -> 10 | D10: =+D$3 -> 3 | E10: =+E$3 -> 2 | F10: =+F$3 -> 2 | G10: =+G$3 -> 3 | H10: =+H$3 -> 3 | I10: =+I$3 -> 1 | J10: =+J$3 -> 1 | ... V10: =+V$3 -> 0.15 | W10: 17 | AB10: 1 | AG10: 4 | AL10: 2 | AN10: 1 | AP10: 2 | AQ10: 0.5 | AS10: 0.3 | AU10: 2 | AV10: 3 | AW10: 3 | AX10: 3 | BA10: 18 | BC10: 20
A11: 4 | B11: BADA LANDRY | C11: =+C$3 -> 10 | D11: =+D$3 -> 3 | E11: =+E$3 -> 2 | F11: =+F$3 -> 2 | G11: =+G$3 -> 3 | H11: =+H$3 -> 3 | I11: =+I$3 -> 1 | J11: =+J$3 -> 1 | ... V11: =+V$3 -> 0.15 | W11: 18 | AD11: 1 | AF11: 1 | AG11: 6 | AL11: 2 | AN11: 2 | AO11: 1 | AP11: 3 | AQ11: 1.5 | AS11: 0.3 | AT11: 1 | AU11: 1.5 | AV11: 3 | AW11: 3 | AX11: 3 | BA11: 30 | BC11: 25
A12: 5 | B12: KOUAME JOSE | C12: =+C$3 -> 10 | D12: =+D$3 -> 3 | E12: =+E$3 -> 2 | F12: =+F$3 -> 2 | G12: =+G$3 -> 3 | H12: =+H$3 -> 3 | I12: =+I$3 -> 1 | J12: =+J$3 -> 1 | ... V12: =+V$3 -> 0.15 | W12: 15 | AG12: 5 | AL12: 1 | AM12: 1 | AN12: 1 | AP12: 2 | AQ12: 0.5 | AR12: 0.5 | AS12: 0.15 | AU12: 2 | AV12: 3 | AW12: 3 | AX12: 3 | BA12: 18 | BC12: 20
A13: 6 | B13: FANY BARAKISSA | C13: =+C$3 -> 10 | D13: =+D$3 -> 3 | E13: =+E$3 -> 2 | F13: =+F$3 -> 2 | G13: =+G$3 -> 3 | H13: =+H$3 -> 3 | I13: =+I$3 -> 1 | J13: =+J$3 -> 1 | ... V13: =+V$3 -> 0.15 | W13: 21 | AB13: 1 | AF13: 1 | AG13: 4 | AL13: 2 | AN13: 1 | AP13: 3 | AQ13: 0.5 | AS13: 0.15 | AU13: 1.5 | AV13: 3 | AW13: 3 | AX13: 3 | BA13: 12 | BC13: 15
A14: 7 | B14: KONAN IVETTE | C14: =+C$3 -> 10 | D14: =+D$3 -> 3 | E14: =+E$3 -> 2 | F14: =+F$3 -> 2 | G14: =+G$3 -> 3 | H14: =+H$3 -> 3 | I14: =+I$3 -> 1 | J14: =+J$3 -> 1 | ... V14: =+V$3 -> 0.15 | W14: 17 | AG14: 4 | AL14: 1 | AN14: 1 | AP14: 2 | AQ14: 0.5 | AS14: 0.3 | AU14: 2 | AV14: 3 | AW14: 3 | AX14: 3 | BA14: 18 | BC14: 20
A15: 8 | B15: KRA PACOME | C15: =+C$3 -> 10 | D15: =+D$3 -> 3 | E15: =+E$3 -> 2 | F15: =+F$3 -> 2 | G15: =+G$3 -> 3 | H15: =+H$3 -> 3 | I15: =+I$3 -> 1 | J15: =+J$3 -> 1 | ... V15: =+V$3 -> 0.15 | W15: 19 | AF15: 1 | AG15: 5 | AL15: 1 | AN15: 1 | AO15: 1 | AP15: 3 | AQ15: 0.5 | AS15: 0.15 | AT15: 0.5 | AU15: 2 | AV15: 3 | AW15: 3 | AX15: 3 | BA15: 12 | BC15: 25
A16: 9 | B16: KONATE MARIAM | C16: =+C$3 -> 10 | D16: =+D$3 -> 3 | E16: =+E$3 -> 2 | F16: =+F$3 -> 2 | G16: =+G$3 -> 3 | H16: =+H$3 -> 3 | I16: =+I$3 -> 1 | J16: =+J$3 -> 1 | ... V16: =+V$3 -> 0.15 | W16: 17 | AB16: 1 | AE16: 1 | AF16: 1 | AG16: 4 | AL16: 1 | AN16: 2 | AP16: 3 | AQ16: 0.5 | AS16: 0.15 | AU16: 1.5 | AV16: 3 | AW16: 3 | AX16: 3 | BA16: 12 | BC16: 15
A17: 10 | B17: KOUAKOU ROSE | C17: =+C$3 -> 10 | D17: =+D$3 -> 3 | E17: =+E$3 -> 2 | F17: =+F$3 -> 2 | G17: =+G$3 -> 3 | H17: =+H$3 -> 3 | I17: =+I$3 -> 1 | J17: =+J$3 -> 1 | ... V17: =+V$3 -> 0.15 | W17: 24 | AC17: 1 | AE17: 1 | AG17: 4 | AL17: 1 | AM17: 1 | AN17: 1 | AO17: 2 | AP17: 1 | AQ17: 0.5 | AS17: 0.15 | AT17: 1 | AU17: 0.5 | AV17: 3 | AW17: 3 | AX17: 3 | BA17: 12 | BC17: 15
A18: 11 | B18: OULAY WILFRIED | C18: =+C$3 -> 10 | D18: =+D$3 -> 3 | E18: =+E$3 -> 2 | F18: =+F$3 -> 2 | G18: =+G$3 -> 3 | H18: =+H$3 -> 3 | I18: =+I$3 -> 1 | J18: =+J$3 -> 1 | ... V18: =+V$3 -> 0.15 | W18: 19 | AB18: 1 | AF18: 1 | AG18: 4 | AL18: 2 | AM18: 1 | AP18: 2 | AQ18: 0.5 | AR18: 0.5 | AU18: 1.5 | AV18: 3 | AW18: 3 | AX18: 3 | BA18: 12 | BC18: 15
A19: 12 | B19: NGUESSAN INNOCENT | C19: =+C$3 -> 10 | D19: =+D$3 -> 3 | E19: =+E$3 -> 2 | F19: =+F$3 -> 2 | G19: =+G$3 -> 3 | H19: =+H$3 -> 3 | I19: =+I$3 -> 1 | J19: =+J$3 -> 1 | ... V19: =+V$3 -> 0.15 | W19: 15 | AF19: 2 | AG19: 4 | AL19: 1 | AN19: 1 | AP19: 4 | AQ19: 0.5 | AS19: =8/20 -> 0.4 | AU19: 2 | AV19: 3 | AW19: 3 | AX19: 3 | BA19: 18 | BC19: 20
A20: 13 | B20: ARISTIDE KOUAME | C20: =+C$3 -> 10 | D20: =+D$3 -> 3 | E20: =+E$3 -> 2 | F20: =+F$3 -> 2 | G20: =+G$3 -> 3 | H20: =+H$3 -> 3 | I20: =+I$3 -> 1 | J20: =+J$3 -> 1 | ... V20: =+V$3 -> 0.15 | W20: 17 | AB20: 1 | AG20: 3 | AL20: 2 | AN20: 1 | AP20: 1 | AQ20: 0.5 | AS20: 0.15 | AU20: 0.5 | AV20: 3 | AW20: 3 | AX20: 3 | BA20: 12 | BC20: 5
A21: 14 | B21: ANGE STEPHANIE | C21: =+C$3 -> 10 | D21: =+D$3 -> 3 | E21: =+E$3 -> 2 | F21: =+F$3 -> 2 | G21: =+G$3 -> 3 | H21: =+H$3 -> 3 | I21: =+I$3 -> 1 | J21: =+J$3 -> 1 | ... V21: =+V$3 -> 0.15 | W21: 18 | AB21: 1 | AE21: 1 | AG21: 6 | AL21: 2 | AM21: 1 | AN21: 1 | AO21: 1 | AP21: 3 | AQ21: 0.67 | AR21: =1/6 -> 0.16666667 | AS21: 0.15 | AU21: 2 | AV21: 3 | AW21: 3 | AX21: 3 | BA21: 14 | BC21: 20
A22: 15 | B22: KOUADIO FLORENT | C22: =+C$3 -> 10 | D22: =+D$3 -> 3 | E22: =+E$3 -> 2 | F22: =+F$3 -> 2 | G22: =+G$3 -> 3 | H22: =+H$3 -> 3 | I22: =+I$3 -> 1 | J22: =+J$3 -> 1 | ... V22: =+V$3 -> 0.15 | W22: 17 | AC22: 1 | AG22: 5 | AL22: 1 | AM22: 1 | AN22: 1 | AP22: 2 | AQ22: 0.5 | AS22: 0.15 | AU22: 2 | AV22: 3 | AW22: 3 | AX22: 3 | BA22: 12 | BC22: 20
A23: 16 | B23: SERIE ULRICHE | C23: =+C$3 -> 10 | D23: =+D$3 -> 3 | E23: =+E$3 -> 2 | F23: =+F$3 -> 2 | G23: =+G$3 -> 3 | H23: =+H$3 -> 3 | I23: =+I$3 -> 1 | J23: =+J$3 -> 1 | ... V23: =+V$3 -> 0.15 | W23: 17 | AG23: 3 | AL23: 1 | AN23: 1 | AP23: 1 | AQ23: 0.5 | AS23: 0.3 | AU23: 1 | AV23: 3 | AW23: 3 | AX23: 3 | BA23: 18 | BC23: 10
A24: 17 | B24: KOADIO SARAH | C24: =+C$3 -> 10 | D24: =+D$3 -> 3 | E24: =+E$3 -> 2 | F24: =+F$3 -> 2 | G24: =+G$3 -> 3 | H24: =+H$3 -> 3 | I24: =+I$3 -> 1 | J24: =+J$3 -> 1 | ... V24: =+V$3 -> 0.15 | W24: 18 | AD24: 1 | AE24: 1 | AG24: 5 | AL24: 1 | AM24: 1 | AN24: 1 | AO24: 1 | AP24: 1 | AQ24: 0.5 | AR24: 0.5 | AS24: 0.15 | AT24: 0.4 | AU24: 1 | AV24: 3 | AW24: 3 | AX24: 3 | BA24: 18 | BC24: 14
A25: 18 | B25: MLEHI ANGE | C25: =+C$3 -> 10 | D25: =+D$3 -> 3 | E25: =+E$3 -> 2 | F25: =+F$3 -> 2 | G25: =+G$3 -> 3 | H25: =+H$3 -> 3 | I25: =+I$3 -> 1 | J25: =+J$3 -> 1 | ... V25: =+V$3 -> 0.15 | W25: 20 | AF25: 2 | AG25: 3 | AL25: 1 | AN25: 1 | AP25: 3 | AQ25: 0.5 | AS25: 0.15 | AU25: 0.5 | AV25: 3 | AW25: 3 | AX25: 3 | BA25: 12 | BC25: 5
A26: 19 | C26: =+C$3 -> 10 | D26: =+D$3 -> 3 | E26: =+E$3 -> 2 | F26: =+F$3 -> 2 | G26: =+G$3 -> 3 | H26: =+H$3 -> 3 | I26: =+I$3 -> 1 | J26: =+J$3 -> 1 | ... V26: =+V$3 -> 0.15
A27: 20 | C27: =+C$3 -> 10 | D27: =+D$3 -> 3 | E27: =+E$3 -> 2 | F27: =+F$3 -> 2 | G27: =+G$3 -> 3 | H27: =+H$3 -> 3 | I27: =+I$3 -> 1 | J27: =+J$3 -> 1 | ... V27: =+V$3 -> 0.15
B28: TOTAL | C28: =SUM(C8:C27) -> 200 | D28: =SUM(D8:D27) -> 60 | E28: =SUM(E8:E27) -> 40 | F28: =SUM(F8:F27) -> 40 | G28: =SUM(G8:G27) -> 60 | H28: =SUM(H8:H27) -> 60 | I28: =SUM(I8:I27) -> 20 | J28: =SUM(J8:J27) -> 20 | ... BE28: =SUM(BE8:BE27) -> 0
AQ30: 10*8ch | AR30: 2c*1sa | AS30: 3c 11 sa | AT30: 3* 9ch | AU30: 25,5 c
AR33: =13/6 -> 2.1666667 | AS33: =11/20 -> 0.55 | AT33: =9 -> 9

Sheet Synthèse semaine
B2: VILLE
C3: 10 | D3: 3 | E3: 2 | F3: 2 | G3: 3 | H3: 3 | I3: 1 | J3: 1 | K3: 1 | L3: 1 | M3: =+H3 -> 3 | N3: 1 | O3: =+H3 -> 3 | R3: =+(2*M3)/12 -> 0.5 | S3: =+(1*I3)/6 -> 0.16666667 | T3: =+(2*I3)/20 -> 0.1 | U3: =+(2*H3)/10 -> 0.6 | V3: =+(3*I3)/20 -> 0.15
C5: OBJECTIFS JOURNALIERS | W5: REALISATIONS | BD5: Commentaires | BE5: Impressions des PDV et des clients
A6: N° | B6: Agent promoteur | C6: Nombre de visite / Type de PDV | H6: Nombre de référencement / Type de PDV | M6: Pose de matériel de visibilité | R6: Vente en cartons | W6: Nombre de visite / Type de PDV | AB6: Présence produits antérieure | AG6: Nombre de référencement / Type de PDV | AL6: Nouveau Référencement par SKU | AQ6: Vente en cartons | AV6: Pose de matériel de visibilité | BA6: Gratuits offerts en sachet
C7: Boutique | D7: Superette | E7: Kiosque | F7: Tablier | G7: Pushcart | H7: Boutique | I7: Superette | J7: Kiosque | K7: Tablier | L7: Pushcart | M7: Affiche Biblos Lait Prémium 16g & 360g | N7: Affiche Biblos Lait Excellence | O7: Affiche Biblos Flocons d' Avoine | P7: Hanger | Q7: Wobbler | R7: Biblos Lait Premium 16g | S7: Biblos Lait Premium 360g | T7: Biblos Lait Excellence 900g | U7: Biblos Flocon d'avoine 50g | V7: Biblos Flocon d'avoine 400g | W7: Boutique | X7: Superette | Y7: Kiosque | Z7: Tablier | AA7: Pushcart | AB7: Biblos Lait Premium 16g | AC7: Biblos Lait Premium 360g | AD7: Biblos Lait Excellence 900g | AE7: Biblos Flocon d'avoine 50g | AF7: Biblos Flocon d'avoine 400g | AG7: Boutique | AH7: Superette | AI7: Kiosque | AJ7: Tablier | AK7: Pushcart | AL7: Biblos Lait Premium 16g | AM7: Biblos Lait Premium 360g | AN7: Biblos Lait Excellence 900g | AO7: Biblos Flocon d'avoine 50g | AP7: Biblos Flocon d'avoine 400g | AQ7: Biblos Lait Premium 16g | AR7: Biblos Lait Premium 360g | AS7: Biblos Lait Excellence 900g | AT7: Biblos Flocon d'avoine 50g | AU7: Biblos Flocon d'avoine 400g | AV7: Affiche Biblos Lait Prémium 16g & 360g | AW7: Affiche Biblos Lait Excellence | AX7: Affiche Biblos Flocons d' Avoine | AY7: Hanger | AZ7: Wobbler | BA7: Biblos Lait Premium 16g | BB7: Biblos Lait Excellence 900g | BC7: Biblos Flocon d'avoine 50g
A8: 1 | C8: =+C$3 -> 10 | D8: =+D$3 -> 3 | E8: =+E$3 -> 2 | F8: =+F$3 -> 2 | G8: =+G$3 -> 3 | H8: =+H$3 -> 3 | I8: =+I$3 -> 1 | J8: =+J$3 -> 1 | ... V8: =+V$3 -> 0.15 | W8: ='JEUDI 22 JANV'!W8+'VEND 23 JANV'!W8+'SAM 24 JANV'!W8+'LUND 26 JANV'!W8+'MAR 27 JANV'!W8+#REF! -> #REF! | X8: ='JEUDI 22 JANV'!X8+'VEND 23 JANV'!X8+'SAM 24 JANV'!X8+'LUND 26 JANV'!X8+'MAR 27 JANV'!X8+#REF! -> #REF! | Y8: ='JEUDI 22 JANV'!Y8+'VEND 23 JANV'!Y8+'SAM 24 JANV'!Y8+'LUND 26 JANV'!Y8+'MAR 27 JANV'!Y8+#REF! -> #REF! | Z8: ='JEUDI 22 JANV'!Z8+'VEND 23 JANV'!Z8+'SAM 24 JANV'!Z8+'LUND 26 JANV'!Z8+'MAR 27 JANV'!Z8+#REF! -> #REF! | AA8: ='JEUDI 22 JANV'!AA8+'VEND 23 JANV'!AA8+'SAM 24 JANV'!AA8+'LUND 26 JANV'!AA8+'MAR 27 JANV'!AA8+#REF! -> #REF! | AB8: ='JEUDI 22 JANV'!AB8+'VEND 23 JANV'!AB8+'SAM 24 JANV'!AB8+'LUND 26 JANV'!AB8+'MAR 27 JANV'!AB8+#REF! -> #REF! | AC8: ='JEUDI 22 JANV'!AC8+'VEND 23 JANV'!AC8+'SAM 24 JANV'!AC8+'LUND 26 JANV'!AC8+'MAR 27 JANV'!AC8+#REF! -> #REF! | AD8: ='JEUDI 22 JANV'!AD8+'VEND 23 JANV'!AD8+'SAM 24 JANV'!AD8+'LUND 26 JANV'!AD8+'MAR 27 JANV'!AD8+#REF! -> #REF! | ... BC8: ='JEUDI 22 JANV'!BC8+'VEND 23 JANV'!BC8+'SAM 24 JANV'!BC8+'LUND 26 JANV'!BC8+'MAR 27 JANV'!BC8+#REF! -> #REF!
A9: 2 | C9: =+C$3 -> 10 | D9: =+D$3 -> 3 | E9: =+E$3 -> 2 | F9: =+F$3 -> 2 | G9: =+G$3 -> 3 | H9: =+H$3 -> 3 | I9: =+I$3 -> 1 | J9: =+J$3 -> 1 | ... V9: =+V$3 -> 0.15 | W9: ='JEUDI 22 JANV'!W9+'VEND 23 JANV'!W9+'SAM 24 JANV'!W9+'LUND 26 JANV'!W9+'MAR 27 JANV'!W9+#REF! -> #REF! | X9: ='JEUDI 22 JANV'!X9+'VEND 23 JANV'!X9+'SAM 24 JANV'!X9+'LUND 26 JANV'!X9+'MAR 27 JANV'!X9+#REF! -> #REF! | Y9: ='JEUDI 22 JANV'!Y9+'VEND 23 JANV'!Y9+'SAM 24 JANV'!Y9+'LUND 26 JANV'!Y9+'MAR 27 JANV'!Y9+#REF! -> #REF! | Z9: ='JEUDI 22 JANV'!Z9+'VEND 23 JANV'!Z9+'SAM 24 JANV'!Z9+'LUND 26 JANV'!Z9+'MAR 27 JANV'!Z9+#REF! -> #REF! | AA9: ='JEUDI 22 JANV'!AA9+'VEND 23 JANV'!AA9+'SAM 24 JANV'!AA9+'LUND 26 JANV'!AA9+'MAR 27 JANV'!AA9+#REF! -> #REF! | AB9: ='JEUDI 22 JANV'!AB9+'VEND 23 JANV'!AB9+'SAM 24 JANV'!AB9+'LUND 26 JANV'!AB9+'MAR 27 JANV'!AB9+#REF! -> #REF! | AC9: ='JEUDI 22 JANV'!AC9+'VEND 23 JANV'!AC9+'SAM 24 JANV'!AC9+'LUND 26 JANV'!AC9+'MAR 27 JANV'!AC9+#REF! -> #REF! | AD9: ='JEUDI 22 JANV'!AD9+'VEND 23 JANV'!AD9+'SAM 24 JANV'!AD9+'LUND 26 JANV'!AD9+'MAR 27 JANV'!AD9+#REF! -> #REF! | ... BC9: ='JEUDI 22 JANV'!BC9+'VEND 23 JANV'!BC9+'SAM 24 JANV'!BC9+'LUND 26 JANV'!BC9+'MAR 27 JANV'!BC9+#REF! -> #REF!
A10: 3 | C10: =+C$3 -> 10 | D10: =+D$3 -> 3 | E10: =+E$3 -> 2 | F10: =+F$3 -> 2 | G10: =+G$3 -> 3 | H10: =+H$3 -> 3 | I10: =+I$3 -> 1 | J10: =+J$3 -> 1 | ... V10: =+V$3 -> 0.15 | W10: ='JEUDI 22 JANV'!W10+'VEND 23 JANV'!W10+'SAM 24 JANV'!W10+'LUND 26 JANV'!W10+'MAR 27 JANV'!W10+#REF! -> #REF! | X10: ='JEUDI 22 JANV'!X10+'VEND 23 JANV'!X10+'SAM 24 JANV'!X10+'LUND 26 JANV'!X10+'MAR 27 JANV'!X10+#REF! -> #REF! | Y10: ='JEUDI 22 JANV'!Y10+'VEND 23 JANV'!Y10+'SAM 24 JANV'!Y10+'LUND 26 JANV'!Y10+'MAR 27 JANV'!Y10+#REF! -> #REF! | Z10: ='JEUDI 22 JANV'!Z10+'VEND 23 JANV'!Z10+'SAM 24 JANV'!Z10+'LUND 26 JANV'!Z10+'MAR 27 JANV'!Z10+#REF! -> #REF! | AA10: ='JEUDI 22 JANV'!AA10+'VEND 23 JANV'!AA10+'SAM 24 JANV'!AA10+'LUND 26 JANV'!AA10+'MAR 27 JANV'!AA10+#REF! -> #REF! | AB10: ='JEUDI 22 JANV'!AB10+'VEND 23 JANV'!AB10+'SAM 24 JANV'!AB10+'LUND 26 JANV'!AB10+'MAR 27 JANV'!AB10+#REF! -> #REF! | AC10: ='JEUDI 22 JANV'!AC10+'VEND 23 JANV'!AC10+'SAM 24 JANV'!AC10+'LUND 26 JANV'!AC10+'MAR 27 JANV'!AC10+#REF! -> #REF! | AD10: ='JEUDI 22 JANV'!AD10+'VEND 23 JANV'!AD10+'SAM 24 JANV'!AD10+'LUND 26 JANV'!AD10+'MAR 27 JANV'!AD10+#REF! -> #REF! | ... BC10: ='JEUDI 22 JANV'!BC10+'VEND 23 JANV'!BC10+'SAM 24 JANV'!BC10+'LUND 26 JANV'!BC10+'MAR 27 JANV'!BC10+#REF! -> #REF!
A11: 4 | C11: =+C$3 -> 10 | D11: =+D$3 -> 3 | E11: =+E$3 -> 2 | F11: =+F$3 -> 2 | G11: =+G$3 -> 3 | H11: =+H$3 -> 3 | I11: =+I$3 -> 1 | J11: =+J$3 -> 1 | ... V11: =+V$3 -> 0.15 | W11: ='JEUDI 22 JANV'!W11+'VEND 23 JANV'!W11+'SAM 24 JANV'!W11+'LUND 26 JANV'!W11+'MAR 27 JANV'!W11+#REF! -> #REF! | X11: ='JEUDI 22 JANV'!X11+'VEND 23 JANV'!X11+'SAM 24 JANV'!X11+'LUND 26 JANV'!X11+'MAR 27 JANV'!X11+#REF! -> #REF! | Y11: ='JEUDI 22 JANV'!Y11+'VEND 23 JANV'!Y11+'SAM 24 JANV'!Y11+'LUND 26 JANV'!Y11+'MAR 27 JANV'!Y11+#REF! -> #REF! | Z11: ='JEUDI 22 JANV'!Z11+'VEND 23 JANV'!Z11+'SAM 24 JANV'!Z11+'LUND 26 JANV'!Z11+'MAR 27 JANV'!Z11+#REF! -> #REF! | AA11: ='JEUDI 22 JANV'!AA11+'VEND 23 JANV'!AA11+'SAM 24 JANV'!AA11+'LUND 26 JANV'!AA11+'MAR 27 JANV'!AA11+#REF! -> #REF! | AB11: ='JEUDI 22 JANV'!AB11+'VEND 23 JANV'!AB11+'SAM 24 JANV'!AB11+'LUND 26 JANV'!AB11+'MAR 27 JANV'!AB11+#REF! -> #REF! | AC11: ='JEUDI 22 JANV'!AC11+'VEND 23 JANV'!AC11+'SAM 24 JANV'!AC11+'LUND 26 JANV'!AC11+'MAR 27 JANV'!AC11+#REF! -> #REF! | AD11: ='JEUDI 22 JANV'!AD11+'VEND 23 JANV'!AD11+'SAM 24 JANV'!AD11+'LUND 26 JANV'!AD11+'MAR 27 JANV'!AD11+#REF! -> #REF! | ... BC11: ='JEUDI 22 JANV'!BC11+'VEND 23 JANV'!BC11+'SAM 24 JANV'!BC11+'LUND 26 JANV'!BC11+'MAR 27 JANV'!BC11+#REF! -> #REF!
A12: 5 | C12: =+C$3 -> 10 | D12: =+D$3 -> 3 | E12: =+E$3 -> 2 | F12: =+F$3 -> 2 | G12: =+G$3 -> 3 | H12: =+H$3 -> 3 | I12: =+I$3 -> 1 | J12: =+J$3 -> 1 | ... V12: =+V$3 -> 0.15 | W12: ='JEUDI 22 JANV'!W12+'VEND 23 JANV'!W12+'SAM 24 JANV'!W12+'LUND 26 JANV'!W12+'MAR 27 JANV'!W12+#REF! -> #REF! | X12: ='JEUDI 22 JANV'!X12+'VEND 23 JANV'!X12+'SAM 24 JANV'!X12+'LUND 26 JANV'!X12+'MAR 27 JANV'!X12+#REF! -> #REF! | Y12: ='JEUDI 22 JANV'!Y12+'VEND 23 JANV'!Y12+'SAM 24 JANV'!Y12+'LUND 26 JANV'!Y12+'MAR 27 JANV'!Y12+#REF! -> #REF! | Z12: ='JEUDI 22 JANV'!Z12+'VEND 23 JANV'!Z12+'SAM 24 JANV'!Z12+'LUND 26 JANV'!Z12+'MAR 27 JANV'!Z12+#REF! -> #REF! | AA12: ='JEUDI 22 JANV'!AA12+'VEND 23 JANV'!AA12+'SAM 24 JANV'!AA12+'LUND 26 JANV'!AA12+'MAR 27 JANV'!AA12+#REF! -> #REF! | AB12: ='JEUDI 22 JANV'!AB12+'VEND 23 JANV'!AB12+'SAM 24 JANV'!AB12+'LUND 26 JANV'!AB12+'MAR 27 JANV'!AB12+#REF! -> #REF! | AC12: ='JEUDI 22 JANV'!AC12+'VEND 23 JANV'!AC12+'SAM 24 JANV'!AC12+'LUND 26 JANV'!AC12+'MAR 27 JANV'!AC12+#REF! -> #REF! | AD12: ='JEUDI 22 JANV'!AD12+'VEND 23 JANV'!AD12+'SAM 24 JANV'!AD12+'LUND 26 JANV'!AD12+'MAR 27 JANV'!AD12+#REF! -> #REF! | ... BC12: ='JEUDI 22 JANV'!BC12+'VEND 23 JANV'!BC12+'SAM 24 JANV'!BC12+'LUND 26 JANV'!BC12+'MAR 27 JANV'!BC12+#REF! -> #REF!
A13: 6 | C13: =+C$3 -> 10 | D13: =+D$3 -> 3 | E13: =+E$3 -> 2 | F13: =+F$3 -> 2 | G13: =+G$3 -> 3 | H13: =+H$3 -> 3 | I13: =+I$3 -> 1 | J13: =+J$3 -> 1 | ... V13: =+V$3 -> 0.15 | W13: ='JEUDI 22 JANV'!W13+'VEND 23 JANV'!W13+'SAM 24 JANV'!W13+'LUND 26 JANV'!W13+'MAR 27 JANV'!W13+#REF! -> #REF! | X13: ='JEUDI 22 JANV'!X13+'VEND 23 JANV'!X13+'SAM 24 JANV'!X13+'LUND 26 JANV'!X13+'MAR 27 JANV'!X13+#REF! -> #REF! | Y13: ='JEUDI 22 JANV'!Y13+'VEND 23 JANV'!Y13+'SAM 24 JANV'!Y13+'LUND 26 JANV'!Y13+'MAR 27 JANV'!Y13+#REF! -> #REF! | Z13: ='JEUDI 22 JANV'!Z13+'VEND 23 JANV'!Z13+'SAM 24 JANV'!Z13+'LUND 26 JANV'!Z13+'MAR 27 JANV'!Z13+#REF! -> #REF! | AA13: ='JEUDI 22 JANV'!AA13+'VEND 23 JANV'!AA13+'SAM 24 JANV'!AA13+'LUND 26 JANV'!AA13+'MAR 27 JANV'!AA13+#REF! -> #REF! | AB13: ='JEUDI 22 JANV'!AB13+'VEND 23 JANV'!AB13+'SAM 24 JANV'!AB13+'LUND 26 JANV'!AB13+'MAR 27 JANV'!AB13+#REF! -> #REF! | AC13: ='JEUDI 22 JANV'!AC13+'VEND 23 JANV'!AC13+'SAM 24 JANV'!AC13+'LUND 26 JANV'!AC13+'MAR 27 JANV'!AC13+#REF! -> #REF! | AD13: ='JEUDI 22 JANV'!AD13+'VEND 23 JANV'!AD13+'SAM 24 JANV'!AD13+'LUND 26 JANV'!AD13+'MAR 27 JANV'!AD13+#REF! -> #REF! | ... BC13: ='JEUDI 22 JANV'!BC13+'VEND 23 JANV'!BC13+'SAM 24 JANV'!BC13+'LUND 26 JANV'!BC13+'MAR 27 JANV'!BC13+#REF! -> #REF!
A14: 7 | C14: =+C$3 -> 10 | D14: =+D$3 -> 3 | E14: =+E$3 -> 2 | F14: =+F$3 -> 2 | G14: =+G$3 -> 3 | H14: =+H$3 -> 3 | I14: =+I$3 -> 1 | J14: =+J$3 -> 1 | ... V14: =+V$3 -> 0.15 | W14: ='JEUDI 22 JANV'!W14+'VEND 23 JANV'!W14+'SAM 24 JANV'!W14+'LUND 26 JANV'!W14+'MAR 27 JANV'!W14+#REF! -> #REF! | X14: ='JEUDI 22 JANV'!X14+'VEND 23 JANV'!X14+'SAM 24 JANV'!X14+'LUND 26 JANV'!X14+'MAR 27 JANV'!X14+#REF! -> #REF! | Y14: ='JEUDI 22 JANV'!Y14+'VEND 23 JANV'!Y14+'SAM 24 JANV'!Y14+'LUND 26 JANV'!Y14+'MAR 27 JANV'!Y14+#REF! -> #REF! | Z14: ='JEUDI 22 JANV'!Z14+'VEND 23 JANV'!Z14+'SAM 24 JANV'!Z14+'LUND 26 JANV'!Z14+'MAR 27 JANV'!Z14+#REF! -> #REF! | AA14: ='JEUDI 22 JANV'!AA14+'VEND 23 JANV'!AA14+'SAM 24 JANV'!AA14+'LUND 26 JANV'!AA14+'MAR 27 JANV'!AA14+#REF! -> #REF! | AB14: ='JEUDI 22 JANV'!AB14+'VEND 23 JANV'!AB14+'SAM 24 JANV'!AB14+'LUND 26 JANV'!AB14+'MAR 27 JANV'!AB14+#REF! -> #REF! | AC14: ='JEUDI 22 JANV'!AC14+'VEND 23 JANV'!AC14+'SAM 24 JANV'!AC14+'LUND 26 JANV'!AC14+'MAR 27 JANV'!AC14+#REF! -> #REF! | AD14: ='JEUDI 22 JANV'!AD14+'VEND 23 JANV'!AD14+'SAM 24 JANV'!AD14+'LUND 26 JANV'!AD14+'MAR 27 JANV'!AD14+#REF! -> #REF! | ... BC14: ='JEUDI 22 JANV'!BC14+'VEND 23 JANV'!BC14+'SAM 24 JANV'!BC14+'LUND 26 JANV'!BC14+'MAR 27 JANV'!BC14+#REF! -> #REF!
