Workbook

Sheet RECAP PAR JOUR
B3: CONTACTS | E3: ACHETEURS | I3: OBJECTIF VOLUME PRODUITS | O3: REALISATION VOLUME PRODUITS | U3: REALISATION VOLUME PRODUITS
B4: Objectif | C4: Réalisé | D4: Tx Réal. | E4: Objectif | F4: Réalisé | G4: Tx Réal. | I4: Biblos Lait Premium 16g | J4: Biblos Lait Premium 360g | K4: Biblos Lait Excellence 900g | L4: Biblos Avoine 50g | M4: Biblos Avoine 400g | N4: Biblos 3 en 1 Café au lait 32g | O4: Biblos Lait Premium 16g | P4: Biblos Lait Premium 360g | Q4: Biblos Lait Excellence 900g | R4: Biblos Avoine 50g | S4: Biblos Avoine 400g | T4: Biblos 3 en 1 Café au lait 32g | U4: =O4 -> Biblos Lait Premium 16g | V4: =P4 -> Biblos Lait Premium 360g | W4: =Q4 -> Biblos Lait Excellence 900g | X4: =R4 -> Biblos Avoine 50g | Y4: =S4 -> Biblos Avoine 400g | Z4: =T4 -> Biblos 3 en 1 Café au lait 32g
A5: JOUR 1 | B5: =13*40 -> 520 | C5: ='JOUR 1'!S27 -> 512 | D5: =C5/B5 -> 0.98461538 | E5: =13*20 -> 260 | F5: ='JOUR 1'!T27 -> 370 | G5: =F5/E5 -> 1.4230769 | I5: =120*13/120 -> 13 | J5: =7*13/6 -> 15.166667 | K5: =13*4/10 -> 5.2 | O5: ='JOUR 1'!U27 -> 11.525 | P5: ='JOUR 1'!V27 -> 16.5 | Q5: ='JOUR 1'!W27 -> 7.2 | R5: ='JOUR 1'!X27 -> 5.54 | S5: ='JOUR 1'!Y27 -> 8.85 | T5: ='JOUR 1'!Z27 -> 0 | U5: =O5/I5 -> 0.88653846 | V5: =P5/J5 -> 1.0879121 | W5: =Q5/K5 -> 1.3846154
A6: JOUR 2 | B6: =13*40 -> 520 | C6: ='JOUR 2'!S27 -> 489 | D6: =C6/B6 -> 0.94038462 | E6: =13*20 -> 260 | F6: ='JOUR 2'!T27 -> 352 | G6: =F6/E6 -> 1.3538462 | I6: =I5 -> 13 | J6: =J5 -> 15.166667 | K6: =K5 -> 5.2 | O6: ='JOUR 2'!U27 -> 16.133333 | P6: ='JOUR 2'!V27 -> 19.333333 | Q6: ='JOUR 2'!W27 -> 9.6 | R6: ='JOUR 2'!X27 -> 7.66 | S6: ='JOUR 2'!Y27 -> 9.85 | T6: ='JOUR 2'!Z27 -> 0.05 | U6: =O6/I6 -> 1.2410256 | V6: =P6/J6 -> 1.2747253 | W6: =Q6/K6 -> 1.8461538
A7: JOUR 3 | B7: =13*40 -> 520 | C7: ='JOUR 3'!S27 -> 565 | D7: =C7/B7 -> 1.0865385 | E7: =13*20 -> 260 | F7: ='JOUR 3'!T27 -> 363 | G7: =F7/E7 -> 1.3961538 | I7: =I6 -> 13 | J7: =J6 -> 15.166667 | K7: =K6 -> 5.2 | O7: ='JOUR 3'!U27 -> 16.925 | P7: ='JOUR 3'!V27 -> 25.666667 | Q7: ='JOUR 3'!W27 -> 8.6 | R7: ='JOUR 3'!X27 -> 7.17 | S7: ='JOUR 3'!Y27 -> 14.65 | T7: ='JOUR 3'!Z27 -> 0.11666667 | U7: =O7/I7 -> 1.3019231 | V7: =P7/J7 -> 1.6923077 | W7: =Q7/K7 -> 1.6538462
A8: JOUR 4 | B8: =13*40 -> 520 | C8: ='JOUR 4'!S27 -> 587 | D8: =C8/B8 -> 1.1288462 | E8: =13*20 -> 260 | F8: ='JOUR 4'!T27 -> 344 | G8: =F8/E8 -> 1.3230769 | I8: =I7 -> 13 | J8: =J7 -> 15.166667 | K8: =K7 -> 5.2 | O8: ='JOUR 4'!U27 -> 15.741667 | P8: ='JOUR 4'!V27 -> 16.166667 | Q8: ='JOUR 4'!W27 -> 6.8 | R8: ='JOUR 4'!X27 -> 7.27 | S8: ='JOUR 4'!Y27 -> 22.4 | T8: ='JOUR 4'!Z27 -> 0.16666667 | U8: =O8/I8 -> 1.2108974 | V8: =P8/J8 -> 1.0659341 | W8: =Q8/K8 -> 1.3076923
A9: JOUR 5 | B9: =13*40 -> 520 | C9: ='JOUR 5'!S27 -> 483 | D9: =C9/B9 -> 0.92884615 | E9: =13*20 -> 260 | F9: ='JOUR 5'!T27 -> 345 | G9: =F9/E9 -> 1.3269231 | I9: =I8 -> 13 | J9: =J8 -> 15.166667 | K9: =K8 -> 5.2 | O9: ='JOUR 5'!U27 -> 18.825 | P9: ='JOUR 5'!V27 -> 15.5 | Q9: ='JOUR 5'!W27 -> 4.7 | R9: ='JOUR 5'!X27 -> 8.22 | S9: ='JOUR 5'!Y27 -> 18.6 | T9: ='JOUR 5'!Z27 -> 0.11666667 | U9: =O9/I9 -> 1.4480769 | V9: =P9/J9 -> 1.021978 | W9: =Q9/K9 -> 0.90384615
A10: JOUR 6 | B10: =13*40 -> 520 | C10: ='JOUR 6'!S27 -> 546 | D10: =C10/B10 -> 1.05 | E10: =13*20 -> 260 | F10: ='JOUR 6'!T27 -> 344 | G10: =F10/E10 -> 1.3230769 | I10: =I9 -> 13 | J10: =J9 -> 15.166667 | K10: =K9 -> 5.2 | O10: ='JOUR 6'!U27 -> 17.558333 | P10: ='JOUR 6'!V27 -> 13.333333 | Q10: ='JOUR 6'!W27 -> 7.3 | R10: ='JOUR 6'!X27 -> 11.65 | S10: ='JOUR 6'!Y27 -> 11.6 | T10: ='JOUR 6'!Z27 -> 0.11666667 | U10: =O10/I10 -> 1.350641 | V10: =P10/J10 -> 0.87912088 | W10: =Q10/K10 -> 1.4038462
A11: JOUR 7 | B11: =13*40 -> 520 | C11: ='JOUR 7'!S27 -> 550 | D11: =C11/B11 -> 1.0576923 | E11: =13*20 -> 260 | F11: ='JOUR 7'!T27 -> 349 | G11: =F11/E11 -> 1.3423077 | I11: =I10 -> 13 | J11: =J10 -> 15.166667 | K11: =K10 -> 5.2 | O11: ='JOUR 7'!U27 -> 14.375 | P11: ='JOUR 7'!V27 -> 20 | Q11: ='JOUR 7'!W27 -> 7.4 | R11: ='JOUR 7'!X27 -> 13.33 | S11: ='JOUR 7'!Y27 -> 6.95 | T11: ='JOUR 7'!Z27 -> 0.13333333 | U11: =O11/I11 -> 1.1057692 | V11: =P11/J11 -> 1.3186813 | W11: =Q11/K11 -> 1.4230769
A12: JOUR 8 | B12: =13*40 -> 520 | C12: ='JOUR 8'!S27 -> 535 | D12: =C12/B12 -> 1.0288462 | E12: =13*20 -> 260 | F12: ='JOUR 8'!T27 -> 358 | G12: =F12/E12 -> 1.3769231 | I12: =I11 -> 13 | J12: =J11 -> 15.166667 | K12: =K11 -> 5.2 | O12: ='JOUR 8'!U27 -> 17.35 | P12: ='JOUR 8'!V27 -> 31 | Q12: ='JOUR 8'!W27 -> 14.3 | R12: ='JOUR 8'!X27 -> 12.98 | S12: ='JOUR 8'!Y27 -> 11.9 | T12: ='JOUR 8'!Z27 -> 0.4 | U12: =O12/I12 -> 1.3346154 | V12: =P12/J12 -> 2.043956 | W12: =Q12/K12 -> 2.75
A13: JOUR 9 | B13: =13*40 -> 520 | C13: ='JOUR 9'!S27 -> 516 | D13: =C13/B13 -> 0.99230769 | E13: =13*20 -> 260 | F13: ='JOUR 9'!T27 -> 337 | G13: =F13/E13 -> 1.2961538 | I13: =I12 -> 13 | J13: =J12 -> 15.166667 | K13: =K12 -> 5.2 | O13: ='JOUR 9'!U27 -> 21.608333 | P13: ='JOUR 9'!V27 -> 43.666667 | Q13: ='JOUR 9'!W27 -> 8.7 | R13: ='JOUR 9'!X27 -> 13.41 | S13: ='JOUR 9'!Y27 -> 15 | T13: ='JOUR 9'!Z27 -> 0 | U13: =O13/I13 -> 1.6621795 | V13: =P13/J13 -> 2.8791209 | W13: =Q13/K13 -> 1.6730769
A14: JOUR 10 | B14: =13*40 -> 520 | C14: ='JOUR 10'!S27 -> 523 | D14: =C14/B14 -> 1.0057692 | E14: =13*20 -> 260 | F14: ='JOUR 10'!T27 -> 323 | G14: =F14/E14 -> 1.2423077 | I14: =I13 -> 13 | J14: =J13 -> 15.166667 | K14: =K13 -> 5.2 | O14: ='JOUR 10'!U27 -> 14.55 | P14: ='JOUR 10'!V27 -> 15.666667 | Q14: ='JOUR 10'!W27 -> 10.2 | R14: ='JOUR 10'!X27 -> 10.5 | S14: ='JOUR 10'!Y27 -> 7.75 | T14: ='JOUR 10'!Z27 -> 0 | U14: =O14/I14 -> 1.1192308 | V14: =P14/J14 -> 1.032967 | W14: =Q14/K14 -> 1.9615385
A15: JOUR 11 | B15: =13*40 -> 520 | C15: ='JOUR 11'!S27 -> 459 | D15: =C15/B15 -> 0.88269231 | E15: =13*20 -> 260 | F15: ='JOUR 11'!T27 -> 317 | G15: =F15/E15 -> 1.2192308 | I15: =I14 -> 13 | J15: =J14 -> 15.166667 | K15: =K14 -> 5.2 | O15: ='JOUR 11'!U27 -> 17.016667 | P15: ='JOUR 11'!V27 -> 22.5 | Q15: ='JOUR 11'!W27 -> 10.4 | R15: ='JOUR 11'!X27 -> 11.54 | S15: ='JOUR 11'!Y27 -> 10.3 | T15: ='JOUR 11'!Z27 -> 0.05 | U15: =O15/I15 -> 1.3089744 | V15: =P15/J15 -> 1.4835165 | W15: =Q15/K15 -> 2
A16: JOUR 12 | B16: =13*40 -> 520 | D16: =C16/B16 -> 0 | E16: =13*20 -> 260 | G16: =F16/E16 -> 0 | I16: =I15 -> 13 | J16: =J15 -> 15.166667 | K16: =K15 -> 5.2 | U16: =O16/I16 -> 0 | V16: =P16/J16 -> 0 | W16: =Q16/K16 -> 0
A17: JOUR 13
A18: JOUR 14
A19: JOUR 15
A20: JOUR 16
A21: TOTAL | B21: =SUM(B5:B20) -> 6240 | C21: =SUM(C5:C20) -> 5765 | D21: =C21/B21 -> 0.92387821 | E21: =SUM(E5:E20) -> 3120 | F21: =SUM(F5:F20) -> 3802 | G21: =F21/E21 -> 1.2185897 | I21: =SUM(I5:I20) -> 156 | J21: =SUM(J5:J20) -> 182 | K21: =SUM(K5:K20) -> 62.4 | L21: =SUM(L5:L20) -> 0 | M21: =SUM(M5:M20) -> 0 | O21: =SUM(O5:O20) -> 181.60833 | P21: =SUM(P5:P20) -> 239.33333 | Q21: =SUM(Q5:Q20) -> 95.2 | R21: =SUM(R5:R20) -> 109.27 | S21: =SUM(S5:S20) -> 137.85 | U21: =O21/I21 -> 1.164156 | V21: =P21/J21 -> 1.3150183 | W21: =Q21/K21 -> 1.525641

Sheet RECAP PAR MAGASIN
B2: Date | C2: TOTAL PROMO | D2: OBJECTIFS | S2: REALISATIONS | AK2: TAUX DE REALISATION
B3: Enseigne | C3: Nom du PDV en promotion | D3: Contacts | E3: =T3 -> Acheteurs | F3: Produits (en unités) | L3: Gratuités pour achats (en unités) | S3: Contacts | T3: Acheteurs | U3: Produits | AA3: =L3 -> Gratuités pour achats (en unités) | AD3: GOODIES | AH3: Commentaires | AI3: Impressions des PDV et des clients | AK3: Contacts | AL3: Acheteurs | AM3: Produits | AS3: =AD3 -> GOODIES | AV3: GOODIES
D4: =S4 -> Nombre de personnes ayant été contactées au rayon | E4: =T4 -> Nombre de personnes ayant acheté | F4: Biblos Lait Premium 16g | G4: Biblos Lait Premium 360g | H4: Biblos Lait Excellence | I4: Biblos Flocon d'avoine 50g | J4: Biblos Flocon d'avoine 400g | K4: Biblos 3 en 1 Café au lait 32g | L4: Biblos Lait Premium 16g | M4: Biblos Flocon d'avoine 50g | N4: Biblos 3 en Café au Lait | O4: Goodies 1 | P4: Goodies 2 | Q4: Goodies 3 | R4: Goodie 4 | S4: Nombre de personnes ayant été contactées au rayon | T4: Nombre de personnes ayant acheté | U4: Biblos Lait Premium 16g | V4: Biblos Lait Premium 360g | W4: Biblos Lait Excellence | X4: Biblos Flocon d'avoine 50g | Y4: Biblos Flocon d'avoine 400g | Z4: Biblos 3 en 1 Café au lait | AA4: Biblos Lait Premium 16g | AB4: Biblos Flocon d'avoine 50g | AC4: Biblos 3 en 1 Café au lait | AD4: =O4 -> Goodies 1 | AE4: =P4 -> Goodies 2 | AF4: =Q4 -> Goodies 3 | AG4: =R4 -> Goodie 4 | AK4: Nombre de personnes ayant été contactées au rayon | AL4: Nombre de personnes ayant acheté | AM4: Biblos Lait Premium 16g | AN4: Biblos Lait Premium 360g | AO4: Biblos Lait Excellence | AP4: Biblos Flocon d'avoine 50g | AQ4: Biblos Flocon d'avoine 400g | AR4: Biblos 3 en 1 Café au lait | AS4: Biblos Lait Premium 16g | AT4: Biblos Flocon d'avoine 50g | AU4: Biblos 3 en 1 Café au lait | AV4: Goodies 1 | AW4: Goodies 2 | AX4: Goodies 3 | AY4: Goodies 4
B5: AUCHAN | C5: AUCHAN ABATTA | D5: ='JOUR 1'!D5+'JOUR 2'!D5+'JOUR 3'!D5+'JOUR 4'!D5+'JOUR 5'!D5+'JOUR 6'!D5+'JOUR 7'!D5+'JOUR 8'!D5+'JOUR 9'!D5+'JOUR 10'!D5+'JOUR 11'!D5+#REF!+#REF!+#REF!+#REF!+#REF! -> #REF! | E5: ='JOUR 1'!E5+'JOUR 2'!E5+'JOUR 3'!E5+'JOUR 4'!E5+'JOUR 5'!E5+'JOUR 6'!E5+'JOUR 7'!E5+'JOUR 8'!E5+'JOUR 9'!E5+'JOUR 10'!E5+'JOUR 11'!E5+#REF!+#REF!+#REF!+#REF!+#REF! -> #REF! | F5: ='JOUR 1'!F5+'JOUR 2'!F5+'JOUR 3'!F5+'JOUR 4'!F5+'JOUR 5'!F5+'JOUR 6'!F5+'JOUR 7'!F5+'JOUR 8'!F5+'JOUR 9'!F5+'JOUR 10'!F5+'JOUR 11'!F5+#REF!+#REF!+#REF!+#REF!+#REF! -> #REF! | G5: ='JOUR 1'!G5+'JOUR 2'!G5+'JOUR 3'!G5+'JOUR 4'!G5+'JOUR 5'!G5+'JOUR 6'!G5+'JOUR 7'!G5+'JOUR 8'!G5+'JOUR 9'!G5+'JOUR 10'!G5+'JOUR 11'!G5+#REF!+#REF!+#REF!+#REF!+#REF! -> #REF! | H5: ='JOUR 1'!H5+'JOUR 2'!H5+'JOUR 3'!H5+'JOUR 4'!H5+'JOUR 5'!H5+'JOUR 6'!H5+'JOUR 7'!H5+'JOUR 8'!H5+'JOUR 9'!H5+'JOUR 10'!H5+'JOUR 11'!H5+#REF!+#REF!+#REF!+#REF!+#REF! -> #REF! | I5: ='JOUR 1'!I5+'JOUR 2'!I5+'JOUR 3'!I5+'JOUR 4'!I5+'JOUR 5'!I5+'JOUR 6'!I5+'JOUR 7'!I5+'JOUR 8'!I5+'JOUR 9'!I5+'JOUR 10'!I5+'JOUR 11'!I5+#REF!+#REF!+#REF!+#REF!+#REF! -> #REF! | J5: ='JOUR 1'!J5+'JOUR 2'!J5+'JOUR 3'!J5+'JOUR 4'!J5+'JOUR 5'!J5+'JOUR 6'!J5+'JOUR 7'!J5+'JOUR 8'!J5+'JOUR 9'!J5+'JOUR 10'!J5+'JOUR 11'!J5+#REF!+#REF!+#REF!+#REF!+#REF! -> #REF! | K5: ='JOUR 1'!K5+'JOUR 2'!K5+'JOUR 3'!K5+'JOUR 4'!K5+'JOUR 5'!K5+'JOUR 6'!K5+'JOUR 7'!K5+'JOUR 8'!K5+'JOUR 9'!K5+'JOUR 10'!K5+'JOUR 11'!K5+#REF!+#REF!+#REF!+#REF!+#REF! -> #REF! | ... AG5: ='JOUR 1'!AG5+'JOUR 2'!AG5+'JOUR 3'!AG5+'JOUR 4'!AG5+'JOUR 5'!AG5+'JOUR 6'!AG5+'JOUR 7'!AG5+'JOUR 8'!AG5+'JOUR 9'!AG5+'JOUR 10'!AG5+'JOUR 11'!AG5+#REF!+#REF!+#REF!+#REF!+#REF! -> #REF! | AK5: =S5/D5 -> #REF! | AL5: =T5/E5 -> #REF! | AM5: =U5/F5 -> #REF! | AN5: =V5/G5 -> #REF! | AO5: =W5/H5 -> #REF! | AS5: =AA5/L5 -> #REF!
B6: AUCHAN | C6: AUCHAN ABOBO SAMAKE | D6: ='JOUR 1'!D6+'JOUR 2'!D6+'JOUR 3'!D6+'JOUR 4'!D6+'JOUR 5'!D6+'JOUR 6'!D6+'JOUR 7'!D6+'JOUR 8'!D6+'JOUR 9'!D6+'JOUR 10'!D6+'JOUR 11'!D6+#REF!+#REF!+#REF!+#REF!+#REF! -> #REF! | E6: ='JOUR 1'!E6+'JOUR 2'!E6+'JOUR 3'!E6+'JOUR 4'!E6+'JOUR 5'!E6+'JOUR 6'!E6+'JOUR 7'!E6+'JOUR 8'!E6+'JOUR 9'!E6+'JOUR 10'!E6+'JOUR 11'!E6+#REF!+#REF!+#REF!+#REF!+#REF! -> #REF! | F6: ='JOUR 1'!F6+'JOUR 2'!F6+'JOUR 3'!F6+'JOUR 4'!F6+'JOUR 5'!F6+'JOUR 6'!F6+'JOUR 7'!F6+'JOUR 8'!F6+'JOUR 9'!F6+'JOUR 10'!F6+'JOUR 11'!F6+#REF!+#REF!+#REF!+#REF!+#REF! -> #REF! | G6: ='JOUR 1'!G6+'JOUR 2'!G6+'JOUR 3'!G6+'JOUR 4'!G6+'JOUR 5'!G6+'JOUR 6'!G6+'JOUR 7'!G6+'JOUR 8'!G6+'JOUR 9'!G6+'JOUR 10'!G6+'JOUR 11'!G6+#REF!+#REF!+#REF!+#REF!+#REF! -> #REF! | H6: ='JOUR 1'!H6+'JOUR 2'!H6+'JOUR 3'!H6+'JOUR 4'!H6+'JOUR 5'!H6+'JOUR 6'!H6+'JOUR 7'!H6+'JOUR 8'!H6+'JOUR 9'!H6+'JOUR 10'!H6+'JOUR 11'!H6+#REF!+#REF!+#REF!+#REF!+#REF! -> #REF! | I6: ='JOUR 1'!I6+'JOUR 2'!I6+'JOUR 3'!I6+'JOUR 4'!I6+'JOUR 5'!I6+'JOUR 6'!I6+'JOUR 7'!I6+'JOUR 8'!I6+'JOUR 9'!I6+'JOUR 10'!I6+'JOUR 11'!I6+#REF!+#REF!+#REF!+#REF!+#REF! -> #REF! | J6: ='JOUR 1'!J6+'JOUR 2'!J6+'JOUR 3'!J6+'JOUR 4'!J6+'JOUR 5'!J6+'JOUR 6'!J6+'JOUR 7'!J6+'JOUR 8'!J6+'JOUR 9'!J6+'JOUR 10'!J6+'JOUR 11'!J6+#REF!+#REF!+#REF!+#REF!+#REF! -> #REF! | K6: ='JOUR 1'!K6+'JOUR 2'!K6+'JOUR 3'!K6+'JOUR 4'!K6+'JOUR 5'!K6+'JOUR 6'!K6+'JOUR 7'!K6+'JOUR 8'!K6+'JOUR 9'!K6+'JOUR 10'!K6+'JOUR 11'!K6+#REF!+#REF!+#REF!+#REF!+#REF! -> #REF! | ... AG6: ='JOUR 1'!AG6+'JOUR 2'!AG6+'JOUR 3'!AG6+'JOUR 4'!AG6+'JOUR 5'!AG6+'JOUR 6'!AG6+'JOUR 7'!AG6+'JOUR 8'!AG6+'JOUR 9'!AG6+'JOUR 10'!AG6+'JOUR 11'!AG6+#REF!+#REF!+#REF!+#REF!+#REF! -> #REF! | AK6: =S6/D6 -> #REF! | AL6: =T6/E6 -> #REF! | AM6: =U6/F6 -> #REF! | AN6: =V6/G6 -> #REF! | AO6: =W6/H6 -> #REF! | AS6: =AA6/L6 -> #REF!
B7: AUCHAN | C7: AUCHAN ANGRE DJIBI | D7: ='JOUR 1'!D7+'JOUR 2'!D7+'JOUR 3'!D7+'JOUR 4'!D7+'JOUR 5'!D7+'JOUR 6'!D7+'JOUR 7'!D7+'JOUR 8'!D7+'JOUR 9'!D7+'JOUR 10'!D7+'JOUR 11'!D7+#REF!+#REF!+#REF!+#REF!+#REF! -> #REF! | E7: ='JOUR 1'!E7+'JOUR 2'!E7+'JOUR 3'!E7+'JOUR 4'!E7+'JOUR 5'!E7+'JOUR 6'!E7+'JOUR 7'!E7+'JOUR 8'!E7+'JOUR 9'!E7+'JOUR 10'!E7+'JOUR 11'!E7+#REF!+#REF!+#REF!+#REF!+#REF! -> #REF! | F7: ='JOUR 1'!F7+'JOUR 2'!F7+'JOUR 3'!F7+'JOUR 4'!F7+'JOUR 5'!F7+'JOUR 6'!F7+'JOUR 7'!F7+'JOUR 8'!F7+'JOUR 9'!F7+'JOUR 10'!F7+'JOUR 11'!F7+#REF!+#REF!+#REF!+#REF!+#REF! -> #REF! | G7: ='JOUR 1'!G7+'JOUR 2'!G7+'JOUR 3'!G7+'JOUR 4'!G7+'JOUR 5'!G7+'JOUR 6'!G7+'JOUR 7'!G7+'JOUR 8'!G7+'JOUR 9'!G7+'JOUR 10'!G7+'JOUR 11'!G7+#REF!+#REF!+#REF!+#REF!+#REF! -> #REF! | H7: ='JOUR 1'!H7+'JOUR 2'!H7+'JOUR 3'!H7+'JOUR 4'!H7+'JOUR 5'!H7+'JOUR 6'!H7+'JOUR 7'!H7+'JOUR 8'!H7+'JOUR 9'!H7+'JOUR 10'!H7+'JOUR 11'!H7+#REF!+#REF!+#REF!+#REF!+#REF! -> #REF! | I7: ='JOUR 1'!I7+'JOUR 2'!I7+'JOUR 3'!I7+'JOUR 4'!I7+'JOUR 5'!I7+'JOUR 6'!I7+'JOUR 7'!I7+'JOUR 8'!I7+'JOUR 9'!I7+'JOUR 10'!I7+'JOUR 11'!I7+#REF!+#REF!+#REF!+#REF!+#REF! -> #REF! | J7: ='JOUR 1'!J7+'JOUR 2'!J7+'JOUR 3'!J7+'JOUR 4'!J7+'JOUR 5'!J7+'JOUR 6'!J7+'JOUR 7'!J7+'JOUR 8'!J7+'JOUR 9'!J7+'JOUR 10'!J7+'JOUR 11'!J7+#REF!+#REF!+#REF!+#REF!+#REF! -> #REF! | K7: ='JOUR 1'!K7+'JOUR 2'!K7+'JOUR 3'!K7+'JOUR 4'!K7+'JOUR 5'!K7+'JOUR 6'!K7+'JOUR 7'!K7+'JOUR 8'!K7+'JOUR 9'!K7+'JOUR 10'!K7+'JOUR 11'!K7+#REF!+#REF!+#REF!+#REF!+#REF! -> #REF! | ... AG7: ='JOUR 1'!AG7+'JOUR 2'!AG7+'JOUR 3'!AG7+'JOUR 4'!AG7+'JOUR 5'!AG7+'JOUR 6'!AG7+'JOUR 7'!AG7+'JOUR 8'!AG7+'JOUR 9'!AG7+'JOUR 10'!AG7+'JOUR 11'!AG7+#REF!+#REF!+#REF!+#REF!+#REF! -> #REF! | AK7: =S7/D7 -> #REF! | AL7: =T7/E7 -> #REF! | AM7: =U7/F7 -> #REF! | AN7: =V7/G7 -> #REF! | AO7: =W7/H7 -> #REF! | AS7: =AA7/L7 -> #REF!
B8: AUCHAN | C8: AUCHAN ATTOBAN | D8: ='JOUR 1'!D8+'JOUR 2'!D8+'JOUR 3'!D8+'JOUR 4'!D8+'JOUR 5'!D8+'JOUR 6'!D8+'JOUR 7'!D8+'JOUR 8'!D8+'JOUR 9'!D8+'JOUR 10'!D8+'JOUR 11'!D8+#REF!+#REF!+#REF!+#REF!+#REF! -> #REF! | E8: ='JOUR 1'!E8+'JOUR 2'!E8+'JOUR 3'!E8+'JOUR 4'!E8+'JOUR 5'!E8+'JOUR 6'!E8+'JOUR 7'!E8+'JOUR 8'!E8+'JOUR 9'!E8+'JOUR 10'!E8+'JOUR 11'!E8+#REF!+#REF!+#REF!+#REF!+#REF! -> #REF! | F8: ='JOUR 1'!F8+'JOUR 2'!F8+'JOUR 3'!F8+'JOUR 4'!F8+'JOUR 5'!F8+'JOUR 6'!F8+'JOUR 7'!F8+'JOUR 8'!F8+'JOUR 9'!F8+'JOUR 10'!F8+'JOUR 11'!F8+#REF!+#REF!+#REF!+#REF!+#REF! -> #REF! | G8: ='JOUR 1'!G8+'JOUR 2'!G8+'JOUR 3'!G8+'JOUR 4'!G8+'JOUR 5'!G8+'JOUR 6'!G8+'JOUR 7'!G8+'JOUR 8'!G8+'JOUR 9'!G8+'JOUR 10'!G8+'JOUR 11'!G8+#REF!+#REF!+#REF!+#REF!+#REF! -> #REF! | H8: ='JOUR 1'!H8+'JOUR 2'!H8+'JOUR 3'!H8+'JOUR 4'!H8+'JOUR 5'!H8+'JOUR 6'!H8+'JOUR 7'!H8+'JOUR 8'!H8+'JOUR 9'!H8+'JOUR 10'!H8+'JOUR 11'!H8+#REF!+#REF!+#REF!+#REF!+#REF! -> #REF! | I8: ='JOUR 1'!I8+'JOUR 2'!I8+'JOUR 3'!I8+'JOUR 4'!I8+'JOUR 5'!I8+'JOUR 6'!I8+'JOUR 7'!I8+'JOUR 8'!I8+'JOUR 9'!I8+'JOUR 10'!I8+'JOUR 11'!I8+#REF!+#REF!+#REF!+#REF!+#REF! -> #REF! | J8: ='JOUR 1'!J8+'JOUR 2'!J8+'JOUR 3'!J8+'JOUR 4'!J8+'JOUR 5'!J8+'JOUR 6'!J8+'JOUR 7'!J8+'JOUR 8'!J8+'JOUR 9'!J8+'JOUR 10'!J8+'JOUR 11'!J8+#REF!+#REF!+#REF!+#REF!+#REF! -> #REF! | K8: ='JOUR 1'!K8+'JOUR 2'!K8+'JOUR 3'!K8+'JOUR 4'!K8+'JOUR 5'!K8+'JOUR 6'!K8+'JOUR 7'!K8+'JOUR 8'!K8+'JOUR 9'!K8+'JOUR 10'!K8+'JOUR 11'!K8+#REF!+#REF!+#REF!+#REF!+#REF! -> #REF! | ... AG8: ='JOUR 1'!AG8+'JOUR 2'!AG8+'JOUR 3'!AG8+'JOUR 4'!AG8+'JOUR 5'!AG8+'JOUR 6'!AG8+'JOUR 7'!AG8+'JOUR 8'!AG8+'JOUR 9'!AG8+'JOUR 10'!AG8+'JOUR 11'!AG8+#REF!+#REF!+#REF!+#REF!+#REF! -> #REF! | AK8: =S8/D8 -> #REF! | AL8: =T8/E8 -> #REF! | AM8: =U8/F8 -> #REF! | AN8: =V8/G8 -> #REF! | AO8: =W8/H8 -> #REF! | AS8: =AA8/L8 -> #REF!
B9: AUCHAN | C9: AUCHAN BINGERVILLE | D9: ='JOUR 1'!D9+'JOUR 2'!D9+'JOUR 3'!D9+'JOUR 4'!D9+'JOUR 5'!D9+'JOUR 6'!D9+'JOUR 7'!D9+'JOUR 8'!D9+'JOUR 9'!D9+'JOUR 10'!D9+'JOUR 11'!D9+#REF!+#REF!+#REF!+#REF!+#REF! -> #REF! | E9: ='JOUR 1'!E9+'JOUR 2'!E9+'JOUR 3'!E9+'JOUR 4'!E9+'JOUR 5'!E9+'JOUR 6'!E9+'JOUR 7'!E9+'JOUR 8'!E9+'JOUR 9'!E9+'JOUR 10'!E9+'JOUR 11'!E9+#REF!+#REF!+#REF!+#REF!+#REF! -> #REF! | F9: ='JOUR 1'!F9+'JOUR 2'!F9+'JOUR 3'!F9+'JOUR 4'!F9+'JOUR 5'!F9+'JOUR 6'!F9+'JOUR 7'!F9+'JOUR 8'!F9+'JOUR 9'!F9+'JOUR 10'!F9+'JOUR 11'!F9+#REF!+#REF!+#REF!+#REF!+#REF! -> #REF! | G9: ='JOUR 1'!G9+'JOUR 2'!G9+'JOUR 3'!G9+'JOUR 4'!G9+'JOUR 5'!G9+'JOUR 6'!G9+'JOUR 7'!G9+'JOUR 8'!G9+'JOUR 9'!G9+'JOUR 10'!G9+'JOUR 11'!G9+#REF!+#REF!+#REF!+#REF!+#REF! -> #REF! | H9: ='JOUR 1'!H9+'JOUR 2'!H9+'JOUR 3'!H9+'JOUR 4'!H9+'JOUR 5'!H9+'JOUR 6'!H9+'JOUR 7'!H9+'JOUR 8'!H9+'JOUR 9'!H9+'JOUR 10'!H9+'JOUR 11'!H9+#REF!+#REF!+#REF!+#REF!+#REF! -> #REF! | I9: ='JOUR 1'!I9+'JOUR 2'!I9+'JOUR 3'!I9+'JOUR 4'!I9+'JOUR 5'!I9+'JOUR 6'!I9+'JOUR 7'!I9+'JOUR 8'!I9+'JOUR 9'!I9+'JOUR 10'!I9+'JOUR 11'!I9+#REF!+#REF!+#REF!+#REF!+#REF! -> #REF! | J9: ='JOUR 1'!J9+'JOUR 2'!J9+'JOUR 3'!J9+'JOUR 4'!J9+'JOUR 5'!J9+'JOUR 6'!J9+'JOUR 7'!J9+'JOUR 8'!J9+'JOUR 9'!J9+'JOUR 10'!J9+'JOUR 11'!J9+#REF!+#REF!+#REF!+#REF!+#REF! -> #REF! | K9: ='JOUR 1'!K9+'JOUR 2'!K9+'JOUR 3'!K9+'JOUR 4'!K9+'JOUR 5'!K9+'JOUR 6'!K9+'JOUR 7'!K9+'JOUR 8'!K9+'JOUR 9'!K9+'JOUR 10'!K9+'JOUR 11'!K9+#REF!+#REF!+#REF!+#REF!+#REF! -> #REF! | ... AG9: ='JOUR 1'!AG9+'JOUR 2'!AG9+'JOUR 3'!AG9+'JOUR 4'!AG9+'JOUR 5'!AG9+'JOUR 6'!AG9+'JOUR 7'!AG9+'JOUR 8'!AG9+'JOUR 9'!AG9+'JOUR 10'!AG9+'JOUR 11'!AG9+#REF!+#REF!+#REF!+#REF!+#REF! -> #REF! | AK9: =S9/D9 -> #REF! | AL9: =T9/E9 -> #REF! | AM9: =U9/F9 -> #REF! | AN9: =V9/G9 -> #REF! | AO9: =W9/H9 -> #REF! | AS9: =AA9/L9 -> #REF!
B10: AUCHAN | C10: AUCHAN GARDEN LATRILLE | D10: ='JOUR 1'!D10+'JOUR 2'!D10+'JOUR 3'!D10+'JOUR 4'!D10+'JOUR 5'!D10+'JOUR 6'!D10+'JOUR 7'!D10+'JOUR 8'!D10+'JOUR 9'!D10+'JOUR 10'!D10+'JOUR 11'!D10+#REF!+#REF!+#REF!+#REF!+#REF! -> #REF! | E10: ='JOUR 1'!E10+'JOUR 2'!E10+'JOUR 3'!E10+'JOUR 4'!E10+'JOUR 5'!E10+'JOUR 6'!E10+'JOUR 7'!E10+'JOUR 8'!E10+'JOUR 9'!E10+'JOUR 10'!E10+'JOUR 11'!E10+#REF!+#REF!+#REF!+#REF!+#REF! -> #REF! | F10: ='JOUR 1'!F10+'JOUR 2'!F10+'JOUR 3'!F10+'JOUR 4'!F10+'JOUR 5'!F10+'JOUR 6'!F10+'JOUR 7'!F10+'JOUR 8'!F10+'JOUR 9'!F10+'JOUR 10'!F10+'JOUR 11'!F10+#REF!+#REF!+#REF!+#REF!+#REF! -> #REF! | G10: ='JOUR 1'!G10+'JOUR 2'!G10+'JOUR 3'!G10+'JOUR 4'!G10+'JOUR 5'!G10+'JOUR 6'!G10+'JOUR 7'!G10+'JOUR 8'!G10+'JOUR 9'!G10+'JOUR 10'!G10+'JOUR 11'!G10+#REF!+#REF!+#REF!+#REF!+#REF! -> #REF! | H10: ='JOUR 1'!H10+'JOUR 2'!H10+'JOUR 3'!H10+'JOUR 4'!H10+'JOUR 5'!H10+'JOUR 6'!H10+'JOUR 7'!H10+'JOUR 8'!H10+'JOUR 9'!H10+'JOUR 10'!H10+'JOUR 11'!H10+#REF!+#REF!+#REF!+#REF!+#REF! -> #REF! | I10: ='JOUR 1'!I10+'JOUR 2'!I10+'JOUR 3'!I10+'JOUR 4'!I10+'JOUR 5'!I10+'JOUR 6'!I10+'JOUR 7'!I10+'JOUR 8'!I10+'JOUR 9'!I10+'JOUR 10'!I10+'JOUR 11'!I10+#REF!+#REF!+#REF!+#REF!+#REF! -> #REF! | J10: ='JOUR 1'!J10+'JOUR 2'!J10+'JOUR 3'!J10+'JOUR 4'!J10+'JOUR 5'!J10+'JOUR 6'!J10+'JOUR 7'!J10+'JOUR 8'!J10+'JOUR 9'!J10+'JOUR 10'!J10+'JOUR 11'!J10+#REF!+#REF!+#REF!+#REF!+#REF! -> #REF! | K10: ='JOUR 1'!K10+'JOUR 2'!K10+'JOUR 3'!K10+'JOUR 4'!K10+'JOUR 5'!K10+'JOUR 6'!K10+'JOUR 7'!K10+'JOUR 8'!K10+'JOUR 9'!K10+'JOUR 10'!K10+'JOUR 11'!K10+#REF!+#REF!+#REF!+#REF!+#REF! -> #REF! | ... AG10: ='JOUR 1'!AG10+'JOUR 2'!AG10+'JOUR 3'!AG10+'JOUR 4'!AG10+'JOUR 5'!AG10+'JOUR 6'!AG10+'JOUR 7'!AG10+'JOUR 8'!AG10+'JOUR 9'!AG10+'JOUR 10'!AG10+'JOUR 11'!AG10+#REF!+#REF!+#REF!+#REF!+#REF! -> #REF! | AK10: =S10/D10 -> #REF! | AL10: =T10/E10 -> #REF! | AM10: =U10/F10 -> #REF! | AN10: =V10/G10 -> #REF! | AO10: =W10/H10 -> #REF! | AS10: =AA10/L10 -> #REF!
B11: AUCHAN | C11: AUCHAN GRAND-BASSAM | D11: ='JOUR 1'!D11+'JOUR 2'!D11+'JOUR 3'!D11+'JOUR 4'!D11+'JOUR 5'!D11+'JOUR 6'!D11+'JOUR 7'!D11+'JOUR 8'!D11+'JOUR 9'!D11+'JOUR 10'!D11+'JOUR 11'!D11+#REF!+#REF!+#REF!+#REF!+#REF! -> #REF! | E11: ='JOUR 1'!E11+'JOUR 2'!E11+'JOUR 3'!E11+'JOUR 4'!E11+'JOUR 5'!E11+'JOUR 6'!E11+'JOUR 7'!E11+'JOUR 8'!E11+'JOUR 9'!E11+'JOUR 10'!E11+'JOUR 11'!E11+#REF!+#REF!+#REF!+#REF!+#REF! -> #REF! | F11: ='JOUR 1'!F11+'JOUR 2'!F11+'JOUR 3'!F11+'JOUR 4'!F11+'JOUR 5'!F11+'JOUR 6'!F11+'JOUR 7'!F11+'JOUR 8'!F11+'JOUR 9'!F11+'JOUR 10'!F11+'JOUR 11'!F11+#REF!+#REF!+#REF!+#REF!+#REF! -> #REF! | G11: ='JOUR 1'!G11+'JOUR 2'!G11+'JOUR 3'!G11+'JOUR 4'!G11+'JOUR 5'!G11+'JOUR 6'!G11+'JOUR 7'!G11+'JOUR 8'!G11+'JOUR 9'!G11+'JOUR 10'!G11+'JOUR 11'!G11+#REF!+#REF!+#REF!+#REF!+#REF! -> #REF! | H11: ='JOUR 1'!H11+'JOUR 2'!H11+'JOUR 3'!H11+'JOUR 4'!H11+'JOUR 5'!H11+'JOUR 6'!H11+'JOUR 7'!H11+'JOUR 8'!H11+'JOUR 9'!H11+'JOUR 10'!H11+'JOUR 11'!H11+#REF!+#REF!+#REF!+#REF!+#REF! -> #REF! | I11: ='JOUR 1'!I11+'JOUR 2'!I11+'JOUR 3'!I11+'JOUR 4'!I11+'JOUR 5'!I11+'JOUR 6'!I11+'JOUR 7'!I11+'JOUR 8'!I11+'JOUR 9'!I11+'JOUR 10'!I11+'JOUR 11'!I11+#REF!+#REF!+#REF!+#REF!+#REF! -> #REF! | J11: ='JOUR 1'!J11+'JOUR 2'!J11+'JOUR 3'!J11+'JOUR 4'!J11+'JOUR 5'!J11+'JOUR 6'!J11+'JOUR 7'!J11+'JOUR 8'!J11+'JOUR 9'!J11+'JOUR 10'!J11+'JOUR 11'!J11+#REF!+#REF!+#REF!+#REF!+#REF! -> #REF! | K11: ='JOUR 1'!K11+'JOUR 2'!K11+'JOUR 3'!K11+'JOUR 4'!K11+'JOUR 5'!K11+'JOUR 6'!K11+'JOUR 7'!K11+'JOUR 8'!K11+'JOUR 9'!K11+'JOUR 10'!K11+'JOUR 11'!K11+#REF!+#REF!+#REF!+#REF!+#REF! -> #REF! | ... AG11: ='JOUR 1'!AG11+'JOUR 2'!AG11+'JOUR 3'!AG11+'JOUR 4'!AG11+'JOUR 5'!AG11+'JOUR 6'!AG11+'JOUR 7'!AG11+'JOUR 8'!AG11+'JOUR 9'!AG11+'JOUR 10'!AG11+'JOUR 11'!AG11+#REF!+#REF!+#REF!+#REF!+#REF! -> #REF! | AK11: =S11/D11 -> #REF! | AL11: =T11/E11 -> #REF! | AM11: =U11/F11 -> #REF! | AN11: =V11/G11 -> #REF! | AO11: =W11/H11 -> #REF! | AS11: =AA11/L11 -> #REF!
B12: AUCHAN | C12: AUCHAN KOUMASSI SOLEIL | D12: ='JOUR 1'!D12+'JOUR 2'!D12+'JOUR 3'!D12+'JOUR 4'!D12+'JOUR 5'!D12+'JOUR 6'!D12+'JOUR 7'!D12+'JOUR 8'!D12+'JOUR 9'!D12+'JOUR 10'!D12+'JOUR 11'!D12+#REF!+#REF!+#REF!+#REF!+#REF! -> #REF! | E12: ='JOUR 1'!E12+'JOUR 2'!E12+'JOUR 3'!E12+'JOUR 4'!E12+'JOUR 5'!E12+'JOUR 6'!E12+'JOUR 7'!E12+'JOUR 8'!E12+'JOUR 9'!E12+'JOUR 10'!E12+'JOUR 11'!E12+#REF!+#REF!+#REF!+#REF!+#REF! -> #REF! | F12: ='JOUR 1'!F12+'JOUR 2'!F12+'JOUR 3'!F12+'JOUR 4'!F12+'JOUR 5'!F12+'JOUR 6'!F12+'JOUR 7'!F12+'JOUR 8'!F12+'JOUR 9'!F12+'JOUR 10'!F12+'JOUR 11'!F12+#REF!+#REF!+#REF!+#REF!+#REF! -> #REF! | G12: ='JOUR 1'!G12+'JOUR 2'!G12+'JOUR 3'!G12+'JOUR 4'!G12+'JOUR 5'!G12+'JOUR 6'!G12+'JOUR 7'!G12+'JOUR 8'!G12+'JOUR 9'!G12+'JOUR 10'!G12+'JOUR 11'!G12+#REF!+#REF!+#REF!+#REF!+#REF! -> #REF! | H12: ='JOUR 1'!H12+'JOUR 2'!H12+'JOUR 3'!H12+'JOUR 4'!H12+'JOUR 5'!H12+'JOUR 6'!H12+'JOUR 7'!H12+'JOUR 8'!H12+'JOUR 9'!H12+'JOUR 10'!H12+'JOUR 11'!H12+#REF!+#REF!+#REF!+#REF!+#REF! -> #REF! | I12: ='JOUR 1'!I12+'JOUR 2'!I12+'JOUR 3'!I12+'JOUR 4'!I12+'JOUR 5'!I12+'JOUR 6'!I12+'JOUR 7'!I12+'JOUR 8'!I12+'JOUR 9'!I12+'JOUR 10'!I12+'JOUR 11'!I12+#REF!+#REF!+#REF!+#REF!+#REF! -> #REF! | J12: ='JOUR 1'!J12+'JOUR 2'!J12+'JOUR 3'!J12+'JOUR 4'!J12+'JOUR 5'!J12+'JOUR 6'!J12+'JOUR 7'!J12+'JOUR 8'!J12+'JOUR 9'!J12+'JOUR 10'!J12+'JOUR 11'!J12+#REF!+#REF!+#REF!+#REF!+#REF! -> #REF! | K12: ='JOUR 1'!K12+'JOUR 2'!K12+'JOUR 3'!K12+'JOUR 4'!K12+'JOUR 5'!K12+'JOUR 6'!K12+'JOUR 7'!K12+'JOUR 8'!K12+'JOUR 9'!K12+'JOUR 10'!K12+'JOUR 11'!K12+#REF!+#REF!+#REF!+#REF!+#REF! -> #REF! | ... AG12: ='JOUR 1'!AG12+'JOUR 2'!AG12+'JOUR 3'!AG12+'JOUR 4'!AG12+'JOUR 5'!AG12+'JOUR 6'!AG12+'JOUR 7'!AG12+'JOUR 8'!AG12+'JOUR 9'!AG12+'JOUR 10'!AG12+'JOUR 11'!AG12+#REF!+#REF!+#REF!+#REF!+#REF! -> #REF! | AK12: =S12/D12 -> #REF! | AL12: =T12/E12 -> #REF! | AM12: =U12/F12 -> #REF! | AN12: =V12/G12 -> #REF! | AO12: =W12/H12 -> #REF! | AS12: =AA12/L12 -> #REF!
B13: AUCHAN | C13: AUCHAN YOPOUGON COMPLEXE | D13: ='JOUR 1'!D13+'JOUR 2'!D13+'JOUR 3'!D13+'JOUR 4'!D13+'JOUR 5'!D13+'JOUR 6'!D13+'JOUR 7'!D13+'JOUR 8'!D13+'JOUR 9'!D13+'JOUR 10'!D13+'JOUR 11'!D13+#REF!+#REF!+#REF!+#REF!+#REF! -> #REF! | E13: ='JOUR 1'!E13+'JOUR 2'!E13+'JOUR 3'!E13+'JOUR 4'!E13+'JOUR 5'!E13+'JOUR 6'!E13+'JOUR 7'!E13+'JOUR 8'!E13+'JOUR 9'!E13+'JOUR 10'!E13+'JOUR 11'!E13+#REF!+#REF!+#REF!+#REF!+#REF! -> #REF! | F13: ='JOUR 1'!F13+'JOUR 2'!F13+'JOUR 3'!F13+'JOUR 4'!F13+'JOUR 5'!F13+'JOUR 6'!F13+'JOUR 7'!F13+'JOUR 8'!F13+'JOUR 9'!F13+'JOUR 10'!F13+'JOUR 11'!F13+#REF!+#REF!+#REF!+#REF!+#REF! -> #REF! | G13: ='JOUR 1'!G13+'JOUR 2'!G13+'JOUR 3'!G13+'JOUR 4'!G13+'JOUR 5'!G13+'JOUR 6'!G13+'JOUR 7'!G13+'JOUR 8'!G13+'JOUR 9'!G13+'JOUR 10'!G13+'JOUR 11'!G13+#REF!+#REF!+#REF!+#REF!+#REF! -> #REF! | H13: ='JOUR 1'!H13+'JOUR 2'!H13+'JOUR 3'!H13+'JOUR 4'!H13+'JOUR 5'!H13+'JOUR 6'!H13+'JOUR 7'!H13+'JOUR 8'!H13+'JOUR 9'!H13+'JOUR 10'!H13+'JOUR 11'!H13+#REF!+#REF!+#REF!+#REF!+#REF! -> #REF! | I13: ='JOUR 1'!I13+'JOUR 2'!I13+'JOUR 3'!I13+'JOUR 4'!I13+'JOUR 5'!I13+'JOUR 6'!I13+'JOUR 7'!I13+'JOUR 8'!I13+'JOUR 9'!I13+'JOUR 10'!I13+'JOUR 11'!I13+#REF!+#REF!+#REF!+#REF!+#REF! -> #REF! | J13: ='JOUR 1'!J13+'JOUR 2'!J13+'JOUR 3'!J13+'JOUR 4'!J13+'JOUR 5'!J13+'JOUR 6'!J13+'JOUR 7'!J13+'JOUR 8'!J13+'JOUR 9'!J13+'JOUR 10'!J13+'JOUR 11'!J13+#REF!+#REF!+#REF!+#REF!+#REF! -> #REF! | K13: ='JOUR 1'!K13+'JOUR 2'!K13+'JOUR 3'!K13+'JOUR 4'!K13+'JOUR 5'!K13+'JOUR 6'!K13+'JOUR 7'!K13+'JOUR 8'!K13+'JOUR 9'!K13+'JOUR 10'!K13+'JOUR 11'!K13+#REF!+#REF!+#REF!+#REF!+#REF! -> #REF! | ... AG13: ='JOUR 1'!AG13+'JOUR 2'!AG13+'JOUR 3'!AG13+'JOUR 4'!AG13+'JOUR 5'!AG13+'JOUR 6'!AG13+'JOUR 7'!AG13+'JOUR 8'!AG13+'JOUR 9'!AG13+'JOUR 10'!AG13+'JOUR 11'!AG13+#REF!+#REF!+#REF!+#REF!+#REF! -> #REF! | AK13: =S13/D13 -> #REF! | AL13: =T13/E13 -> #REF! | AM13: =U13/F13 -> #REF! | AN13: =V13/G13 -> #REF! | AO13: =W13/H13 -> #REF! | AS13: =AA13/L13 -> #REF!
B14: AUCHAN | C14: AUCHAN TREICHVILLE ROND-POINT | D14: ='JOUR 1'!D14+'JOUR 2'!D14+'JOUR 3'!D14+'JOUR 4'!D14+'JOUR 5'!D14+'JOUR 6'!D14+'JOUR 7'!D14+'JOUR 8'!D14+'JOUR 9'!D14+'JOUR 10'!D14+'JOUR 11'!D14+#REF!+#REF!+#REF!+#REF!+#REF! -> #REF! | E14: ='JOUR 1'!E14+'JOUR 2'!E14+'JOUR 3'!E14+'JOUR 4'!E14+'JOUR 5'!E14+'JOUR 6'!E14+'JOUR 7'!E14+'JOUR 8'!E14+'JOUR 9'!E14+'JOUR 10'!E14+'JOUR 11'!E14+#REF!+#REF!+#REF!+#REF!+#REF! -> #REF! | F14: ='JOUR 1'!F14+'JOUR 2'!F14+'JOUR 3'!F14+'JOUR 4'!F14+'JOUR 5'!F14+'JOUR 6'!F14+'JOUR 7'!F14+'JOUR 8'!F14+'JOUR 9'!F14+'JOUR 10'!F14+'JOUR 11'!F14+#REF!+#REF!+#REF!+#REF!+#REF! -> #REF! | G14: ='JOUR 1'!G14+'JOUR 2'!G14+'JOUR 3'!G14+'JOUR 4'!G14+'JOUR 5'!G14+'JOUR 6'!G14+'JOUR 7'!G14+'JOUR 8'!G14+'JOUR 9'!G14+'JOUR 10'!G14+'JOUR 11'!G14+#REF!+#REF!+#REF!+#REF!+#REF! -> #REF! | H14: ='JOUR 1'!H14+'JOUR 2'!H14+'JOUR 3'!H14+'JOUR 4'!H14+'JOUR 5'!H14+'JOUR 6'!H14+'JOUR 7'!H14+'JOUR 8'!H14+'JOUR 9'!H14+'JOUR 10'!H14+'JOUR 11'!H14+#REF!+#REF!+#REF!+#REF!+#REF! -> #REF! | I14: ='JOUR 1'!I14+'JOUR 2'!I14+'JOUR 3'!I14+'JOUR 4'!I14+'JOUR 5'!I14+'JOUR 6'!I14+'JOUR 7'!I14+'JOUR 8'!I14+'JOUR 9'!I14+'JOUR 10'!I14+'JOUR 11'!I14+#REF!+#REF!+#REF!+#REF!+#REF! -> #REF! | J14: ='JOUR 1'!J14+'JOUR 2'!J14+'JOUR 3'!J14+'JOUR 4'!J14+'JOUR 5'!J14+'JOUR 6'!J14+'JOUR 7'!J14+'JOUR 8'!J14+'JOUR 9'!J14+'JOUR 10'!J14+'JOUR 11'!J14+#REF!+#REF!+#REF!+#REF!+#REF! -> #REF! | K14: ='JOUR 1'!K14+'JOUR 2'!K14+'JOUR 3'!K14+'JOUR 4'!K14+'JOUR 5'!K14+'JOUR 6'!K14+'JOUR 7'!K14+'JOUR 8'!K14+'JOUR 9'!K14+'JOUR 10'!K14+'JOUR 11'!K14+#REF!+#REF!+#REF!+#REF!+#REF! -> #REF! | ... AG14: ='JOUR 1'!AG14+'JOUR 2'!AG14+'JOUR 3'!AG14+'JOUR 4'!AG14+'JOUR 5'!AG14+'JOUR 6'!AG14+'JOUR 7'!AG14+'JOUR 8'!AG14+'JOUR 9'!AG14+'JOUR 10'!AG14+'JOUR 11'!AG14+#REF!+#REF!+#REF!+#REF!+#REF! -> #REF! | AK14: =S14/D14 -> #REF! | AL14: =T14/E14 -> #REF! | AM14: =U14/F14 -> #REF! | AN14: =V14/G14 -> #REF! | AO14: =W14/H14 -> #REF! | AS14: =AA14/L14 -> #REF!
B15: AUCHAN | C15: AUCHAN ZONE 4 | D15: ='JOUR 1'!D15+'JOUR 2'!D15+'JOUR 3'!D15+'JOUR 4'!D15+'JOUR 5'!D15+'JOUR 6'!D15+'JOUR 7'!D15+'JOUR 8'!D15+'JOUR 9'!D15+'JOUR 10'!D15+'JOUR 11'!D15+#REF!+#REF!+#REF!+#REF!+#REF! -> #REF! | E15: ='JOUR 1'!E15+'JOUR 2'!E15+'JOUR 3'!E15+'JOUR 4'!E15+'JOUR 5'!E15+'JOUR 6'!E15+'JOUR 7'!E15+'JOUR 8'!E15+'JOUR 9'!E15+'JOUR 10'!E15+'JOUR 11'!E15+#REF!+#REF!+#REF!+#REF!+#REF! -> #REF! | F15: ='JOUR 1'!F15+'JOUR 2'!F15+'JOUR 3'!F15+'JOUR 4'!F15+'JOUR 5'!F15+'JOUR 6'!F15+'JOUR 7'!F15+'JOUR 8'!F15+'JOUR 9'!F15+'JOUR 10'!F15+'JOUR 11'!F15+#REF!+#REF!+#REF!+#REF!+#REF! -> #REF! | G15: ='JOUR 1'!G15+'JOUR 2'!G15+'JOUR 3'!G15+'JOUR 4'!G15+'JOUR 5'!G15+'JOUR 6'!G15+'JOUR 7'!G15+'JOUR 8'!G15+'JOUR 9'!G15+'JOUR 10'!G15+'JOUR 11'!G15+#REF!+#REF!+#REF!+#REF!+#REF! -> #REF! | H15: ='JOUR 1'!H15+'JOUR 2'!H15+'JOUR 3'!H15+'JOUR 4'!H15+'JOUR 5'!H15+'JOUR 6'!H15+'JOUR 7'!H15+'JOUR 8'!H15+'JOUR 9'!H15+'JOUR 10'!H15+'JOUR 11'!H15+#REF!+#REF!+#REF!+#REF!+#REF! -> #REF! | I15: ='JOUR 1'!I15+'JOUR 2'!I15+'JOUR 3'!I15+'JOUR 4'!I15+'JOUR 5'!I15+'JOUR 6'!I15+'JOUR 7'!I15+'JOUR 8'!I15+'JOUR 9'!I15+'JOUR 10'!I15+'JOUR 11'!I15+#REF!+#REF!+#REF!+#REF!+#REF! -> #REF! | J15: ='JOUR 1'!J15+'JOUR 2'!J15+'JOUR 3'!J15+'JOUR 4'!J15+'JOUR 5'!J15+'JOUR 6'!J15+'JOUR 7'!J15+'JOUR 8'!J15+'JOUR 9'!J15+'JOUR 10'!J15+'JOUR 11'!J15+#REF!+#REF!+#REF!+#REF!+#REF! -> #REF! | K15: ='JOUR 1'!K15+'JOUR 2'!K15+'JOUR 3'!K15+'JOUR 4'!K15+'JOUR 5'!K15+'JOUR 6'!K15+'JOUR 7'!K15+'JOUR 8'!K15+'JOUR 9'!K15+'JOUR 10'!K15+'JOUR 11'!K15+#REF!+#REF!+#REF!+#REF!+#REF! -> #REF! | ... AG15: ='JOUR 1'!AG15+'JOUR 2'!AG15+'JOUR 3'!AG15+'JOUR 4'!AG15+'JOUR 5'!AG15+'JOUR 6'!AG15+'JOUR 7'!AG15+'JOUR 8'!AG15+'JOUR 9'!AG15+'JOUR 10'!AG15+'JOUR 11'!AG15+#REF!+#REF!+#REF!+#REF!+#REF! -> #REF! | AK15: =S15/D15 -> #REF! | AL15: =T15/E15 -> #REF! | AM15: =U15/F15 -> #REF! | AN15: =V15/G15 -> #REF! | AO15: =W15/H15 -> #REF! | AS15: =AA15/L15 -> #REF!
B16: AUCHAN | C16: AUCHAN BOUAKE | D16: ='JOUR 1'!D16+'JOUR 2'!D16+'JOUR 3'!D16+'JOUR 4'!D16+'JOUR 5'!D16+'JOUR 6'!D16+'JOUR 7'!D16+'JOUR 8'!D16+'JOUR 9'!D16+'JOUR 10'!D16+'JOUR 11'!D16+#REF!+#REF!+#REF!+#REF!+#REF! -> #REF! | E16: ='JOUR 1'!E16+'JOUR 2'!E16+'JOUR 3'!E16+'JOUR 4'!E16+'JOUR 5'!E16+'JOUR 6'!E16+'JOUR 7'!E16+'JOUR 8'!E16+'JOUR 9'!E16+'JOUR 10'!E16+'JOUR 11'!E16+#REF!+#REF!+#REF!+#REF!+#REF! -> #REF! | F16: ='JOUR 1'!F16+'JOUR 2'!F16+'JOUR 3'!F16+'JOUR 4'!F16+'JOUR 5'!F16+'JOUR 6'!F16+'JOUR 7'!F16+'JOUR 8'!F16+'JOUR 9'!F16+'JOUR 10'!F16+'JOUR 11'!F16+#REF!+#REF!+#REF!+#REF!+#REF! -> #REF! | G16: ='JOUR 1'!G16+'JOUR 2'!G16+'JOUR 3'!G16+'JOUR 4'!G16+'JOUR 5'!G16+'JOUR 6'!G16+'JOUR 7'!G16+'JOUR 8'!G16+'JOUR 9'!G16+'JOUR 10'!G16+'JOUR 11'!G16+#REF!+#REF!+#REF!+#REF!+#REF! -> #REF! | H16: ='JOUR 1'!H16+'JOUR 2'!H16+'JOUR 3'!H16+'JOUR 4'!H16+'JOUR 5'!H16+'JOUR 6'!H16+'JOUR 7'!H16+'JOUR 8'!H16+'JOUR 9'!H16+'JOUR 10'!H16+'JOUR 11'!H16+#REF!+#REF!+#REF!+#REF!+#REF! -> #REF! | I16: ='JOUR 1'!I16+'JOUR 2'!I16+'JOUR 3'!I16+'JOUR 4'!I16+'JOUR 5'!I16+'JOUR 6'!I16+'JOUR 7'!I16+'JOUR 8'!I16+'JOUR 9'!I16+'JOUR 10'!I16+'JOUR 11'!I16+#REF!+#REF!+#REF!+#REF!+#REF! -> #REF! | J16: ='JOUR 1'!J16+'JOUR 2'!J16+'JOUR 3'!J16+'JOUR 4'!J16+'JOUR 5'!J16+'JOUR 6'!J16+'JOUR 7'!J16+'JOUR 8'!J16+'JOUR 9'!J16+'JOUR 10'!J16+'JOUR 11'!J16+#REF!+#REF!+#REF!+#REF!+#REF! -> #REF! | K16: ='JOUR 1'!K16+'JOUR 2'!K16+'JOUR 3'!K16+'JOUR 4'!K16+'JOUR 5'!K16+'JOUR 6'!K16+'JOUR 7'!K16+'JOUR 8'!K16+'JOUR 9'!K16+'JOUR 10'!K16+'JOUR 11'!K16+#REF!+#REF!+#REF!+#REF!+#REF! -> #REF! | ... AG16: ='JOUR 1'!AG16+'JOUR 2'!AG16+'JOUR 3'!AG16+'JOUR 4'!AG16+'JOUR 5'!AG16+'JOUR 6'!AG16+'JOUR 7'!AG16+'JOUR 8'!AG16+'JOUR 9'!AG16+'JOUR 10'!AG16+'JOUR 11'!AG16+#REF!+#REF!+#REF!+#REF!+#REF! -> #REF! | AK16: =S16/D16 -> #REF! | AL16: =T16/E16 -> #REF! | AM16: =U16/F16 -> #REF! | AN16: =V16/G16 -> #REF! | AO16: =W16/H16 -> #REF! | AS16: =AA16/L16 -> #REF!
B17: AUCHAN | C17: AUCHAN YAMOUSSOUKRO | D17: ='JOUR 1'!D17+'JOUR 2'!D17+'JOUR 3'!D17+'JOUR 4'!D17+'JOUR 5'!D17+'JOUR 6'!D17+'JOUR 7'!D17+'JOUR 8'!D17+'JOUR 9'!D17+'JOUR 10'!D17+'JOUR 11'!D17+#REF!+#REF!+#REF!+#REF!+#REF! -> #REF! | E17: ='JOUR 1'!E17+'JOUR 2'!E17+'JOUR 3'!E17+'JOUR 4'!E17+'JOUR 5'!E17+'JOUR 6'!E17+'JOUR 7'!E17+'JOUR 8'!E17+'JOUR 9'!E17+'JOUR 10'!E17+'JOUR 11'!E17+#REF!+#REF!+#REF!+#REF!+#REF! -> #REF! | F17: ='JOUR 1'!F17+'JOUR 2'!F17+'JOUR 3'!F17+'JOUR 4'!F17+'JOUR 5'!F17+'JOUR 6'!F17+'JOUR 7'!F17+'JOUR 8'!F17+'JOUR 9'!F17+'JOUR 10'!F17+'JOUR 11'!F17+#REF!+#REF!+#REF!+#REF!+#REF! -> #REF! | G17: ='JOUR 1'!G17+'JOUR 2'!G17+'JOUR 3'!G17+'JOUR 4'!G17+'JOUR 5'!G17+'JOUR 6'!G17+'JOUR 7'!G17+'JOUR 8'!G17+'JOUR 9'!G17+'JOUR 10'!G17+'JOUR 11'!G17+#REF!+#REF!+#REF!+#REF!+#REF! -> #REF! | H17: ='JOUR 1'!H17+'JOUR 2'!H17+'JOUR 3'!H17+'JOUR 4'!H17+'JOUR 5'!H17+'JOUR 6'!H17+'JOUR 7'!H17+'JOUR 8'!H17+'JOUR 9'!H17+'JOUR 10'!H17+'JOUR 11'!H17+#REF!+#REF!+#REF!+#REF!+#REF! -> #REF! | I17: ='JOUR 1'!I17+'JOUR 2'!I17+'JOUR 3'!I17+'JOUR 4'!I17+'JOUR 5'!I17+'JOUR 6'!I17+'JOUR 7'!I17+'JOUR 8'!I17+'JOUR 9'!I17+'JOUR 10'!I17+'JOUR 11'!I17+#REF!+#REF!+#REF!+#REF!+#REF! -> #REF! | J17: ='JOUR 1'!J17+'JOUR 2'!J17+'JOUR 3'!J17+'JOUR 4'!J17+'JOUR 5'!J17+'JOUR 6'!J17+'JOUR 7'!J17+'JOUR 8'!J17+'JOUR 9'!J17+'JOUR 10'!J17+'JOUR 11'!J17+#REF!+#REF!+#REF!+#REF!+#REF! -> #REF! | K17: ='JOUR 1'!K17+'JOUR 2'!K17+'JOUR 3'!K17+'JOUR 4'!K17+'JOUR 5'!K17+'JOUR 6'!K17+'JOUR 7'!K17+'JOUR 8'!K17+'JOUR 9'!K17+'JOUR 10'!K17+'JOUR 11'!K17+#REF!+#REF!+#REF!+#REF!+#REF! -> #REF! | ... AG17: ='JOUR 1'!AG17+'JOUR 2'!AG17+'JOUR 3'!AG17+'JOUR 4'!AG17+'JOUR 5'!AG17+'JOUR 6'!AG17+'JOUR 7'!AG17+'JOUR 8'!AG17+'JOUR 9'!AG17+'JOUR 10'!AG17+'JOUR 11'!AG17+#REF!+#REF!+#REF!+#REF!+#REF! -> #REF! | AK17: =S17/D17 -> #REF! | AL17: =T17/E17 -> #REF! | AM17: =U17/F17 -> #REF! | AN17: =V17/G17 -> #REF! | AO17: =W17/H17 -> #REF! | AS17: =AA17/L17 -> #REF!
D18: ='JOUR 1'!D18+'JOUR 2'!D18+'JOUR 3'!D18+'JOUR 4'!D18+'JOUR 5'!D18+'JOUR 6'!D18+'JOUR 7'!D18+'JOUR 8'!D18+'JOUR 9'!D18+'JOUR 10'!D18+'JOUR 11'!D18+#REF!+#REF!+#REF!+#REF!+#REF! -> #VALUE! | E18: ='JOUR 1'!E18+'JOUR 2'!E18+'JOUR 3'!E18+'JOUR 4'!E18+'JOUR 5'!E18+'JOUR 6'!E18+'JOUR 7'!E18+'JOUR 8'!E18+'JOUR 9'!E18+'JOUR 10'!E18+'JOUR 11'!E18+#REF!+#REF!+#REF!+#REF!+#REF! -> #REF! | F18: ='JOUR 1'!F18+'JOUR 2'!F18+'JOUR 3'!F18+'JOUR 4'!F18+'JOUR 5'!F18+'JOUR 6'!F18+'JOUR 7'!F18+'JOUR 8'!F18+'JOUR 9'!F18+'JOUR 10'!F18+'JOUR 11'!F18+#REF!+#REF!+#REF!+#REF!+#REF! -> #REF! | G18: ='JOUR 1'!G18+'JOUR 2'!G18+'JOUR 3'!G18+'JOUR 4'!G18+'JOUR 5'!G18+'JOUR 6'!G18+'JOUR 7'!G18+'JOUR 8'!G18+'JOUR 9'!G18+'JOUR 10'!G18+'JOUR 11'!G18+#REF!+#REF!+#REF!+#REF!+#REF! -> #REF! | H18: ='JOUR 1'!H18+'JOUR 2'!H18+'JOUR 3'!H18+'JOUR 4'!H18+'JOUR 5'!H18+'JOUR 6'!H18+'JOUR 7'!H18+'JOUR 8'!H18+'JOUR 9'!H18+'JOUR 10'!H18+'JOUR 11'!H18+#REF!+#REF!+#REF!+#REF!+#REF! -> #REF! | I18: ='JOUR 1'!I18+'JOUR 2'!I18+'JOUR 3'!I18+'JOUR 4'!I18+'JOUR 5'!I18+'JOUR 6'!I18+'JOUR 7'!I18+'JOUR 8'!I18+'JOUR 9'!I18+'JOUR 10'!I18+'JOUR 11'!I18+#REF!+#REF!+#REF!+#REF!+#REF! -> #REF! | J18: ='JOUR 1'!J18+'JOUR 2'!J18+'JOUR 3'!J18+'JOUR 4'!J18+'JOUR 5'!J18+'JOUR 6'!J18+'JOUR 7'!J18+'JOUR 8'!J18+'JOUR 9'!J18+'JOUR 10'!J18+'JOUR 11'!J18+#REF!+#REF!+#REF!+#REF!+#REF! -> #REF! | K18: ='JOUR 1'!K18+'JOUR 2'!K18+'JOUR 3'!K18+'JOUR 4'!K18+'JOUR 5'!K18+'JOUR 6'!K18+'JOUR 7'!K18+'JOUR 8'!K18+'JOUR 9'!K18+'JOUR 10'!K18+'JOUR 11'!K18+#REF!+#REF!+#REF!+#REF!+#REF! -> #REF! | ... AG18: ='JOUR 1'!AG18+'JOUR 2'!AG18+'JOUR 3'!AG18+'JOUR 4'!AG18+'JOUR 5'!AG18+'JOUR 6'!AG18+'JOUR 7'!AG18+'JOUR 8'!AG18+'JOUR 9'!AG18+'JOUR 10'!AG18+'JOUR 11'!AG18+#REF!+#REF!+#REF!+#REF!+#REF! -> #REF!
D19: ='JOUR 1'!D19+'JOUR 2'!D19+'JOUR 3'!D19+'JOUR 4'!D19+'JOUR 5'!D19+'JOUR 6'!D19+'JOUR 7'!D19+'JOUR 8'!D19+'JOUR 9'!D19+'JOUR 10'!D19+'JOUR 11'!D19+#REF!+#REF!+#REF!+#REF!+#REF! -> #REF! | E19: ='JOUR 1'!E19+'JOUR 2'!E19+'JOUR 3'!E19+'JOUR 4'!E19+'JOUR 5'!E19+'JOUR 6'!E19+'JOUR 7'!E19+'JOUR 8'!E19+'JOUR 9'!E19+'JOUR 10'!E19+'JOUR 11'!E19+#REF!+#REF!+#REF!+#REF!+#REF! -> #REF! | F19: ='JOUR 1'!F19+'JOUR 2'!F19+'JOUR 3'!F19+'JOUR 4'!F19+'JOUR 5'!F19+'JOUR 6'!F19+'JOUR 7'!F19+'JOUR 8'!F19+'JOUR 9'!F19+'JOUR 10'!F19+'JOUR 11'!F19+#REF!+#REF!+#REF!+#REF!+#REF! -> #REF! | G19: ='JOUR 1'!G19+'JOUR 2'!G19+'JOUR 3'!G19+'JOUR 4'!G19+'JOUR 5'!G19+'JOUR 6'!G19+'JOUR 7'!G19+'JOUR 8'!G19+'JOUR 9'!G19+'JOUR 10'!G19+'JOUR 11'!G19+#REF!+#REF!+#REF!+#REF!+#REF! -> #REF! | H19: ='JOUR 1'!H19+'JOUR 2'!H19+'JOUR 3'!H19+'JOUR 4'!H19+'JOUR 5'!H19+'JOUR 6'!H19+'JOUR 7'!H19+'JOUR 8'!H19+'JOUR 9'!H19+'JOUR 10'!H19+'JOUR 11'!H19+#REF!+#REF!+#REF!+#REF!+#REF! -> #REF! | I19: ='JOUR 1'!I19+'JOUR 2'!I19+'JOUR 3'!I19+'JOUR 4'!I19+'JOUR 5'!I19+'JOUR 6'!I19+'JOUR 7'!I19+'JOUR 8'!I19+'JOUR 9'!I19+'JOUR 10'!I19+'JOUR 11'!I19+#REF!+#REF!+#REF!+#REF!+#REF! -> #REF! | J19: ='JOUR 1'!J19+'JOUR 2'!J19+'JOUR 3'!J19+'JOUR 4'!J19+'JOUR 5'!J19+'JOUR 6'!J19+'JOUR 7'!J19+'JOUR 8'!J19+'JOUR 9'!J19+'JOUR 10'!J19+'JOUR 11'!J19+#REF!+#REF!+#REF!+#REF!+#REF! -> #REF! | K19: ='JOUR 1'!K19+'JOUR 2'!K19+'JOUR 3'!K19+'JOUR 4'!K19+'JOUR 5'!K19+'JOUR 6'!K19+'JOUR 7'!K19+'JOUR 8'!K19+'JOUR 9'!K19+'JOUR 10'!K19+'JOUR 11'!K19+#REF!+#REF!+#REF!+#REF!+#REF! -> #REF! | ... AG19: ='JOUR 1'!AG19+'JOUR 2'!AG19+'JOUR 3'!AG19+'JOUR 4'!AG19+'JOUR 5'!AG19+'JOUR 6'!AG19+'JOUR 7'!AG19+'JOUR 8'!AG19+'JOUR 9'!AG19+'JOUR 10'!AG19+'JOUR 11'!AG19+#REF!+#REF!+#REF!+#REF!+#REF! -> #REF!
D20: ='JOUR 1'!D20+'JOUR 2'!D20+'JOUR 3'!D20+'JOUR 4'!D20+'JOUR 5'!D20+'JOUR 6'!D20+'JOUR 7'!D20+'JOUR 8'!D20+'JOUR 9'!D20+'JOUR 10'!D20+'JOUR 11'!D20+#REF!+#REF!+#REF!+#REF!+#REF! -> #REF! | E20: ='JOUR 1'!E20+'JOUR 2'!E20+'JOUR 3'!E20+'JOUR 4'!E20+'JOUR 5'!E20+'JOUR 6'!E20+'JOUR 7'!E20+'JOUR 8'!E20+'JOUR 9'!E20+'JOUR 10'!E20+'JOUR 11'!E20+#REF!+#REF!+#REF!+#REF!+#REF! -> #REF! | F20: ='JOUR 1'!F20+'JOUR 2'!F20+'JOUR 3'!F20+'JOUR 4'!F20+'JOUR 5'!F20+'JOUR 6'!F20+'JOUR 7'!F20+'JOUR 8'!F20+'JOUR 9'!F20+'JOUR 10'!F20+'JOUR 11'!F20+#REF!+#REF!+#REF!+#REF!+#REF! -> #REF! | G20: ='JOUR 1'!G20+'JOUR 2'!G20+'JOUR 3'!G20+'JOUR 4'!G20+'JOUR 5'!G20+'JOUR 6'!G20+'JOUR 7'!G20+'JOUR 8'!G20+'JOUR 9'!G20+'JOUR 10'!G20+'JOUR 11'!G20+#REF!+#REF!+#REF!+#REF!+#REF! -> #REF! | H20: ='JOUR 1'!H20+'JOUR 2'!H20+'JOUR 3'!H20+'JOUR 4'!H20+'JOUR 5'!H20+'JOUR 6'!H20+'JOUR 7'!H20+'JOUR 8'!H20+'JOUR 9'!H20+'JOUR 10'!H20+'JOUR 11'!H20+#REF!+#REF!+#REF!+#REF!+#REF! -> #REF! | I20: ='JOUR 1'!I20+'JOUR 2'!I20+'JOUR 3'!I20+'JOUR 4'!I20+'JOUR 5'!I20+'JOUR 6'!I20+'JOUR 7'!I20+'JOUR 8'!I20+'JOUR 9'!I20+'JOUR 10'!I20+'JOUR 11'!I20+#REF!+#REF!+#REF!+#REF!+#REF! -> #REF! | J20: ='JOUR 1'!J20+'JOUR 2'!J20+'JOUR 3'!J20+'JOUR 4'!J20+'JOUR 5'!J20+'JOUR 6'!J20+'JOUR 7'!J20+'JOUR 8'!J20+'JOUR 9'!J20+'JOUR 10'!J20+'JOUR 11'!J20+#REF!+#REF!+#REF!+#REF!+#REF! -> #REF! | K20: ='JOUR 1'!K20+'JOUR 2'!K20+'JOUR 3'!K20+'JOUR 4'!K20+'JOUR 5'!K20+'JOUR 6'!K20+'JOUR 7'!K20+'JOUR 8'!K20+'JOUR 9'!K20+'JOUR 10'!K20+'JOUR 11'!K20+#REF!+#REF!+#REF!+#REF!+#REF! -> #REF! | ... AG20: ='JOUR 1'!AG20+'JOUR 2'!AG20+'JOUR 3'!AG20+'JOUR 4'!AG20+'JOUR 5'!AG20+'JOUR 6'!AG20+'JOUR 7'!AG20+'JOUR 8'!AG20+'JOUR 9'!AG20+'JOUR 10'!AG20+'JOUR 11'!AG20+#REF!+#REF!+#REF!+#REF!+#REF! -> #REF!
D21: ='JOUR 1'!D21+'JOUR 2'!D21+'JOUR 3'!D21+'JOUR 4'!D21+'JOUR 5'!D21+'JOUR 6'!D21+'JOUR 7'!D21+'JOUR 8'!D21+'JOUR 9'!D21+'JOUR 10'!D21+'JOUR 11'!D21+#REF!+#REF!+#REF!+#REF!+#REF! -> #REF! | E21: ='JOUR 1'!E21+'JOUR 2'!E21+'JOUR 3'!E21+'JOUR 4'!E21+'JOUR 5'!E21+'JOUR 6'!E21+'JOUR 7'!E21+'JOUR 8'!E21+'JOUR 9'!E21+'JOUR 10'!E21+'JOUR 11'!E21+#REF!+#REF!+#REF!+#REF!+#REF! -> #REF! | F21: ='JOUR 1'!F21+'JOUR 2'!F21+'JOUR 3'!F21+'JOUR 4'!F21+'JOUR 5'!F21+'JOUR 6'!F21+'JOUR 7'!F21+'JOUR 8'!F21+'JOUR 9'!F21+'JOUR 10'!F21+'JOUR 11'!F21+#REF!+#REF!+#REF!+#REF!+#REF! -> #REF! | G21: ='JOUR 1'!G21+'JOUR 2'!G21+'JOUR 3'!G21+'JOUR 4'!G21+'JOUR 5'!G21+'JOUR 6'!G21+'JOUR 7'!G21+'JOUR 8'!G21+'JOUR 9'!G21+'JOUR 10'!G21+'JOUR 11'!G21+#REF!+#REF!+#REF!+#REF!+#REF! -> #REF! | H21: ='JOUR 1'!H21+'JOUR 2'!H21+'JOUR 3'!H21+'JOUR 4'!H21+'JOUR 5'!H21+'JOUR 6'!H21+'JOUR 7'!H21+'JOUR 8'!H21+'JOUR 9'!H21+'JOUR 10'!H21+'JOUR 11'!H21+#REF!+#REF!+#REF!+#REF!+#REF! -> #REF! | I21: ='JOUR 1'!I21+'JOUR 2'!I21+'JOUR 3'!I21+'JOUR 4'!I21+'JOUR 5'!I21+'JOUR 6'!I21+'JOUR 7'!I21+'JOUR 8'!I21+'JOUR 9'!I21+'JOUR 10'!I21+'JOUR 11'!I21+#REF!+#REF!+#REF!+#REF!+#REF! -> #REF! | J21: ='JOUR 1'!J21+'JOUR 2'!J21+'JOUR 3'!J21+'JOUR 4'!J21+'JOUR 5'!J21+'JOUR 6'!J21+'JOUR 7'!J21+'JOUR 8'!J21+'JOUR 9'!J21+'JOUR 10'!J21+'JOUR 11'!J21+#REF!+#REF!+#REF!+#REF!+#REF! -> #REF! | K21: ='JOUR 1'!K21+'JOUR 2'!K21+'JOUR 3'!K21+'JOUR 4'!K21+'JOUR 5'!K21+'JOUR 6'!K21+'JOUR 7'!K21+'JOUR 8'!K21+'JOUR 9'!K21+'JOUR 10'!K21+'JOUR 11'!K21+#REF!+#REF!+#REF!+#REF!+#REF! -> #REF! | ... AG21: ='JOUR 1'!AG21+'JOUR 2'!AG21+'JOUR 3'!AG21+'JOUR 4'!AG21+'JOUR 5'!AG21+'JOUR 6'!AG21+'JOUR 7'!AG21+'JOUR 8'!AG21+'JOUR 9'!AG21+'JOUR 10'!AG21+'JOUR 11'!AG21+#REF!+#REF!+#REF!+#REF!+#REF! -> #REF!
D22: ='JOUR 1'!D22+'JOUR 2'!D22+'JOUR 3'!D22+'JOUR 4'!D22+'JOUR 5'!D22+'JOUR 6'!D22+'JOUR 7'!D22+'JOUR 8'!D22+'JOUR 9'!D22+'JOUR 10'!D22+'JOUR 11'!D22+#REF!+#REF!+#REF!+#REF!+#REF! -> #REF! | E22: ='JOUR 1'!E22+'JOUR 2'!E22+'JOUR 3'!E22+'JOUR 4'!E22+'JOUR 5'!E22+'JOUR 6'!E22+'JOUR 7'!E22+'JOUR 8'!E22+'JOUR 9'!E22+'JOUR 10'!E22+'JOUR 11'!E22+#REF!+#REF!+#REF!+#REF!+#REF! -> #REF! | F22: ='JOUR 1'!F22+'JOUR 2'!F22+'JOUR 3'!F22+'JOUR 4'!F22+'JOUR 5'!F22+'JOUR 6'!F22+'JOUR 7'!F22+'JOUR 8'!F22+'JOUR 9'!F22+'JOUR 10'!F22+'JOUR 11'!F22+#REF!+#REF!+#REF!+#REF!+#REF! -> #REF! | G22: ='JOUR 1'!G22+'JOUR 2'!G22+'JOUR 3'!G22+'JOUR 4'!G22+'JOUR 5'!G22+'JOUR 6'!G22+'JOUR 7'!G22+'JOUR 8'!G22+'JOUR 9'!G22+'JOUR 10'!G22+'JOUR 11'!G22+#REF!+#REF!+#REF!+#REF!+#REF! -> #REF! | H22: ='JOUR 1'!H22+'JOUR 2'!H22+'JOUR 3'!H22+'JOUR 4'!H22+'JOUR 5'!H22+'JOUR 6'!H22+'JOUR 7'!H22+'JOUR 8'!H22+'JOUR 9'!H22+'JOUR 10'!H22+'JOUR 11'!H22+#REF!+#REF!+#REF!+#REF!+#REF! -> #REF! | I22: ='JOUR 1'!I22+'JOUR 2'!I22+'JOUR 3'!I22+'JOUR 4'!I22+'JOUR 5'!I22+'JOUR 6'!I22+'JOUR 7'!I22+'JOUR 8'!I22+'JOUR 9'!I22+'JOUR 10'!I22+'JOUR 11'!I22+#REF!+#REF!+#REF!+#REF!+#REF! -> #REF! | J22: ='JOUR 1'!J22+'JOUR 2'!J22+'JOUR 3'!J22+'JOUR 4'!J22+'JOUR 5'!J22+'JOUR 6'!J22+'JOUR 7'!J22+'JOUR 8'!J22+'JOUR 9'!J22+'JOUR 10'!J22+'JOUR 11'!J22+#REF!+#REF!+#REF!+#REF!+#REF! -> #REF! | K22: ='JOUR 1'!K22+'JOUR 2'!K22+'JOUR 3'!K22+'JOUR 4'!K22+'JOUR 5'!K22+'JOUR 6'!K22+'JOUR 7'!K22+'JOUR 8'!K22+'JOUR 9'!K22+'JOUR 10'!K22+'JOUR 11'!K22+#REF!+#REF!+#REF!+#REF!+#REF! -> #REF! | ... AG22: ='JOUR 1'!AG22+'JOUR 2'!AG22+'JOUR 3'!AG22+'JOUR 4'!AG22+'JOUR 5'!AG22+'JOUR 6'!AG22+'JOUR 7'!AG22+'JOUR 8'!AG22+'JOUR 9'!AG22+'JOUR 10'!AG22+'JOUR 11'!AG22+#REF!+#REF!+#REF!+#REF!+#REF! -> #REF!
D23: ='JOUR 1'!D23+'JOUR 2'!D23+'JOUR 3'!D23+'JOUR 4'!D23+'JOUR 5'!D23+'JOUR 6'!D23+'JOUR 7'!D23+'JOUR 8'!D23+'JOUR 9'!D23+'JOUR 10'!D23+'JOUR 11'!D23+#REF!+#REF!+#REF!+#REF!+#REF! -> #REF! | E23: ='JOUR 1'!E23+'JOUR 2'!E23+'JOUR 3'!E23+'JOUR 4'!E23+'JOUR 5'!E23+'JOUR 6'!E23+'JOUR 7'!E23+'JOUR 8'!E23+'JOUR 9'!E23+'JOUR 10'!E23+'JOUR 11'!E23+#REF!+#REF!+#REF!+#REF!+#REF! -> #REF! | F23: ='JOUR 1'!F23+'JOUR 2'!F23+'JOUR 3'!F23+'JOUR 4'!F23+'JOUR 5'!F23+'JOUR 6'!F23+'JOUR 7'!F23+'JOUR 8'!F23+'JOUR 9'!F23+'JOUR 10'!F23+'JOUR 11'!F23+#REF!+#REF!+#REF!+#REF!+#REF! -> #REF! | G23: ='JOUR 1'!G23+'JOUR 2'!G23+'JOUR 3'!G23+'JOUR 4'!G23+'JOUR 5'!G23+'JOUR 6'!G23+'JOUR 7'!G23+'JOUR 8'!G23+'JOUR 9'!G23+'JOUR 10'!G23+'JOUR 11'!G23+#REF!+#REF!+#REF!+#REF!+#REF! -> #REF! | H23: ='JOUR 1'!H23+'JOUR 2'!H23+'JOUR 3'!H23+'JOUR 4'!H23+'JOUR 5'!H23+'JOUR 6'!H23+'JOUR 7'!H23+'JOUR 8'!H23+'JOUR 9'!H23+'JOUR 10'!H23+'JOUR 11'!H23+#REF!+#REF!+#REF!+#REF!+#REF! -> #REF! | I23: ='JOUR 1'!I23+'JOUR 2'!I23+'JOUR 3'!I23+'JOUR 4'!I23+'JOUR 5'!I23+'JOUR 6'!I23+'JOUR 7'!I23+'JOUR 8'!I23+'JOUR 9'!I23+'JOUR 10'!I23+'JOUR 11'!I23+#REF!+#REF!+#REF!+#REF!+#REF! -> #REF! | J23: ='JOUR 1'!J23+'JOUR 2'!J23+'JOUR 3'!J23+'JOUR 4'!J23+'JOUR 5'!J23+'JOUR 6'!J23+'JOUR 7'!J23+'JOUR 8'!J23+'JOUR 9'!J23+'JOUR 10'!J23+'JOUR 11'!J23+#REF!+#REF!+#REF!+#REF!+#REF! -> #REF! | K23: ='JOUR 1'!K23+'JOUR 2'!K23+'JOUR 3'!K23+'JOUR 4'!K23+'JOUR 5'!K23+'JOUR 6'!K23+'JOUR 7'!K23+'JOUR 8'!K23+'JOUR 9'!K23+'JOUR 10'!K23+'JOUR 11'!K23+#REF!+#REF!+#REF!+#REF!+#REF! -> #REF! | ... AG23: ='JOUR 1'!AG23+'JOUR 2'!AG23+'JOUR 3'!AG23+'JOUR 4'!AG23+'JOUR 5'!AG23+'JOUR 6'!AG23+'JOUR 7'!AG23+'JOUR 8'!AG23+'JOUR 9'!AG23+'JOUR 10'!AG23+'JOUR 11'!AG23+#REF!+#REF!+#REF!+#REF!+#REF! -> #REF!
D24: ='JOUR 1'!D24+'JOUR 2'!D24+'JOUR 3'!D24+'JOUR 4'!D24+'JOUR 5'!D24+'JOUR 6'!D24+'JOUR 7'!D24+'JOUR 8'!D24+'JOUR 9'!D24+'JOUR 10'!D24+'JOUR 11'!D24+#REF!+#REF!+#REF!+#REF!+#REF! -> #REF! | E24: ='JOUR 1'!E24+'JOUR 2'!E24+'JOUR 3'!E24+'JOUR 4'!E24+'JOUR 5'!E24+'JOUR 6'!E24+'JOUR 7'!E24+'JOUR 8'!E24+'JOUR 9'!E24+'JOUR 10'!E24+'JOUR 11'!E24+#REF!+#REF!+#REF!+#REF!+#REF! -> #REF! | F24: ='JOUR 1'!F24+'JOUR 2'!F24+'JOUR 3'!F24+'JOUR 4'!F24+'JOUR 5'!F24+'JOUR 6'!F24+'JOUR 7'!F24+'JOUR 8'!F24+'JOUR 9'!F24+'JOUR 10'!F24+'JOUR 11'!F24+#REF!+#REF!+#REF!+#REF!+#REF! -> #REF! | G24: ='JOUR 1'!G24+'JOUR 2'!G24+'JOUR 3'!G24+'JOUR 4'!G24+'JOUR 5'!G24+'JOUR 6'!G24+'JOUR 7'!G24+'JOUR 8'!G24+'JOUR 9'!G24+'JOUR 10'!G24+'JOUR 11'!G24+#REF!+#REF!+#REF!+#REF!+#REF! -> #REF! | H24: ='JOUR 1'!H24+'JOUR 2'!H24+'JOUR 3'!H24+'JOUR 4'!H24+'JOUR 5'!H24+'JOUR 6'!H24+'JOUR 7'!H24+'JOUR 8'!H24+'JOUR 9'!H24+'JOUR 10'!H24+'JOUR 11'!H24+#REF!+#REF!+#REF!+#REF!+#REF! -> #REF! | I24: ='JOUR 1'!I24+'JOUR 2'!I24+'JOUR 3'!I24+'JOUR 4'!I24+'JOUR 5'!I24+'JOUR 6'!I24+'JOUR 7'!I24+'JOUR 8'!I24+'JOUR 9'!I24+'JOUR 10'!I24+'JOUR 11'!I24+#REF!+#REF!+#REF!+#REF!+#REF! -> #REF! | J24: ='JOUR 1'!J24+'JOUR 2'!J24+'JOUR 3'!J24+'JOUR 4'!J24+'JOUR 5'!J24+'JOUR 6'!J24+'JOUR 7'!J24+'JOUR 8'!J24+'JOUR 9'!J24+'JOUR 10'!J24+'JOUR 11'!J24+#REF!+#REF!+#REF!+#REF!+#REF! -> #REF! | K24: ='JOUR 1'!K24+'JOUR 2'!K24+'JOUR 3'!K24+'JOUR 4'!K24+'JOUR 5'!K24+'JOUR 6'!K24+'JOUR 7'!K24+'JOUR 8'!K24+'JOUR 9'!K24+'JOUR 10'!K24+'JOUR 11'!K24+#REF!+#REF!+#REF!+#REF!+#REF! -> #REF! | ... AG24: ='JOUR 1'!AG24+'JOUR 2'!AG24+'JOUR 3'!AG24+'JOUR 4'!AG24+'JOUR 5'!AG24+'JOUR 6'!AG24+'JOUR 7'!AG24+'JOUR 8'!AG24+'JOUR 9'!AG24+'JOUR 10'!AG24+'JOUR 11'!AG24+#REF!+#REF!+#REF!+#REF!+#REF! -> #REF!
A25: 2 | B25: TOTAL | D25: ='JOUR 1'!D25+'JOUR 2'!D25+'JOUR 3'!D25+'JOUR 4'!D25+'JOUR 5'!D25+'JOUR 6'!D25+'JOUR 7'!D25+'JOUR 8'!D25+'JOUR 9'!D25+'JOUR 10'!D25+'JOUR 11'!D25+#REF!+#REF!+#REF!+#REF!+#REF! -> #REF! | E25: ='JOUR 1'!E25+'JOUR 2'!E25+'JOUR 3'!E25+'JOUR 4'!E25+'JOUR 5'!E25+'JOUR 6'!E25+'JOUR 7'!E25+'JOUR 8'!E25+'JOUR 9'!E25+'JOUR 10'!E25+'JOUR 11'!E25+#REF!+#REF!+#REF!+#REF!+#REF! -> #REF! | F25: ='JOUR 1'!F25+'JOUR 2'!F25+'JOUR 3'!F25+'JOUR 4'!F25+'JOUR 5'!F25+'JOUR 6'!F25+'JOUR 7'!F25+'JOUR 8'!F25+'JOUR 9'!F25+'JOUR 10'!F25+'JOUR 11'!F25+#REF!+#REF!+#REF!+#REF!+#REF! -> #REF! | G25: ='JOUR 1'!G25+'JOUR 2'!G25+'JOUR 3'!G25+'JOUR 4'!G25+'JOUR 5'!G25+'JOUR 6'!G25+'JOUR 7'!G25+'JOUR 8'!G25+'JOUR 9'!G25+'JOUR 10'!G25+'JOUR 11'!G25+#REF!+#REF!+#REF!+#REF!+#REF! -> #REF! | H25: ='JOUR 1'!H25+'JOUR 2'!H25+'JOUR 3'!H25+'JOUR 4'!H25+'JOUR 5'!H25+'JOUR 6'!H25+'JOUR 7'!H25+'JOUR 8'!H25+'JOUR 9'!H25+'JOUR 10'!H25+'JOUR 11'!H25+#REF!+#REF!+#REF!+#REF!+#REF! -> #REF! | I25: ='JOUR 1'!I25+'JOUR 2'!I25+'JOUR 3'!I25+'JOUR 4'!I25+'JOUR 5'!I25+'JOUR 6'!I25+'JOUR 7'!I25+'JOUR 8'!I25+'JOUR 9'!I25+'JOUR 10'!I25+'JOUR 11'!I25+#REF!+#REF!+#REF!+#REF!+#REF! -> #REF! | J25: ='JOUR 1'!J25+'JOUR 2'!J25+'JOUR 3'!J25+'JOUR 4'!J25+'JOUR 5'!J25+'JOUR 6'!J25+'JOUR 7'!J25+'JOUR 8'!J25+'JOUR 9'!J25+'JOUR 10'!J25+'JOUR 11'!J25+#REF!+#REF!+#REF!+#REF!+#REF! -> #REF! | K25: ='JOUR 1'!K25+'JOUR 2'!K25+'JOUR 3'!K25+'JOUR 4'!K25+'JOUR 5'!K25+'JOUR 6'!K25+'JOUR 7'!K25+'JOUR 8'!K25+'JOUR 9'!K25+'JOUR 10'!K25+'JOUR 11'!K25+#REF!+#REF!+#REF!+#REF!+#REF! -> #REF! | ... AG25: ='JOUR 1'!AG25+'JOUR 2'!AG25+'JOUR 3'!AG25+'JOUR 4'!AG25+'JOUR 5'!AG25+'JOUR 6'!AG25+'JOUR 7'!AG25+'JOUR 8'!AG25+'JOUR 9'!AG25+'JOUR 10'!AG25+'JOUR 11'!AG25+#REF!+#REF!+#REF!+#REF!+#REF! -> #REF! | AH25: =SUM(AH5:AH5) -> 0 | AI25: =SUM(AI5:AI5) -> 0 | AK25: =S25/D25 -> #REF! | AL25: =T25/E25 -> #REF! | AM25: =U25/F25 -> #REF! | AN25: =V25/G25 -> #REF! | AO25: =W25/H25 -> #REF! | AS25: =AA25/L25 -> #REF!
D26: ='JOUR 1'!D26+'JOUR 2'!D26+'JOUR 3'!D26+'JOUR 4'!D26+'JOUR 5'!D26+'JOUR 6'!D26+'JOUR 7'!D26+'JOUR 8'!D26+'JOUR 9'!D26+'JOUR 10'!D26+'JOUR 11'!D26+#REF!+#REF!+#REF!+#REF!+#REF! -> #REF! | E26: ='JOUR 1'!E26+'JOUR 2'!E26+'JOUR 3'!E26+'JOUR 4'!E26+'JOUR 5'!E26+'JOUR 6'!E26+'JOUR 7'!E26+'JOUR 8'!E26+'JOUR 9'!E26+'JOUR 10'!E26+'JOUR 11'!E26+#REF!+#REF!+#REF!+#REF!+#REF! -> #REF! | F26: ='JOUR 1'!F26+'JOUR 2'!F26+'JOUR 3'!F26+'JOUR 4'!F26+'JOUR 5'!F26+'JOUR 6'!F26+'JOUR 7'!F26+'JOUR 8'!F26+'JOUR 9'!F26+'JOUR 10'!F26+'JOUR 11'!F26+#REF!+#REF!+#REF!+#REF!+#REF! -> #REF! | G26: ='JOUR 1'!G26+'JOUR 2'!G26+'JOUR 3'!G26+'JOUR 4'!G26+'JOUR 5'!G26+'JOUR 6'!G26+'JOUR 7'!G26+'JOUR 8'!G26+'JOUR 9'!G26+'JOUR 10'!G26+'JOUR 11'!G26+#REF!+#REF!+#REF!+#REF!+#REF! -> #REF! | H26: ='JOUR 1'!H26+'JOUR 2'!H26+'JOUR 3'!H26+'JOUR 4'!H26+'JOUR 5'!H26+'JOUR 6'!H26+'JOUR 7'!H26+'JOUR 8'!H26+'JOUR 9'!H26+'JOUR 10'!H26+'JOUR 11'!H26+#REF!+#REF!+#REF!+#REF!+#REF! -> #REF! | I26: ='JOUR 1'!I26+'JOUR 2'!I26+'JOUR 3'!I26+'JOUR 4'!I26+'JOUR 5'!I26+'JOUR 6'!I26+'JOUR 7'!I26+'JOUR 8'!I26+'JOUR 9'!I26+'JOUR 10'!I26+'JOUR 11'!I26+#REF!+#REF!+#REF!+#REF!+#REF! -> #REF! | J26: ='JOUR 1'!J26+'JOUR 2'!J26+'JOUR 3'!J26+'JOUR 4'!J26+'JOUR 5'!J26+'JOUR 6'!J26+'JOUR 7'!J26+'JOUR 8'!J26+'JOUR 9'!J26+'JOUR 10'!J26+'JOUR 11'!J26+#REF!+#REF!+#REF!+#REF!+#REF! -> #REF! | K26: ='JOUR 1'!K26+'JOUR 2'!K26+'JOUR 3'!K26+'JOUR 4'!K26+'JOUR 5'!K26+'JOUR 6'!K26+'JOUR 7'!K26+'JOUR 8'!K26+'JOUR 9'!K26+'JOUR 10'!K26+'JOUR 11'!K26+#REF!+#REF!+#REF!+#REF!+#REF! -> #REF! | ... AG26: ='JOUR 1'!AG26+'JOUR 2'!AG26+'JOUR 3'!AG26+'JOUR 4'!AG26+'JOUR 5'!AG26+'JOUR 6'!AG26+'JOUR 7'!AG26+'JOUR 8'!AG26+'JOUR 9'!AG26+'JOUR 10'!AG26+'JOUR 11'!AG26+#REF!+#REF!+#REF!+#REF!+#REF! -> #REF!
B27: TOTAL EN CARTONS | D27: =D25 -> #REF! | E27: =E25 -> #REF! | F27: =F25/120 -> #REF! | G27: =G25/6 -> #REF! | H27: =H25/10 -> #REF! | I27: =I25/100 -> #REF! | J27: =J25/10 -> #REF! | K27: =K25/60 -> #REF! | L27: =L25/120 -> #REF! | M27: =M25/100 -> #REF! | N27: =N25/60 -> #REF! | O27: =O25 -> #REF! | P27: =P25 -> #REF! | Q27: =Q25 -> #REF! | R27: =R25 -> #REF! | S27: =S25 -> #REF! | T27: =T25 -> #REF! | U27: =U25/120 -> #REF! | V27: =V25/6 -> #REF! | W27: =W25/10 -> #REF! | X27: =X25/100 -> #REF! | Y27: =Y25/20 -> #REF! | Z27: =Z25/60 -> #REF! | AA27: =AA25/120 -> #REF! | AB27: =AB25/100 -> #REF! | AC27: =AC25/60 -> #REF! | AD27: =AD25 -> #REF! | AE27: =AE25 -> #REF! | AF27: =AF25 -> #REF! | AG27: =AG25 -> #REF!

Sheet JOUR 1
B2: Date | C2: 46107 | D2: OBJECTIFS | S2: REALISATIONS | AK2: TAUX DE REALISATION
B3: Enseigne | C3: Nom du PDV en promotion | D3: Contacts | E3: =T3 -> Acheteurs | F3: Produits (en unités) | L3: Gratuités pour achats (en unités) | S3: Contacts | T3: Acheteurs | U3: Produits | AA3: =L3 -> Gratuités pour achats (en unités) | AD3: GOODIES | AH3: Commentaires | AI3: Impressions des PDV et des clients | AK3: Contacts | AL3: Acheteurs | AM3: Produits | AS3: =AD3 -> GOODIES | AV3: GOODIES
D4: =S4 -> Nombre de personnes ayant été contactées au rayon | E4: =T4 -> Nombre de personnes ayant acheté | F4: Biblos Lait Premium 16g | G4: Biblos Lait Premium 360g | H4: Biblos Lait Excellence | I4: Biblos Flocon d'avoine 50g | J4: Biblos Flocon d'avoine 400g | K4: Biblos 3 en 1 Café au lait | L4: Biblos Lait Premium 16g | M4: Biblos Flocon d'avoine 50g | N4: Biblos 3 en Café au Lait | O4: Goodies 1 | P4: Goodies 2 | Q4: Goodies 3 | R4: Goodie 4 | S4: Nombre de personnes ayant été contactées au rayon | T4: Nombre de personnes ayant acheté | U4: Biblos Lait Premium 16g | V4: Biblos Lait Premium 360g | W4: Biblos Lait Excellence | X4: Biblos Flocon d'avoine 50g | Y4: Biblos Flocon d'avoine 400g | Z4: Biblos 3 en 1 Café au lait | AA4: Biblos Lait Premium 16g | AB4: Biblos Flocon d'avoine 50g | AC4: Biblos 3 en 1 Café au lait | AD4: Tasse à café porcelaine | AE4: Bocal transparent | AF4: Plateau | AG4: Tasse plastique | AK4: Nombre de personnes ayant été contactées au rayon | AL4: Nombre de personnes ayant acheté | AM4: Biblos Lait Premium 16g | AN4: Biblos Lait Premium 360g | AO4: Biblos Lait Excellence | AP4: Biblos Flocon d'avoine 50g | AQ4: Biblos Flocon d'avoine 400g | AR4: Biblos 3 en 1 Café au lait | AS4: Biblos Lait Premium 16g | AT4: Biblos Flocon d'avoine 50g | AU4: Biblos 3 en 1 Café au lait | AV4: Goodies 1 | AW4: Goodies 2 | AX4: Goodies 3 | AY4: Goodies 4
B5: AUCHAN | C5: AUCHAN ABATTA | D5: 40 | E5: 20 | F5: 120 | G5: 7 | H5: 4 | I5: 0 | J5: 0 | K5: 0 | L5: =5*35 -> 175 | N5: 0 | S5: 45 | T5: 35 | U5: 83 | V5: 0 | W5: 1 | X5: 20 | Y5: 5 | Z5: 0 | AA5: 0 | AB5: 0 | AC5: 0 | AD5: 0 | AE5: 0 | AF5: 0 | AG5: 0 | AI5: Les clients veulent déguster avant l'achat | AK5: =S5/D5 -> 1.125 | AL5: =T5/E5 -> 1.75 | AM5: =U5/F5 -> 0.69166667 | AN5: =V5/G5 -> 0 | AO5: =W5/H5 -> 0.25 | AS5: =AA5/L5 -> 0
B6: AUCHAN | C6: AUCHAN ABOBO SAMAKE | D6: 40 | E6: 20 | F6: 120 | G6: 7 | H6: 4 | I6: 0 | J6: 0 | K6: 0 | L6: =5*35 -> 175 | N6: 0 | S6: 25 | T6: 12 | U6: 80 | V6: 10 | W6: 4 | X6: 100 | Y6: 9 | Z6: 0 | AA6: 50 | AB6: 20 | AC6: 0 | AD6: 0 | AE6: 0 | AF6: 5 | AG6: 0 | AI6: Les clients apprécient le flocon d'avoine | AK6: =S6/D6 -> 0.625 | AL6: =T6/E6 -> 0.6 | AM6: =U6/F6 -> 0.66666667 | AN6: =V6/G6 -> 1.4285714 | AO6: =W6/H6 -> 1 | AS6: =AA6/L6 -> 0.28571429
B7: AUCHAN | C7: AUCHAN ANGRE DJIBI | D7: 40 | E7: 20 | F7: 120 | G7: 7 | H7: 4 | I7: 0 | J7: 0 | K7: 0 | L7: =5*35 -> 175 | N7: 0 | S7: 39 | T7: 34 | U7: 190 | V7: 3 | W7: 2 | X7: 25 | Y7: 6 | Z7: 0 | AA7: 15 | AB7: 0 | AC7: 0 | AD7: 0 | AE7: 0 | AF7: 0 | AG7: 0 | AI7: Clients satisfaits du goût du lait et demandent le flocon d'avoine | AK7: =S7/D7 -> 0.975 | AL7: =T7/E7 -> 1.7 | AM7: =U7/F7 -> 1.5833333 | AN7: =V7/G7 -> 0.42857143 | AO7: =W7/H7 -> 0.5 | AS7: =AA7/L7 -> 0.085714286
B8: AUCHAN | C8: AUCHAN ATTOBAN | D8: 40 | E8: 20 | F8: 120 | G8: 7 | H8: 4 | I8: 0 | J8: 0 | K8: 0 | L8: =5*35 -> 175 | N8: 0 | S8: 35 | T8: 20 | U8: 40 | V8: 2 | W8: 0 | X8: 10 | Y8: 10 | Z8: 0 | AA8: 0 | AB8: 0 | AC8: 0 | AD8: 0 | AE8: 0 | AF8: 0 | AG8: 0 | AI8: Les clients aiment Biblos lait, demandent les gratuités et les goodies | AK8: =S8/D8 -> 0.875 | AL8: =T8/E8 -> 1 | AM8: =U8/F8 -> 0.33333333 | AN8: =V8/G8 -> 0.28571429 | AO8: =W8/H8 -> 0 | AS8: =AA8/L8 -> 0
B9: AUCHAN | C9: AUCHAN BINGERVILLE | D9: 40 | E9: 20 | F9: 120 | G9: 7 | H9: 4 | I9: 0 | J9: 0 | K9: 0 | L9: =5*35 -> 175 | N9: 0 | S9: 31 | T9: 11 | U9: 90 | V9: 5 | W9: 2 | X9: 35 | Y9: 11 | Z9: 0 | AA9: 19 | AB9: 0 | AC9: 0 | AD9: 0 | AE9: 0 | AF9: 0 | AG9: 0 | AI9: Les clients sont satisfait du goût | AK9: =S9/D9 -> 0.775 | AL9: =T9/E9 -> 0.55 | AM9: =U9/F9 -> 0.75 | AN9: =V9/G9 -> 0.71428571 | AO9: =W9/H9 -> 0.5 | AS9: =AA9/L9 -> 0.10857143
B10: AUCHAN | C10: AUCHAN GARDEN LATRILLE | D10: 40 | E10: 20 | F10: 120 | G10: 7 | H10: 4 | I10: 0 | J10: 0 | K10: 0 | L10: =5*35 -> 175 | N10: 0 | S10: 35 | T10: 28 | U10: 91 | V10: 3 | W10: 3 | X10: 10 | Y10: 9 | Z10: 0 | AA10: 15 | AB10: 15 | AC10: 0 | AD10: 1 | AE10: 0 | AF10: 1 | AG10: 0 | AI10: Les clients sont content de Biblos lait et veulent en gros | AK10: =S10/D10 -> 0.875 | AL10: =T10/E10 -> 1.4 | AM10: =U10/F10 -> 0.75833333 | AN10: =V10/G10 -> 0.42857143 | AO10: =W10/H10 -> 0.75 | AS10: =AA10/L10 -> 0.085714286
B11: AUCHAN | C11: AUCHAN GRAND-BASSAM | D11: 40 | E11: 20 | F11: 120 | G11: 7 | H11: 4 | I11: 0 | J11: 0 | K11: 0 | L11: =5*35 -> 175 | N11: 0 | S11: 30 | T11: 25 | U11: 80 | V11: 0 | W11: 3 | X11: 20 | Y11: 15 | AA11: 20 | AB11: 0 | AC11: 0 | AD11: 0 | AE11: 0 | AF11: 0 | AG11: 0 | AK11: =S11/D11 -> 0.75 | AL11: =T11/E11 -> 1.25 | AM11: =U11/F11 -> 0.66666667 | AN11: =V11/G11 -> 0 | AO11: =W11/H11 -> 0.75 | AS11: =AA11/L11 -> 0.11428571
B12: AUCHAN | C12: AUCHAN KOUMASSI SOLEIL | D12: 40 | E12: 20 | F12: 120 | G12: 7 | H12: 4 | I12: 0 | J12: 0 | K12: 0 | L12: =5*35 -> 175 | N12: 0 | S12: 55 | T12: 40 | U12: 71 | V12: 2 | W12: 45 | X12: 40 | Y12: 0 | Z12: 0 | AA12: 37 | AB12: 0 | AC12: 0 | AD12: 0 | AE12: 0 | AF12: 0 | AG12: 0 | AI12: Les clients apprécient les produits et demandent une réduction | AK12: =S12/D12 -> 1.375 | AL12: =T12/E12 -> 2 | AM12: =U12/F12 -> 0.59166667 | AN12: =V12/G12 -> 0.28571429 | AO12: =W12/H12 -> 11.25 | AS12: =AA12/L12 -> 0.21142857
B13: AUCHAN | C13: AUCHAN YOPOUGON COMPLEXE | D13: 40 | E13: 20 | F13: 120 | G13: 7 | H13: 4 | I13: 0 | J13: 0 | K13: 0 | L13: =5*35 -> 175 | N13: 0 | S13: 30 | T13: 10 | U13: 10 | V13: 5 | W13: 3 | X13: 20 | Y13: 7 | Z13: 0 | AA13: 0 | AB13: 0 | AC13: 0 | AD13: 0 | AE13: 0 | AF13: 0 | AG13: 0 | AI13: Les clients veulent déguster avant l'achat | AK13: =S13/D13 -> 0.75 | AL13: =T13/E13 -> 0.5 | AM13: =U13/F13 -> 0.083333333 | AN13: =V13/G13 -> 0.71428571 | AO13: =W13/H13 -> 0.75 | AS13: =AA13/L13 -> 0
B14: AUCHAN | C14: AUCHAN TREICHVILLE ROND-POINT | D14: 40 | E14: 20 | F14: 120 | G14: 7 | H14: 4 | I14: 0 | J14: 0 | K14: 0 | L14: =5*35 -> 175 | N14: 0 | S14: 50 | T14: 45 | U14: 70 | V14: 4 | W14: 2 | X14: 40 | Y14: 10 | AA14: 35 | AB14: 10 | AC14: 0 | AD14: 0 | AE14: 0 | AF14: 3 | AG14: 0 | AI14: Satisfaits du goût et de la qualité des produits | AK14: =S14/D14 -> 1.25 | AL14: =T14/E14 -> 2.25 | AM14: =U14/F14 -> 0.58333333 | AN14: =V14/G14 -> 0.57142857 | AO14: =W14/H14 -> 0.5 | AS14: =AA14/L14 -> 0.2
B15: AUCHAN | C15: AUCHAN ZONE 4 | D15: 40 | E15: 20 | F15: 120 | G15: 7 | H15: 4 | I15: 0 | J15: 0 | K15: 0 | L15: =5*35 -> 175 | N15: 0 | S15: 50 | T15: 35 | U15: 72 | V15: 0 | W15: 0 | X15: 20 | Y15: 4 | Z15: 0 | AA15: 12 | AB15: 0 | AC15: 0 | AD15: 0 | AE15: 0 | AF15: 1 | AG15: 0 | AI15: Peu d'affluence, les clients apprécient | AK15: =S15/D15 -> 1.25 | AL15: =T15/E15 -> 1.75 | AM15: =U15/F15 -> 0.6 | AN15: =V15/G15 -> 0 | AO15: =W15/H15 -> 0 | AS15: =AA15/L15 -> 0.068571429
B16: AUCHAN | C16: AUCHAN BOUAKE | D16: 40 | E16: 20 | F16: 120 | G16: 7 | H16: 4 | I16: 0 | J16: 0 | K16: 0 | L16: =5*35 -> 175 | N16: 0 | S16: 37 | T16: 30 | U16: 202 | V16: 3 | W16: 0 | X16: 5 | Y16: 4 | Z16: 0 | AA16: 0 | AB16: 2 | AC16: 0 | AD16: 0 | AE16: 0 | AF16: 0 | AG16: 0 | AH16: 2 déguê | AK16: =S16/D16 -> 0.925 | AL16: =T16/E16 -> 1.5 | AM16: =U16/F16 -> 1.6833333 | AN16: =V16/G16 -> 0.42857143 | AO16: =W16/H16 -> 0 | AS16: =AA16/L16 -> 0
B17: AUCHAN | C17: AUCHAN YAMOUSSOUKRO | D17: 40 | E17: 20 | F17: 120 | G17: 7 | H17: 4 | I17: 0 | J17: 0 | K17: 0 | L17: =5*35 -> 175 | N17: 0 | S17: 50 | T17: 45 | U17: 304 | V17: 62 | W17: 7 | X17: 209 | Y17: 87 | Z17: 0 | AA17: 0 | AB17: 0 | AC17: 0 | AD17: 0 | AE17: 0 | AF17: 10 | AG17: 0 | AI17: Clients satisfaits du lait | AK17: =S17/D17 -> 1.25 | AL17: =T17/E17 -> 2.25 | AM17: =U17/F17 -> 2.5333333 | AN17: =V17/G17 -> 8.8571429 | AO17: =W17/H17 -> 1.75 | AS17: =AA17/L17 -> 0
A25: 2 | B25: TOTAL | D25: =SUM(D5:D24) -> 520 | E25: =SUM(E5:E24) -> 260 | F25: =SUM(F5:F24) -> 1560 | G25: =SUM(G5:G24) -> 91 | H25: =SUM(H5:H24) -> 52 | I25: =SUM(I5:I24) -> 0 | J25: =SUM(J5:J24) -> 0 | K25: =SUM(K5:K24) -> 0 | ... AG25: =SUM(AG5:AG24) -> 0 | AK25: =S25/D25 -> 0.98461538 | AL25: =T25/E25 -> 1.4230769 | AM25: =U25/F25 -> 0.88653846 | AN25: =V25/G25 -> 1.0879121 | AO25: =W25/H25 -> 1.3846154 | AS25: =AA25/L25 -> 0.089230769
B27: TOTAL EN CARTONS | D27: =D25 -> 520 | E27: =E25 -> 260 | F27: =F25/120 -> 13 | G27: =G25/6 -> 15.166667 | H27: =H25/10 -> 5.2 | I27: =I25/100 -> 0 | J27: =J25/10 -> 0 | K27: =K25/60 -> 0 | L27: =L25/120 -> 18.958333 | M27: =M25/100 -> 0 | N27: =N25/60 -> 0 | O27: =O25 -> 0 | P27: =P25 -> 0 | Q27: =Q25 -> 0 | R27: =R25 -> 0 | S27: =S25 -> 512 | T27: =T25 -> 370 | U27: =U25/120 -> 11.525 | V27: =V25/6 -> 16.5 | W27: =W25/10 -> 7.2 | X27: =X25/100 -> 5.54 | Y27: =Y25/20 -> 8.85 | Z27: =Z25/60 -> 0 | AA27: =AA25/120 -> 1.6916667 | AB27: =AB25/100 -> 0.47 | AC27: =AC25/60 -> 0 | AD27: =AD25 -> 1 | AE27: =AE25 -> 0 | AF27: =AF25 -> 20 | AG27: =AG25 -> 0 | AM27: =AM25/120 -> 0.0073878205 | AN27: =AN25/6 -> 0.18131868 | AO27: =AO25/20 -> 0.069230769 | AP27: =AP25/100 -> 0 | AR27: =AR25/20 -> 0 | AS27: =AS25/120 -> 0.00074358974 | AU27: =AU25/100 -> 0 | AV27: =AV25/100 -> 0 | AW27: =AW25/100 -> 0 | AX27: =AX25/100 -> 0 | AY27: =AY25/100 -> 0

Sheet JOUR 2
B2: Date | C2: 46108 | D2: OBJECTIFS | S2: REALISATIONS | AK2: TAUX DE REALISATION
