Workbook

Sheet RECAP PAR JOUR
B3: CONTACTS | E3: ACHETEURS | I3: OBJECTIF VOLUME PRODUITS | O3: REALISATION VOLUME PRODUITS | U3: REALISATION VOLUME PRODUITS
B4: Objectif | C4: Réalisé | D4: Tx Réal. | E4: Objectif | F4: Réalisé | G4: Tx Réal. | I4: Biblos Lait Premium 16g | J4: Biblos Lait Premium 360g | K4: Biblos Lait Excellence 900g | L4: Biblos Avoine 50g | M4: Biblos Avoine 400g | N4: Biblos 3 en 1 Café au lait 32g | O4: Biblos Lait Premium 16g | P4: Biblos Lait Premium 360g | Q4: Biblos Lait Excellence 900g | R4: Biblos Avoine 50g | S4: Biblos Avoine 400g | T4: Biblos 3 en 1 Café au lait 32g | U4: =O4 -> Biblos Lait Premium 16g | V4: =P4 -> Biblos Lait Premium 360g | W4: =Q4 -> Biblos Lait Excellence 900g | X4: =R4 -> Biblos Avoine 50g | Y4: =S4 -> Biblos Avoine 400g | Z4: =T4 -> Biblos 3 en 1 Café au lait 32g
A5: JOUR 1 | B5: =50*40 -> 2000 | C5: ='JOUR 1'!S57 -> 1397 | D5: =C5/B5 -> 0.6985 | E5: =50*20 -> 1000 | F5: ='JOUR 1'!T57 -> 296 | G5: =F5/E5 -> 0.296 | I5: =120*50/120 -> 50 | J5: =7*50/6 -> 58.333333 | K5: =50*4/10 -> 20 | O5: ='JOUR 1'!U57 -> 10.583333 | P5: ='JOUR 1'!V57 -> 16.666667 | Q5: ='JOUR 1'!W57 -> 0 | R5: ='JOUR 1'!X57 -> 4.4 | S5: ='JOUR 1'!Y57 -> 5.9 | T5: ='JOUR 1'!Z57 -> 0 | U5: =O5/I5 -> 0.21166667 | V5: =P5/J5 -> 0.28571429 | W5: =Q5/K5 -> 0
A6: JOUR 2 | B6: =50*40 -> 2000 | C6: ='JOUR 2'!S57 -> 1545 | D6: =C6/B6 -> 0.7725 | E6: =50*20 -> 1000 | F6: ='JOUR 2'!T57 -> 421 | G6: =F6/E6 -> 0.421 | I6: =I5 -> 50 | J6: =J5 -> 58.333333 | K6: =K5 -> 20 | O6: ='JOUR 2'!U57 -> 16.325 | P6: ='JOUR 2'!V57 -> 5.5 | Q6: ='JOUR 2'!W57 -> 0 | R6: ='JOUR 2'!X57 -> 4.72 | S6: ='JOUR 2'!Y57 -> 4.9 | T6: ='JOUR 2'!Z57 -> 0 | U6: =O6/I6 -> 0.3265 | V6: =P6/J6 -> 0.094285714 | W6: =Q6/K6 -> 0
A7: JOUR 3 | B7: =50*40 -> 2000 | C7: ='JOUR 3'!S57 -> 1469 | D7: =C7/B7 -> 0.7345 | E7: =50*20 -> 1000 | F7: ='JOUR 3'!T57 -> 855 | G7: =F7/E7 -> 0.855 | I7: =I6 -> 50 | J7: =J6 -> 58.333333 | K7: =K6 -> 20 | O7: ='JOUR 3'!U57 -> 43.333333 | P7: ='JOUR 3'!V57 -> 17 | Q7: ='JOUR 3'!W57 -> 0 | R7: ='JOUR 3'!X57 -> 16.66 | S7: ='JOUR 3'!Y57 -> 19.1 | T7: ='JOUR 3'!Z57 -> 0 | U7: =O7/I7 -> 0.86666667 | V7: =P7/J7 -> 0.29142857 | W7: =Q7/K7 -> 0
A8: JOUR 4 | B8: =50*40 -> 2000 | C8: ='JOUR 4'!S57 -> 1457 | D8: =C8/B8 -> 0.7285 | E8: =50*20 -> 1000 | F8: ='JOUR 4'!T57 -> 862 | G8: =F8/E8 -> 0.862 | I8: =I7 -> 50 | J8: =J7 -> 58.333333 | K8: =K7 -> 20 | O8: ='JOUR 4'!U57 -> 43.441667 | P8: ='JOUR 4'!V57 -> 18.166667 | Q8: ='JOUR 4'!W57 -> 0 | R8: ='JOUR 4'!X57 -> 18.06 | S8: ='JOUR 4'!Y57 -> 12.25 | T8: ='JOUR 4'!Z57 -> 0 | U8: =O8/I8 -> 0.86883333 | V8: =P8/J8 -> 0.31142857 | W8: =Q8/K8 -> 0
A9: JOUR 5 | B9: =50*40 -> 2000 | C9: ='JOUR 5'!S57 -> 1393 | D9: =C9/B9 -> 0.6965 | E9: =50*20 -> 1000 | F9: ='JOUR 5'!T57 -> 801 | G9: =F9/E9 -> 0.801 | I9: =I8 -> 50 | J9: =J8 -> 58.333333 | K9: =K8 -> 20 | O9: ='JOUR 5'!U57 -> 43.208333 | P9: ='JOUR 5'!V57 -> 17.5 | Q9: ='JOUR 5'!W57 -> 2.5 | R9: ='JOUR 5'!X57 -> 19.36 | S9: ='JOUR 5'!Y57 -> 11.1 | T9: ='JOUR 5'!Z57 -> 0 | U9: =O9/I9 -> 0.86416667 | V9: =P9/J9 -> 0.3 | W9: =Q9/K9 -> 0.125
A10: JOUR 6 | B10: =50*40 -> 2000 | C10: ='JOUR 6'!S57 -> 1472 | D10: =C10/B10 -> 0.736 | E10: =50*20 -> 1000 | F10: ='JOUR 6'!T57 -> 928 | G10: =F10/E10 -> 0.928 | I10: =I9 -> 50 | J10: =J9 -> 58.333333 | K10: =K9 -> 20 | O10: ='JOUR 6'!U57 -> 47.05 | P10: ='JOUR 6'!V57 -> 19.666667 | Q10: ='JOUR 6'!W57 -> 0 | R10: ='JOUR 6'!X57 -> 18.24 | S10: ='JOUR 6'!Y57 -> 7.9 | T10: ='JOUR 6'!Z57 -> 0 | U10: =O10/I10 -> 0.941 | V10: =P10/J10 -> 0.33714286 | W10: =Q10/K10 -> 0
A11: JOUR 7 | B11: =50*40 -> 2000 | C11: ='JOUR 7'!S57 -> 1441 | D11: =C11/B11 -> 0.7205 | E11: =50*20 -> 1000 | F11: ='JOUR 7'!T57 -> 881 | G11: =F11/E11 -> 0.881 | I11: =I10 -> 50 | J11: =J10 -> 58.333333 | K11: =K10 -> 20 | O11: ='JOUR 7'!U57 -> 37.725 | P11: ='JOUR 7'!V57 -> 22.833333 | Q11: ='JOUR 7'!W57 -> 0 | R11: ='JOUR 7'!X57 -> 20.04 | S11: ='JOUR 7'!Y57 -> 14.6 | T11: ='JOUR 7'!Z57 -> 0 | U11: =O11/I11 -> 0.7545 | V11: =P11/J11 -> 0.39142857 | W11: =Q11/K11 -> 0
A12: JOUR 8 | B12: =50*40 -> 2000 | C12: ='JOUR 8'!S57 -> 1474 | D12: =C12/B12 -> 0.737 | E12: =50*20 -> 1000 | F12: ='JOUR 8'!T57 -> 841 | G12: =F12/E12 -> 0.841 | I12: =I11 -> 50 | J12: =J11 -> 58.333333 | K12: =K11 -> 20 | O12: ='JOUR 8'!U57 -> 49.641667 | P12: ='JOUR 8'!V57 -> 42.833333 | Q12: ='JOUR 8'!W57 -> 0.2 | R12: ='JOUR 8'!X57 -> 21.26 | S12: ='JOUR 8'!Y57 -> 21 | T12: ='JOUR 8'!Z57 -> 0 | U12: =O12/I12 -> 0.99283333 | V12: =P12/J12 -> 0.73428571 | W12: =Q12/K12 -> 0.01
A13: JOUR 9 | B13: =50*40 -> 2000 | C13: ='JOUR 9'!S57 -> 1495 | D13: =C13/B13 -> 0.7475 | E13: =50*20 -> 1000 | F13: ='JOUR 9'!T57 -> 862 | G13: =F13/E13 -> 0.862 | I13: =I12 -> 50 | J13: =J12 -> 58.333333 | K13: =K12 -> 20 | O13: ='JOUR 9'!U57 -> 54.858333 | P13: ='JOUR 9'!V57 -> 20.666667 | Q13: ='JOUR 9'!W57 -> 0 | R13: ='JOUR 9'!X57 -> 16.41 | S13: ='JOUR 9'!Y57 -> 16.2 | T13: ='JOUR 9'!Z57 -> 0 | U13: =O13/I13 -> 1.0971667 | V13: =P13/J13 -> 0.35428571 | W13: =Q13/K13 -> 0
A14: JOUR 10 | B14: =50*40 -> 2000 | C14: ='JOUR 10'!S57 -> 1410 | D14: =C14/B14 -> 0.705 | E14: =50*20 -> 1000 | F14: ='JOUR 10'!T57 -> 806 | G14: =F14/E14 -> 0.806 | I14: =I13 -> 50 | J14: =J13 -> 58.333333 | K14: =K13 -> 20 | O14: ='JOUR 10'!U57 -> 42.391667 | P14: ='JOUR 10'!V57 -> 23 | Q14: ='JOUR 10'!W57 -> 0 | R14: ='JOUR 10'!X57 -> 17.13 | S14: ='JOUR 10'!Y57 -> 15.15 | T14: ='JOUR 10'!Z57 -> 0 | U14: =O14/I14 -> 0.84783333 | V14: =P14/J14 -> 0.39428571 | W14: =Q14/K14 -> 0
A15: JOUR 11 | B15: =50*40 -> 2000 | C15: ='JOUR 11'!S57 -> 1328 | D15: =C15/B15 -> 0.664 | E15: =50*20 -> 1000 | F15: ='JOUR 11'!T57 -> 826 | G15: =F15/E15 -> 0.826 | I15: =I14 -> 50 | J15: =J14 -> 58.333333 | K15: =K14 -> 20 | O15: ='JOUR 11'!U57 -> 44.816667 | P15: ='JOUR 11'!V57 -> 20.666667 | Q15: ='JOUR 11'!W57 -> 0.1 | R15: ='JOUR 11'!X57 -> 14.54 | S15: ='JOUR 11'!Y57 -> 17.45 | T15: ='JOUR 11'!Z57 -> 0 | U15: =O15/I15 -> 0.89633333 | V15: =P15/J15 -> 0.35428571 | W15: =Q15/K15 -> 0.005
A16: JOUR 12 | B16: =50*40 -> 2000 | C16: ='JOUR 12'!S57 -> 1507 | D16: =C16/B16 -> 0.7535 | E16: =50*20 -> 1000 | F16: ='JOUR 12'!T57 -> 885 | G16: =F16/E16 -> 0.885 | I16: =I15 -> 50 | J16: =J15 -> 58.333333 | K16: =K15 -> 20 | O16: ='JOUR 12'!U57 -> 49.708333 | P16: ='JOUR 12'!V57 -> 23.833333 | Q16: ='JOUR 12'!W57 -> 0 | R16: ='JOUR 12'!X57 -> 16.58 | S16: ='JOUR 12'!Y57 -> 24.35 | T16: ='JOUR 12'!Z57 -> 0 | U16: =O16/I16 -> 0.99416667 | V16: =P16/J16 -> 0.40857143 | W16: =Q16/K16 -> 0
A17: JOUR 13 | B17: =50*40 -> 2000 | C17: ='JOUR 13'!S57 -> 1380 | D17: =C17/B17 -> 0.69 | E17: =50*20 -> 1000 | F17: ='JOUR 13'!T57 -> 904 | G17: =F17/E17 -> 0.904 | I17: =I16 -> 50 | J17: =J16 -> 58.333333 | K17: =K16 -> 20 | O17: ='JOUR 13'!U57 -> 54.183333 | P17: ='JOUR 13'!V57 -> 22.5 | Q17: ='JOUR 13'!W57 -> 0.8 | R17: ='JOUR 13'!X57 -> 17.09 | S17: ='JOUR 13'!Y57 -> 18.75 | T17: ='JOUR 13'!Z57 -> 0 | U17: =O17/I17 -> 1.0836667 | V17: =P17/J17 -> 0.38571429 | W17: =Q17/K17 -> 0.04
A18: JOUR 14 | B18: =50*40 -> 2000 | C18: ='JOUR 14'!S57 -> 1491 | D18: =C18/B18 -> 0.7455 | E18: =50*20 -> 1000 | F18: ='JOUR 14'!T57 -> 915 | G18: =F18/E18 -> 0.915 | I18: =I17 -> 50 | J18: =J17 -> 58.333333 | K18: =K17 -> 20 | O18: ='JOUR 14'!U57 -> 51.308333 | P18: ='JOUR 14'!V57 -> 27 | Q18: ='JOUR 14'!W57 -> 1.5 | R18: ='JOUR 14'!X57 -> 16.86 | S18: ='JOUR 14'!Y57 -> 21.95 | T18: ='JOUR 14'!Z57 -> 0 | U18: =O18/I18 -> 1.0261667 | V18: =P18/J18 -> 0.46285714 | W18: =Q18/K18 -> 0.075
A19: JOUR 15 | B19: 0 | I19: 0 | J19: 0 | K19: 0
A20: JOUR 16 | B20: 0 | I20: 0 | J20: 0 | K20: 0
A21: TOTAL | B21: =SUM(B5:B20) -> 28000 | C21: =SUM(C5:C20) -> 20259 | D21: =C21/B21 -> 0.72353571 | E21: =SUM(E5:E20) -> 14000 | F21: =SUM(F5:F20) -> 11083 | G21: =F21/E21 -> 0.79164286 | I21: =SUM(I5:I20) -> 700 | J21: =SUM(J5:J20) -> 816.66667 | K21: =SUM(K5:K20) -> 280 | L21: =SUM(L5:L20) -> 0 | M21: =SUM(M5:M20) -> 0 | O21: =SUM(O5:O20) -> 588.575 | P21: =SUM(P5:P20) -> 297.83333 | Q21: =SUM(Q5:Q20) -> 5.1 | R21: =SUM(R5:R20) -> 221.35 | S21: =SUM(S5:S20) -> 210.6 | U21: =O21/I21 -> 0.84082143 | V21: =P21/J21 -> 0.36469388 | W21: =Q21/K21 -> 0.018214286

Sheet RECAP PAR MAGASIN
B2: Date | C2: TOTAL PROMO | D2: OBJECTIFS | S2: REALISATIONS | AK2: TAUX DE REALISATION
B3: Enseigne | C3: Nom du PDV en promotion | D3: Contacts | E3: =T3 -> Acheteurs | F3: Produits (en unités) | L3: Gratuités pour achats (en unités) | S3: Contacts | T3: Acheteurs | U3: Produits | AA3: =L3 -> Gratuités pour achats (en unités) | AD3: GOODIES | AH3: Commentaires | AI3: Impressions des PDV et des clients | AK3: Contacts | AL3: Acheteurs | AM3: Produits | AS3: =AD3 -> GOODIES | AV3: GOODIES
D4: =S4 -> Nombre de personnes ayant été contactées au rayon | E4: =T4 -> Nombre de personnes ayant acheté | F4: Biblos Lait Premium 16g | G4: Biblos Lait Premium 360g | H4: Biblos Lait Excellence | I4: Biblos Flocon d'avoine 50g | J4: Biblos Flocon d'avoine 400g | K4: Biblos 3 en 1 Café au lait 32g | L4: Biblos Lait Premium 16g | M4: Biblos Flocon d'avoine 50g | N4: Biblos 3 en Café au Lait | O4: Goodies 1 | P4: Goodies 2 | Q4: Goodies 3 | R4: Goodie 4 | S4: Nombre de personnes ayant été contactées au rayon | T4: Nombre de personnes ayant acheté | U4: Biblos Lait Premium 16g | V4: Biblos Lait Premium 360g | W4: Biblos Lait Excellence | X4: Biblos Flocon d'avoine 50g | Y4: Biblos Flocon d'avoine 400g | Z4: Biblos 3 en 1 Café au lait | AA4: Biblos Lait Premium 16g | AB4: Biblos Flocon d'avoine 50g | AC4: Biblos 3 en 1 Café au lait | AD4: =O4 -> Goodies 1 | AE4: =P4 -> Goodies 2 | AF4: =Q4 -> Goodies 3 | AG4: =R4 -> Goodie 4 | AK4: Nombre de personnes ayant été contactées au rayon | AL4: Nombre de personnes ayant acheté | AM4: Biblos Lait Premium 16g | AN4: Biblos Lait Premium 360g | AO4: Biblos Lait Excellence | AP4: Biblos Flocon d'avoine 50g | AQ4: Biblos Flocon d'avoine 400g | AR4: Biblos 3 en 1 Café au lait | AS4: Biblos Lait Premium 16g | AT4: Biblos Flocon d'avoine 50g | AU4: Biblos 3 en 1 Café au lait | AV4: Goodies 1 | AW4: Goodies 2 | AX4: Goodies 3 | AY4: Goodies 4
B5: KING CASH | C5: KING CASH PALAIS YOP | D5: ='JOUR 1'!D5+'JOUR 2'!D5+'JOUR 3'!D5+'JOUR 4'!D5+'JOUR 5'!D5+'JOUR 6'!D5+'JOUR 7'!D5+'JOUR 8'!D5+'JOUR 9'!D5+'JOUR 10'!D5+'JOUR 11'!D5+'JOUR 12'!D5+'JOUR 13'!D5+'JOUR 14'!D5+#REF!+#REF! -> #REF! | E5: ='JOUR 1'!E5+'JOUR 2'!E5+'JOUR 3'!E5+'JOUR 4'!E5+'JOUR 5'!E5+'JOUR 6'!E5+'JOUR 7'!E5+'JOUR 8'!E5+'JOUR 9'!E5+'JOUR 10'!E5+'JOUR 11'!E5+'JOUR 12'!E5+'JOUR 13'!E5+'JOUR 14'!E5+#REF!+#REF! -> #REF! | F5: ='JOUR 1'!F5+'JOUR 2'!F5+'JOUR 3'!F5+'JOUR 4'!F5+'JOUR 5'!F5+'JOUR 6'!F5+'JOUR 7'!F5+'JOUR 8'!F5+'JOUR 9'!F5+'JOUR 10'!F5+'JOUR 11'!F5+'JOUR 12'!F5+'JOUR 13'!F5+'JOUR 14'!F5+#REF!+#REF! -> #REF! | G5: ='JOUR 1'!G5+'JOUR 2'!G5+'JOUR 3'!G5+'JOUR 4'!G5+'JOUR 5'!G5+'JOUR 6'!G5+'JOUR 7'!G5+'JOUR 8'!G5+'JOUR 9'!G5+'JOUR 10'!G5+'JOUR 11'!G5+'JOUR 12'!G5+'JOUR 13'!G5+'JOUR 14'!G5+#REF!+#REF! -> #REF! | H5: ='JOUR 1'!H5+'JOUR 2'!H5+'JOUR 3'!H5+'JOUR 4'!H5+'JOUR 5'!H5+'JOUR 6'!H5+'JOUR 7'!H5+'JOUR 8'!H5+'JOUR 9'!H5+'JOUR 10'!H5+'JOUR 11'!H5+'JOUR 12'!H5+'JOUR 13'!H5+'JOUR 14'!H5+#REF!+#REF! -> #REF! | I5: ='JOUR 1'!I5+'JOUR 2'!I5+'JOUR 3'!I5+'JOUR 4'!I5+'JOUR 5'!I5+'JOUR 6'!I5+'JOUR 7'!I5+'JOUR 8'!I5+'JOUR 9'!I5+'JOUR 10'!I5+'JOUR 11'!I5+'JOUR 12'!I5+'JOUR 13'!I5+'JOUR 14'!I5+#REF!+#REF! -> #REF! | J5: ='JOUR 1'!J5+'JOUR 2'!J5+'JOUR 3'!J5+'JOUR 4'!J5+'JOUR 5'!J5+'JOUR 6'!J5+'JOUR 7'!J5+'JOUR 8'!J5+'JOUR 9'!J5+'JOUR 10'!J5+'JOUR 11'!J5+'JOUR 12'!J5+'JOUR 13'!J5+'JOUR 14'!J5+#REF!+#REF! -> #REF! | K5: ='JOUR 1'!K5+'JOUR 2'!K5+'JOUR 3'!K5+'JOUR 4'!K5+'JOUR 5'!K5+'JOUR 6'!K5+'JOUR 7'!K5+'JOUR 8'!K5+'JOUR 9'!K5+'JOUR 10'!K5+'JOUR 11'!K5+'JOUR 12'!K5+'JOUR 13'!K5+'JOUR 14'!K5+#REF!+#REF! -> #REF! | ... AG5: ='JOUR 1'!AG5+'JOUR 2'!AG5+'JOUR 3'!AG5+'JOUR 4'!AG5+'JOUR 5'!AG5+'JOUR 6'!AG5+'JOUR 7'!AG5+'JOUR 8'!AG5+'JOUR 9'!AG5+'JOUR 10'!AG5+'JOUR 11'!AG5+'JOUR 12'!AG5+'JOUR 13'!AG5+'JOUR 14'!AG5+#REF!+#REF! -> #REF! | AK5: =S5/D5 -> #REF! | AL5: =T5/E5 -> #REF! | AM5: =U5/F5 -> #REF! | AN5: =V5/G5 -> #REF! | AO5: =W5/H5 -> #REF! | AS5: =AA5/L5 -> #REF!
B6: KING CASH | C6: KING CASH PORT BOUET 2 | D6: ='JOUR 1'!D6+'JOUR 2'!D6+'JOUR 3'!D6+'JOUR 4'!D6+'JOUR 5'!D6+'JOUR 6'!D6+'JOUR 7'!D6+'JOUR 8'!D6+'JOUR 9'!D6+'JOUR 10'!D6+'JOUR 11'!D6+'JOUR 12'!D6+'JOUR 13'!D6+'JOUR 14'!D6+#REF!+#REF! -> #REF! | E6: ='JOUR 1'!E6+'JOUR 2'!E6+'JOUR 3'!E6+'JOUR 4'!E6+'JOUR 5'!E6+'JOUR 6'!E6+'JOUR 7'!E6+'JOUR 8'!E6+'JOUR 9'!E6+'JOUR 10'!E6+'JOUR 11'!E6+'JOUR 12'!E6+'JOUR 13'!E6+'JOUR 14'!E6+#REF!+#REF! -> #REF! | F6: ='JOUR 1'!F6+'JOUR 2'!F6+'JOUR 3'!F6+'JOUR 4'!F6+'JOUR 5'!F6+'JOUR 6'!F6+'JOUR 7'!F6+'JOUR 8'!F6+'JOUR 9'!F6+'JOUR 10'!F6+'JOUR 11'!F6+'JOUR 12'!F6+'JOUR 13'!F6+'JOUR 14'!F6+#REF!+#REF! -> #REF! | G6: ='JOUR 1'!G6+'JOUR 2'!G6+'JOUR 3'!G6+'JOUR 4'!G6+'JOUR 5'!G6+'JOUR 6'!G6+'JOUR 7'!G6+'JOUR 8'!G6+'JOUR 9'!G6+'JOUR 10'!G6+'JOUR 11'!G6+'JOUR 12'!G6+'JOUR 13'!G6+'JOUR 14'!G6+#REF!+#REF! -> #REF! | H6: ='JOUR 1'!H6+'JOUR 2'!H6+'JOUR 3'!H6+'JOUR 4'!H6+'JOUR 5'!H6+'JOUR 6'!H6+'JOUR 7'!H6+'JOUR 8'!H6+'JOUR 9'!H6+'JOUR 10'!H6+'JOUR 11'!H6+'JOUR 12'!H6+'JOUR 13'!H6+'JOUR 14'!H6+#REF!+#REF! -> #REF! | I6: ='JOUR 1'!I6+'JOUR 2'!I6+'JOUR 3'!I6+'JOUR 4'!I6+'JOUR 5'!I6+'JOUR 6'!I6+'JOUR 7'!I6+'JOUR 8'!I6+'JOUR 9'!I6+'JOUR 10'!I6+'JOUR 11'!I6+'JOUR 12'!I6+'JOUR 13'!I6+'JOUR 14'!I6+#REF!+#REF! -> #REF! | J6: ='JOUR 1'!J6+'JOUR 2'!J6+'JOUR 3'!J6+'JOUR 4'!J6+'JOUR 5'!J6+'JOUR 6'!J6+'JOUR 7'!J6+'JOUR 8'!J6+'JOUR 9'!J6+'JOUR 10'!J6+'JOUR 11'!J6+'JOUR 12'!J6+'JOUR 13'!J6+'JOUR 14'!J6+#REF!+#REF! -> #REF! | K6: ='JOUR 1'!K6+'JOUR 2'!K6+'JOUR 3'!K6+'JOUR 4'!K6+'JOUR 5'!K6+'JOUR 6'!K6+'JOUR 7'!K6+'JOUR 8'!K6+'JOUR 9'!K6+'JOUR 10'!K6+'JOUR 11'!K6+'JOUR 12'!K6+'JOUR 13'!K6+'JOUR 14'!K6+#REF!+#REF! -> #REF! | ... AG6: ='JOUR 1'!AG6+'JOUR 2'!AG6+'JOUR 3'!AG6+'JOUR 4'!AG6+'JOUR 5'!AG6+'JOUR 6'!AG6+'JOUR 7'!AG6+'JOUR 8'!AG6+'JOUR 9'!AG6+'JOUR 10'!AG6+'JOUR 11'!AG6+'JOUR 12'!AG6+'JOUR 13'!AG6+'JOUR 14'!AG6+#REF!+#REF! -> #REF! | AK6: =S6/D6 -> #REF! | AL6: =T6/E6 -> #REF! | AM6: =U6/F6 -> #REF! | AN6: =V6/G6 -> #REF! | AO6: =W6/H6 -> #REF! | AS6: =AA6/L6 -> #REF!
B7: KING CASH | C7: KING CASH ABOBO MAIRIE | D7: ='JOUR 1'!D7+'JOUR 2'!D7+'JOUR 3'!D7+'JOUR 4'!D7+'JOUR 5'!D7+'JOUR 6'!D7+'JOUR 7'!D7+'JOUR 8'!D7+'JOUR 9'!D7+'JOUR 10'!D7+'JOUR 11'!D7+'JOUR 12'!D7+'JOUR 13'!D7+'JOUR 14'!D7+#REF!+#REF! -> #REF! | E7: ='JOUR 1'!E7+'JOUR 2'!E7+'JOUR 3'!E7+'JOUR 4'!E7+'JOUR 5'!E7+'JOUR 6'!E7+'JOUR 7'!E7+'JOUR 8'!E7+'JOUR 9'!E7+'JOUR 10'!E7+'JOUR 11'!E7+'JOUR 12'!E7+'JOUR 13'!E7+'JOUR 14'!E7+#REF!+#REF! -> #REF! | F7: ='JOUR 1'!F7+'JOUR 2'!F7+'JOUR 3'!F7+'JOUR 4'!F7+'JOUR 5'!F7+'JOUR 6'!F7+'JOUR 7'!F7+'JOUR 8'!F7+'JOUR 9'!F7+'JOUR 10'!F7+'JOUR 11'!F7+'JOUR 12'!F7+'JOUR 13'!F7+'JOUR 14'!F7+#REF!+#REF! -> #REF! | G7: ='JOUR 1'!G7+'JOUR 2'!G7+'JOUR 3'!G7+'JOUR 4'!G7+'JOUR 5'!G7+'JOUR 6'!G7+'JOUR 7'!G7+'JOUR 8'!G7+'JOUR 9'!G7+'JOUR 10'!G7+'JOUR 11'!G7+'JOUR 12'!G7+'JOUR 13'!G7+'JOUR 14'!G7+#REF!+#REF! -> #REF! | H7: ='JOUR 1'!H7+'JOUR 2'!H7+'JOUR 3'!H7+'JOUR 4'!H7+'JOUR 5'!H7+'JOUR 6'!H7+'JOUR 7'!H7+'JOUR 8'!H7+'JOUR 9'!H7+'JOUR 10'!H7+'JOUR 11'!H7+'JOUR 12'!H7+'JOUR 13'!H7+'JOUR 14'!H7+#REF!+#REF! -> #REF! | I7: ='JOUR 1'!I7+'JOUR 2'!I7+'JOUR 3'!I7+'JOUR 4'!I7+'JOUR 5'!I7+'JOUR 6'!I7+'JOUR 7'!I7+'JOUR 8'!I7+'JOUR 9'!I7+'JOUR 10'!I7+'JOUR 11'!I7+'JOUR 12'!I7+'JOUR 13'!I7+'JOUR 14'!I7+#REF!+#REF! -> #REF! | J7: ='JOUR 1'!J7+'JOUR 2'!J7+'JOUR 3'!J7+'JOUR 4'!J7+'JOUR 5'!J7+'JOUR 6'!J7+'JOUR 7'!J7+'JOUR 8'!J7+'JOUR 9'!J7+'JOUR 10'!J7+'JOUR 11'!J7+'JOUR 12'!J7+'JOUR 13'!J7+'JOUR 14'!J7+#REF!+#REF! -> #REF! | K7: ='JOUR 1'!K7+'JOUR 2'!K7+'JOUR 3'!K7+'JOUR 4'!K7+'JOUR 5'!K7+'JOUR 6'!K7+'JOUR 7'!K7+'JOUR 8'!K7+'JOUR 9'!K7+'JOUR 10'!K7+'JOUR 11'!K7+'JOUR 12'!K7+'JOUR 13'!K7+'JOUR 14'!K7+#REF!+#REF! -> #REF! | ... AG7: ='JOUR 1'!AG7+'JOUR 2'!AG7+'JOUR 3'!AG7+'JOUR 4'!AG7+'JOUR 5'!AG7+'JOUR 6'!AG7+'JOUR 7'!AG7+'JOUR 8'!AG7+'JOUR 9'!AG7+'JOUR 10'!AG7+'JOUR 11'!AG7+'JOUR 12'!AG7+'JOUR 13'!AG7+'JOUR 14'!AG7+#REF!+#REF! -> #REF! | AK7: =S7/D7 -> #REF! | AL7: =T7/E7 -> #REF! | AM7: =U7/F7 -> #REF! | AN7: =V7/G7 -> #REF! | AO7: =W7/H7 -> #REF! | AS7: =AA7/L7 -> #REF!
B8: KING CASH | C8: KING CASH SIPOREX | D8: ='JOUR 1'!D8+'JOUR 2'!D8+'JOUR 3'!D8+'JOUR 4'!D8+'JOUR 5'!D8+'JOUR 6'!D8+'JOUR 7'!D8+'JOUR 8'!D8+'JOUR 9'!D8+'JOUR 10'!D8+'JOUR 11'!D8+'JOUR 12'!D8+'JOUR 13'!D8+'JOUR 14'!D8+#REF!+#REF! -> #REF! | E8: ='JOUR 1'!E8+'JOUR 2'!E8+'JOUR 3'!E8+'JOUR 4'!E8+'JOUR 5'!E8+'JOUR 6'!E8+'JOUR 7'!E8+'JOUR 8'!E8+'JOUR 9'!E8+'JOUR 10'!E8+'JOUR 11'!E8+'JOUR 12'!E8+'JOUR 13'!E8+'JOUR 14'!E8+#REF!+#REF! -> #REF! | F8: ='JOUR 1'!F8+'JOUR 2'!F8+'JOUR 3'!F8+'JOUR 4'!F8+'JOUR 5'!F8+'JOUR 6'!F8+'JOUR 7'!F8+'JOUR 8'!F8+'JOUR 9'!F8+'JOUR 10'!F8+'JOUR 11'!F8+'JOUR 12'!F8+'JOUR 13'!F8+'JOUR 14'!F8+#REF!+#REF! -> #REF! | G8: ='JOUR 1'!G8+'JOUR 2'!G8+'JOUR 3'!G8+'JOUR 4'!G8+'JOUR 5'!G8+'JOUR 6'!G8+'JOUR 7'!G8+'JOUR 8'!G8+'JOUR 9'!G8+'JOUR 10'!G8+'JOUR 11'!G8+'JOUR 12'!G8+'JOUR 13'!G8+'JOUR 14'!G8+#REF!+#REF! -> #REF! | H8: ='JOUR 1'!H8+'JOUR 2'!H8+'JOUR 3'!H8+'JOUR 4'!H8+'JOUR 5'!H8+'JOUR 6'!H8+'JOUR 7'!H8+'JOUR 8'!H8+'JOUR 9'!H8+'JOUR 10'!H8+'JOUR 11'!H8+'JOUR 12'!H8+'JOUR 13'!H8+'JOUR 14'!H8+#REF!+#REF! -> #REF! | I8: ='JOUR 1'!I8+'JOUR 2'!I8+'JOUR 3'!I8+'JOUR 4'!I8+'JOUR 5'!I8+'JOUR 6'!I8+'JOUR 7'!I8+'JOUR 8'!I8+'JOUR 9'!I8+'JOUR 10'!I8+'JOUR 11'!I8+'JOUR 12'!I8+'JOUR 13'!I8+'JOUR 14'!I8+#REF!+#REF! -> #REF! | J8: ='JOUR 1'!J8+'JOUR 2'!J8+'JOUR 3'!J8+'JOUR 4'!J8+'JOUR 5'!J8+'JOUR 6'!J8+'JOUR 7'!J8+'JOUR 8'!J8+'JOUR 9'!J8+'JOUR 10'!J8+'JOUR 11'!J8+'JOUR 12'!J8+'JOUR 13'!J8+'JOUR 14'!J8+#REF!+#REF! -> #REF! | K8: ='JOUR 1'!K8+'JOUR 2'!K8+'JOUR 3'!K8+'JOUR 4'!K8+'JOUR 5'!K8+'JOUR 6'!K8+'JOUR 7'!K8+'JOUR 8'!K8+'JOUR 9'!K8+'JOUR 10'!K8+'JOUR 11'!K8+'JOUR 12'!K8+'JOUR 13'!K8+'JOUR 14'!K8+#REF!+#REF! -> #REF! | ... AG8: ='JOUR 1'!AG8+'JOUR 2'!AG8+'JOUR 3'!AG8+'JOUR 4'!AG8+'JOUR 5'!AG8+'JOUR 6'!AG8+'JOUR 7'!AG8+'JOUR 8'!AG8+'JOUR 9'!AG8+'JOUR 10'!AG8+'JOUR 11'!AG8+'JOUR 12'!AG8+'JOUR 13'!AG8+'JOUR 14'!AG8+#REF!+#REF! -> #REF! | AK8: =S8/D8 -> #REF! | AL8: =T8/E8 -> #REF! | AM8: =U8/F8 -> #REF! | AN8: =V8/G8 -> #REF! | AO8: =W8/H8 -> #REF! | AS8: =AA8/L8 -> #REF!
B9: KING CASH | C9: KING CASH PRINCES. | D9: ='JOUR 1'!D9+'JOUR 2'!D9+'JOUR 3'!D9+'JOUR 4'!D9+'JOUR 5'!D9+'JOUR 6'!D9+'JOUR 7'!D9+'JOUR 8'!D9+'JOUR 9'!D9+'JOUR 10'!D9+'JOUR 11'!D9+'JOUR 12'!D9+'JOUR 13'!D9+'JOUR 14'!D9+#REF!+#REF! -> #REF! | E9: ='JOUR 1'!E9+'JOUR 2'!E9+'JOUR 3'!E9+'JOUR 4'!E9+'JOUR 5'!E9+'JOUR 6'!E9+'JOUR 7'!E9+'JOUR 8'!E9+'JOUR 9'!E9+'JOUR 10'!E9+'JOUR 11'!E9+'JOUR 12'!E9+'JOUR 13'!E9+'JOUR 14'!E9+#REF!+#REF! -> #REF! | F9: ='JOUR 1'!F9+'JOUR 2'!F9+'JOUR 3'!F9+'JOUR 4'!F9+'JOUR 5'!F9+'JOUR 6'!F9+'JOUR 7'!F9+'JOUR 8'!F9+'JOUR 9'!F9+'JOUR 10'!F9+'JOUR 11'!F9+'JOUR 12'!F9+'JOUR 13'!F9+'JOUR 14'!F9+#REF!+#REF! -> #REF! | G9: ='JOUR 1'!G9+'JOUR 2'!G9+'JOUR 3'!G9+'JOUR 4'!G9+'JOUR 5'!G9+'JOUR 6'!G9+'JOUR 7'!G9+'JOUR 8'!G9+'JOUR 9'!G9+'JOUR 10'!G9+'JOUR 11'!G9+'JOUR 12'!G9+'JOUR 13'!G9+'JOUR 14'!G9+#REF!+#REF! -> #REF! | H9: ='JOUR 1'!H9+'JOUR 2'!H9+'JOUR 3'!H9+'JOUR 4'!H9+'JOUR 5'!H9+'JOUR 6'!H9+'JOUR 7'!H9+'JOUR 8'!H9+'JOUR 9'!H9+'JOUR 10'!H9+'JOUR 11'!H9+'JOUR 12'!H9+'JOUR 13'!H9+'JOUR 14'!H9+#REF!+#REF! -> #REF! | I9: ='JOUR 1'!I9+'JOUR 2'!I9+'JOUR 3'!I9+'JOUR 4'!I9+'JOUR 5'!I9+'JOUR 6'!I9+'JOUR 7'!I9+'JOUR 8'!I9+'JOUR 9'!I9+'JOUR 10'!I9+'JOUR 11'!I9+'JOUR 12'!I9+'JOUR 13'!I9+'JOUR 14'!I9+#REF!+#REF! -> #REF! | J9: ='JOUR 1'!J9+'JOUR 2'!J9+'JOUR 3'!J9+'JOUR 4'!J9+'JOUR 5'!J9+'JOUR 6'!J9+'JOUR 7'!J9+'JOUR 8'!J9+'JOUR 9'!J9+'JOUR 10'!J9+'JOUR 11'!J9+'JOUR 12'!J9+'JOUR 13'!J9+'JOUR 14'!J9+#REF!+#REF! -> #REF! | K9: ='JOUR 1'!K9+'JOUR 2'!K9+'JOUR 3'!K9+'JOUR 4'!K9+'JOUR 5'!K9+'JOUR 6'!K9+'JOUR 7'!K9+'JOUR 8'!K9+'JOUR 9'!K9+'JOUR 10'!K9+'JOUR 11'!K9+'JOUR 12'!K9+'JOUR 13'!K9+'JOUR 14'!K9+#REF!+#REF! -> #REF! | ... AG9: ='JOUR 1'!AG9+'JOUR 2'!AG9+'JOUR 3'!AG9+'JOUR 4'!AG9+'JOUR 5'!AG9+'JOUR 6'!AG9+'JOUR 7'!AG9+'JOUR 8'!AG9+'JOUR 9'!AG9+'JOUR 10'!AG9+'JOUR 11'!AG9+'JOUR 12'!AG9+'JOUR 13'!AG9+'JOUR 14'!AG9+#REF!+#REF! -> #REF! | AK9: =S9/D9 -> #REF! | AL9: =T9/E9 -> #REF! | AM9: =U9/F9 -> #REF! | AN9: =V9/G9 -> #REF! | AO9: =W9/H9 -> #REF! | AS9: =AA9/L9 -> #REF!
B10: KING CASH | C10: KING CASH WAKOUBOUE | D10: ='JOUR 1'!D10+'JOUR 2'!D10+'JOUR 3'!D10+'JOUR 4'!D10+'JOUR 5'!D10+'JOUR 6'!D10+'JOUR 7'!D10+'JOUR 8'!D10+'JOUR 9'!D10+'JOUR 10'!D10+'JOUR 11'!D10+'JOUR 12'!D10+'JOUR 13'!D10+'JOUR 14'!D10+#REF!+#REF! -> #REF! | E10: ='JOUR 1'!E10+'JOUR 2'!E10+'JOUR 3'!E10+'JOUR 4'!E10+'JOUR 5'!E10+'JOUR 6'!E10+'JOUR 7'!E10+'JOUR 8'!E10+'JOUR 9'!E10+'JOUR 10'!E10+'JOUR 11'!E10+'JOUR 12'!E10+'JOUR 13'!E10+'JOUR 14'!E10+#REF!+#REF! -> #REF! | F10: ='JOUR 1'!F10+'JOUR 2'!F10+'JOUR 3'!F10+'JOUR 4'!F10+'JOUR 5'!F10+'JOUR 6'!F10+'JOUR 7'!F10+'JOUR 8'!F10+'JOUR 9'!F10+'JOUR 10'!F10+'JOUR 11'!F10+'JOUR 12'!F10+'JOUR 13'!F10+'JOUR 14'!F10+#REF!+#REF! -> #REF! | G10: ='JOUR 1'!G10+'JOUR 2'!G10+'JOUR 3'!G10+'JOUR 4'!G10+'JOUR 5'!G10+'JOUR 6'!G10+'JOUR 7'!G10+'JOUR 8'!G10+'JOUR 9'!G10+'JOUR 10'!G10+'JOUR 11'!G10+'JOUR 12'!G10+'JOUR 13'!G10+'JOUR 14'!G10+#REF!+#REF! -> #REF! | H10: ='JOUR 1'!H10+'JOUR 2'!H10+'JOUR 3'!H10+'JOUR 4'!H10+'JOUR 5'!H10+'JOUR 6'!H10+'JOUR 7'!H10+'JOUR 8'!H10+'JOUR 9'!H10+'JOUR 10'!H10+'JOUR 11'!H10+'JOUR 12'!H10+'JOUR 13'!H10+'JOUR 14'!H10+#REF!+#REF! -> #REF! | I10: ='JOUR 1'!I10+'JOUR 2'!I10+'JOUR 3'!I10+'JOUR 4'!I10+'JOUR 5'!I10+'JOUR 6'!I10+'JOUR 7'!I10+'JOUR 8'!I10+'JOUR 9'!I10+'JOUR 10'!I10+'JOUR 11'!I10+'JOUR 12'!I10+'JOUR 13'!I10+'JOUR 14'!I10+#REF!+#REF! -> #REF! | J10: ='JOUR 1'!J10+'JOUR 2'!J10+'JOUR 3'!J10+'JOUR 4'!J10+'JOUR 5'!J10+'JOUR 6'!J10+'JOUR 7'!J10+'JOUR 8'!J10+'JOUR 9'!J10+'JOUR 10'!J10+'JOUR 11'!J10+'JOUR 12'!J10+'JOUR 13'!J10+'JOUR 14'!J10+#REF!+#REF! -> #REF! | K10: ='JOUR 1'!K10+'JOUR 2'!K10+'JOUR 3'!K10+'JOUR 4'!K10+'JOUR 5'!K10+'JOUR 6'!K10+'JOUR 7'!K10+'JOUR 8'!K10+'JOUR 9'!K10+'JOUR 10'!K10+'JOUR 11'!K10+'JOUR 12'!K10+'JOUR 13'!K10+'JOUR 14'!K10+#REF!+#REF! -> #REF! | ... AG10: ='JOUR 1'!AG10+'JOUR 2'!AG10+'JOUR 3'!AG10+'JOUR 4'!AG10+'JOUR 5'!AG10+'JOUR 6'!AG10+'JOUR 7'!AG10+'JOUR 8'!AG10+'JOUR 9'!AG10+'JOUR 10'!AG10+'JOUR 11'!AG10+'JOUR 12'!AG10+'JOUR 13'!AG10+'JOUR 14'!AG10+#REF!+#REF! -> #REF! | AK10: =S10/D10 -> #REF! | AL10: =T10/E10 -> #REF! | AM10: =U10/F10 -> #REF! | AN10: =V10/G10 -> #REF! | AO10: =W10/H10 -> #REF! | AS10: =AA10/L10 -> #REF!
B11: KING CASH | C11: KING CASH ABOBO KAZA | D11: ='JOUR 1'!D11+'JOUR 2'!D11+'JOUR 3'!D11+'JOUR 4'!D11+'JOUR 5'!D11+'JOUR 6'!D11+'JOUR 7'!D11+'JOUR 8'!D11+'JOUR 9'!D11+'JOUR 10'!D11+'JOUR 11'!D11+'JOUR 12'!D11+'JOUR 13'!D11+'JOUR 14'!D11+#REF!+#REF! -> #REF! | E11: ='JOUR 1'!E11+'JOUR 2'!E11+'JOUR 3'!E11+'JOUR 4'!E11+'JOUR 5'!E11+'JOUR 6'!E11+'JOUR 7'!E11+'JOUR 8'!E11+'JOUR 9'!E11+'JOUR 10'!E11+'JOUR 11'!E11+'JOUR 12'!E11+'JOUR 13'!E11+'JOUR 14'!E11+#REF!+#REF! -> #REF! | F11: ='JOUR 1'!F11+'JOUR 2'!F11+'JOUR 3'!F11+'JOUR 4'!F11+'JOUR 5'!F11+'JOUR 6'!F11+'JOUR 7'!F11+'JOUR 8'!F11+'JOUR 9'!F11+'JOUR 10'!F11+'JOUR 11'!F11+'JOUR 12'!F11+'JOUR 13'!F11+'JOUR 14'!F11+#REF!+#REF! -> #REF! | G11: ='JOUR 1'!G11+'JOUR 2'!G11+'JOUR 3'!G11+'JOUR 4'!G11+'JOUR 5'!G11+'JOUR 6'!G11+'JOUR 7'!G11+'JOUR 8'!G11+'JOUR 9'!G11+'JOUR 10'!G11+'JOUR 11'!G11+'JOUR 12'!G11+'JOUR 13'!G11+'JOUR 14'!G11+#REF!+#REF! -> #REF! | H11: ='JOUR 1'!H11+'JOUR 2'!H11+'JOUR 3'!H11+'JOUR 4'!H11+'JOUR 5'!H11+'JOUR 6'!H11+'JOUR 7'!H11+'JOUR 8'!H11+'JOUR 9'!H11+'JOUR 10'!H11+'JOUR 11'!H11+'JOUR 12'!H11+'JOUR 13'!H11+'JOUR 14'!H11+#REF!+#REF! -> #REF! | I11: ='JOUR 1'!I11+'JOUR 2'!I11+'JOUR 3'!I11+'JOUR 4'!I11+'JOUR 5'!I11+'JOUR 6'!I11+'JOUR 7'!I11+'JOUR 8'!I11+'JOUR 9'!I11+'JOUR 10'!I11+'JOUR 11'!I11+'JOUR 12'!I11+'JOUR 13'!I11+'JOUR 14'!I11+#REF!+#REF! -> #REF! | J11: ='JOUR 1'!J11+'JOUR 2'!J11+'JOUR 3'!J11+'JOUR 4'!J11+'JOUR 5'!J11+'JOUR 6'!J11+'JOUR 7'!J11+'JOUR 8'!J11+'JOUR 9'!J11+'JOUR 10'!J11+'JOUR 11'!J11+'JOUR 12'!J11+'JOUR 13'!J11+'JOUR 14'!J11+#REF!+#REF! -> #REF! | K11: ='JOUR 1'!K11+'JOUR 2'!K11+'JOUR 3'!K11+'JOUR 4'!K11+'JOUR 5'!K11+'JOUR 6'!K11+'JOUR 7'!K11+'JOUR 8'!K11+'JOUR 9'!K11+'JOUR 10'!K11+'JOUR 11'!K11+'JOUR 12'!K11+'JOUR 13'!K11+'JOUR 14'!K11+#REF!+#REF! -> #REF! | ... AG11: ='JOUR 1'!AG11+'JOUR 2'!AG11+'JOUR 3'!AG11+'JOUR 4'!AG11+'JOUR 5'!AG11+'JOUR 6'!AG11+'JOUR 7'!AG11+'JOUR 8'!AG11+'JOUR 9'!AG11+'JOUR 10'!AG11+'JOUR 11'!AG11+'JOUR 12'!AG11+'JOUR 13'!AG11+'JOUR 14'!AG11+#REF!+#REF! -> #REF! | AK11: =S11/D11 -> #REF! | AL11: =T11/E11 -> #REF! | AM11: =U11/F11 -> #REF! | AN11: =V11/G11 -> #REF! | AO11: =W11/H11 -> #REF! | AS11: =AA11/L11 -> #REF!
B12: KING CASH | C12: KING CASH KENEYA | D12: ='JOUR 1'!D12+'JOUR 2'!D12+'JOUR 3'!D12+'JOUR 4'!D12+'JOUR 5'!D12+'JOUR 6'!D12+'JOUR 7'!D12+'JOUR 8'!D12+'JOUR 9'!D12+'JOUR 10'!D12+'JOUR 11'!D12+'JOUR 12'!D12+'JOUR 13'!D12+'JOUR 14'!D12+#REF!+#REF! -> #REF! | E12: ='JOUR 1'!E12+'JOUR 2'!E12+'JOUR 3'!E12+'JOUR 4'!E12+'JOUR 5'!E12+'JOUR 6'!E12+'JOUR 7'!E12+'JOUR 8'!E12+'JOUR 9'!E12+'JOUR 10'!E12+'JOUR 11'!E12+'JOUR 12'!E12+'JOUR 13'!E12+'JOUR 14'!E12+#REF!+#REF! -> #REF! | F12: ='JOUR 1'!F12+'JOUR 2'!F12+'JOUR 3'!F12+'JOUR 4'!F12+'JOUR 5'!F12+'JOUR 6'!F12+'JOUR 7'!F12+'JOUR 8'!F12+'JOUR 9'!F12+'JOUR 10'!F12+'JOUR 11'!F12+'JOUR 12'!F12+'JOUR 13'!F12+'JOUR 14'!F12+#REF!+#REF! -> #REF! | G12: ='JOUR 1'!G12+'JOUR 2'!G12+'JOUR 3'!G12+'JOUR 4'!G12+'JOUR 5'!G12+'JOUR 6'!G12+'JOUR 7'!G12+'JOUR 8'!G12+'JOUR 9'!G12+'JOUR 10'!G12+'JOUR 11'!G12+'JOUR 12'!G12+'JOUR 13'!G12+'JOUR 14'!G12+#REF!+#REF! -> #REF! | H12: ='JOUR 1'!H12+'JOUR 2'!H12+'JOUR 3'!H12+'JOUR 4'!H12+'JOUR 5'!H12+'JOUR 6'!H12+'JOUR 7'!H12+'JOUR 8'!H12+'JOUR 9'!H12+'JOUR 10'!H12+'JOUR 11'!H12+'JOUR 12'!H12+'JOUR 13'!H12+'JOUR 14'!H12+#REF!+#REF! -> #REF! | I12: ='JOUR 1'!I12+'JOUR 2'!I12+'JOUR 3'!I12+'JOUR 4'!I12+'JOUR 5'!I12+'JOUR 6'!I12+'JOUR 7'!I12+'JOUR 8'!I12+'JOUR 9'!I12+'JOUR 10'!I12+'JOUR 11'!I12+'JOUR 12'!I12+'JOUR 13'!I12+'JOUR 14'!I12+#REF!+#REF! -> #REF! | J12: ='JOUR 1'!J12+'JOUR 2'!J12+'JOUR 3'!J12+'JOUR 4'!J12+'JOUR 5'!J12+'JOUR 6'!J12+'JOUR 7'!J12+'JOUR 8'!J12+'JOUR 9'!J12+'JOUR 10'!J12+'JOUR 11'!J12+'JOUR 12'!J12+'JOUR 13'!J12+'JOUR 14'!J12+#REF!+#REF! -> #REF! | K12: ='JOUR 1'!K12+'JOUR 2'!K12+'JOUR 3'!K12+'JOUR 4'!K12+'JOUR 5'!K12+'JOUR 6'!K12+'JOUR 7'!K12+'JOUR 8'!K12+'JOUR 9'!K12+'JOUR 10'!K12+'JOUR 11'!K12+'JOUR 12'!K12+'JOUR 13'!K12+'JOUR 14'!K12+#REF!+#REF! -> #REF! | ... AG12: ='JOUR 1'!AG12+'JOUR 2'!AG12+'JOUR 3'!AG12+'JOUR 4'!AG12+'JOUR 5'!AG12+'JOUR 6'!AG12+'JOUR 7'!AG12+'JOUR 8'!AG12+'JOUR 9'!AG12+'JOUR 10'!AG12+'JOUR 11'!AG12+'JOUR 12'!AG12+'JOUR 13'!AG12+'JOUR 14'!AG12+#REF!+#REF! -> #REF! | AK12: =S12/D12 -> #REF! | AL12: =T12/E12 -> #REF! | AM12: =U12/F12 -> #REF! | AN12: =V12/G12 -> #REF! | AO12: =W12/H12 -> #REF! | AS12: =AA12/L12 -> #REF!
B13: KING CASH | C13: KING CASH ABOBO PALAIS 2 | D13: ='JOUR 1'!D13+'JOUR 2'!D13+'JOUR 3'!D13+'JOUR 4'!D13+'JOUR 5'!D13+'JOUR 6'!D13+'JOUR 7'!D13+'JOUR 8'!D13+'JOUR 9'!D13+'JOUR 10'!D13+'JOUR 11'!D13+'JOUR 12'!D13+'JOUR 13'!D13+'JOUR 14'!D13+#REF!+#REF! -> #REF! | E13: ='JOUR 1'!E13+'JOUR 2'!E13+'JOUR 3'!E13+'JOUR 4'!E13+'JOUR 5'!E13+'JOUR 6'!E13+'JOUR 7'!E13+'JOUR 8'!E13+'JOUR 9'!E13+'JOUR 10'!E13+'JOUR 11'!E13+'JOUR 12'!E13+'JOUR 13'!E13+'JOUR 14'!E13+#REF!+#REF! -> #REF! | F13: ='JOUR 1'!F13+'JOUR 2'!F13+'JOUR 3'!F13+'JOUR 4'!F13+'JOUR 5'!F13+'JOUR 6'!F13+'JOUR 7'!F13+'JOUR 8'!F13+'JOUR 9'!F13+'JOUR 10'!F13+'JOUR 11'!F13+'JOUR 12'!F13+'JOUR 13'!F13+'JOUR 14'!F13+#REF!+#REF! -> #REF! | G13: ='JOUR 1'!G13+'JOUR 2'!G13+'JOUR 3'!G13+'JOUR 4'!G13+'JOUR 5'!G13+'JOUR 6'!G13+'JOUR 7'!G13+'JOUR 8'!G13+'JOUR 9'!G13+'JOUR 10'!G13+'JOUR 11'!G13+'JOUR 12'!G13+'JOUR 13'!G13+'JOUR 14'!G13+#REF!+#REF! -> #REF! | H13: ='JOUR 1'!H13+'JOUR 2'!H13+'JOUR 3'!H13+'JOUR 4'!H13+'JOUR 5'!H13+'JOUR 6'!H13+'JOUR 7'!H13+'JOUR 8'!H13+'JOUR 9'!H13+'JOUR 10'!H13+'JOUR 11'!H13+'JOUR 12'!H13+'JOUR 13'!H13+'JOUR 14'!H13+#REF!+#REF! -> #REF! | I13: ='JOUR 1'!I13+'JOUR 2'!I13+'JOUR 3'!I13+'JOUR 4'!I13+'JOUR 5'!I13+'JOUR 6'!I13+'JOUR 7'!I13+'JOUR 8'!I13+'JOUR 9'!I13+'JOUR 10'!I13+'JOUR 11'!I13+'JOUR 12'!I13+'JOUR 13'!I13+'JOUR 14'!I13+#REF!+#REF! -> #REF! | J13: ='JOUR 1'!J13+'JOUR 2'!J13+'JOUR 3'!J13+'JOUR 4'!J13+'JOUR 5'!J13+'JOUR 6'!J13+'JOUR 7'!J13+'JOUR 8'!J13+'JOUR 9'!J13+'JOUR 10'!J13+'JOUR 11'!J13+'JOUR 12'!J13+'JOUR 13'!J13+'JOUR 14'!J13+#REF!+#REF! -> #REF! | K13: ='JOUR 1'!K13+'JOUR 2'!K13+'JOUR 3'!K13+'JOUR 4'!K13+'JOUR 5'!K13+'JOUR 6'!K13+'JOUR 7'!K13+'JOUR 8'!K13+'JOUR 9'!K13+'JOUR 10'!K13+'JOUR 11'!K13+'JOUR 12'!K13+'JOUR 13'!K13+'JOUR 14'!K13+#REF!+#REF! -> #REF! | ... AG13: ='JOUR 1'!AG13+'JOUR 2'!AG13+'JOUR 3'!AG13+'JOUR 4'!AG13+'JOUR 5'!AG13+'JOUR 6'!AG13+'JOUR 7'!AG13+'JOUR 8'!AG13+'JOUR 9'!AG13+'JOUR 10'!AG13+'JOUR 11'!AG13+'JOUR 12'!AG13+'JOUR 13'!AG13+'JOUR 14'!AG13+#REF!+#REF! -> #REF! | AK13: =S13/D13 -> #REF! | AL13: =T13/E13 -> #REF! | AM13: =U13/F13 -> #REF! | AN13: =V13/G13 -> #REF! | AO13: =W13/H13 -> #REF! | AS13: =AA13/L13 -> #REF!
B14: KING CASH | C14: KING CASH DABOU | D14: ='JOUR 1'!D14+'JOUR 2'!D14+'JOUR 3'!D14+'JOUR 4'!D14+'JOUR 5'!D14+'JOUR 6'!D14+'JOUR 7'!D14+'JOUR 8'!D14+'JOUR 9'!D14+'JOUR 10'!D14+'JOUR 11'!D14+'JOUR 12'!D14+'JOUR 13'!D14+'JOUR 14'!D14+#REF!+#REF! -> #REF! | E14: ='JOUR 1'!E14+'JOUR 2'!E14+'JOUR 3'!E14+'JOUR 4'!E14+'JOUR 5'!E14+'JOUR 6'!E14+'JOUR 7'!E14+'JOUR 8'!E14+'JOUR 9'!E14+'JOUR 10'!E14+'JOUR 11'!E14+'JOUR 12'!E14+'JOUR 13'!E14+'JOUR 14'!E14+#REF!+#REF! -> #REF! | F14: ='JOUR 1'!F14+'JOUR 2'!F14+'JOUR 3'!F14+'JOUR 4'!F14+'JOUR 5'!F14+'JOUR 6'!F14+'JOUR 7'!F14+'JOUR 8'!F14+'JOUR 9'!F14+'JOUR 10'!F14+'JOUR 11'!F14+'JOUR 12'!F14+'JOUR 13'!F14+'JOUR 14'!F14+#REF!+#REF! -> #REF! | G14: ='JOUR 1'!G14+'JOUR 2'!G14+'JOUR 3'!G14+'JOUR 4'!G14+'JOUR 5'!G14+'JOUR 6'!G14+'JOUR 7'!G14+'JOUR 8'!G14+'JOUR 9'!G14+'JOUR 10'!G14+'JOUR 11'!G14+'JOUR 12'!G14+'JOUR 13'!G14+'JOUR 14'!G14+#REF!+#REF! -> #REF! | H14: ='JOUR 1'!H14+'JOUR 2'!H14+'JOUR 3'!H14+'JOUR 4'!H14+'JOUR 5'!H14+'JOUR 6'!H14+'JOUR 7'!H14+'JOUR 8'!H14+'JOUR 9'!H14+'JOUR 10'!H14+'JOUR 11'!H14+'JOUR 12'!H14+'JOUR 13'!H14+'JOUR 14'!H14+#REF!+#REF! -> #REF! | I14: ='JOUR 1'!I14+'JOUR 2'!I14+'JOUR 3'!I14+'JOUR 4'!I14+'JOUR 5'!I14+'JOUR 6'!I14+'JOUR 7'!I14+'JOUR 8'!I14+'JOUR 9'!I14+'JOUR 10'!I14+'JOUR 11'!I14+'JOUR 12'!I14+'JOUR 13'!I14+'JOUR 14'!I14+#REF!+#REF! -> #REF! | J14: ='JOUR 1'!J14+'JOUR 2'!J14+'JOUR 3'!J14+'JOUR 4'!J14+'JOUR 5'!J14+'JOUR 6'!J14+'JOUR 7'!J14+'JOUR 8'!J14+'JOUR 9'!J14+'JOUR 10'!J14+'JOUR 11'!J14+'JOUR 12'!J14+'JOUR 13'!J14+'JOUR 14'!J14+#REF!+#REF! -> #REF! | K14: ='JOUR 1'!K14+'JOUR 2'!K14+'JOUR 3'!K14+'JOUR 4'!K14+'JOUR 5'!K14+'JOUR 6'!K14+'JOUR 7'!K14+'JOUR 8'!K14+'JOUR 9'!K14+'JOUR 10'!K14+'JOUR 11'!K14+'JOUR 12'!K14+'JOUR 13'!K14+'JOUR 14'!K14+#REF!+#REF! -> #REF! | ... AG14: ='JOUR 1'!AG14+'JOUR 2'!AG14+'JOUR 3'!AG14+'JOUR 4'!AG14+'JOUR 5'!AG14+'JOUR 6'!AG14+'JOUR 7'!AG14+'JOUR 8'!AG14+'JOUR 9'!AG14+'JOUR 10'!AG14+'JOUR 11'!AG14+'JOUR 12'!AG14+'JOUR 13'!AG14+'JOUR 14'!AG14+#REF!+#REF! -> #REF! | AK14: =S14/D14 -> #REF! | AL14: =T14/E14 -> #REF! | AM14: =U14/F14 -> #REF! | AN14: =V14/G14 -> #REF! | AO14: =W14/H14 -> #REF! | AS14: =AA14/L14 -> #REF!
B15: KING CASH | C15: KING CASH 07 DECEMBRE | D15: ='JOUR 1'!D15+'JOUR 2'!D15+'JOUR 3'!D15+'JOUR 4'!D15+'JOUR 5'!D15+'JOUR 6'!D15+'JOUR 7'!D15+'JOUR 8'!D15+'JOUR 9'!D15+'JOUR 10'!D15+'JOUR 11'!D15+'JOUR 12'!D15+'JOUR 13'!D15+'JOUR 14'!D15+#REF!+#REF! -> #REF! | E15: ='JOUR 1'!E15+'JOUR 2'!E15+'JOUR 3'!E15+'JOUR 4'!E15+'JOUR 5'!E15+'JOUR 6'!E15+'JOUR 7'!E15+'JOUR 8'!E15+'JOUR 9'!E15+'JOUR 10'!E15+'JOUR 11'!E15+'JOUR 12'!E15+'JOUR 13'!E15+'JOUR 14'!E15+#REF!+#REF! -> #REF! | F15: ='JOUR 1'!F15+'JOUR 2'!F15+'JOUR 3'!F15+'JOUR 4'!F15+'JOUR 5'!F15+'JOUR 6'!F15+'JOUR 7'!F15+'JOUR 8'!F15+'JOUR 9'!F15+'JOUR 10'!F15+'JOUR 11'!F15+'JOUR 12'!F15+'JOUR 13'!F15+'JOUR 14'!F15+#REF!+#REF! -> #REF! | G15: ='JOUR 1'!G15+'JOUR 2'!G15+'JOUR 3'!G15+'JOUR 4'!G15+'JOUR 5'!G15+'JOUR 6'!G15+'JOUR 7'!G15+'JOUR 8'!G15+'JOUR 9'!G15+'JOUR 10'!G15+'JOUR 11'!G15+'JOUR 12'!G15+'JOUR 13'!G15+'JOUR 14'!G15+#REF!+#REF! -> #REF! | H15: ='JOUR 1'!H15+'JOUR 2'!H15+'JOUR 3'!H15+'JOUR 4'!H15+'JOUR 5'!H15+'JOUR 6'!H15+'JOUR 7'!H15+'JOUR 8'!H15+'JOUR 9'!H15+'JOUR 10'!H15+'JOUR 11'!H15+'JOUR 12'!H15+'JOUR 13'!H15+'JOUR 14'!H15+#REF!+#REF! -> #REF! | I15: ='JOUR 1'!I15+'JOUR 2'!I15+'JOUR 3'!I15+'JOUR 4'!I15+'JOUR 5'!I15+'JOUR 6'!I15+'JOUR 7'!I15+'JOUR 8'!I15+'JOUR 9'!I15+'JOUR 10'!I15+'JOUR 11'!I15+'JOUR 12'!I15+'JOUR 13'!I15+'JOUR 14'!I15+#REF!+#REF! -> #REF! | J15: ='JOUR 1'!J15+'JOUR 2'!J15+'JOUR 3'!J15+'JOUR 4'!J15+'JOUR 5'!J15+'JOUR 6'!J15+'JOUR 7'!J15+'JOUR 8'!J15+'JOUR 9'!J15+'JOUR 10'!J15+'JOUR 11'!J15+'JOUR 12'!J15+'JOUR 13'!J15+'JOUR 14'!J15+#REF!+#REF! -> #REF! | K15: ='JOUR 1'!K15+'JOUR 2'!K15+'JOUR 3'!K15+'JOUR 4'!K15+'JOUR 5'!K15+'JOUR 6'!K15+'JOUR 7'!K15+'JOUR 8'!K15+'JOUR 9'!K15+'JOUR 10'!K15+'JOUR 11'!K15+'JOUR 12'!K15+'JOUR 13'!K15+'JOUR 14'!K15+#REF!+#REF! -> #REF! | ... AG15: ='JOUR 1'!AG15+'JOUR 2'!AG15+'JOUR 3'!AG15+'JOUR 4'!AG15+'JOUR 5'!AG15+'JOUR 6'!AG15+'JOUR 7'!AG15+'JOUR 8'!AG15+'JOUR 9'!AG15+'JOUR 10'!AG15+'JOUR 11'!AG15+'JOUR 12'!AG15+'JOUR 13'!AG15+'JOUR 14'!AG15+#REF!+#REF! -> #REF! | AK15: =S15/D15 -> #REF! | AL15: =T15/E15 -> #REF! | AM15: =U15/F15 -> #REF! | AN15: =V15/G15 -> #REF! | AO15: =W15/H15 -> #REF! | AS15: =AA15/L15 -> #REF!
B16: KING CASH | C16: KING CASH REMBLAIS | D16: ='JOUR 1'!D16+'JOUR 2'!D16+'JOUR 3'!D16+'JOUR 4'!D16+'JOUR 5'!D16+'JOUR 6'!D16+'JOUR 7'!D16+'JOUR 8'!D16+'JOUR 9'!D16+'JOUR 10'!D16+'JOUR 11'!D16+'JOUR 12'!D16+'JOUR 13'!D16+'JOUR 14'!D16+#REF!+#REF! -> #REF! | E16: ='JOUR 1'!E16+'JOUR 2'!E16+'JOUR 3'!E16+'JOUR 4'!E16+'JOUR 5'!E16+'JOUR 6'!E16+'JOUR 7'!E16+'JOUR 8'!E16+'JOUR 9'!E16+'JOUR 10'!E16+'JOUR 11'!E16+'JOUR 12'!E16+'JOUR 13'!E16+'JOUR 14'!E16+#REF!+#REF! -> #REF! | F16: ='JOUR 1'!F16+'JOUR 2'!F16+'JOUR 3'!F16+'JOUR 4'!F16+'JOUR 5'!F16+'JOUR 6'!F16+'JOUR 7'!F16+'JOUR 8'!F16+'JOUR 9'!F16+'JOUR 10'!F16+'JOUR 11'!F16+'JOUR 12'!F16+'JOUR 13'!F16+'JOUR 14'!F16+#REF!+#REF! -> #REF! | G16: ='JOUR 1'!G16+'JOUR 2'!G16+'JOUR 3'!G16+'JOUR 4'!G16+'JOUR 5'!G16+'JOUR 6'!G16+'JOUR 7'!G16+'JOUR 8'!G16+'JOUR 9'!G16+'JOUR 10'!G16+'JOUR 11'!G16+'JOUR 12'!G16+'JOUR 13'!G16+'JOUR 14'!G16+#REF!+#REF! -> #REF! | H16: ='JOUR 1'!H16+'JOUR 2'!H16+'JOUR 3'!H16+'JOUR 4'!H16+'JOUR 5'!H16+'JOUR 6'!H16+'JOUR 7'!H16+'JOUR 8'!H16+'JOUR 9'!H16+'JOUR 10'!H16+'JOUR 11'!H16+'JOUR 12'!H16+'JOUR 13'!H16+'JOUR 14'!H16+#REF!+#REF! -> #REF! | I16: ='JOUR 1'!I16+'JOUR 2'!I16+'JOUR 3'!I16+'JOUR 4'!I16+'JOUR 5'!I16+'JOUR 6'!I16+'JOUR 7'!I16+'JOUR 8'!I16+'JOUR 9'!I16+'JOUR 10'!I16+'JOUR 11'!I16+'JOUR 12'!I16+'JOUR 13'!I16+'JOUR 14'!I16+#REF!+#REF! -> #REF! | J16: ='JOUR 1'!J16+'JOUR 2'!J16+'JOUR 3'!J16+'JOUR 4'!J16+'JOUR 5'!J16+'JOUR 6'!J16+'JOUR 7'!J16+'JOUR 8'!J16+'JOUR 9'!J16+'JOUR 10'!J16+'JOUR 11'!J16+'JOUR 12'!J16+'JOUR 13'!J16+'JOUR 14'!J16+#REF!+#REF! -> #REF! | K16: ='JOUR 1'!K16+'JOUR 2'!K16+'JOUR 3'!K16+'JOUR 4'!K16+'JOUR 5'!K16+'JOUR 6'!K16+'JOUR 7'!K16+'JOUR 8'!K16+'JOUR 9'!K16+'JOUR 10'!K16+'JOUR 11'!K16+'JOUR 12'!K16+'JOUR 13'!K16+'JOUR 14'!K16+#REF!+#REF! -> #REF! | ... AG16: ='JOUR 1'!AG16+'JOUR 2'!AG16+'JOUR 3'!AG16+'JOUR 4'!AG16+'JOUR 5'!AG16+'JOUR 6'!AG16+'JOUR 7'!AG16+'JOUR 8'!AG16+'JOUR 9'!AG16+'JOUR 10'!AG16+'JOUR 11'!AG16+'JOUR 12'!AG16+'JOUR 13'!AG16+'JOUR 14'!AG16+#REF!+#REF! -> #REF! | AK16: =S16/D16 -> #REF! | AL16: =T16/E16 -> #REF! | AM16: =U16/F16 -> #REF! | AN16: =V16/G16 -> #REF! | AO16: =W16/H16 -> #REF! | AS16: =AA16/L16 -> #REF!
... B54: CDCI | C54: CDCI DEMI GROS GONZAGUEVILLE | D54: ='JOUR 1'!D54+'JOUR 2'!D54+'JOUR 3'!D54+'JOUR 4'!D54+'JOUR 5'!D54+'JOUR 6'!D54+'JOUR 7'!D54+'JOUR 8'!D54+'JOUR 9'!D54+'JOUR 10'!D54+'JOUR 11'!D54+'JOUR 12'!D54+'JOUR 13'!D54+'JOUR 14'!D54+#REF!+#REF! -> #REF! | E54: ='JOUR 1'!E54+'JOUR 2'!E54+'JOUR 3'!E54+'JOUR 4'!E54+'JOUR 5'!E54+'JOUR 6'!E54+'JOUR 7'!E54+'JOUR 8'!E54+'JOUR 9'!E54+'JOUR 10'!E54+'JOUR 11'!E54+'JOUR 12'!E54+'JOUR 13'!E54+'JOUR 14'!E54+#REF!+#REF! -> #REF! | F54: ='JOUR 1'!F54+'JOUR 2'!F54+'JOUR 3'!F54+'JOUR 4'!F54+'JOUR 5'!F54+'JOUR 6'!F54+'JOUR 7'!F54+'JOUR 8'!F54+'JOUR 9'!F54+'JOUR 10'!F54+'JOUR 11'!F54+'JOUR 12'!F54+'JOUR 13'!F54+'JOUR 14'!F54+#REF!+#REF! -> #REF! | G54: ='JOUR 1'!G54+'JOUR 2'!G54+'JOUR 3'!G54+'JOUR 4'!G54+'JOUR 5'!G54+'JOUR 6'!G54+'JOUR 7'!G54+'JOUR 8'!G54+'JOUR 9'!G54+'JOUR 10'!G54+'JOUR 11'!G54+'JOUR 12'!G54+'JOUR 13'!G54+'JOUR 14'!G54+#REF!+#REF! -> #REF! | H54: ='JOUR 1'!H54+'JOUR 2'!H54+'JOUR 3'!H54+'JOUR 4'!H54+'JOUR 5'!H54+'JOUR 6'!H54+'JOUR 7'!H54+'JOUR 8'!H54+'JOUR 9'!H54+'JOUR 10'!H54+'JOUR 11'!H54+'JOUR 12'!H54+'JOUR 13'!H54+'JOUR 14'!H54+#REF!+#REF! -> #REF! | I54: ='JOUR 1'!I54+'JOUR 2'!I54+'JOUR 3'!I54+'JOUR 4'!I54+'JOUR 5'!I54+'JOUR 6'!I54+'JOUR 7'!I54+'JOUR 8'!I54+'JOUR 9'!I54+'JOUR 10'!I54+'JOUR 11'!I54+'JOUR 12'!I54+'JOUR 13'!I54+'JOUR 14'!I54+#REF!+#REF! -> #REF! | J54: ='JOUR 1'!J54+'JOUR 2'!J54+'JOUR 3'!J54+'JOUR 4'!J54+'JOUR 5'!J54+'JOUR 6'!J54+'JOUR 7'!J54+'JOUR 8'!J54+'JOUR 9'!J54+'JOUR 10'!J54+'JOUR 11'!J54+'JOUR 12'!J54+'JOUR 13'!J54+'JOUR 14'!J54+#REF!+#REF! -> #REF! | K54: ='JOUR 1'!K54+'JOUR 2'!K54+'JOUR 3'!K54+'JOUR 4'!K54+'JOUR 5'!K54+'JOUR 6'!K54+'JOUR 7'!K54+'JOUR 8'!K54+'JOUR 9'!K54+'JOUR 10'!K54+'JOUR 11'!K54+'JOUR 12'!K54+'JOUR 13'!K54+'JOUR 14'!K54+#REF!+#REF! -> #REF! | ... AG54: ='JOUR 1'!AG54+'JOUR 2'!AG54+'JOUR 3'!AG54+'JOUR 4'!AG54+'JOUR 5'!AG54+'JOUR 6'!AG54+'JOUR 7'!AG54+'JOUR 8'!AG54+'JOUR 9'!AG54+'JOUR 10'!AG54+'JOUR 11'!AG54+'JOUR 12'!AG54+'JOUR 13'!AG54+'JOUR 14'!AG54+#REF!+#REF! -> #REF! | AK54: =S54/D54 -> #REF! | AL54: =T54/E54 -> #REF! | AM54: =U54/F54 -> #REF! | AN54: =V54/G54 -> #REF! | AO54: =W54/H54 -> #REF! | AS54: =AA54/L54 -> #REF!
A55: 2 | B55: TOTAL | D55: =SUM(D5:D54) -> #REF! | E55: =SUM(E5:E34) -> #REF! | F55: =SUM(F5:F54) -> #REF! | G55: =SUM(G5:G54) -> #REF! | H55: =SUM(H5:H54) -> #REF! | I55: =SUM(I5:I54) -> #REF! | J55: =SUM(J5:J54) -> #REF! | K55: =SUM(K5:K54) -> #REF! | L55: =SUM(L5:L54) -> #REF! | M55: =SUM(M5:M54) -> #REF! | ... AG55: =SUM(AG5:AG54) -> #REF! | AH55: =SUM(AH5:AH34) -> 0 | AI55: =SUM(AI5:AI34) -> 0 | AK55: =S55/D55 -> #REF! | AL55: =T55/E55 -> #REF! | AM55: =U55/F55 -> #REF! | AN55: =V55/G55 -> #REF! | AO55: =W55/H55 -> #REF! | AS55: =AA55/L55 -> #REF!
B57: TOTAL EN CARTONS | D57: =D55 -> #REF! | E57: =E55 -> #REF! | F57: =F55/120 -> #REF! | G57: =G55/6 -> #REF! | H57: =H55/10 -> #REF! | I57: =I55/100 -> #REF! | J57: =J55/10 -> #REF! | K57: =K55/60 -> #REF! | L57: =L55/120 -> #REF! | M57: =M55/100 -> #REF! | N57: =N55/60 -> #REF! | O57: =O55 -> #REF! | P57: =P55 -> #REF! | Q57: =Q55 -> #REF! | R57: =R55 -> #REF! | S57: =S55 -> #REF! | T57: =T55 -> #REF! | U57: =U55/120 -> #REF! | V57: =V55/6 -> #REF! | W57: =W55/10 -> #REF! | X57: =X55/100 -> #REF! | Y57: =Y55/20 -> #REF! | Z57: =Z55/60 -> #REF! | AA57: =AA55/120 -> #REF! | AB57: =AB55/100 -> #REF! | AC57: =AC55/60 -> #REF! | AD57: =AD55 -> #REF! | AE57: =AE55 -> #REF! | AF57: =AF55 -> #REF! | AG57: =AG55 -> #REF!

Sheet JOUR 1
B2: Date | C2: 46108 | D2: OBJECTIFS | S2: REALISATIONS | AK2: TAUX DE REALISATION
B3: Enseigne | C3: Nom du PDV en promotion | D3: Contacts | E3: =T3 -> Acheteurs | F3: Produits (en unités) | L3: Gratuités pour achats (en unités) | S3: Contacts | T3: Acheteurs | U3: Produits | AA3: =L3 -> Gratuités pour achats (en unités) | AD3: GOODIES | AH3: Commentaires | AI3: Impressions des PDV et des clients | AK3: Contacts | AL3: Acheteurs | AM3: Produits | AS3: =AD3 -> GOODIES | AV3: GOODIES
D4: =S4 -> Nombre de personnes ayant été contactées au rayon | E4: =T4 -> Nombre de personnes ayant acheté | F4: Biblos Lait Premium 16g | G4: Biblos Lait Premium 360g | H4: Biblos Lait Excellence | I4: Biblos Flocon d'avoine 50g | J4: Biblos Flocon d'avoine 400g | K4: Biblos 3 en 1 Café au lait | L4: Biblos Lait Premium 16g | M4: Biblos Flocon d'avoine 50g | N4: Biblos 3 en Café au Lait | O4: Goodies 1 | P4: Goodies 2 | Q4: Goodies 3 | R4: Goodie 4 | S4: Nombre de personnes ayant été contactées au rayon | T4: Nombre de personnes ayant acheté | U4: Biblos Lait Premium 16g | V4: Biblos Lait Premium 360g | W4: Biblos Lait Excellence | X4: Biblos Flocon d'avoine 50g | Y4: Biblos Flocon d'avoine 400g | Z4: Biblos 3 en 1 Café au lait | AA4: Biblos Lait Premium 16g | AB4: Biblos Flocon d'avoine 50g | AC4: Biblos 3 en 1 Café au lait | AD4: =O4 -> Goodies 1 | AE4: =P4 -> Goodies 2 | AF4: =Q4 -> Goodies 3 | AG4: =R4 -> Goodie 4 | AK4: Nombre de personnes ayant été contactées au rayon | AL4: Nombre de personnes ayant acheté | AM4: Biblos Lait Premium 16g | AN4: Biblos Lait Premium 360g | AO4: Biblos Lait Excellence | AP4: Biblos Flocon d'avoine 50g | AQ4: Biblos Flocon d'avoine 400g | AR4: Biblos 3 en 1 Café au lait | AS4: Biblos Lait Premium 16g | AT4: Biblos Flocon d'avoine 50g | AU4: Biblos 3 en 1 Café au lait | AV4: Goodies 1 | AW4: Goodies 2 | AX4: Goodies 3 | AY4: Goodies 4
B5: KING CASH | C5: KING CASH PALAIS YOP | D5: 40 | E5: 20 | F5: 120 | G5: 7 | H5: 4 | I5: 0 | J5: 0 | K5: 0 | L5: =5*35 -> 175 | N5: 0 | S5: 30 | T5: 0 | U5: 0 | V5: 0 | W5: 0 | X5: 0 | Y5: 0 | Z5: 0 | AA5: 0 | AB5: 0 | AC5: 0 | AD5: 0 | AE5: 0 | AF5: 0 | AG5: 0 | AH5: PAS RECU DE PRODUITS | AK5: =S5/D5 -> 0.75 | AL5: =T5/E5 -> 0 | AM5: =U5/F5 -> 0 | AN5: =V5/G5 -> 0 | AO5: =W5/H5 -> 0 | AS5: =AA5/L5 -> 0
B6: KING CASH | C6: KING CASH PORT BOUET 2 | D6: 40 | E6: 20 | F6: 120 | G6: 7 | H6: 4 | I6: 0 | J6: 0 | K6: 0 | L6: =5*35 -> 175 | N6: 0 | S6: 20 | T6: 0 | U6: 0 | V6: 0 | W6: 0 | X6: 0 | Y6: 0 | Z6: 0 | AA6: 0 | AB6: 0 | AC6: 0 | AD6: 0 | AE6: 0 | AF6: 0 | AG6: 0 | AH6: PAS RECU DE PRODUITS | AK6: =S6/D6 -> 0.5 | AL6: =T6/E6 -> 0 | AM6: =U6/F6 -> 0 | AN6: =V6/G6 -> 0 | AO6: =W6/H6 -> 0 | AS6: =AA6/L6 -> 0
B7: KING CASH | C7: KING CASH ABOBO MAIRIE | D7: 40 | E7: 20 | F7: 120 | G7: 7 | H7: 4 | I7: 0 | J7: 0 | K7: 0 | L7: =5*35 -> 175 | N7: 0 | S7: 35 | T7: 0 | U7: 0 | V7: 0 | W7: 0 | X7: 0 | Y7: 0 | Z7: 0 | AA7: 0 | AB7: 0 | AC7: 0 | AD7: 0 | AE7: 0 | AF7: 0 | AG7: 0 | AH7: PAS RECU DE PRODUITS | AK7: =S7/D7 -> 0.875 | AL7: =T7/E7 -> 0 | AM7: =U7/F7 -> 0 | AN7: =V7/G7 -> 0 | AO7: =W7/H7 -> 0 | AS7: =AA7/L7 -> 0
B8: KING CASH | C8: KING CASH SIPOREX | D8: 40 | E8: 20 | F8: 120 | G8: 7 | H8: 4 | I8: 0 | J8: 0 | K8: 0 | L8: =5*35 -> 175 | N8: 0 | S8: 25 | T8: 0 | U8: 0 | V8: 0 | W8: 0 | X8: 0 | Y8: 0 | Z8: 0 | AA8: 0 | AB8: 0 | AC8: 0 | AD8: 0 | AE8: 0 | AF8: 0 | AG8: 0 | AH8: PAS RECU DE PRODUITS | AK8: =S8/D8 -> 0.625 | AL8: =T8/E8 -> 0 | AM8: =U8/F8 -> 0 | AN8: =V8/G8 -> 0 | AO8: =W8/H8 -> 0 | AS8: =AA8/L8 -> 0
B9: KING CASH | C9: KING CASH PRINCES. | D9: 40 | E9: 20 | F9: 120 | G9: 7 | H9: 4 | I9: 0 | J9: 0 | K9: 0 | L9: =5*35 -> 175 | N9: 0 | S9: 20 | T9: 0 | U9: 0 | V9: 0 | W9: 0 | X9: 0 | Y9: 0 | Z9: 0 | AA9: 0 | AB9: 0 | AC9: 0 | AD9: 0 | AE9: 0 | AF9: 0 | AG9: 0 | AH9: PAS RECU DE PRODUITS | AK9: =S9/D9 -> 0.5 | AL9: =T9/E9 -> 0 | AM9: =U9/F9 -> 0 | AN9: =V9/G9 -> 0 | AO9: =W9/H9 -> 0 | AS9: =AA9/L9 -> 0
B10: KING CASH | C10: KING CASH WAKOUBOUE | D10: 40 | E10: 20 | F10: 120 | G10: 7 | H10: 4 | I10: 0 | J10: 0 | K10: 0 | L10: =5*35 -> 175 | N10: 0 | S10: 20 | T10: 0 | U10: 0 | V10: 0 | W10: 0 | X10: 0 | Y10: 0 | Z10: 0 | AA10: 0 | AB10: 0 | AC10: 0 | AD10: 0 | AE10: 0 | AF10: 0 | AG10: 0 | AH10: PAS RECU DE PRODUITS | AK10: =S10/D10 -> 0.5 | AL10: =T10/E10 -> 0 | AM10: =U10/F10 -> 0 | AN10: =V10/G10 -> 0 | AO10: =W10/H10 -> 0 | AS10: =AA10/L10 -> 0
B11: KING CASH | C11: KING CASH ABOBO KAZA | D11: 40 | E11: 20 | F11: 120 | G11: 7 | H11: 4 | I11: 0 | J11: 0 | K11: 0 | L11: =5*35 -> 175 | N11: 0 | S11: 35 | T11: 0 | U11: 0 | V11: 0 | W11: 0 | X11: 0 | Y11: 0 | Z11: 0 | AA11: 0 | AB11: 0 | AC11: 0 | AD11: 0 | AE11: 0 | AF11: 0 | AG11: 0 | AH11: PAS RECU DE PRODUITS | AK11: =S11/D11 -> 0.875 | AL11: =T11/E11 -> 0 | AM11: =U11/F11 -> 0 | AN11: =V11/G11 -> 0 | AO11: =W11/H11 -> 0 | AS11: =AA11/L11 -> 0
B12: KING CASH | C12: KING CASH KENEYA | D12: 40 | E12: 20 | F12: 120 | G12: 7 | H12: 4 | I12: 0 | J12: 0 | K12: 0 | L12: =5*35 -> 175 | N12: 0 | S12: 38 | T12: 0 | U12: 0 | V12: 0 | W12: 0 | X12: 0 | Y12: 0 | Z12: 0 | AA12: 0 | AB12: 0 | AC12: 0 | AD12: 0 | AE12: 0 | AF12: 0 | AG12: 0 | AH12: PAS RECU DE PRODUITS | AK12: =S12/D12 -> 0.95 | AL12: =T12/E12 -> 0 | AM12: =U12/F12 -> 0 | AN12: =V12/G12 -> 0 | AO12: =W12/H12 -> 0 | AS12: =AA12/L12 -> 0
B13: KING CASH | C13: KING CASH ABOBO PALAIS 2 | D13: 40 | E13: 20 | F13: 120 | G13: 7 | H13: 4 | I13: 0 | J13: 0 | K13: 0 | L13: =5*35 -> 175 | N13: 0 | S13: 40 | T13: 0 | U13: 0 | V13: 0 | W13: 0 | X13: 0 | Y13: 0 | Z13: 0 | AA13: 0 | AB13: 0 | AC13: 0 | AD13: 0 | AE13: 0 | AF13: 0 | AG13: 0 | AH13: PAS RECU DE PRODUITS | AK13: =S13/D13 -> 1 | AL13: =T13/E13 -> 0 | AM13: =U13/F13 -> 0 | AN13: =V13/G13 -> 0 | AO13: =W13/H13 -> 0 | AS13: =AA13/L13 -> 0
B14: KING CASH | C14: KING CASH DABOU | D14: 40 | E14: 20 | F14: 120 | G14: 7 | H14: 4 | I14: 0 | J14: 0 | K14: 0 | L14: =5*35 -> 175 | N14: 0 | S14: 25 | T14: 0 | U14: 0 | V14: 0 | W14: 0 | X14: 0 | Y14: 0 | Z14: 0 | AA14: 0 | AB14: 0 | AC14: 0 | AD14: 0 | AE14: 0 | AF14: 0 | AG14: 0 | AH14: PAS RECU DE PRODUITS | AK14: =S14/D14 -> 0.625 | AL14: =T14/E14 -> 0 | AM14: =U14/F14 -> 0 | AN14: =V14/G14 -> 0 | AO14: =W14/H14 -> 0 | AS14: =AA14/L14 -> 0
B15: KING CASH | C15: KING CASH 07 DECEMBRE | D15: 40 | E15: 20 | F15: 120 | G15: 7 | H15: 4 | I15: 0 | J15: 0 | K15: 0 | L15: =5*35 -> 175 | N15: 0 | S15: 20 | T15: 0 | U15: 0 | V15: 0 | W15: 0 | X15: 0 | Y15: 0 | Z15: 0 | AA15: 0 | AB15: 0 | AC15: 0 | AD15: 0 | AE15: 0 | AF15: 0 | AG15: 0 | AH15: PAS RECU DE PRODUITS | AK15: =S15/D15 -> 0.5 | AL15: =T15/E15 -> 0 | AM15: =U15/F15 -> 0 | AN15: =V15/G15 -> 0 | AO15: =W15/H15 -> 0 | AS15: =AA15/L15 -> 0
B16: KING CASH | C16: KING CASH REMBLAIS | D16: 40 | E16: 20 | F16: 120 | G16: 7 | H16: 4 | I16: 0 | J16: 0 | K16: 0 | L16: =5*35 -> 175 | N16: 0 | S16: 22 | T16: 0 | U16: 0 | V16: 0 | W16: 0 | X16: 0 | Y16: 0 | Z16: 0 | AA16: 0 | AB16: 0 | AC16: 0 | AD16: 0 | AE16: 0 | AF16: 0 | AG16: 0 | AH16: PAS RECU DE PRODUITS | AK16: =S16/D16 -> 0.55 | AL16: =T16/E16 -> 0 | AM16: =U16/F16 -> 0 | AN16: =V16/G16 -> 0 | AO16: =W16/H16 -> 0 | AS16: =AA16/L16 -> 0
... B24: KING CASH | C24: ING CASH JULES VERNE | D24: 40 | E24: 20 | F24: 120 | G24: 7 | H24: 4 | I24: 0 | J24: 0 | K24: 0 | L24: =5*35 -> 175 | N24: 0 | S24: 36 | T24: 19 | U24: 104 | V24: 1 | W24: 0 | X24: 0 | Y24: 0 | Z24: 0 | AA24: 27 | AB24: 0 | AC24: 0 | AD24: 0 | AE24: 0 | AF24: 0 | AG24: 0 | AH24: PAS RECU DE PRODUITS | AK24: =S24/D24 -> 0.9 | AL24: =T24/E24 -> 0.95 | AM24: =U24/F24 -> 0.86666667 | AN24: =V24/G24 -> 0.14285714 | AO24: =W24/H24 -> 0 | AS24: =AA24/L24 -> 0.15428571
B25: KING CASH | C25: ING CASH BASSAM | D25: 40 | E25: 20 | F25: 120 | G25: 7 | H25: 4 | I25: 0 | J25: 0 | K25: 0 | L25: =5*35 -> 175 | N25: 0 | S25: 37 | T25: 21 | U25: 80 | V25: 9 | W25: 0 | X25: 0 | Y25: 5 | Z25: 0 | AA25: 20 | AB25: 0 | AC25: 0 | AD25: 0 | AE25: 0 | AF25: 0 | AG25: 0 | AH25: PAS RECU DE PRODUITS | AI25: Très bons produits | AK25: =S25/D25 -> 0.925 | AL25: =T25/E25 -> 1.05 | AM25: =U25/F25 -> 0.66666667 | AN25: =V25/G25 -> 1.2857143 | AO25: =W25/H25 -> 0 | AS25: =AA25/L25 -> 0.11428571
B26: KING CASH | C26: KING CASH KOUMASSI 05 | D26: 40 | E26: 20 | F26: 120 | G26: 7 | H26: 4 | I26: 0 | J26: 0 | K26: 0 | L26: =5*35 -> 175 | N26: 0 | S26: 20 | T26: 0 | U26: 0 | V26: 0 | W26: 0 | X26: 0 | Y26: 0 | Z26: 0 | AA26: 0 | AB26: 0 | AC26: 0 | AD26: 0 | AE26: 0 | AF26: 0 | AG26: 0 | AH26: PAS RECU DE PRODUITS | AK26: =S26/D26 -> 0.5 | AL26: =T26/E26 -> 0 | AM26: =U26/F26 -> 0 | AN26: =V26/G26 -> 0 | AO26: =W26/H26 -> 0 | AS26: =AA26/L26 -> 0
B27: KING CASH | C27: KING CASH PORT BOUET | D27: 40 | E27: 20 | F27: 120 | G27: 7 | H27: 4 | I27: 0 | J27: 0 | K27: 0 | L27: =5*35 -> 175 | N27: 0 | S27: 24 | T27: 0 | U27: 0 | V27: 0 | W27: 0 | X27: 0 | Y27: 0 | Z27: 0 | AA27: 0 | AB27: 0 | AC27: 0 | AD27: 0 | AE27: 0 | AF27: 0 | AG27: 0 | AH27: PAS RECU DE PRODUITS | AK27: =S27/D27 -> 0.6 | AL27: =T27/E27 -> 0 | AM27: =U27/F27 -> 0 | AN27: =V27/G27 -> 0 | AO27: =W27/H27 -> 0 | AS27: =AA27/L27 -> 0
B28: KING CASH | C28: KING CASH AVENUE 16 | D28: 40 | E28: 20 | F28: 120 | G28: 7 | H28: 4 | I28: 0 | J28: 0 | K28: 0 | L28: =5*35 -> 175 | N28: 0 | S28: 27 | T28: 0 | U28: 0 | V28: 0 | W28: 0 | X28: 0 | Y28: 0 | Z28: 0 | AA28: 0 | AB28: 0 | AC28: 0 | AD28: 0 | AE28: 0 | AF28: 0 | AG28: 0 | AH28: PAS RECU DE PRODUITS | AK28: =S28/D28 -> 0.675 | AL28: =T28/E28 -> 0 | AM28: =U28/F28 -> 0 | AN28: =V28/G28 -> 0 | AO28: =W28/H28 -> 0 | AS28: =AA28/L28 -> 0
B29: KING CASH | C29: IKING CASH ANOUMANBO | D29: 40 | E29: 20 | F29: 120 | G29: 7 | H29: 4 | I29: 0 | J29: 0 | K29: 0 | L29: =5*35 -> 175 | N29: 0 | S29: 15 | T29: 0 | U29: 0 | V29: 0 | W29: 0 | X29: 0 | Y29: 0 | Z29: 0 | AA29: 0 | AB29: 0 | AC29: 0 | AD29: 0 | AE29: 0 | AF29: 0 | AG29: 0 | AH29: PAS RECU DE PRODUITS | AK29: =S29/D29 -> 0.375 | AL29: =T29/E29 -> 0 | AM29: =U29/F29 -> 0 | AN29: =V29/G29 -> 0 | AO29: =W29/H29 -> 0 | AS29: =AA29/L29 -> 0
B30: KING CASH | C30: KING CASH MARA | D30: 40 | E30: 20 | F30: 120 | G30: 7 | H30: 4 | I30: 0 | J30: 0 | K30: 0 | L30: =5*35 -> 175 | N30: 0 | S30: 29 | T30: 0 | U30: 0 | V30: 0 | W30: 0 | X30: 0 | Y30: 0 | Z30: 0 | AA30: 0 | AB30: 0 | AC30: 0 | AD30: 0 | AE30: 0 | AF30: 0 | AG30: 0 | AH30: PAS RECU DE PRODUITS | AK30: =S30/D30 -> 0.725 | AL30: =T30/E30 -> 0 | AM30: =U30/F30 -> 0 | AN30: =V30/G30 -> 0 | AO30: =W30/H30 -> 0 | AS30: =AA30/L30 -> 0
B31: KING CASH | C31: KING CASH BONOUA, | D31: 40 | E31: 20 | F31: 120 | G31: 7 | H31: 4 | I31: 0 | J31: 0 | K31: 0 | L31: =5*35 -> 175 | N31: 0 | S31: 15 | T31: 0 | U31: 0 | V31: 0 | W31: 0 | X31: 0 | Y31: 0 | Z31: 0 | AA31: 0 | AB31: 0 | AC31: 0 | AD31: 0 | AE31: 0 | AF31: 0 | AG31: 0 | AH31: PAS RECU DE PRODUITS | AK31: =S31/D31 -> 0.375 | AL31: =T31/E31 -> 0 | AM31: =U31/F31 -> 0 | AN31: =V31/G31 -> 0 | AO31: =W31/H31 -> 0 | AS31: =AA31/L31 -> 0
B32: KING CASH | C32: KING CASH ADIAKE | D32: 40 | E32: 20 | F32: 120 | G32: 7 | H32: 4 | I32: 0 | J32: 0 | K32: 0 | L32: =5*35 -> 175 | N32: 0 | S32: 30 | T32: 0 | U32: 0 | V32: 0 | W32: 0 | X32: 0 | Y32: 0 | Z32: 0 | AA32: 0 | AB32: 0 | AC32: 0 | AD32: 0 | AE32: 0 | AF32: 0 | AG32: 0 | AH32: PAS RECU DE PRODUITS | AK32: =S32/D32 -> 0.75 | AL32: =T32/E32 -> 0 | AM32: =U32/F32 -> 0 | AN32: =V32/G32 -> 0 | AO32: =W32/H32 -> 0 | AS32: =AA32/L32 -> 0
B33: KING CASH | C33: KING CASH BLVD GABON | D33: 40 | E33: 20 | F33: 120 | G33: 7 | H33: 4 | I33: 0 | J33: 0 | K33: 0 | L33: =5*35 -> 175 | N33: 0 | S33: 14 | T33: 0 | U33: 0 | V33: 0 | W33: 0 | X33: 0 | Y33: 0 | Z33: 0 | AA33: 0 | AB33: 0 | AC33: 0 | AD33: 0 | AE33: 0 | AF33: 0 | AG33: 0 | AH33: PAS RECU DE PRODUITS | AK33: =S33/D33 -> 0.35 | AL33: =T33/E33 -> 0 | AM33: =U33/F33 -> 0 | AN33: =V33/G33 -> 0 | AO33: =W33/H33 -> 0 | AS33: =AA33/L33 -> 0
B34: CDCI | C34: CDCI DEMI GROS SAMAKE | D34: 40 | E34: 20 | F34: 120 | G34: 7 | H34: 4 | I34: 0 | J34: 0 | K34: 0 | L34: =5*35 -> 175 | N34: 0 | S34: 34 | T34: 10 | U34: 100 | V34: 4 | W34: 0 | X34: 0 | Y34: 0 | Z34: 0 | AA34: 18 | AB34: 0 | AC34: 0 | AD34: 0 | AE34: 0 | AF34: 0 | AG34: 0 | AH34: PAS RECU DE PRODUITS | AK34: =S34/D34 -> 0.85 | AL34: =T34/E34 -> 0.5 | AM34: =U34/F34 -> 0.83333333 | AN34: =V34/G34 -> 0.57142857 | AO34: =W34/H34 -> 0 | AS34: =AA34/L34 -> 0.10285714
B35: CDCI | C35: CDCI DEMI GROS KOUTE | D35: 40 | E35: 20 | F35: 120 | G35: 7 | H35: 4 | I35: 0 | J35: 0 | K35: 0 | L35: =5*35 -> 175 | N35: 0 | S35: 15 | T35: 5 | U35: 70 | V35: 0 | W35: 0 | X35: 0 | Y35: 0 | Z35: 0 | AA35: 0 | AB35: 0 | AC35: 0 | AD35: 0 | AE35: 0 | AF35: 0 | AG35: 0 | AH35: PAS RECU DE PRODUITS | AK35: =S35/D35 -> 0.375 | AL35: =T35/E35 -> 0.25 | AM35: =U35/F35 -> 0.58333333 | AN35: =V35/G35 -> 0 | AO35: =W35/H35 -> 0 | AS35: =AA35/L35 -> 0
B36: CDCI | C36: CDCI DEMI GROS NIANGON | D36: 40 | E36: 20 | F36: 120 | G36: 7 | H36: 4 | I36: 0 | J36: 0 | K36: 0 | L36: =5*35 -> 175 | N36: 0 | S36: 22 | T36: 0 | U36: 0 | V36: 0 | W36: 0 | X36: 0 | Y36: 0 | Z36: 0 | AA36: 0 | AB36: 0 | AC36: 0 | AD36: 0 | AE36: 0 | AF36: 0 | AG36: 0 | AH36: PAS RECU DE PRODUITS | AK36: =S36/D36 -> 0.55 | AL36: =T36/E36 -> 0 | AM36: =U36/F36 -> 0 | AN36: =V36/G36 -> 0 | AO36: =W36/H36 -> 0 | AS36: =AA36/L36 -> 0
B37: CDCI | C37: CDCI DEMI GROS ABOBO BAOULE | D37: 40 | E37: 20 | F37: 120 | G37: 7 | H37: 4 | I37: 0 | J37: 0 | K37: 0 | L37: =5*35 -> 175 | N37: 0 | S37: 28 | T37: 0 | U37: 0 | V37: 0 | W37: 0 | X37: 0 | Y37: 0 | Z37: 0 | AA37: 0 | AB37: 0 | AC37: 0 | AD37: 0 | AE37: 0 | AF37: 0 | AG37: 0 | AH37: PAS RECU DE PRODUITS | AK37: =S37/D37 -> 0.7 | AL37: =T37/E37 -> 0 | AM37: =U37/F37 -> 0 | AN37: =V37/G37 -> 0 | AO37: =W37/H37 -> 0 | AS37: =AA37/L37 -> 0
B38: CDCI | C38: CDCI DEMI GROS AKEIKOI | D38: 40 | E38: 20 | F38: 120 | G38: 7 | H38: 4 | I38: 0 | J38: 0 | K38: 0 | L38: =5*35 -> 175 | N38: 0 | S38: 35 | T38: 20 | U38: 120 | V38: 5 | W38: 0 | X38: 40 | Y38: 15 | Z38: 0 | AA38: 42 | AB38: 0 | AC38: 0 | AD38: 0 | AE38: 0 | AF38: 0 | AG38: 0 | AH38: PAS RECU DE PRODUITS | AK38: =S38/D38 -> 0.875 | AL38: =T38/E38 -> 1 | AM38: =U38/F38 -> 1 | AN38: =V38/G38 -> 0.71428571 | AO38: =W38/H38 -> 0 | AS38: =AA38/L38 -> 0.24
B39: CDCI | C39: CDCI DEMI GROS 4 ETAGES | D39: 40 | E39: 20 | F39: 120 | G39: 7 | H39: 4 | I39: 0 | J39: 0 | K39: 0 | L39: =5*35 -> 175 | N39: 0 | S39: 40 | T39: 20 | U39: 80 | V39: 1 | W39: 0 | X39: 82 | Y39: 1 | Z39: 0 | AA39: 50 | AB39: 0 | AC39: 0 | AD39: 0 | AE39: 0 | AF39: 0 | AG39: 0 | AH39: PAS RECU DE PRODUITS | AI39: Les clients aiment les produits Biblos | AK39: =S39/D39 -> 1 | AL39: =T39/E39 -> 1 | AM39: =U39/F39 -> 0.66666667 | AN39: =V39/G39 -> 0.14285714 | AO39: =W39/H39 -> 0 | AS39: =AA39/L39 -> 0.28571429
B40: CDCI | C40: CDCI DEMI GROS PK 18 | D40: 40 | E40: 20 | F40: 120 | G40: 7 | H40: 4 | I40: 0 | J40: 0 | K40: 0 | L40: =5*35 -> 175 | N40: 0 | S40: 33 | T40: 0 | AH40: PAS RECU DE PRODUITS | AK40: =S40/D40 -> 0.825 | AL40: =T40/E40 -> 0 | AM40: =U40/F40 -> 0 | AN40: =V40/G40 -> 0 | AO40: =W40/H40 -> 0 | AS40: =AA40/L40 -> 0
B41: CDCI | C41: CDCI DEMI GROS ANYAMA | D41: 40 | E41: 20 | F41: 120 | G41: 7 | H41: 4 | I41: 0 | J41: 0 | K41: 0 | L41: =5*35 -> 175 | N41: 0 | S41: 48 | T41: 32 | U41: 180 | V41: 2 | W41: 0 | X41: 80 | Y41: 5 | Z41: 0 | AA41: 65 | AB41: 0 | AC41: 0 | AD41: 0 | AE41: 0 | AF41: 0 | AG41: 0 | AH41: PAS RECU DE PRODUITS | AK41: =S41/D41 -> 1.2 | AL41: =T41/E41 -> 1.6 | AM41: =U41/F41 -> 1.5 | AN41: =V41/G41 -> 0.28571429 | AO41: =W41/H41 -> 0 | AS41: =AA41/L41 -> 0.37142857
B42: CDCI | C42: CDCI DEMI GROS ANANERAIE | D42: 40 | E42: 20 | F42: 120 | G42: 7 | H42: 4 | I42: 0 | J42: 0 | K42: 0 | L42: =5*35 -> 175 | N42: 0 | S42: 15 | T42: 5 | U42: 0 | V42: 0 | W42: 0 | X42: 30 | Y42: 0 | Z42: 0 | AA42: 0 | AB42: 0 | AC42: 0 | AD42: 0 | AE42: 0 | AF42: 0 | AG42: 0 | AH42: PAS RECU DE PRODUITS | AK42: =S42/D42 -> 0.375 | AL42: =T42/E42 -> 0.25 | AM42: =U42/F42 -> 0 | AN42: =V42/G42 -> 0 | AO42: =W42/H42 -> 0 | AS42: =AA42/L42 -> 0
B43: CDCI | C43: CDCI DEMI GROS EBENEZER | D43: 40 | E43: 20 | F43: 120 | G43: 7 | H43: 4 | I43: 0 | J43: 0 | K43: 0 | L43: =5*35 -> 175 | N43: 0 | S43: 25 | T43: 0 | U43: 0 | V43: 0 | W43: 0 | X43: 0 | Y43: 0 | Z43: 0 | AA43: 0 | AB43: 0 | AC43: 0 | AD43: 0 | AE43: 0 | AF43: 0 | AG43: 0 | AH43: PAS RECU DE PRODUITS | AK43: =S43/D43 -> 0.625 | AL43: =T43/E43 -> 0 | AM43: =U43/F43 -> 0 | AN43: =V43/G43 -> 0 | AO43: =W43/H43 -> 0 | AS43: =AA43/L43 -> 0
B44: CDCI | C44: CDCI DEMI GROS TOIT ROUGE | D44: 40 | E44: 20 | F44: 120 | G44: 7 | H44: 4 | I44: 0 | J44: 0 | K44: 0 | L44: =5*35 -> 175 | N44: 0 | S44: 27 | T44: 0 | U44: 0 | V44: 0 | W44: 0 | X44: 0 | Y44: 0 | Z44: 0 | AA44: 0 | AB44: 0 | AC44: 0 | AD44: 0 | AE44: 0 | AF44: 0 | AG44: 0 | AH44: PAS RECU DE PRODUITS | AK44: =S44/D44 -> 0.675 | AL44: =T44/E44 -> 0 | AM44: =U44/F44 -> 0 | AN44: =V44/G44 -> 0 | AO44: =W44/H44 -> 0 | AS44: =AA44/L44 -> 0
B45: CDCI | C45: CDCI DEMI GROS BANCO 2 | D45: 40 | E45: 20 | F45: 120 | G45: 7 | H45: 4 | I45: 0 | J45: 0 | K45: 0 | L45: =5*35 -> 175 | N45: 0 | S45: 22 | T45: 0 | U45: 0 | V45: 0 | W45: 0 | X45: 0 | Y45: 0 | Z45: 0 | AA45: 0 | AB45: 0 | AC45: 0 | AD45: 0 | AE45: 0 | AF45: 0 | AG45: 0 | AH45: PAS RECU DE PRODUITS | AK45: =S45/D45 -> 0.55 | AL45: =T45/E45 -> 0 | AM45: =U45/F45 -> 0 | AN45: =V45/G45 -> 0 | AO45: =W45/H45 -> 0 | AS45: =AA45/L45 -> 0
B46: CDCI | C46: CDCI DEMI GROS RIVIERA 3 | D46: 40 | E46: 20 | F46: 120 | G46: 7 | H46: 4 | I46: 0 | J46: 0 | K46: 0 | L46: =5*35 -> 175 | N46: 0 | S46: 20 | T46: 0 | U46: 0 | V46: 0 | W46: 0 | X46: 0 | Y46: 0 | Z46: 0 | AA46: 0 | AB46: 0 | AC46: 0 | AD46: 0 | AE46: 0 | AF46: 0 | AG46: 0 | AH46: PAS RECU DE PRODUITS | AK46: =S46/D46 -> 0.5 | AL46: =T46/E46 -> 0 | AM46: =U46/F46 -> 0 | AN46: =V46/G46 -> 0 | AO46: =W46/H46 -> 0 | AS46: =AA46/L46 -> 0
B47: CDCI | C47: CDCI DEMI GROS VGE | D47: 40 | E47: 20 | F47: 120 | G47: 7 | H47: 4 | I47: 0 | J47: 0 | K47: 0 | L47: =5*35 -> 175 | N47: 0 | S47: 25 | T47: 0 | U47: 0 | V47: 0 | W47: 0 | X47: 0 | Y47: 0 | Z47: 0 | AA47: 0 | AB47: 0 | AC47: 0 | AD47: 0 | AE47: 0 | AF47: 0 | AG47: 0 | AH47: PAS RECU DE PRODUITS | AK47: =S47/D47 -> 0.625 | AL47: =T47/E47 -> 0 | AM47: =U47/F47 -> 0 | AN47: =V47/G47 -> 0 | AO47: =W47/H47 -> 0 | AS47: =AA47/L47 -> 0
B48: CDCI | C48: CDCI DEMI GROS ANGRE | D48: 40 | E48: 20 | F48: 120 | G48: 7 | H48: 4 | I48: 0 | J48: 0 | K48: 0 | L48: =5*35 -> 175 | N48: 0 | S48: 36 | T48: 27 | U48: 67 | V48: 10 | W48: 0 | X48: 30 | Y48: 25 | Z48: 0 | AA48: 20 | AB48: 0 | AC48: 0 | AD48: 0 | AE48: 0 | AF48: 0 | AG48: 0 | AH48: PAS RECU DE PRODUITS | AK48: =S48/D48 -> 0.9 | AL48: =T48/E48 -> 1.35 | AM48: =U48/F48 -> 0.55833333 | AN48: =V48/G48 -> 1.4285714 | AO48: =W48/H48 -> 0 | AS48: =AA48/L48 -> 0.11428571
...

Sheet JOUR 2
B2: Date | C2: 46109 | D2: OBJECTIFS | S2: REALISATIONS | AK2: TAUX DE REALISATION
B3: Enseigne | C3: Nom du PDV en promotion | D3: Contacts | E3: =T3 -> Acheteurs | F3: Produits (en unités) | L3: Gratuités pour achats (en unités) | S3: Contacts | T3: Acheteurs | U3: Produits | AA3: =L3 -> Gratuités pour achats (en unités) | AD3: GOODIES | AH3: Commentaires | AI3: Impressions des PDV et des clients | AK3: Contacts | AL3: Acheteurs | AM3: Produits | AS3: =AD3 -> GOODIES | AV3: GOODIES
D4: =S4 -> Nombre de personnes ayant été contactées au rayon | E4: =T4 -> Nombre de personnes ayant acheté | F4: Biblos Lait Premium 16g | G4: Biblos Lait Premium 360g | H4: Biblos Lait Excellence | I4: Biblos Flocon d'avoine 50g | J4: Biblos Flocon d'avoine 400g | K4: Biblos 3 en 1 Café au lait | L4: Biblos Lait Premium 16g | M4: Biblos Flocon d'avoine 50g | N4: Biblos 3 en Café au Lait | O4: Goodies 1 | P4: Goodies 2 | Q4: Goodies 3 | R4: Goodie 4 | S4: Nombre de personnes ayant été contactées au rayon | T4: Nombre de personnes ayant acheté | U4: Biblos Lait Premium 16g | V4: Biblos Lait Premium 360g | W4: Biblos Lait Excellence | X4: Biblos Flocon d'avoine 50g | Y4: Biblos Flocon d'avoine 400g | Z4: Biblos 3 en 1 Café au lait | AA4: Biblos Lait Premium 16g | AB4: Biblos Flocon d'avoine 50g | AC4: Biblos 3 en 1 Café au lait | AD4: =O4 -> Goodies 1 | AE4: =P4 -> Goodies 2 | AF4: =Q4 -> Goodies 3 | AG4: =R4 -> Goodie 4 | AK4: Nombre de personnes ayant été contactées au rayon | AL4: Nombre de personnes ayant acheté | AM4: Biblos Lait Premium 16g | AN4: Biblos Lait Premium 360g | AO4: Biblos Lait Excellence | AP4: Biblos Flocon d'avoine 50g | AQ4: Biblos Flocon d'avoine 400g | AR4: Biblos 3 en 1 Café au lait | AS4: Biblos Lait Premium 16g | AT4: Biblos Flocon d'avoine 50g | AU4: Biblos 3 en 1 Café au lait | AV4: Goodies 1 | AW4: Goodies 2 | AX4: Goodies 3 | AY4: Goodies 4
B5: KING CASH | C5: KING CASH PALAIS YOP | D5: 40 | E5: 20 | F5: 120 | G5: 7 | H5: 4 | I5: 0 | J5: 0 | K5: 0 | L5: =5*35 -> 175 | N5: 0 | S5: 25 | T5: 0 | U5: 0 | V5: 0 | W5: 0 | X5: 0 | Y5: 0 | Z5: 0 | AA5: 0 | AB5: 0 | AC5: 0 | AD5: 0 | AE5: 0 | AF5: 0 | AG5: 0 | AH5: PAS RECU DE PRODUITS | AK5: =S5/D5 -> 0.625 | AL5: =T5/E5 -> 0 | AM5: =U5/F5 -> 0 | AN5: =V5/G5 -> 0 | AO5: =W5/H5 -> 0 | AS5: =AA5/L5 -> 0
