Workbook

Sheet Mercredi
B2: VILLE
C3: 10 | D3: 3 | E3: 2 | F3: 2 | G3: 3 | H3: 3 | I3: 1 | J3: 1 | K3: 1 | L3: 1 | M3: =+H3 -> 3 | N3: 1 | O3: =+H3 -> 3 | R3: =+(2*M3)/12 -> 0.5 | S3: =+(1*I3)/6 -> 0.16666667 | T3: =+(2*I3)/20 -> 0.1 | U3: =+(2*H3)/10 -> 0.6 | V3: =+(3*I3)/20 -> 0.15 | AR3: =80/5 -> 16 | AU3: =24/2 -> 12
C5: OBJECTIFS JOURNALIERS | W5: REALISATIONS | BD5: Commentaires | BE5: Impressions des PDV et des clients
A6: N° | B6: Agent promoteur | C6: Nombre de visite / Type de PDV | H6: Nombre de référencement / Type de PDV | M6: Pose de matériel de visibilité | R6: Vente en cartons | W6: Nombre de visite / Type de PDV | AB6: Présence produits antérieure | AG6: Nombre de référencement / Type de PDV | AL6: Nouveau Référencement par SKU | AQ6: Vente en cartons | AV6: Pose de matériel de visibilité | BA6: Gratuits offerts en sachet
C7: Boutique | D7: Superette | E7: Kiosque | F7: Tablier | G7: Pushcart | H7: Boutique | I7: Superette | J7: Kiosque | K7: Tablier | L7: Pushcart | M7: Affiche Biblos Lait Prémium 16g & 360g | N7: Affiche Biblos Lait Excellence | O7: Affiche Biblos Flocons d' Avoine | P7: Hanger | Q7: Wobbler | R7: Biblos Lait Premium 16g | S7: Biblos Lait Premium 360g | T7: Biblos Lait Excellence 900g | U7: Biblos Flocon d'avoine 50g | V7: Biblos Flocon d'avoine 400g | W7: Boutique | X7: Superette | Y7: Kiosque | Z7: Tablier | AA7: Pushcart | AB7: Biblos Lait Premium 16g | AC7: Biblos Lait Premium 360g | AD7: Biblos Lait Excellence 900g | AE7: Biblos Flocon d'avoine 50g | AF7: Biblos Flocon d'avoine 400g | AG7: Boutique | AH7: Superette | AI7: Kiosque | AJ7: Tablier | AK7: Pushcart | AL7: Biblos Lait Premium 16g | AM7: Biblos Lait Premium 360g | AN7: Biblos Lait Excellence 900g | AO7: Biblos Flocon d'avoine 50g | AP7: Biblos Flocon d'avoine 400g | AQ7: Biblos Lait Premium 16g | AR7: Biblos Lait Premium 360g | AS7: Biblos Lait Excellence 900g | AT7: Biblos Flocon d'avoine 50g | AU7: Biblos Flocon d'avoine 400g | AV7: Affiche Biblos Lait Prémium 16g & 360g | AW7: Affiche Biblos Lait Excellence | AX7: Affiche Biblos Flocons d' Avoine | AY7: Hanger | AZ7: Wobbler | BA7: Biblos Lait Premium 16g | BB7: Biblos Lait Excellence 900g | BC7: Biblos Flocon d'avoine 50g
A8: 1 | B8: DIBI SIMEON | C8: =+C$3 -> 10 | D8: =+D$3 -> 3 | E8: =+E$3 -> 2 | F8: =+F$3 -> 2 | G8: =+G$3 -> 3 | H8: =+H$3 -> 3 | I8: =+I$3 -> 1 | J8: =+J$3 -> 1 | ... V8: =+V$3 -> 0.15 | W8: 25 | AG8: =3+2+8 -> 13 | AL8: 3 | AO8: 2 | AP8: 8 | AQ8: =12/12 -> 1 | AT8: 0.5 | AU8: 3 | AV8: 3 | AW8: 3 | AX8: 3 | BA8: 10 | BC8: =5+30 -> 35
A9: 2 | B9: DAGO BRICE | C9: =+C$3 -> 10 | D9: =+D$3 -> 3 | E9: =+E$3 -> 2 | F9: =+F$3 -> 2 | G9: =+G$3 -> 3 | H9: =+H$3 -> 3 | I9: =+I$3 -> 1 | J9: =+J$3 -> 1 | ... V9: =+V$3 -> 0.15 | W9: 24 | AG9: =1+1+1+10 -> 13 | AL9: 1 | AN9: 1 | AO9: 1 | AP9: 10 | AQ9: =5/12 -> 0.41666667 | AS9: =3/20 -> 0.15 | AT9: 0.4 | AU9: 5 | AV9: 3 | AW9: 3 | AX9: 3 | BA9: =5+5 -> 10 | BC9: =4+50 -> 54
A10: 3 | B10: KRA EVAVARISTE | C10: =+C$3 -> 10 | D10: =+D$3 -> 3 | E10: =+E$3 -> 2 | F10: =+F$3 -> 2 | G10: =+G$3 -> 3 | H10: =+H$3 -> 3 | I10: =+I$3 -> 1 | J10: =+J$3 -> 1 | ... V10: =+V$3 -> 0.15 | W10: 26 | AC10: 1 | AG10: =1+1+8 -> 10 | AL10: 1 | AM10: 1 | AN10: 1 | AP10: 8 | AQ10: =6/12 -> 0.5 | AS10: =6/20 -> 0.3 | AU10: 3 | AV10: 3 | AW10: 3 | AX10: 3 | BA10: =6+10 -> 16 | BC10: 30
A11: 4 | B11: DIOMANDE ESTHER | C11: =+C$3 -> 10 | D11: =+D$3 -> 3 | E11: =+E$3 -> 2 | F11: =+F$3 -> 2 | G11: =+G$3 -> 3 | H11: =+H$3 -> 3 | I11: =+I$3 -> 1 | J11: =+J$3 -> 1 | ... V11: =+V$3 -> 0.15 | W11: 25 | AF11: 1 | AG11: =2+1+12 -> 15 | AL11: 2 | AO11: 1 | AP11: 13 | AQ11: =12/12 -> 1 | AT11: 0.6 | AU11: 4 | AV11: 3 | AW11: 3 | AX11: 3 | BA11: 10 | BC11: =6+40 -> 46
A12: 5 | B12: BADA LANDRY | C12: =+C$3 -> 10 | D12: =+D$3 -> 3 | E12: =+E$3 -> 2 | F12: =+F$3 -> 2 | G12: =+G$3 -> 3 | H12: =+H$3 -> 3 | I12: =+I$3 -> 1 | J12: =+J$3 -> 1 | ... V12: =+V$3 -> 0.15 | W12: 27 | AB12: 1 | AG12: =2+1+1+7 -> 11 | AL12: 2 | AN12: 1 | AO12: 1 | AP12: 7 | AQ12: =10/12 -> 0.83333333 | AS12: =3/20 -> 0.15 | AT12: 0.4 | AU12: 3 | AV12: 3 | AW12: 3 | AX12: 3 | BA12: =10+5 -> 15 | BC12: =4+30 -> 34
A13: 6 | B13: KOUAME JOSE | C13: =+C$3 -> 10 | D13: =+D$3 -> 3 | E13: =+E$3 -> 2 | F13: =+F$3 -> 2 | G13: =+G$3 -> 3 | H13: =+H$3 -> 3 | I13: =+I$3 -> 1 | J13: =+J$3 -> 1 | ... V13: =+V$3 -> 0.15 | W13: 26 | AB13: 1 | AE13: 1 | AG13: =2+1+1+6 -> 10 | AL13: 3 | AN13: 1 | AO13: 2 | AP13: 6 | AQ13: =12/12 -> 1 | AS13: =6/20 -> 0.3 | AT13: 0.5 | AU13: 2 | AV13: 3 | AW13: 3 | AX13: 3 | BA13: =10+10 -> 20 | BC13: =5+20 -> 25
A14: 7 | B14: FANY BARAKISSA | C14: =+C$3 -> 10 | D14: =+D$3 -> 3 | E14: =+E$3 -> 2 | F14: =+F$3 -> 2 | G14: =+G$3 -> 3 | H14: =+H$3 -> 3 | I14: =+I$3 -> 1 | J14: =+J$3 -> 1 | ... V14: =+V$3 -> 0.15 | W14: 26 | AG14: =1+1+1 -> 3 | AL14: 1 | AN14: 1 | AP14: 1 | AQ14: =6/12 -> 0.5 | AS14: =3/20 -> 0.15 | AU14: 1 | AV14: 3 | AW14: 3 | AX14: 3 | BA14: =6+5 -> 11 | BC14: 10
A15: 8 | B15: KONAN IVETTE | C15: =+C$3 -> 10 | D15: =+D$3 -> 3 | E15: =+E$3 -> 2 | F15: =+F$3 -> 2 | G15: =+G$3 -> 3 | H15: =+H$3 -> 3 | I15: =+I$3 -> 1 | J15: =+J$3 -> 1 | ... V15: =+V$3 -> 0.15 | W15: 27 | AD15: 1 | AE15: 1 | AG15: =1+1+1+8 -> 11 | AL15: 1 | AN15: 2 | AO15: 2 | AP15: 8 | AQ15: =8/12 -> 0.66666667 | AS15: =3/20 -> 0.15 | AT15: 0.5 | AU15: 2 | AV15: 3 | AW15: 3 | AX15: 3 | BA15: =8+5 -> 13 | BC15: =5+20 -> 25
A16: 9 | B16: KRA PACOME | C16: =+C$3 -> 10 | D16: =+D$3 -> 3 | E16: =+E$3 -> 2 | F16: =+F$3 -> 2 | G16: =+G$3 -> 3 | H16: =+H$3 -> 3 | I16: =+I$3 -> 1 | J16: =+J$3 -> 1 | ... V16: =+V$3 -> 0.15 | W16: 27 | AG16: =1+1+2 -> 4 | AL16: 1 | AN16: 1 | AP16: 2 | AQ16: =6/12 -> 0.5 | AS16: =3/20 -> 0.15 | AU16: 1 | AV16: 3 | AW16: 3 | AX16: 3 | BA16: =6+5 -> 11 | BC16: 10
A17: 10 | B17: OULAY EMMENUELLA | C17: =+C$3 -> 10 | D17: =+D$3 -> 3 | E17: =+E$3 -> 2 | F17: =+F$3 -> 2 | G17: =+G$3 -> 3 | H17: =+H$3 -> 3 | I17: =+I$3 -> 1 | J17: =+J$3 -> 1 | ... V17: =+V$3 -> 0.15 | W17: 24 | AG17: =2+1+1+7 -> 11 | AL17: 2 | AN17: 1 | AO17: 1 | AP17: 7 | AQ17: =12/12 -> 1 | AS17: =3/20 -> 0.15 | AT17: 0.6 | AU17: 2 | AV17: 3 | AW17: 3 | AX17: 3 | BA17: =10+5 -> 15 | BC17: =6+20 -> 26
A18: 11 | B18: KONATE MARIAM | C18: =+C$3 -> 10 | D18: =+D$3 -> 3 | E18: =+E$3 -> 2 | F18: =+F$3 -> 2 | G18: =+G$3 -> 3 | H18: =+H$3 -> 3 | I18: =+I$3 -> 1 | J18: =+J$3 -> 1 | ... V18: =+V$3 -> 0.15 | W18: 23 | AB18: 1 | AF18: 1 | AG18: =3+1+1+10 -> 15 | AL18: 4 | AN18: 1 | AO18: 1 | AP18: 11 | AQ18: =12/12 -> 1 | AS18: =3/20 -> 0.15 | AT18: 0.5 | AU18: 3 | AV18: 3 | AW18: 3 | AX18: 3 | BA18: =10+5 -> 15 | BC18: =5+30 -> 35
A19: 12 | B19: KOUAME JORES | C19: =+C$3 -> 10 | D19: =+D$3 -> 3 | E19: =+E$3 -> 2 | F19: =+F$3 -> 2 | G19: =+G$3 -> 3 | H19: =+H$3 -> 3 | I19: =+I$3 -> 1 | J19: =+J$3 -> 1 | ... V19: =+V$3 -> 0.15 | W19: 25 | AG19: =1+1+2 -> 4 | AL19: 1 | AN19: 1 | AP19: 2 | AQ19: =7/12 -> 0.58333333 | AS19: =6/20 -> 0.3 | AU19: 1 | AV19: 3 | AW19: 3 | AX19: 3 | BA19: =7+10 -> 17 | BC19: 20
A20: 13 | B20: KOUAKOU ADJOUA ROSE | C20: =+C$3 -> 10 | D20: =+D$3 -> 3 | E20: =+E$3 -> 2 | F20: =+F$3 -> 2 | G20: =+G$3 -> 3 | H20: =+H$3 -> 3 | I20: =+I$3 -> 1 | J20: =+J$3 -> 1 | ... V20: =+V$3 -> 0.15 | W20: 25 | AG20: =1+1+10 -> 12 | AL20: 1 | AO20: 1 | AP20: 10 | AQ20: =4/12 -> 0.33333333 | AT20: 0.4 | AU20: 3.5 | AV20: 3 | AW20: 3 | AX20: 3 | BA20: 4 | BC20: =4+34 -> 38
A21: 14 | B21: OULAY WILFRIED | C21: =+C$3 -> 10 | D21: =+D$3 -> 3 | E21: =+E$3 -> 2 | F21: =+F$3 -> 2 | G21: =+G$3 -> 3 | H21: =+H$3 -> 3 | I21: =+I$3 -> 1 | J21: =+J$3 -> 1 | ... V21: =+V$3 -> 0.15 | W21: 26 | AE21: 2 | AG21: =1+1+1+8 -> 11 | AL21: 1 | AN21: 1 | AO21: 3 | AP21: 8 | AQ21: =6/12 -> 0.5 | AS21: =3/20 -> 0.15 | AT21: 0.4 | AU21: 3 | AV21: 3 | AW21: 3 | AX21: 3 | BA21: =5+5 -> 10 | BC21: =4+30 -> 34
A22: 15 | B22: KONATE MOUSSA | C22: =+C$3 -> 10 | D22: =+D$3 -> 3 | E22: =+E$3 -> 2 | F22: =+F$3 -> 2 | G22: =+G$3 -> 3 | H22: =+H$3 -> 3 | I22: =+I$3 -> 1 | J22: =+J$3 -> 1 | ... V22: =+V$3 -> 0.15 | W22: 22 | AG22: =3+1+2+5 -> 11 | AL22: 3 | AN22: 1 | AO22: 2 | AP22: 5 | AQ22: =12/12 -> 1 | AS22: =6/20 -> 0.3 | AT22: 0.8 | AU22: 2 | AV22: 3 | AW22: 3 | AX22: 3 | BA22: =10+10 -> 20 | BC22: =8+20 -> 28
A23: 16 | B23: NGORAN AXCEL | C23: =+C$3 -> 10 | D23: =+D$3 -> 3 | E23: =+E$3 -> 2 | F23: =+F$3 -> 2 | G23: =+G$3 -> 3 | H23: =+H$3 -> 3 | I23: =+I$3 -> 1 | J23: =+J$3 -> 1 | ... V23: =+V$3 -> 0.15 | W23: 22 | AF23: 1 | AG23: =1+1+1+4 -> 7 | AL23: 1 | AN23: 1 | AO23: 1 | AP23: 5 | AQ23: =6/12 -> 0.5 | AS23: =3/20 -> 0.15 | AT23: 0.4 | AU23: 1.5 | AV23: 3 | AW23: 3 | AX23: 3 | BA23: =6+5 -> 11 | BC23: =4+14 -> 18
A24: 17 | B24: GRACE | C24: =+C$3 -> 10 | D24: =+D$3 -> 3 | E24: =+E$3 -> 2 | F24: =+F$3 -> 2 | G24: =+G$3 -> 3 | H24: =+H$3 -> 3 | I24: =+I$3 -> 1 | J24: =+J$3 -> 1 | ... V24: =+V$3 -> 0.15 | W24: 25 | AG24: =1+1+1+2 -> 5 | AL24: 1 | AN24: 1 | AO24: 1 | AP24: 2 | AQ24: =8/12 -> 0.66666667 | AS24: =3/20 -> 0.15 | AT24: 0.5 | AU24: 1 | AV24: 3 | AW24: 3 | AX24: 3 | BA24: =8+15 -> 23 | BC24: =5+10 -> 15
A25: 18 | B25: NGUESSAN INNOCENT | C25: =+C$3 -> 10 | D25: =+D$3 -> 3 | E25: =+E$3 -> 2 | F25: =+F$3 -> 2 | G25: =+G$3 -> 3 | H25: =+H$3 -> 3 | I25: =+I$3 -> 1 | J25: =+J$3 -> 1 | ... V25: =+V$3 -> 0.15 | W25: 20 | AG25: =1+1+1+7 -> 10 | AL25: 1 | AN25: 1 | AO25: 1 | AP25: 7 | AQ25: =6/12 -> 0.5 | AS25: =3/20 -> 0.15 | AT25: 0.4 | AU25: 2.5 | AV25: 3 | AW25: 3 | AX25: 3 | BA25: =6+5 -> 11 | BC25: =4+24 -> 28
A26: 19 | B26: RAMATOU SETIO | C26: =+C$3 -> 10 | D26: =+D$3 -> 3 | E26: =+E$3 -> 2 | F26: =+F$3 -> 2 | G26: =+G$3 -> 3 | H26: =+H$3 -> 3 | I26: =+I$3 -> 1 | J26: =+J$3 -> 1 | ... V26: =+V$3 -> 0.15 | W26: 24 | AE26: 1 | AG26: =2+1+1+9 -> 13 | AL26: 2 | AN26: 1 | AO26: 1 | AP26: 9 | AQ26: =12/12 -> 1 | AS26: =3/20 -> 0.15 | AT26: 0.4 | AU26: 3 | AV26: 3 | AW26: 3 | AX26: 3 | BA26: =10+5 -> 15 | BC26: =4+30 -> 34
A27: 20 | B27: NGUESSAN | C27: =+C$3 -> 10 | D27: =+D$3 -> 3 | E27: =+E$3 -> 2 | F27: =+F$3 -> 2 | G27: =+G$3 -> 3 | H27: =+H$3 -> 3 | I27: =+I$3 -> 1 | J27: =+J$3 -> 1 | ... V27: =+V$3 -> 0.15 | W27: 20 | AB27: 1 | AG27: =1+1+5 -> 7 | AL27: 2 | AO27: 1 | AP27: 5 | AQ27: =7/12 -> 0.58333333 | AT27: 0.5 | AU27: 2 | AV27: 3 | AW27: 3 | AX27: 3 | BA27: 7 | BC27: =5+20 -> 25
B28: TOTAL | C28: =SUM(C8:C27) -> 200 | D28: =SUM(D8:D27) -> 60 | E28: =SUM(E8:E27) -> 40 | F28: =SUM(F8:F27) -> 40 | G28: =SUM(G8:G27) -> 60 | H28: =SUM(H8:H27) -> 60 | I28: =SUM(I8:I27) -> 20 | J28: =SUM(J8:J27) -> 20 | ... BE28: =SUM(BE8:BE27) -> 0

Sheet jeudi
B2: VILLE
C3: 10 | D3: 3 | E3: 2 | F3: 2 | G3: 3 | H3: 3 | I3: 1 | J3: 1 | K3: 1 | L3: 1 | M3: =+H3 -> 3 | N3: 1 | O3: =+H3 -> 3 | R3: =+(2*M3)/12 -> 0.5 | S3: =+(1*I3)/6 -> 0.16666667 | T3: =+(2*I3)/20 -> 0.1 | U3: =+(2*H3)/10 -> 0.6 | V3: =+(3*I3)/20 -> 0.15 | AW3: =18/20 -> 0.9
C5: OBJECTIFS JOURNALIERS | W5: REALISATIONS | BD5: Commentaires | BE5: Impressions des PDV et des clients
A6: N° | B6: Agent promoteur | C6: Nombre de visite / Type de PDV | H6: Nombre de référencement / Type de PDV | M6: Pose de matériel de visibilité | R6: Vente en cartons | W6: Nombre de visite / Type de PDV | AB6: Présence produits antérieure | AG6: Nombre de référencement / Type de PDV | AL6: Nouveau Référencement par SKU | AQ6: Vente en cartons | AV6: Pose de matériel de visibilité | BA6: Gratuits offerts en sachet
C7: Boutique | D7: Superette | E7: Kiosque | F7: Tablier | G7: Pushcart | H7: Boutique | I7: Superette | J7: Kiosque | K7: Tablier | L7: Pushcart | M7: Affiche Biblos Lait Prémium 16g & 360g | N7: Affiche Biblos Lait Excellence | O7: Affiche Biblos Flocons d' Avoine | P7: Hanger | Q7: Wobbler | R7: Biblos Lait Premium 16g | S7: Biblos Lait Premium 360g | T7: Biblos Lait Excellence 900g | U7: Biblos Flocon d'avoine 50g | V7: Biblos Flocon d'avoine 400g | W7: Boutique | X7: Superette | Y7: Kiosque | Z7: Tablier | AA7: Pushcart | AB7: Biblos Lait Premium 16g | AC7: Biblos Lait Premium 360g | AD7: Biblos Lait Excellence 900g | AE7: Biblos Flocon d'avoine 50g | AF7: Biblos Flocon d'avoine 400g | AG7: Boutique | AH7: Superette | AI7: Kiosque | AJ7: Tablier | AK7: Pushcart | AL7: Biblos Lait Premium 16g | AM7: Biblos Lait Premium 360g | AN7: Biblos Lait Excellence 900g | AO7: Biblos Flocon d'avoine 50g | AP7: Biblos Flocon d'avoine 400g | AQ7: Biblos Lait Premium 16g | AR7: Biblos Lait Premium 360g | AS7: Biblos Lait Excellence 900g | AT7: Biblos Flocon d'avoine 50g | AU7: Biblos Flocon d'avoine 400g | AV7: Affiche Biblos Lait Prémium 16g & 360g | AW7: Affiche Biblos Lait Excellence | AX7: Affiche Biblos Flocons d' Avoine | AY7: Hanger | AZ7: Wobbler | BA7: Biblos Lait Premium 16g | BB7: Biblos Lait Excellence 900g | BC7: Biblos Flocon d'avoine 50g
A8: 1 | B8: DIBI SIMEON | C8: =+C$3 -> 10 | D8: =+D$3 -> 3 | E8: =+E$3 -> 2 | F8: =+F$3 -> 2 | G8: =+G$3 -> 3 | H8: =+H$3 -> 3 | I8: =+I$3 -> 1 | J8: =+J$3 -> 1 | ... V8: =+V$3 -> 0.15 | W8: 20 | AB8: 1 | AG8: =1+1+8 -> 10 | AL8: 2 | AN8: 1 | AP8: 8 | AQ8: =5/12 -> 0.41666667 | AS8: =3/20 -> 0.15 | AU8: 3 | AV8: 3 | AW8: 3 | AX8: 3 | BA8: =5+5 -> 10 | BC8: =30 -> 30
A9: 2 | B9: DAGO BRICE | C9: =+C$3 -> 10 | D9: =+D$3 -> 3 | E9: =+E$3 -> 2 | F9: =+F$3 -> 2 | G9: =+G$3 -> 3 | H9: =+H$3 -> 3 | I9: =+I$3 -> 1 | J9: =+J$3 -> 1 | ... V9: =+V$3 -> 0.15 | W9: 25 | AG9: =1+1+1+3 -> 6 | AL9: 1 | AN9: 1 | AO9: 1 | AP9: 3 | AQ9: 0.5 | AS9: =3/20 -> 0.15 | AT9: 0.5 | AU9: 1 | AV9: 3 | AW9: 3 | AX9: 3 | BA9: =6+5 -> 11 | BC9: =5+10 -> 15
A10: 3 | B10: KRA EVARISTE | C10: =+C$3 -> 10 | D10: =+D$3 -> 3 | E10: =+E$3 -> 2 | F10: =+F$3 -> 2 | G10: =+G$3 -> 3 | H10: =+H$3 -> 3 | I10: =+I$3 -> 1 | J10: =+J$3 -> 1 | ... V10: =+V$3 -> 0.15 | W10: 21 | AE10: 1 | AG10: =2+1+5 -> 8 | AL10: 2 | AO10: 2 | AP10: 5 | AQ10: =8/12 -> 0.66666667 | AT10: 0.5 | AU10: 2 | AV10: 3 | AW10: 3 | AX10: 3 | BA10: 8 | BC10: =5+10 -> 15
A11: 4 | B11: DIOMANDE ESTHER | C11: =+C$3 -> 10 | D11: =+D$3 -> 3 | E11: =+E$3 -> 2 | F11: =+F$3 -> 2 | G11: =+G$3 -> 3 | H11: =+H$3 -> 3 | I11: =+I$3 -> 1 | J11: =+J$3 -> 1 | ... V11: =+V$3 -> 0.15 | W11: 25 | AE11: 1 | AG11: =1+7 -> 8 | AN11: 1 | AO11: 1 | AP11: 7 | AS11: =3/20 -> 0.15 | AU11: 3 | AV11: 3 | AW11: 3 | AX11: 3 | BA11: 5 | BC11: 30
A12: 5 | B12: BADA LANDRY | C12: =+C$3 -> 10 | D12: =+D$3 -> 3 | E12: =+E$3 -> 2 | F12: =+F$3 -> 2 | G12: =+G$3 -> 3 | H12: =+H$3 -> 3 | I12: =+I$3 -> 1 | J12: =+J$3 -> 1 | ... V12: =+V$3 -> 0.15 | W12: 27 | AB12: 1 | AG12: =1+1+2+5 -> 9 | AL12: 2 | AN12: 1 | AO12: 2 | AP12: 5 | AQ12: =5/12 -> 0.41666667 | AS12: =6/20 -> 0.3 | AT12: 1 | AU12: 1.5 | AV12: 3 | AW12: 3 | AX12: 3 | BA12: =5+10 -> 15 | BC12: =10+10+4 -> 24
A13: 6 | B13: KOUAME JOSE | C13: =+C$3 -> 10 | D13: =+D$3 -> 3 | E13: =+E$3 -> 2 | F13: =+F$3 -> 2 | G13: =+G$3 -> 3 | H13: =+H$3 -> 3 | I13: =+I$3 -> 1 | J13: =+J$3 -> 1 | ... V13: =+V$3 -> 0.15 | W13: 26 | AE13: 1 | AG13: =3+1+1+6 -> 11 | AL13: 3 | AN13: 1 | AO13: 2 | AP13: 6 | AQ13: =12/12 -> 1 | AS13: =3/20 -> 0.15 | AT13: 0.3 | AU13: 2 | AV13: 3 | AW13: 3 | AX13: 3 | BA13: =10+5 -> 15 | BC13: =3+20 -> 23
A14: 7 | B14: FANY BARAKISSA | C14: =+C$3 -> 10 | D14: =+D$3 -> 3 | E14: =+E$3 -> 2 | F14: =+F$3 -> 2 | G14: =+G$3 -> 3 | H14: =+H$3 -> 3 | I14: =+I$3 -> 1 | J14: =+J$3 -> 1 | ... V14: =+V$3 -> 0.15 | W14: 23 | AG14: =1+1+1+1 -> 4 | AL14: 1 | AN14: 1 | AO14: 1 | AP14: 1 | AQ14: =8/12 -> 0.66666667 | AS14: =3/20 -> 0.15 | AT14: 0.5 | AU14: 3 | AV14: 3 | AW14: 3 | AX14: 3 | BA14: =8+5 -> 13 | BC14: =5+30 -> 35
A15: 8 | B15: KONAN IVETTE | C15: =+C$3 -> 10 | D15: =+D$3 -> 3 | E15: =+E$3 -> 2 | F15: =+F$3 -> 2 | G15: =+G$3 -> 3 | H15: =+H$3 -> 3 | I15: =+I$3 -> 1 | J15: =+J$3 -> 1 | ... V15: =+V$3 -> 0.15 | W15: 20 | AD15: 1 | AF15: 1 | AG15: =1+1+1+1 -> 4 | AL15: 1 | AN15: 1 | AO15: 1 | AP15: 1 | AQ15: =9/12 -> 0.75 | AS15: =3/20 -> 0.15 | AT15: 0.5 | AU15: 0.5 | AV15: 3 | AW15: 3 | AX15: 3 | BA15: =9+5 -> 14 | BC15: =5+4 -> 9
A16: 9 | B16: KRA PACOME | C16: =+C$3 -> 10 | D16: =+D$3 -> 3 | E16: =+E$3 -> 2 | F16: =+F$3 -> 2 | G16: =+G$3 -> 3 | H16: =+H$3 -> 3 | I16: =+I$3 -> 1 | J16: =+J$3 -> 1 | ... V16: =+V$3 -> 0.15 | W16: 26 | AB16: 1 | AG16: =1+1+1+6 -> 9 | AL16: 2 | AN16: 1 | AO16: 1 | AP16: 6 | AQ16: =6/12 -> 0.5 | AS16: =3/20 -> 0.15 | AT16: 0.5 | AU16: 2 | AV16: 3 | AW16: 3 | AX16: 3 | BA16: =6+5 -> 11 | BC16: =5+10 -> 15
A17: 10 | B17: OULAY EMMENUELLA | C17: =+C$3 -> 10 | D17: =+D$3 -> 3 | E17: =+E$3 -> 2 | F17: =+F$3 -> 2 | G17: =+G$3 -> 3 | H17: =+H$3 -> 3 | I17: =+I$3 -> 1 | J17: =+J$3 -> 1 | ... V17: =+V$3 -> 0.15 | W17: 24 | AG17: =1+1+1+4 -> 7 | AL17: 1 | AN17: 1 | AO17: 1 | AP17: 4 | AQ17: =6/12 -> 0.5 | AS17: =3/20 -> 0.15 | AT17: 0.6 | AU17: 2 | AV17: 3 | AW17: 3 | AX17: 3 | BA17: =6+5 -> 11 | BC17: =6+20 -> 26
A18: 11 | B18: KONATE MARIAM | C18: =+C$3 -> 10 | D18: =+D$3 -> 3 | E18: =+E$3 -> 2 | F18: =+F$3 -> 2 | G18: =+G$3 -> 3 | H18: =+H$3 -> 3 | I18: =+I$3 -> 1 | J18: =+J$3 -> 1 | ... V18: =+V$3 -> 0.15 | W18: 22 | AB18: 1 | AF18: 1 | AG18: =1+1+7 -> 9 | AL18: 1 | AN18: 1 | AO18: 1 | AP18: 7 | AS18: =3/20 -> 0.15 | AT18: 0.4 | AU18: 2 | AV18: 3 | AW18: 3 | AX18: 3 | BA18: 5 | BC18: =4+20 -> 24
A19: 12 | B19: KOUAME JORES | C19: =+C$3 -> 10 | D19: =+D$3 -> 3 | E19: =+E$3 -> 2 | F19: =+F$3 -> 2 | G19: =+G$3 -> 3 | H19: =+H$3 -> 3 | I19: =+I$3 -> 1 | J19: =+J$3 -> 1 | ... V19: =+V$3 -> 0.15 | W19: 26 | AE19: 1 | AG19: =1+7 -> 8 | AL19: 1 | AO19: 1 | AP19: 7 | AQ19: =5/12 -> 0.41666667 | AU19: 2 | AV19: 3 | AW19: 3 | AX19: 3 | BA19: 5 | BC19: 20
A20: 13 | B20: KOUAKOU ADJOUA ROSE | C20: =+C$3 -> 10 | D20: =+D$3 -> 3 | E20: =+E$3 -> 2 | F20: =+F$3 -> 2 | G20: =+G$3 -> 3 | H20: =+H$3 -> 3 | I20: =+I$3 -> 1 | J20: =+J$3 -> 1 | ... V20: =+V$3 -> 0.15 | W20: 24 | AG20: =1+1+4 -> 6 | AN20: 1 | AO20: 1 | AP20: 4 | AS20: =6/20 -> 0.3 | AT20: 0.4 | AU20: 2 | AV20: 3 | AW20: 3 | AX20: 3 | BA20: 10 | BC20: =4+20 -> 24
A21: 14 | B21: OULAY WILFRIED | C21: =+C$3 -> 10 | D21: =+D$3 -> 3 | E21: =+E$3 -> 2 | F21: =+F$3 -> 2 | G21: =+G$3 -> 3 | H21: =+H$3 -> 3 | I21: =+I$3 -> 1 | J21: =+J$3 -> 1 | ... V21: =+V$3 -> 0.15 | W21: 27 | AB21: 1 | AG21: =1+1+5 -> 7 | AL21: 2 | AN21: 1 | AP21: 5 | AQ21: =6/12 -> 0.5 | AS21: =3/20 -> 0.15 | AU21: 2 | AV21: 3 | AW21: 3 | AX21: 3 | BA21: =6+5 -> 11 | BC21: 20
A22: 15 | B22: KONATE MOUSSA | C22: =+C$3 -> 10 | D22: =+D$3 -> 3 | E22: =+E$3 -> 2 | F22: =+F$3 -> 2 | G22: =+G$3 -> 3 | H22: =+H$3 -> 3 | I22: =+I$3 -> 1 | J22: =+J$3 -> 1 | ... V22: =+V$3 -> 0.15 | W22: 24 | AG22: =1+1+1+11 -> 14 | AL22: 1 | AN22: 1 | AO22: 1 | AP22: 11 | AQ22: =12/12 -> 1 | AS22: 0.5 | AT22: 0.5 | AU22: 4.5 | AV22: 3 | AW22: 3 | AX22: 3 | BA22: =12+15 -> 27 | BC22: =5+40+4 -> 49
A23: 16 | B23: NGORAN AXCEL | C23: =+C$3 -> 10 | D23: =+D$3 -> 3 | E23: =+E$3 -> 2 | F23: =+F$3 -> 2 | G23: =+G$3 -> 3 | H23: =+H$3 -> 3 | I23: =+I$3 -> 1 | J23: =+J$3 -> 1 | ... V23: =+V$3 -> 0.15 | W23: 23 | AG23: =1+1+5 -> 7 | AL23: 1 | AO23: 1 | AP23: 5 | AQ23: =6/12 -> 0.5 | AT23: 0.5 | AU23: 2.5 | AV23: 3 | AW23: 3 | AX23: 3 | BA23: 6 | BC23: =5+24 -> 29
A24: 17 | B24: TRAORE ARSENE | C24: =+C$3 -> 10 | D24: =+D$3 -> 3 | E24: =+E$3 -> 2 | F24: =+F$3 -> 2 | G24: =+G$3 -> 3 | H24: =+H$3 -> 3 | I24: =+I$3 -> 1 | J24: =+J$3 -> 1 | ... V24: =+V$3 -> 0.15 | W24: 24 | AG24: =2+1+1+4 -> 8 | AL24: 2 | AN24: 1 | AO24: 1 | AP24: 4 | AQ24: =12/12 -> 1 | AS24: =3/20 -> 0.15 | AT24: 0.3 | AU24: 2 | AV24: 3 | AW24: 3 | AX24: 3 | BA24: =12+5 -> 17 | BC24: =3+20 -> 23
A25: 18 | B25: NGUESSAN INNOCENT | C25: =+C$3 -> 10 | D25: =+D$3 -> 3 | E25: =+E$3 -> 2 | F25: =+F$3 -> 2 | G25: =+G$3 -> 3 | H25: =+H$3 -> 3 | I25: =+I$3 -> 1 | J25: =+J$3 -> 1 | ... V25: =+V$3 -> 0.15 | W25: 25 | AD25: 1 | AE25: 1 | AG25: =1+1+10 -> 12 | AL25: 1 | AN25: 1 | AO25: 1 | AP25: 10 | AQ25: =5/12 -> 0.41666667 | AS25: =3/20 -> 0.15 | AU25: 3 | AV25: 3 | AW25: 3 | AX25: 3 | BA25: =5+5 -> 10 | BC25: 30
A26: 19 | B26: KOUAME ARISTIDE | C26: =+C$3 -> 10 | D26: =+D$3 -> 3 | E26: =+E$3 -> 2 | F26: =+F$3 -> 2 | G26: =+G$3 -> 3 | H26: =+H$3 -> 3 | I26: =+I$3 -> 1 | J26: =+J$3 -> 1 | ... V26: =+V$3 -> 0.15 | W26: 25 | AG26: =1+1+11 -> 13 | AL26: 1 | AO26: 1 | AP26: 11 | AQ26: =6/12 -> 0.5 | AT26: 0.5 | AU26: 4 | AV26: 3 | AW26: 3 | AX26: 3 | BA26: 6 | BC26: =5+40 -> 45
A27: 20 | B27: BERTRAND | C27: =+C$3 -> 10 | D27: =+D$3 -> 3 | E27: =+E$3 -> 2 | F27: =+F$3 -> 2 | G27: =+G$3 -> 3 | H27: =+H$3 -> 3 | I27: =+I$3 -> 1 | J27: =+J$3 -> 1 | ... V27: =+V$3 -> 0.15 | W27: 24 | AD27: 1 | AF27: 2 | AG27: =4+1+1+5 -> 11 | AL27: 4 | AN27: 1 | AO27: 1 | AP27: 7 | AQ27: =15/12 -> 1.25 | AS27: =6/20 -> 0.3 | AT27: 0.5 | AU27: 2 | AV27: 3 | AW27: 3 | AX27: 3 | BA27: =15+10 -> 25 | BC27: =5+20 -> 25
B28: TOTAL | C28: =SUM(C8:C27) -> 200 | D28: =SUM(D8:D27) -> 60 | E28: =SUM(E8:E27) -> 40 | F28: =SUM(F8:F27) -> 40 | G28: =SUM(G8:G27) -> 60 | H28: =SUM(H8:H27) -> 60 | I28: =SUM(I8:I27) -> 20 | J28: =SUM(J8:J27) -> 20 | ... BE28: =SUM(BE8:BE27) -> 0

Sheet Vendredi
B2: VILLE
C3: 10 | D3: 3 | E3: 2 | F3: 2 | G3: 3 | H3: 3 | I3: 1 | J3: 1 | K3: 1 | L3: 1 | M3: =+H3 -> 3 | N3: 1 | O3: =+H3 -> 3 | R3: =+(2*M3)/12 -> 0.5 | S3: =+(1*I3)/6 -> 0.16666667 | T3: =+(2*I3)/20 -> 0.1 | U3: =+(2*H3)/10 -> 0.6 | V3: =+(3*I3)/20 -> 0.15
C5: OBJECTIFS JOURNALIERS | W5: REALISATIONS | BD5: Commentaires | BE5: Impressions des PDV et des clients
A6: N° | B6: Agent promoteur | C6: Nombre de visite / Type de PDV | H6: Nombre de référencement / Type de PDV | M6: Pose de matériel de visibilité | R6: Vente en cartons | W6: Nombre de visite / Type de PDV | AB6: Présence produits antérieure | AG6: Nombre de référencement / Type de PDV | AL6: Nouveau Référencement par SKU | AQ6: Vente en cartons | AV6: Pose de matériel de visibilité | BA6: Gratuits offerts en sachet
C7: Boutique | D7: Superette | E7: Kiosque | F7: Tablier | G7: Pushcart | H7: Boutique | I7: Superette | J7: Kiosque | K7: Tablier | L7: Pushcart | M7: Affiche Biblos Lait Prémium 16g & 360g | N7: Affiche Biblos Lait Excellence | O7: Affiche Biblos Flocons d' Avoine | P7: Hanger | Q7: Wobbler | R7: Biblos Lait Premium 16g | S7: Biblos Lait Premium 360g | T7: Biblos Lait Excellence 900g | U7: Biblos Flocon d'avoine 50g | V7: Biblos Flocon d'avoine 400g | W7: Boutique | X7: Superette | Y7: Kiosque | Z7: Tablier | AA7: Pushcart | AB7: Biblos Lait Premium 16g | AC7: Biblos Lait Premium 360g | AD7: Biblos Lait Excellence 900g | AE7: Biblos Flocon d'avoine 50g | AF7: Biblos Flocon d'avoine 400g | AG7: Boutique | AH7: Superette | AI7: Kiosque | AJ7: Tablier | AK7: Pushcart | AL7: Biblos Lait Premium 16g | AM7: Biblos Lait Premium 360g | AN7: Biblos Lait Excellence 900g | AO7: Biblos Flocon d'avoine 50g | AP7: Biblos Flocon d'avoine 400g | AQ7: Biblos Lait Premium 16g | AR7: Biblos Lait Premium 360g | AS7: Biblos Lait Excellence 900g | AT7: Biblos Flocon d'avoine 50g | AU7: Biblos Flocon d'avoine 400g | AV7: Affiche Biblos Lait Prémium 16g & 360g | AW7: Affiche Biblos Lait Excellence | AX7: Affiche Biblos Flocons d' Avoine | AY7: Hanger | AZ7: Wobbler | BA7: Biblos Lait Premium 16g | BB7: Biblos Lait Excellence 900g | BC7: Biblos Flocon d'avoine 50g
A8: 1 | B8: DIBI SIMEON | C8: =+C$3 -> 10 | D8: =+D$3 -> 3 | E8: =+E$3 -> 2 | F8: =+F$3 -> 2 | G8: =+G$3 -> 3 | H8: =+H$3 -> 3 | I8: =+I$3 -> 1 | J8: =+J$3 -> 1 | ... V8: =+V$3 -> 0.15 | W8: 25 | AE8: 2 | AG8: =1+4 -> 5 | AN8: 1 | AO8: 2 | AP8: 4 | AS8: =3/20 -> 0.15 | AU8: 1 | AV8: 3 | AW8: 3 | AX8: 3 | BA8: 5 | BC8: 10
A9: 2 | B9: DAGO BRICE | C9: =+C$3 -> 10 | D9: =+D$3 -> 3 | E9: =+E$3 -> 2 | F9: =+F$3 -> 2 | G9: =+G$3 -> 3 | H9: =+H$3 -> 3 | I9: =+I$3 -> 1 | J9: =+J$3 -> 1 | ... V9: =+V$3 -> 0.15 | W9: 25 | AG9: =1+3+3 -> 7 | AL9: 1 | AN9: 3 | AP9: 3 | AQ9: 0.5 | AS9: =9/20 -> 0.45 | AU9: 1 | AV9: 3 | AW9: 3 | AX9: 3 | BA9: =6+15 -> 21 | BC9: 10
A10: 3 | B10: KRA EVAVARISTE | C10: =+C$3 -> 10 | D10: =+D$3 -> 3 | E10: =+E$3 -> 2 | F10: =+F$3 -> 2 | G10: =+G$3 -> 3 | H10: =+H$3 -> 3 | I10: =+I$3 -> 1 | J10: =+J$3 -> 1 | ... V10: =+V$3 -> 0.15 | W10: 27 | AE10: 1 | AG10: =1+1+3 -> 5 | AN10: 1 | AO10: 1 | AP10: 3 | AS10: =3/20 -> 0.15 | AT10: 0.5 | AU10: 1 | AV10: 3 | AW10: 3 | AX10: 3 | BA10: 5 | BC10: =5+10 -> 15
A11: 4 | B11: DIOMANDE ESTHER | C11: =+C$3 -> 10 | D11: =+D$3 -> 3 | E11: =+E$3 -> 2 | F11: =+F$3 -> 2 | G11: =+G$3 -> 3 | H11: =+H$3 -> 3 | I11: =+I$3 -> 1 | J11: =+J$3 -> 1 | ... V11: =+V$3 -> 0.15 | W11: 25 | AG11: =1+1+1+2 -> 5 | AL11: 1 | AN11: 1 | AO11: 1 | AP11: 2 | AQ11: 0.5 | AS11: =3/20 -> 0.15 | AT11: 0.5 | AU11: 0.5 | AV11: 3 | AW11: 3 | AX11: 3 | BA11: =6+5 -> 11 | BC11: =5+4 -> 9
A12: 5 | B12: BADA LANDRY | C12: =+C$3 -> 10 | D12: =+D$3 -> 3 | E12: =+E$3 -> 2 | F12: =+F$3 -> 2 | G12: =+G$3 -> 3 | H12: =+H$3 -> 3 | I12: =+I$3 -> 1 | J12: =+J$3 -> 1 | ... V12: =+V$3 -> 0.15 | W12: 24 | AG12: =1+1+1+10 -> 13 | AL12: 1 | AN12: 1 | AO12: 1 | AP12: 10 | AQ12: 0.5 | AS12: =6/20 -> 0.3 | AT12: 0.5 | AU12: 3 | AV12: 3 | AW12: 3 | AX12: 3 | BA12: =6+10 -> 16 | BC12: =5+30 -> 35
A13: 6 | B13: KOUAME JOSE | C13: =+C$3 -> 10 | D13: =+D$3 -> 3 | E13: =+E$3 -> 2 | F13: =+F$3 -> 2 | G13: =+G$3 -> 3 | H13: =+H$3 -> 3 | I13: =+I$3 -> 1 | J13: =+J$3 -> 1 | ... V13: =+V$3 -> 0.15 | W13: 24 | AE13: 1 | AG13: =1+1+5 -> 7 | AN13: 1 | AO13: 2 | AP13: 5 | AS13: =12/20 -> 0.6 | AT13: 0.5 | AU13: 2.5 | AV13: 3 | AW13: 3 | AX13: 3 | BA13: 20 | BC13: =5+24 -> 29
A14: 7 | B14: FANY BARAKISSA | C14: =+C$3 -> 10 | D14: =+D$3 -> 3 | E14: =+E$3 -> 2 | F14: =+F$3 -> 2 | G14: =+G$3 -> 3 | H14: =+H$3 -> 3 | I14: =+I$3 -> 1 | J14: =+J$3 -> 1 | ... V14: =+V$3 -> 0.15 | W14: 23 | AB14: 1 | AG14: =1+1+6 -> 8 | AL14: 2 | AN14: 1 | AP14: 6 | AQ14: 0.5 | AS14: =6/12 -> 0.5 | AU14: 2 | AV14: 3 | AW14: 3 | AX14: 3 | BA14: =6+10 -> 16 | BC14: 20
A15: 8 | B15: KONAN IVETTE | C15: =+C$3 -> 10 | D15: =+D$3 -> 3 | E15: =+E$3 -> 2 | F15: =+F$3 -> 2 | G15: =+G$3 -> 3 | H15: =+H$3 -> 3 | I15: =+I$3 -> 1 | J15: =+J$3 -> 1 | ... V15: =+V$3 -> 0.15 | W15: 23 | AG15: =1+1+5 -> 7 | AL15: 1 | AN15: 1 | AP15: 5 | AQ15: 0.5 | AS15: 0.15 | AU15: 2 | AV15: 3 | AW15: 3 | AX15: 3 | BA15: =6+5 -> 11 | BC15: 20
A16: 9 | B16: KRA PACOME | C16: =+C$3 -> 10 | D16: =+D$3 -> 3 | E16: =+E$3 -> 2 | F16: =+F$3 -> 2 | G16: =+G$3 -> 3 | H16: =+H$3 -> 3 | I16: =+I$3 -> 1 | J16: =+J$3 -> 1 | ... V16: =+V$3 -> 0.15 | W16: 26 | AG16: =1+1+4 -> 6 | AL16: 1 | AN16: 1 | AP16: 4 | AQ16: 0.5 | AS16: 0.15 | AU16: 1 | AV16: 3 | AW16: 3 | AX16: 3 | BA16: =6+5 -> 11 | BC16: 10
A17: 10 | B17: OULAY EMMENUELLA | C17: =+C$3 -> 10 | D17: =+D$3 -> 3 | E17: =+E$3 -> 2 | F17: =+F$3 -> 2 | G17: =+G$3 -> 3 | H17: =+H$3 -> 3 | I17: =+I$3 -> 1 | J17: =+J$3 -> 1 | ... V17: =+V$3 -> 0.15 | W17: 24 | AG17: =2+1+1+8 -> 12 | AL17: 2 | AN17: 1 | AO17: 1 | AP17: 8 | AQ17: 1 | AS17: 0.15 | AT17: 0.6 | AU17: 2 | AV17: 3 | AW17: 3 | AX17: 3 | BA17: =12+5 -> 17 | BC17: =6+20 -> 26
A18: 11 | B18: KONATE MARIAM | C18: =+C$3 -> 10 | D18: =+D$3 -> 3 | E18: =+E$3 -> 2 | F18: =+F$3 -> 2 | G18: =+G$3 -> 3 | H18: =+H$3 -> 3 | I18: =+I$3 -> 1 | J18: =+J$3 -> 1 | ... V18: =+V$3 -> 0.15 | W18: 24 | AE18: 1 | AG18: =1+4 -> 5 | AN18: 1 | AO18: 1 | AP18: 4 | AS18: 0.15 | AU18: 1.5 | AV18: 3 | AW18: 3 | AX18: 3 | BA18: 5 | BC18: 14
A19: 12 | B19: KOUAME JORES | C19: =+C$3 -> 10 | D19: =+D$3 -> 3 | E19: =+E$3 -> 2 | F19: =+F$3 -> 2 | G19: =+G$3 -> 3 | H19: =+H$3 -> 3 | I19: =+I$3 -> 1 | J19: =+J$3 -> 1 | ... V19: =+V$3 -> 0.15 | W19: 25 | AB19: 1 | AD19: 1 | AG19: =1+1+7 -> 9 | AL19: 2 | AN19: 2 | AP19: 7 | AQ19: =8/12 -> 0.66666667 | AS19: 0.15 | AU19: 3 | AV19: 3 | AW19: 3 | AX19: 3 | BA19: =8+5 -> 13 | BC19: 30
A20: 13 | B20: KOUAKOU ADJOUA ROSE | C20: =+C$3 -> 10 | D20: =+D$3 -> 3 | E20: =+E$3 -> 2 | F20: =+F$3 -> 2 | G20: =+G$3 -> 3 | H20: =+H$3 -> 3 | I20: =+I$3 -> 1 | J20: =+J$3 -> 1 | ... V20: =+V$3 -> 0.15 | W20: 24 | AG20: =1+1+1 -> 3 | AN20: 1 | AO20: 1 | AP20: 1 | AS20: =6/20 -> 0.3 | AT20: 0.5 | AU20: 0.5 | AV20: 3 | AW20: 3 | AX20: 3 | BA20: 10 | BC20: =5+4 -> 9
A21: 14 | B21: OULAY WILFRIED | C21: =+C$3 -> 10 | D21: =+D$3 -> 3 | E21: =+E$3 -> 2 | F21: =+F$3 -> 2 | G21: =+G$3 -> 3 | H21: =+H$3 -> 3 | I21: =+I$3 -> 1 | J21: =+J$3 -> 1 | ... V21: =+V$3 -> 0.15 | W21: 27 | AG21: =1+1+5 -> 7 | AL21: 1 | AN21: 1 | AP21: 5 | AQ21: 0.5 | AS21: =3/20 -> 0.15 | AU21: 2 | AV21: 3 | AW21: 3 | AX21: 3 | BA21: =6+5 -> 11 | BC21: 20
A22: 15 | B22: KONATE MOUSSA | C22: =+C$3 -> 10 | D22: =+D$3 -> 3 | E22: =+E$3 -> 2 | F22: =+F$3 -> 2 | G22: =+G$3 -> 3 | H22: =+H$3 -> 3 | I22: =+I$3 -> 1 | J22: =+J$3 -> 1 | ... V22: =+V$3 -> 0.15 | W22: 23 | AE22: 1 | AG22: =1+6 -> 7 | AL22: 1 | AO22: 1 | AP22: 6 | AQ22: 0.5 | AU22: 2 | AV22: 3 | AW22: 3 | AX22: 3 | BA22: 6 | BC22: 20
A23: 16 | B23: GRACE | C23: =+C$3 -> 10 | D23: =+D$3 -> 3 | E23: =+E$3 -> 2 | F23: =+F$3 -> 2 | G23: =+G$3 -> 3 | H23: =+H$3 -> 3 | I23: =+I$3 -> 1 | J23: =+J$3 -> 1 | ... V23: =+V$3 -> 0.15 | W23: 26 | AB23: 1 | AG23: =1+1+7 -> 9 | AL23: 2 | AN23: 1 | AP23: 7 | AQ23: 0.6 | AS23: 0.15 | AU23: 3 | AV23: 3 | AW23: 3 | AX23: 3 | BA23: =7+5 -> 12 | BC23: 30
A24: 17 | B24: TRAORE ARSENE | C24: =+C$3 -> 10 | D24: =+D$3 -> 3 | E24: =+E$3 -> 2 | F24: =+F$3 -> 2 | G24: =+G$3 -> 3 | H24: =+H$3 -> 3 | I24: =+I$3 -> 1 | J24: =+J$3 -> 1 | ... V24: =+V$3 -> 0.15 | W24: 20 | AF24: 1 | AG24: =1+1+7 -> 9 | AL24: 1 | AN24: 1 | AP24: 7 | AQ24: 0.5 | AS24: =3/20 -> 0.15 | AU24: 2.5 | AV24: 3 | AW24: 3 | AX24: 3 | BA24: =6+5 -> 11 | BC24: 24
A25: 18 | B25: NGUESSAN INNOCENT | C25: =+C$3 -> 10 | D25: =+D$3 -> 3 | E25: =+E$3 -> 2 | F25: =+F$3 -> 2 | G25: =+G$3 -> 3 | H25: =+H$3 -> 3 | I25: =+I$3 -> 1 | J25: =+J$3 -> 1 | ... V25: =+V$3 -> 0.15 | W25: 24 | AB25: 1 | AG25: =1+1+5 -> 7 | AL25: 2 | AN25: 1 | AO25: 1 | AP25: 5 | AS25: 0.15 | AT25: 0.4 | AU25: 2 | AV25: 3 | AW25: 3 | AX25: 3 | BA25: 5 | BC25: =4+20 -> 24
A26: 19 | B26: KOUAME ARISTIDE | C26: =+C$3 -> 10 | D26: =+D$3 -> 3 | E26: =+E$3 -> 2 | F26: =+F$3 -> 2 | G26: =+G$3 -> 3 | H26: =+H$3 -> 3 | I26: =+I$3 -> 1 | J26: =+J$3 -> 1 | ... V26: =+V$3 -> 0.15 | W26: 27 | AG26: =1+1+1+5 -> 8 | AL26: 1 | AN26: 1 | AO26: 1 | AP26: 5 | AQ26: 0.5 | AS26: 0.15 | AT26: 0.5 | AU26: 2 | AV26: 3 | AW26: 3 | AX26: 3 | BA26: =6+5 -> 11 | BC26: =5+20 -> 25
A27: 20 | B27: BERTRAND | C27: =+C$3 -> 10 | D27: =+D$3 -> 3 | E27: =+E$3 -> 2 | F27: =+F$3 -> 2 | G27: =+G$3 -> 3 | H27: =+H$3 -> 3 | I27: =+I$3 -> 1 | J27: =+J$3 -> 1 | ... V27: =+V$3 -> 0.15 | W27: 28 | AB27: 1 | AE27: 1 | AG27: =1+1+1 -> 3 | AL27: 2 | AN27: 1 | AO27: 1 | AP27: 1 | AQ27: 0.5 | AS27: 0.15 | AU27: 0.5 | AV27: 3 | AW27: 3 | AX27: 3 | BA27: =6+5 -> 11 | BC27: 4
B28: TOTAL | C28: =SUM(C8:C27) -> 200 | D28: =SUM(D8:D27) -> 60 | E28: =SUM(E8:E27) -> 40 | F28: =SUM(F8:F27) -> 40 | G28: =SUM(G8:G27) -> 60 | H28: =SUM(H8:H27) -> 60 | I28: =SUM(I8:I27) -> 20 | J28: =SUM(J8:J27) -> 20 | ... BE28: =SUM(BE8:BE27) -> 0

Sheet Samedii
B2: VILLE
C3: 10 | D3: 3 | E3: 2 | F3: 2 | G3: 3 | H3: 3 | I3: 1 | J3: 1 | K3: 1 | L3: 1 | M3: =+H3 -> 3 | N3: 1 | O3: =+H3 -> 3 | R3: =+(2*M3)/12 -> 0.5 | S3: =+(1*I3)/6 -> 0.16666667 | T3: =+(2*I3)/20 -> 0.1 | U3: =+(2*H3)/10 -> 0.6 | V3: =+(3*I3)/20 -> 0.15
C5: OBJECTIFS JOURNALIERS | W5: REALISATIONS | BD5: Commentaires | BE5: Impressions des PDV et des clients
A6: N° | B6: Agent promoteur | C6: Nombre de visite / Type de PDV | H6: Nombre de référencement / Type de PDV | M6: Pose de matériel de visibilité | R6: Vente en cartons | W6: Nombre de visite / Type de PDV | AB6: Présence produits antérieure | AG6: Nombre de référencement / Type de PDV | AL6: Nouveau Référencement par SKU | AQ6: Vente en cartons | AV6: Pose de matériel de visibilité | BA6: Gratuits offerts en sachet
C7: Boutique | D7: Superette | E7: Kiosque | F7: Tablier | G7: Pushcart | H7: Boutique | I7: Superette | J7: Kiosque | K7: Tablier | L7: Pushcart | M7: Affiche Biblos Lait Prémium 16g & 360g | N7: Affiche Biblos Lait Excellence | O7: Affiche Biblos Flocons d' Avoine | P7: Hanger | Q7: Wobbler | R7: Biblos Lait Premium 16g | S7: Biblos Lait Premium 360g | T7: Biblos Lait Excellence 900g | U7: Biblos Flocon d'avoine 50g | V7: Biblos Flocon d'avoine 400g | W7: Boutique | X7: Superette | Y7: Kiosque | Z7: Tablier | AA7: Pushcart | AB7: Biblos Lait Premium 16g | AC7: Biblos Lait Premium 360g | AD7: Biblos Lait Excellence 900g | AE7: Biblos Flocon d'avoine 50g | AF7: Biblos Flocon d'avoine 400g | AG7: Boutique | AH7: Superette | AI7: Kiosque | AJ7: Tablier | AK7: Pushcart | AL7: Biblos Lait Premium 16g | AM7: Biblos Lait Premium 360g | AN7: Biblos Lait Excellence 900g | AO7: Biblos Flocon d'avoine 50g | AP7: Biblos Flocon d'avoine 400g | AQ7: Biblos Lait Premium 16g | AR7: Biblos Lait Premium 360g | AS7: Biblos Lait Excellence 900g | AT7: Biblos Flocon d'avoine 50g | AU7: Biblos Flocon d'avoine 400g | AV7: Affiche Biblos Lait Prémium 16g & 360g | AW7: Affiche Biblos Lait Excellence | AX7: Affiche Biblos Flocons d' Avoine | AY7: Hanger | AZ7: Wobbler | BA7: Biblos Lait Premium 16g | BB7: Biblos Lait Excellence 900g | BC7: Biblos Flocon d'avoine 50g
A8: 1 | B8: DIBI SIMEON | C8: =+C$3 -> 10 | D8: =+D$3 -> 3 | E8: =+E$3 -> 2 | F8: =+F$3 -> 2 | G8: =+G$3 -> 3 | H8: =+H$3 -> 3 | I8: =+I$3 -> 1 | J8: =+J$3 -> 1 | ... V8: =+V$3 -> 0.15 | W8: 15 | AG8: =3+2+3 -> 8 | AL8: 3 | AO8: 2 | AP8: 3 | AQ8: =12/12 -> 1 | AT8: 1 | AU8: 1 | AV8: 5 | AW8: 5 | AX8: 5 | BA8: 12 | BC8: =10+10 -> 20 | BD8: Nous, avons combiné tous les points de vente car il ny a pas cette spécficité dans la fiche de suivie promoteurs. Nous nous sommes rendu compte dans le dépoouillement. Est-ce une volonté délibérée?
A9: 2 | B9: DAGO BRICE | C9: =+C$3 -> 10 | D9: =+D$3 -> 3 | E9: =+E$3 -> 2 | F9: =+F$3 -> 2 | G9: =+G$3 -> 3 | H9: =+H$3 -> 3 | I9: =+I$3 -> 1 | J9: =+J$3 -> 1 | ... V9: =+V$3 -> 0.15 | W9: 22 | AD9: 1 | AG9: =1+1+4 -> 6 | AL9: 1 | AN9: 2 | AP9: 4 | AQ9: =4/12 -> 0.33333333 | AS9: =5/20 -> 0.25 | AU9: 1.5 | AV9: 5 | AW9: 5 | AX9: 5 | BA9: =4+5 -> 9 | BC9: =10+4 -> 14
A10: 3 | B10: KRA EVAVARISTE | C10: =+C$3 -> 10 | D10: =+D$3 -> 3 | E10: =+E$3 -> 2 | F10: =+F$3 -> 2 | G10: =+G$3 -> 3 | H10: =+H$3 -> 3 | I10: =+I$3 -> 1 | J10: =+J$3 -> 1 | ... V10: =+V$3 -> 0.15 | W10: 18 | AG10: =1+1+1+2 -> 5 | AL10: 1 | AN10: 1 | AO10: 1 | AP10: 2 | AQ10: =4/12 -> 0.33333333 | AS10: 0.15 | AT10: 0.3 | AU10: 1 | AV10: 5 | AW10: 5 | AX10: 5 | BA10: =4+5 -> 9 | BC10: =3+10 -> 13 | BD10: Dans l'esemble, après 4 jours de ventes à Korhogo, il ressort que les produits on été moins référencés avant le commando. La majeure partie des détaillants font les achats en chapelets ou en sachets pour le grands formats. | BE10: Ils réclament plus de gratuits pour un produit en lancement selon eux. Et aussi du lait en boîte pour les grands formats
A11: 4 | B11: DIOMANDE ESTHER | C11: =+C$3 -> 10 | D11: =+D$3 -> 3 | E11: =+E$3 -> 2 | F11: =+F$3 -> 2 | G11: =+G$3 -> 3 | H11: =+H$3 -> 3 | I11: =+I$3 -> 1 | J11: =+J$3 -> 1 | ... V11: =+V$3 -> 0.15 | W11: 20 | AB11: 1 | AE11: 1 | AG11: =1+5 -> 6 | AO11: 2 | AP11: 5 | AT11: 0.5 | AU11: 2 | AV11: 5 | AW11: 5 | AX11: 5 | BC11: =5+20 -> 25
A12: 5 | B12: BADA LANDRY | C12: =+C$3 -> 10 | D12: =+D$3 -> 3 | E12: =+E$3 -> 2 | F12: =+F$3 -> 2 | G12: =+G$3 -> 3 | H12: =+H$3 -> 3 | I12: =+I$3 -> 1 | J12: =+J$3 -> 1 | ... V12: =+V$3 -> 0.15 | W12: 19 | AG12: =1+1+6 -> 8 | AL12: 1 | AN12: 1 | AP12: 6 | AQ12: =6/12 -> 0.5 | AS12: 0.15 | AU12: 2 | AV12: 5 | AW12: 5 | AX12: 5 | BA12: =6+5 -> 11 | BC12: 20
A13: 6 | B13: KOUAME JOSE | C13: =+C$3 -> 10 | D13: =+D$3 -> 3 | E13: =+E$3 -> 2 | F13: =+F$3 -> 2 | G13: =+G$3 -> 3 | H13: =+H$3 -> 3 | I13: =+I$3 -> 1 | J13: =+J$3 -> 1 | ... V13: =+V$3 -> 0.15 | W13: 15 | AD13: 1 | AE13: 1 | AG13: =1+1+1+2 -> 5 | AL13: 1 | AN13: 2 | AO13: 2 | AP13: 2 | AQ13: =4/12 -> 0.33333333 | AS13: 0.15 | AT13: 0.4 | AU13: 1 | AV13: 5 | AW13: 5 | AX13: 5 | BA13: =4+5 -> 9 | BC13: =4+10 -> 14
A14: 7 | B14: FANY BARAKISSA | C14: =+C$3 -> 10 | D14: =+D$3 -> 3 | E14: =+E$3 -> 2 | F14: =+F$3 -> 2 | G14: =+G$3 -> 3 | H14: =+H$3 -> 3 | I14: =+I$3 -> 1 | J14: =+J$3 -> 1 | ... V14: =+V$3 -> 0.15 | W14: 15 | AG14: =1+7 -> 8 | AL14: 1 | AP14: 7 | AQ14: =5/12 -> 0.41666667 | AU14: 2 | AV14: 5 | AW14: 5 | AX14: 5 | BA14: 5 | BC14: 20
A15: 8 | B15: KONAN IVETTE | C15: =+C$3 -> 10 | D15: =+D$3 -> 3 | E15: =+E$3 -> 2 | F15: =+F$3 -> 2 | G15: =+G$3 -> 3 | H15: =+H$3 -> 3 | I15: =+I$3 -> 1 | J15: =+J$3 -> 1 | ... V15: =+V$3 -> 0.15 | W15: 10 | AE15: 1 | AG15: =2+1+3+5 -> 11 | AL15: 2 | AN15: 1 | AO15: 4 | AP15: 5 | AQ15: =12/12 -> 1 | AS15: 0.15 | AT15: 1 | AU15: 2 | AV15: 5 | AW15: 5 | AX15: 5 | BA15: =12+5 -> 17 | BC15: =10+20 -> 30
A16: 9 | B16: KRA PACOME | C16: =+C$3 -> 10 | D16: =+D$3 -> 3 | E16: =+E$3 -> 2 | F16: =+F$3 -> 2 | G16: =+G$3 -> 3 | H16: =+H$3 -> 3 | I16: =+I$3 -> 1 | J16: =+J$3 -> 1 | ... V16: =+V$3 -> 0.15 | W16: 17 | AB16: 1 | AG16: =1+6 -> 7 | AL16: 1 | AN16: 1 | AP16: 6 | AS16: 0.15 | AU16: 2.5 | AV16: 5 | AW16: 5 | AX16: 5 | BA16: 5 | BC16: 24
A17: 10 | B17: OULAY EMMENUELLA | C17: =+C$3 -> 10 | D17: =+D$3 -> 3 | E17: =+E$3 -> 2 | F17: =+F$3 -> 2 | G17: =+G$3 -> 3 | H17: =+H$3 -> 3 | I17: =+I$3 -> 1 | J17: =+J$3 -> 1 | ... V17: =+V$3 -> 0.15 | W17: 17 | AG17: =2+1+7 -> 10 | AL17: 2 | AN17: 1 | AP17: 7 | AQ17: =12/12 -> 1 | AS17: 0.3 | AU17: 2 | AV17: 5 | AW17: 5 | AX17: 5 | BA17: =12+10 -> 22 | BC17: 20
A18: 11 | B18: KONATE MARIAM | C18: =+C$3 -> 10 | D18: =+D$3 -> 3 | E18: =+E$3 -> 2 | F18: =+F$3 -> 2 | G18: =+G$3 -> 3 | H18: =+H$3 -> 3 | I18: =+I$3 -> 1 | J18: =+J$3 -> 1 | ... V18: =+V$3 -> 0.15 | W18: 18 | AE18: 2 | AG18: =1+3+10 -> 14 | AL18: 1 | AO18: 5 | AP18: 10 | AQ18: =12/12 -> 1 | AT18: 1 | AU18: 4 | AV18: 5 | AW18: 5 | AX18: 5 | BA18: 12 | BC18: =10+40 -> 50
A19: 12 | B19: KOUAME JORES | C19: =+C$3 -> 10 | D19: =+D$3 -> 3 | E19: =+E$3 -> 2 | F19: =+F$3 -> 2 | G19: =+G$3 -> 3 | H19: =+H$3 -> 3 | I19: =+I$3 -> 1 | J19: =+J$3 -> 1 | ... V19: =+V$3 -> 0.15 | W19: 20 | AG19: =1+4 -> 5 | AO19: 1 | AP19: 4 | AT19: 0.6 | AU19: 2 | AV19: 5 | AW19: 5 | AX19: 5 | BC19: =6+20 -> 26
A20: 13 | B20: KOUAKOU ADJOUA ROSE | C20: =+C$3 -> 10 | D20: =+D$3 -> 3 | E20: =+E$3 -> 2 | F20: =+F$3 -> 2 | G20: =+G$3 -> 3 | H20: =+H$3 -> 3 | I20: =+I$3 -> 1 | J20: =+J$3 -> 1 | ... V20: =+V$3 -> 0.15 | W20: 21 | AE20: 1 | AG20: =1+1+3 -> 5 | AL20: 1 | AN20: 1 | AO20: 1 | AP20: 3 | AQ20: =3/12 -> 0.25 | AS20: 0.15 | AU20: 1 | AV20: 5 | AW20: 5 | AX20: 5 | BA20: =3+5 -> 8 | BC20: 20
A21: 14 | B21: OULAY WILFRIED | C21: =+C$3 -> 10 | D21: =+D$3 -> 3 | E21: =+E$3 -> 2 | F21: =+F$3 -> 2 | G21: =+G$3 -> 3 | H21: =+H$3 -> 3 | I21: =+I$3 -> 1 | J21: =+J$3 -> 1 | ... V21: =+V$3 -> 0.15 | W21: 17 | AB21: 1 | AG21: =1+1+1+4 -> 7 | AL21: 2 | AN21: 1 | AO21: 1 | AP21: 4 | AQ21: =10/12 -> 0.83333333 | AS21: 0.3 | AT21: 0.5 | AU21: 1 | AV21: 5 | AW21: 5 | AX21: 5 | BA21: =10+10 -> 20 | BC21: =5+10 -> 15
A22: 15 | B22: KONATE MOUSSA | C22: =+C$3 -> 10 | D22: =+D$3 -> 3 | E22: =+E$3 -> 2 | F22: =+F$3 -> 2 | G22: =+G$3 -> 3 | H22: =+H$3 -> 3 | I22: =+I$3 -> 1 | J22: =+J$3 -> 1 | ... V22: =+V$3 -> 0.15 | W22: 18 | AG22: =2+1+7 -> 10 | AL22: 2 | AO22: 1 | AP22: 7 | AQ22: =12/12 -> 1 | AT22: 0.5 | AU22: 3 | AV22: 5 | AW22: 5 | AX22: 5 | BA22: 10 | BC22: =5+30 -> 35
A23: 16 | B23: KOUAME INNOCENT | C23: =+C$3 -> 10 | D23: =+D$3 -> 3 | E23: =+E$3 -> 2 | F23: =+F$3 -> 2 | G23: =+G$3 -> 3 | H23: =+H$3 -> 3 | I23: =+I$3 -> 1 | J23: =+J$3 -> 1 | ... V23: =+V$3 -> 0.15 | W23: 20 | AE23: 1 | AG23: =1+1+1+4 -> 7 | AL23: 1 | AN23: 1 | AO23: 2 | AP23: 4 | AQ23: =6/12 -> 0.5 | AS23: 0.15 | AT23: 0.5 | AU23: 2 | AV23: 5 | AW23: 5 | AX23: 5 | BA23: =6+5 -> 11 | BC23: =5+20 -> 25
A24: 17 | B24: TRAORE ARSENE | C24: =+C$3 -> 10 | D24: =+D$3 -> 3 | E24: =+E$3 -> 2 | F24: =+F$3 -> 2 | G24: =+G$3 -> 3 | H24: =+H$3 -> 3 | I24: =+I$3 -> 1 | J24: =+J$3 -> 1 | ... V24: =+V$3 -> 0.15 | W24: 20 | AB24: 1 | AG24: =1+1+2 -> 4 | AL24: 1 | AN24: 1 | AP24: 2 | AQ24: =12/12 -> 1 | AS24: 0.15 | AU24: 1 | AV24: 5 | AW24: 5 | AX24: 5 | BA24: =12+5 -> 17 | BC24: 10
A25: 18 | B25: NGUESSAN INNOCENT | C25: =+C$3 -> 10 | D25: =+D$3 -> 3 | E25: =+E$3 -> 2 | F25: =+F$3 -> 2 | G25: =+G$3 -> 3 | H25: =+H$3 -> 3 | I25: =+I$3 -> 1 | J25: =+J$3 -> 1 | ... V25: =+V$3 -> 0.15 | W25: 21 | AG25: =1+1+3 -> 5 | AL25: 1 | AO25: 1 | AP25: 3 | AQ25: =6/12 -> 0.5 | AT25: 0.8 | AU25: 1 | AV25: 5 | AW25: 5 | AX25: 5 | BA25: 6 | BC25: =8+10 -> 18
A26: 19 | B26: KOUAME ARISTIDE | C26: =+C$3 -> 10 | D26: =+D$3 -> 3 | E26: =+E$3 -> 2 | F26: =+F$3 -> 2 | G26: =+G$3 -> 3 | H26: =+H$3 -> 3 | I26: =+I$3 -> 1 | J26: =+J$3 -> 1 | ... V26: =+V$3 -> 0.15 | W26: 25 | AE26: 1 | AG26: =1+1+1+2 -> 5 | AL26: 1 | AN26: 1 | AO26: 2 | AP26: 2 | AQ26: =6/12 -> 0.5 | AS26: =3/20 -> 0.15 | AT26: 0.4 | AU26: 1 | AV26: 5 | AW26: 5 | AX26: 5 | BA26: =6+5 -> 11 | BC26: =4+10 -> 14
A27: 20 | B27: BERTRAND | C27: =+C$3 -> 10 | D27: =+D$3 -> 3 | E27: =+E$3 -> 2 | F27: =+F$3 -> 2 | G27: =+G$3 -> 3 | H27: =+H$3 -> 3 | I27: =+I$3 -> 1 | J27: =+J$3 -> 1 | ... V27: =+V$3 -> 0.15 | W27: 23 | AE27: 2 | AG27: =1+2+1+7 -> 11 | AL27: 1 | AN27: 2 | AO27: 3 | AP27: 7 | AQ27: =6/12 -> 0.5 | AS27: =6/20 -> 0.3 | AT27: 0.5 | AU27: 3 | AV27: 5 | AW27: 5 | AX27: 5 | BA27: =6+10 -> 16 | BC27: =5+30 -> 35
B28: TOTAL | C28: =SUM(C8:C27) -> 200 | D28: =SUM(D8:D27) -> 60 | E28: =SUM(E8:E27) -> 40 | F28: =SUM(F8:F27) -> 40 | G28: =SUM(G8:G27) -> 60 | H28: =SUM(H8:H27) -> 60 | I28: =SUM(I8:I27) -> 20 | J28: =SUM(J8:J27) -> 20 | ... BE28: =SUM(BE8:BE27) -> 0

Sheet lundi
B2: VILLE
C3: 10 | D3: 3 | E3: 2 | F3: 2 | G3: 3 | H3: 3 | I3: 1 | J3: 1 | K3: 1 | L3: 1 | M3: =+H3 -> 3 | N3: 1 | O3: =+H3 -> 3 | R3: =+(2*M3)/12 -> 0.5 | S3: =+(1*I3)/6 -> 0.16666667 | T3: =+(2*I3)/20 -> 0.1 | U3: =+(2*H3)/10 -> 0.6 | V3: =+(3*I3)/20 -> 0.15
C5: OBJECTIFS JOURNALIERS | W5: REALISATIONS | BD5: Commentaires | BE5: Impressions des PDV et des clients
A6: N° | B6: Agent promoteur | C6: Nombre de visite / Type de PDV | H6: Nombre de référencement / Type de PDV | M6: Pose de matériel de visibilité | R6: Vente en cartons | W6: Nombre de visite / Type de PDV | AB6: Présence produits antérieure | AG6: Nombre de référencement / Type de PDV | AL6: Nouveau Référencement par SKU | AQ6: Vente en cartons | AV6: Pose de matériel de visibilité | BA6: Gratuits offerts en sachet
C7: Boutique | D7: Superette | E7: Kiosque | F7: Tablier | G7: Pushcart | H7: Boutique | I7: Superette | J7: Kiosque | K7: Tablier | L7: Pushcart | M7: Affiche Biblos Lait Prémium 16g & 360g | N7: Affiche Biblos Lait Excellence | O7: Affiche Biblos Flocons d' Avoine | P7: Hanger | Q7: Wobbler | R7: Biblos Lait Premium 16g | S7: Biblos Lait Premium 360g | T7: Biblos Lait Excellence 900g | U7: Biblos Flocon d'avoine 50g | V7: Biblos Flocon d'avoine 400g | W7: Boutique | X7: Superette | Y7: Kiosque | Z7: Tablier | AA7: Pushcart | AB7: Biblos Lait Premium 16g | AC7: Biblos Lait Premium 360g | AD7: Biblos Lait Excellence 900g | AE7: Biblos Flocon d'avoine 50g | AF7: Biblos Flocon d'avoine 400g | AG7: Boutique | AH7: Superette | AI7: Kiosque | AJ7: Tablier | AK7: Pushcart | AL7: Biblos Lait Premium 16g | AM7: Biblos Lait Premium 360g | AN7: Biblos Lait Excellence 900g | AO7: Biblos Flocon d'avoine 50g | AP7: Biblos Flocon d'avoine 400g | AQ7: Biblos Lait Premium 16g | AR7: Biblos Lait Premium 360g | AS7: Biblos Lait Excellence 900g | AT7: Biblos Flocon d'avoine 50g | AU7: Biblos Flocon d'avoine 400g | AV7: Affiche Biblos Lait Prémium 16g & 360g | AW7: Affiche Biblos Lait Excellence | AX7: Affiche Biblos Flocons d' Avoine | AY7: Hanger | AZ7: Wobbler | BA7: Biblos Lait Premium 16g | BB7: Biblos Lait Excellence 900g | BC7: Biblos Flocon d'avoine 50g
A8: 1 | B8: DIBI SIMEON | C8: =+C$3 -> 10 | D8: =+D$3 -> 3 | E8: =+E$3 -> 2 | F8: =+F$3 -> 2 | G8: =+G$3 -> 3 | H8: =+H$3 -> 3 | I8: =+I$3 -> 1 | J8: =+J$3 -> 1 | ... V8: =+V$3 -> 0.15
A9: 2 | B9: DAGO BRICE | C9: =+C$3 -> 10 | D9: =+D$3 -> 3 | E9: =+E$3 -> 2 | F9: =+F$3 -> 2 | G9: =+G$3 -> 3 | H9: =+H$3 -> 3 | I9: =+I$3 -> 1 | J9: =+J$3 -> 1 | ... V9: =+V$3 -> 0.15
A10: 3 | B10: KRA K. EVAVARISTE | C10: =+C$3 -> 10 | D10: =+D$3 -> 3 | E10: =+E$3 -> 2 | F10: =+F$3 -> 2 | G10: =+G$3 -> 3 | H10: =+H$3 -> 3 | I10: =+I$3 -> 1 | J10: =+J$3 -> 1 | ... V10: =+V$3 -> 0.15
A11: 4 | B11: DIOMANDE ESTHER | C11: =+C$3 -> 10 | D11: =+D$3 -> 3 | E11: =+E$3 -> 2 | F11: =+F$3 -> 2 | G11: =+G$3 -> 3 | H11: =+H$3 -> 3 | I11: =+I$3 -> 1 | J11: =+J$3 -> 1 | ... V11: =+V$3 -> 0.15
A12: 5 | B12: BADA LANDRY | C12: =+C$3 -> 10 | D12: =+D$3 -> 3 | E12: =+E$3 -> 2 | F12: =+F$3 -> 2 | G12: =+G$3 -> 3 | H12: =+H$3 -> 3 | I12: =+I$3 -> 1 | J12: =+J$3 -> 1 | ... V12: =+V$3 -> 0.15
A13: 6 | B13: KOUAME JOSE | C13: =+C$3 -> 10 | D13: =+D$3 -> 3 | E13: =+E$3 -> 2 | F13: =+F$3 -> 2 | G13: =+G$3 -> 3 | H13: =+H$3 -> 3 | I13: =+I$3 -> 1 | J13: =+J$3 -> 1 | ... V13: =+V$3 -> 0.15
A14: 7 | B14: FANY BARAKISSA | C14: =+C$3 -> 10 | D14: =+D$3 -> 3 | E14: =+E$3 -> 2 | F14: =+F$3 -> 2 | G14: =+G$3 -> 3 | H14: =+H$3 -> 3 | I14: =+I$3 -> 1 | J14: =+J$3 -> 1 | ... V14: =+V$3 -> 0.15
A15: 8 | B15: KONAN IVETTE | C15: =+C$3 -> 10 | D15: =+D$3 -> 3 | E15: =+E$3 -> 2 | F15: =+F$3 -> 2 | G15: =+G$3 -> 3 | H15: =+H$3 -> 3 | I15: =+I$3 -> 1 | J15: =+J$3 -> 1 | ... V15: =+V$3 -> 0.15
A16: 9 | B16: KRA PACOME | C16: =+C$3 -> 10 | D16: =+D$3 -> 3 | E16: =+E$3 -> 2 | F16: =+F$3 -> 2 | G16: =+G$3 -> 3 | H16: =+H$3 -> 3 | I16: =+I$3 -> 1 | J16: =+J$3 -> 1 | ... V16: =+V$3 -> 0.15
A17: 10 | B17: OULAY EMMENUELLA | C17: =+C$3 -> 10 | D17: =+D$3 -> 3 | E17: =+E$3 -> 2 | F17: =+F$3 -> 2 | G17: =+G$3 -> 3 | H17: =+H$3 -> 3 | I17: =+I$3 -> 1 | J17: =+J$3 -> 1 | ... V17: =+V$3 -> 0.15
A18: 11 | B18: KONATE MARIAM | C18: =+C$3 -> 10 | D18: =+D$3 -> 3 | E18: =+E$3 -> 2 | F18: =+F$3 -> 2 | G18: =+G$3 -> 3 | H18: =+H$3 -> 3 | I18: =+I$3 -> 1 | J18: =+J$3 -> 1 | ... V18: =+V$3 -> 0.15
A19: 12 | B19: KOUAME JAURES | C19: =+C$3 -> 10 | D19: =+D$3 -> 3 | E19: =+E$3 -> 2 | F19: =+F$3 -> 2 | G19: =+G$3 -> 3 | H19: =+H$3 -> 3 | I19: =+I$3 -> 1 | J19: =+J$3 -> 1 | ... V19: =+V$3 -> 0.15
... A27: 20 | B27: BERTRAND | C27: =+C$3 -> 10 | D27: =+D$3 -> 3 | E27: =+E$3 -> 2 | F27: =+F$3 -> 2 | G27: =+G$3 -> 3 | H27: =+H$3 -> 3 | I27: =+I$3 -> 1 | J27: =+J$3 -> 1 | ... V27: =+V$3 -> 0.15
B28: TOTAL | C28: =SUM(C8:C27) -> 200 | D28: =SUM(D8:D27) -> 60 | E28: =SUM(E8:E27) -> 40 | F28: =SUM(F8:F27) -> 40 | G28: =SUM(G8:G27) -> 60 | H28: =SUM(H8:H27) -> 60 | I28: =SUM(I8:I27) -> 20 | J28: =SUM(J8:J27) -> 20 | ... BE28: =SUM(BE8:BE27) -> 0

Sheet Jr non travaillé
B2: VILLE
C3: 10 | D3: 3 | E3: 2 | F3: 2 | G3: 3 | H3: 3 | I3: 1 | J3: 1 | K3: 1 | L3: 1 | M3: =+H3 -> 3 | N3: 1 | O3: =+H3 -> 3 | R3: =+(2*M3)/12 -> 0.5 | S3: =+(1*I3)/6 -> 0.16666667 | T3: =+(2*I3)/20 -> 0.1 | U3: =+(2*H3)/10 -> 0.6 | V3: =+(3*I3)/20 -> 0.15
C5: OBJECTIFS JOURNALIERS | W5: REALISATIONS | BD5: Commentaires | BE5: Impressions des PDV et des clients
A6: N° | B6: Agent promoteur | C6: Nombre de visite / Type de PDV | H6: Nombre de référencement / Type de PDV | M6: Pose de matériel de visibilité | R6: Vente en cartons | W6: Nombre de visite / Type de PDV | AB6: Présence produits antérieure | AG6: Nombre de référencement / Type de PDV | AL6: Nouveau Référencement par SKU | AQ6: Vente en cartons | AV6: Pose de matériel de visibilité | BA6: Gratuits offerts en sachet
C7: Boutique | D7: Superette | E7: Kiosque | F7: Tablier | G7: Pushcart | H7: Boutique | I7: Superette | J7: Kiosque | K7: Tablier | L7: Pushcart | M7: Affiche Biblos Lait Prémium 16g & 360g | N7: Affiche Biblos Lait Excellence | O7: Affiche Biblos Flocons d' Avoine | P7: Hanger | Q7: Wobbler | R7: Biblos Lait Premium 16g | S7: Biblos Lait Premium 360g | T7: Biblos Lait Excellence 900g | U7: Biblos Flocon d'avoine 50g | V7: Biblos Flocon d'avoine 400g | W7: Boutique | X7: Superette | Y7: Kiosque | Z7: Tablier | AA7: Pushcart | AB7: Biblos Lait Premium 16g | AC7: Biblos Lait Premium 360g | AD7: Biblos Lait Excellence 900g | AE7: Biblos Flocon d'avoine 50g | AF7: Biblos Flocon d'avoine 400g | AG7: Boutique | AH7: Superette | AI7: Kiosque | AJ7: Tablier | AK7: Pushcart | AL7: Biblos Lait Premium 16g | AM7: Biblos Lait Premium 360g | AN7: Biblos Lait Excellence 900g | AO7: Biblos Flocon d'avoine 50g | AP7: Biblos Flocon d'avoine 400g | AQ7: Biblos Lait Premium 16g | AR7: Biblos Lait Premium 360g | AS7: Biblos Lait Excellence 900g | AT7: Biblos Flocon d'avoine 50g | AU7: Biblos Flocon d'avoine 400g | AV7: Affiche Biblos Lait Prémium 16g & 360g | AW7: Affiche Biblos Lait Excellence | AX7: Affiche Biblos Flocons d' Avoine | AY7: Hanger | AZ7: Wobbler | BA7: Biblos Lait Premium 16g | BB7: Biblos Lait Excellence 900g | BC7: Biblos Flocon d'avoine 50g
A8: 1 | B8: DIBI SIMEON | C8: =+C$3 -> 10 | D8: =+D$3 -> 3 | E8: =+E$3 -> 2 | F8: =+F$3 -> 2 | G8: =+G$3 -> 3 | H8: =+H$3 -> 3 | I8: =+I$3 -> 1 | J8: =+J$3 -> 1 | ... V8: =+V$3 -> 0.15 | W8: 27 | AB8: 1 | AG8: 1+1+5 | AL8: 2 | AO8: 1 | AP8: 5 | AQ8: =5/12 -> 0.41666667 | AT8: 0.4 | AU8: 1 | AV8: 5 | AW8: 5 | AX8: 5
A9: 2 | B9: DAGO BRICE | C9: =+C$3 -> 10 | D9: =+D$3 -> 3 | E9: =+E$3 -> 2 | F9: =+F$3 -> 2 | G9: =+G$3 -> 3 | H9: =+H$3 -> 3 | I9: =+I$3 -> 1 | J9: =+J$3 -> 1 | ... V9: =+V$3 -> 0.15 | W9: 28 | AE9: 1 | AG9: 1+4 | AL9: 1 | AO9: 1 | AP9: 4 | AQ9: =5/12 -> 0.41666667 | AU9: 1 | AV9: 5 | AW9: 5 | AX9: 5
A10: 3 | B10: KRA K. EVAVARISTE | C10: =+C$3 -> 10 | D10: =+D$3 -> 3 | E10: =+E$3 -> 2 | F10: =+F$3 -> 2 | G10: =+G$3 -> 3 | H10: =+H$3 -> 3 | I10: =+I$3 -> 1 | J10: =+J$3 -> 1 | ... V10: =+V$3 -> 0.15 | W10: 29 | AG10: 1+5 | AN10: 1 | AP10: 5 | AS10: =3/20 -> 0.15 | AU10: 1.5 | AV10: 5 | AW10: 5 | AX10: 5
A11: 4 | B11: DIOMANDE ESTHER | C11: =+C$3 -> 10 | D11: =+D$3 -> 3 | E11: =+E$3 -> 2 | F11: =+F$3 -> 2 | G11: =+G$3 -> 3 | H11: =+H$3 -> 3 | I11: =+I$3 -> 1 | J11: =+J$3 -> 1 | ... V11: =+V$3 -> 0.15 | W11: 26 | AG11: 1+1+5 | AL11: 1 | AN11: 1 | AP11: 5 | AQ11: =4/12 -> 0.33333333 | AS11: 0.15 | AU11: 2 | AV11: 5 | AW11: 5 | AX11: 5
A12: 5 | B12: BADA LANDRY | C12: =+C$3 -> 10 | D12: =+D$3 -> 3 | E12: =+E$3 -> 2 | F12: =+F$3 -> 2 | G12: =+G$3 -> 3 | H12: =+H$3 -> 3 | I12: =+I$3 -> 1 | J12: =+J$3 -> 1 | ... V12: =+V$3 -> 0.15 | W12: 29 | AE12: 1 | AG12: 1+2 | AN12: 1 | AO12: 1 | AP12: 2 | AS12: 0.15 | AU12: 1 | AV12: 5 | AW12: 5 | AX12: 5
A13: 6 | B13: KOUAME JOSE | C13: =+C$3 -> 10 | D13: =+D$3 -> 3 | E13: =+E$3 -> 2 | F13: =+F$3 -> 2 | G13: =+G$3 -> 3 | H13: =+H$3 -> 3 | I13: =+I$3 -> 1 | J13: =+J$3 -> 1 | ... V13: =+V$3 -> 0.15 | W13: 27 | AG13: 1+1+1 | AL13: 1 | AO13: 1 | AP13: 1 | AQ13: =5/12 -> 0.41666667 | AT13: 0.6 | AU13: 0.5 | AV13: 5 | AW13: 5 | AX13: 5
A14: 7 | B14: FANY BARAKISSA | C14: =+C$3 -> 10 | D14: =+D$3 -> 3 | E14: =+E$3 -> 2 | F14: =+F$3 -> 2 | G14: =+G$3 -> 3 | H14: =+H$3 -> 3 | I14: =+I$3 -> 1 | J14: =+J$3 -> 1 | ... V14: =+V$3 -> 0.15 | W14: 28 | AG14: 1+3 | AN14: 1 | AP14: 3 | AS14: 0.15 | AU14: 0.5 | AV14: 5 | AW14: 5 | AX14: 5
A15: 8 | B15: KONAN IVETTE | C15: =+C$3 -> 10 | D15: =+D$3 -> 3 | E15: =+E$3 -> 2 | F15: =+F$3 -> 2 | G15: =+G$3 -> 3 | H15: =+H$3 -> 3 | I15: =+I$3 -> 1 | J15: =+J$3 -> 1 | ... V15: =+V$3 -> 0.15 | W15: 25 | AE15: 1 | AG15: 1+1+1+6 | AL15: 1 | AN15: 1 | AO15: 2 | AP15: 6 | AQ15: =5/12 -> 0.41666667 | AS15: 0.15 | AT15: 0.3 | AU15: 2 | AV15: 5 | AW15: 5 | AX15: 5
A16: 9 | B16: KRA PACOME | C16: =+C$3 -> 10 | D16: =+D$3 -> 3 | E16: =+E$3 -> 2 | F16: =+F$3 -> 2 | G16: =+G$3 -> 3 | H16: =+H$3 -> 3 | I16: =+I$3 -> 1 | J16: =+J$3 -> 1 | ... V16: =+V$3 -> 0.15 | W16: 24 | AG16: 1+1+2+5 | AL16: 1 | AN16: 1 | AO16: 2 | AP16: 5 | AQ16: =4/12 -> 0.33333333 | AS16: 0.15 | AT16: 0.5 | AU16: 1.5 | AV16: 5 | AW16: 5 | AX16: 5
A17: 10 | B17: OULAY EMMENUELLA | C17: =+C$3 -> 10 | D17: =+D$3 -> 3 | E17: =+E$3 -> 2 | F17: =+F$3 -> 2 | G17: =+G$3 -> 3 | H17: =+H$3 -> 3 | I17: =+I$3 -> 1 | J17: =+J$3 -> 1 | ... V17: =+V$3 -> 0.15 | W17: 27 | AF17: 1 | AG17: 1 | AL17: 1 | AP17: 1 | AQ17: =5/12 -> 0.41666667 | AV17: 5 | AW17: 5 | AX17: 5
A18: 11 | B18: KONATE MARIAM | C18: =+C$3 -> 10 | D18: =+D$3 -> 3 | E18: =+E$3 -> 2 | F18: =+F$3 -> 2 | G18: =+G$3 -> 3 | H18: =+H$3 -> 3 | I18: =+I$3 -> 1 | J18: =+J$3 -> 1 | ... V18: =+V$3 -> 0.15 | W18: 23 | AB18: 2 | AD18: 1 | AG18: 1+1+1+7 | AL18: 3 | AN18: 2 | AO18: 1 | AP18: 7 | AQ18: =4/12 -> 0.33333333 | AS18: 0.15 | AT18: 0.4 | AU18: 2 | AV18: 5 | AW18: 5 | AX18: 5
A19: 12 | B19: KOUAME JAURES | C19: =+C$3 -> 10 | D19: =+D$3 -> 3 | E19: =+E$3 -> 2 | F19: =+F$3 -> 2 | G19: =+G$3 -> 3 | H19: =+H$3 -> 3 | I19: =+I$3 -> 1 | J19: =+J$3 -> 1 | ... V19: =+V$3 -> 0.15 | W19: 26 | AG19: 1+10 | AN19: 1 | AP19: 10 | AS19: =4/20 -> 0.2 | AU19: 3 | AV19: 5 | AW19: 5 | AX19: 5
A20: 13 | B20: KOUAKOU ADJOUA ROSE | C20: =+C$3 -> 10 | D20: =+D$3 -> 3 | E20: =+E$3 -> 2 | F20: =+F$3 -> 2 | G20: =+G$3 -> 3 | H20: =+H$3 -> 3 | I20: =+I$3 -> 1 | J20: =+J$3 -> 1 | ... V20: =+V$3 -> 0.15 | W20: 24 | AE20: 2 | AG20: 1+4 | AL20: 1 | AO20: 2 | AP20: 4 | AQ20: =5/12 -> 0.41666667 | AU20: 1.5 | AV20: 5 | AW20: 5 | AX20: 5
A21: 14 | B21: OULAY WILFRIED | C21: =+C$3 -> 10 | D21: =+D$3 -> 3 | E21: =+E$3 -> 2 | F21: =+F$3 -> 2 | G21: =+G$3 -> 3 | H21: =+H$3 -> 3 | I21: =+I$3 -> 1 | J21: =+J$3 -> 1 | ... V21: =+V$3 -> 0.15 | W21: 28 | AG21: 1+1+1+3 | AL21: 1 | AN21: 1 | AO21: 1 | AP21: 3 | AQ21: =6/12 -> 0.5 | AS21: 0.15 | AT21: 0.5 | AU21: 1 | AV21: 5 | AW21: 5 | AX21: 5
A22: 15 | B22: TRAORE ARSENE | C22: =+C$3 -> 10 | D22: =+D$3 -> 3 | E22: =+E$3 -> 2 | F22: =+F$3 -> 2 | G22: =+G$3 -> 3 | H22: =+H$3 -> 3 | I22: =+I$3 -> 1 | J22: =+J$3 -> 1 | ... V22: =+V$3 -> 0.15 | W22: 27 | AG22: 1+1 | AL22: 1 | AP22: 1 | AQ22: =5/12 -> 0.41666667 | AU22: 0.5 | AV22: 5 | AW22: 5 | AX22: 5
A23: 16 | B23: NGUESSAN INNOCENT | C23: =+C$3 -> 10 | D23: =+D$3 -> 3 | E23: =+E$3 -> 2 | F23: =+F$3 -> 2 | G23: =+G$3 -> 3 | H23: =+H$3 -> 3 | I23: =+I$3 -> 1 | J23: =+J$3 -> 1 | ... V23: =+V$3 -> 0.15 | W23: 27 | AB23: 1 | AG23: 1+3 | AL23: 1 | AP23: 3 | AQ23: =6/12 -> 0.5 | AU23: 1 | AV23: 5 | AW23: 5 | AX23: 5
A24: 17 | B24: KOUAME ARISTIDE | C24: =+C$3 -> 10 | D24: =+D$3 -> 3 | E24: =+E$3 -> 2 | F24: =+F$3 -> 2 | G24: =+G$3 -> 3 | H24: =+H$3 -> 3 | I24: =+I$3 -> 1 | J24: =+J$3 -> 1 | ... V24: =+V$3 -> 0.15 | W24: 25 | AD24: 1 | AF24: 1 | AG24: 1+1+4 | AN24: 2 | AO24: 1 | AP24: 5 | AS24: 0.15 | AT24: 0.5 | AU24: 1 | AV24: 5 | AW24: 5 | AX24: 5
A25: 18 | B25: GRACE | C25: =+C$3 -> 10 | D25: =+D$3 -> 3 | E25: =+E$3 -> 2 | F25: =+F$3 -> 2 | G25: =+G$3 -> 3 | H25: =+H$3 -> 3 | I25: =+I$3 -> 1 | J25: =+J$3 -> 1 | ... V25: =+V$3 -> 0.15 | W25: 25 | AG25: 1+1+1+8 | AL25: 1 | AN25: 1 | AO25: 1 | AP25: 8 | AQ25: =4/12 -> 0.33333333 | AS25: 0.15 | AT25: 0.4 | AU25: 2 | AV25: 5 | AW25: 5 | AX25: 5
A26: 19 | B26: KOUAME STEPHANIE | C26: =+C$3 -> 10 | D26: =+D$3 -> 3 | E26: =+E$3 -> 2 | F26: =+F$3 -> 2 | G26: =+G$3 -> 3 | H26: =+H$3 -> 3 | I26: =+I$3 -> 1 | J26: =+J$3 -> 1 | ... V26: =+V$3 -> 0.15 | W26: 26 | AF26: 1 | AG26: 1+2 | AL26: 1 | AP26: 3 | AQ26: =5/12 -> 0.41666667 | AU26: 1 | AV26: 5 | AW26: 5 | AX26: 5
A27: 20 | C27: =+C$3 -> 10 | D27: =+D$3 -> 3 | E27: =+E$3 -> 2 | F27: =+F$3 -> 2 | G27: =+G$3 -> 3 | H27: =+H$3 -> 3 | I27: =+I$3 -> 1 | J27: =+J$3 -> 1 | ... V27: =+V$3 -> 0.15 | W27: 25 | AB27: 1 | AE27: 1 | AG27: 1+1+1+3 | AL27: 2 | AN27: 1 | AO27: 2 | AP27: 3 | AQ27: =4/12 -> 0.33333333 | AS27: =6/20 -> 0.3 | AT27: 0.4 | AU27: 1 | AV27: 5 | AW27: 5 | AX27: 5
B28: TOTAL | C28: =SUM(C8:C27) -> 200 | D28: =SUM(D8:D27) -> 60 | E28: =SUM(E8:E27) -> 40 | F28: =SUM(F8:F27) -> 40 | G28: =SUM(G8:G27) -> 60 | H28: =SUM(H8:H27) -> 60 | I28: =SUM(I8:I27) -> 20 | J28: =SUM(J8:J27) -> 20 | ... BE28: =SUM(BE8:BE27) -> 0
AQ30: 6 | AS30: 2 | AT30: 4 | AU30: 25
AQ32: =6*12 -> 72

Sheet Synthèse semaine
B2: VILLE
C3: 10 | D3: 3 | E3: 2 | F3: 2 | G3: 3 | H3: 3 | I3: 1 | J3: 1 | K3: 1 | L3: 1 | M3: =+H3 -> 3 | N3: 1 | O3: =+H3 -> 3 | R3: =+(2*M3)/12 -> 0.5 | S3: =+(1*I3)/6 -> 0.16666667 | T3: =+(2*I3)/20 -> 0.1 | U3: =+(2*H3)/10 -> 0.6 | V3: =+(3*I3)/20 -> 0.15
C5: OBJECTIFS JOURNALIERS | W5: REALISATIONS | BD5: Commentaires | BE5: Impressions des PDV et des clients
A6: N° | B6: Agent promoteur | C6: Nombre de visite / Type de PDV | H6: Nombre de référencement / Type de PDV | M6: Pose de matériel de visibilité | R6: Vente en cartons | W6: Nombre de visite / Type de PDV | AB6: Présence produits antérieure | AG6: Nombre de référencement / Type de PDV | AL6: Nouveau Référencement par SKU | AQ6: Vente en cartons | AV6: Pose de matériel de visibilité | BA6: Gratuits offerts en sachet
C7: Boutique | D7: Superette | E7: Kiosque | F7: Tablier | G7: Pushcart | H7: Boutique | I7: Superette | J7: Kiosque | K7: Tablier | L7: Pushcart | M7: Affiche Biblos Lait Prémium 16g & 360g | N7: Affiche Biblos Lait Excellence | O7: Affiche Biblos Flocons d' Avoine | P7: Hanger | Q7: Wobbler | R7: Biblos Lait Premium 16g | S7: Biblos Lait Premium 360g | T7: Biblos Lait Excellence 900g | U7: Biblos Flocon d'avoine 50g | V7: Biblos Flocon d'avoine 400g | W7: Boutique | X7: Superette | Y7: Kiosque | Z7: Tablier | AA7: Pushcart | AB7: Biblos Lait Premium 16g | AC7: Biblos Lait Premium 360g | AD7: Biblos Lait Excellence 900g | AE7: Biblos Flocon d'avoine 50g | AF7: Biblos Flocon d'avoine 400g | AG7: Boutique | AH7: Superette | AI7: Kiosque | AJ7: Tablier | AK7: Pushcart | AL7: Biblos Lait Premium 16g | AM7: Biblos Lait Premium 360g | AN7: Biblos Lait Excellence 900g | AO7: Biblos Flocon d'avoine 50g | AP7: Biblos Flocon d'avoine 400g | AQ7: Biblos Lait Premium 16g | AR7: Biblos Lait Premium 360g | AS7: Biblos Lait Excellence 900g | AT7: Biblos Flocon d'avoine 50g | AU7: Biblos Flocon d'avoine 400g | AV7: Affiche Biblos Lait Prémium 16g & 360g | AW7: Affiche Biblos Lait Excellence | AX7: Affiche Biblos Flocons d' Avoine | AY7: Hanger | AZ7: Wobbler | BA7: Biblos Lait Premium 16g | BB7: Biblos Lait Excellence 900g | BC7: Biblos Flocon d'avoine 50g
A8: 1 | C8: =+C$3 -> 10 | D8: =+D$3 -> 3 | E8: =+E$3 -> 2 | F8: =+F$3 -> 2 | G8: =+G$3 -> 3 | H8: =+H$3 -> 3 | I8: =+I$3 -> 1 | J8: =+J$3 -> 1 | ... V8: =+V$3 -> 0.15 | W8: =Mercredi!W8+jeudi!W8+Vendredi!W8+Samedii!W8+lundi!W8+'Jr non travaillé'!W8 -> 112 | X8: =Mercredi!X8+jeudi!X8+Vendredi!X8+Samedii!X8+lundi!X8+'Jr non travaillé'!X8 -> 0 | Y8: =Mercredi!Y8+jeudi!Y8+Vendredi!Y8+Samedii!Y8+lundi!Y8+'Jr non travaillé'!Y8 -> 0 | Z8: =Mercredi!Z8+jeudi!Z8+Vendredi!Z8+Samedii!Z8+lundi!Z8+'Jr non travaillé'!Z8 -> 0 | AA8: =Mercredi!AA8+jeudi!AA8+Vendredi!AA8+Samedii!AA8+lundi!AA8+'Jr non travaillé'!AA8 -> 0 | AB8: =Mercredi!AB8+jeudi!AB8+Vendredi!AB8+Samedii!AB8+lundi!AB8+'Jr non travaillé'!AB8 -> 2 | AC8: =Mercredi!AC8+jeudi!AC8+Vendredi!AC8+Samedii!AC8+lundi!AC8+'Jr non travaillé'!AC8 -> 0 | AD8: =Mercredi!AD8+jeudi!AD8+Vendredi!AD8+Samedii!AD8+lundi!AD8+'Jr non travaillé'!AD8 -> 0 | ... BC8: =Mercredi!BC8+jeudi!BC8+Vendredi!BC8+Samedii!BC8+lundi!BC8+'Jr non travaillé'!BC8 -> 95
A9: 2 | C9: =+C$3 -> 10 | D9: =+D$3 -> 3 | E9: =+E$3 -> 2 | F9: =+F$3 -> 2 | G9: =+G$3 -> 3 | H9: =+H$3 -> 3 | I9: =+I$3 -> 1 | J9: =+J$3 -> 1 | ... V9: =+V$3 -> 0.15 | W9: =Mercredi!W9+jeudi!W9+Vendredi!W9+Samedii!W9+lundi!W9+'Jr non travaillé'!W9 -> 124 | X9: =Mercredi!X9+jeudi!X9+Vendredi!X9+Samedii!X9+lundi!X9+'Jr non travaillé'!X9 -> 0 | Y9: =Mercredi!Y9+jeudi!Y9+Vendredi!Y9+Samedii!Y9+lundi!Y9+'Jr non travaillé'!Y9 -> 0 | Z9: =Mercredi!Z9+jeudi!Z9+Vendredi!Z9+Samedii!Z9+lundi!Z9+'Jr non travaillé'!Z9 -> 0 | AA9: =Mercredi!AA9+jeudi!AA9+Vendredi!AA9+Samedii!AA9+lundi!AA9+'Jr non travaillé'!AA9 -> 0 | AB9: =Mercredi!AB9+jeudi!AB9+Vendredi!AB9+Samedii!AB9+lundi!AB9+'Jr non travaillé'!AB9 -> 0 | AC9: =Mercredi!AC9+jeudi!AC9+Vendredi!AC9+Samedii!AC9+lundi!AC9+'Jr non travaillé'!AC9 -> 0 | AD9: =Mercredi!AD9+jeudi!AD9+Vendredi!AD9+Samedii!AD9+lundi!AD9+'Jr non travaillé'!AD9 -> 1 | ... BC9: =Mercredi!BC9+jeudi!BC9+Vendredi!BC9+Samedii!BC9+lundi!BC9+'Jr non travaillé'!BC9 -> 93
